Workbook

Sheet Main
B2: ADBE | C2: Statements as of Q3 FY26 (8/28/26)
B3: Price | C3: 293.12
B4: Shares | C4: 395
B5: Market Cap | C5: =C3*C4 -> 115782.4
B6: Cash | C6: 5639
B7: Debt | C7: 6363
B8: EV | C8: =C5+C7-C6 -> 116506.4
B10: Chair & CEO: | C10: Shantanu Narayen
B11: Interim CFO: | C11: Steve Day
B13: Segments
B14: Segment | C14: Description
B15: ='Digital Media'!C2 -> Digital Media | C15: ='Digital Media'!C3 -> Adobe's largest segment: Creative Cloud (Photoshop, Illustrator, Premiere Pro, Firefly, etc.) and Document Cloud (Acrobat, Acrobat Sign).
B16: ='Digital Experience'!C2 -> Digital Experience | C16: ='Digital Experience'!C3 -> Adobe Experience Cloud: enterprise platform and applications for customer experience management, analytics, and commerce.
B17: ='Publishing and Advertising'!C2 -> Publishing and Advertising | C17: ='Publishing and Advertising'!C3 -> Legacy products/services: eLearning, technical document publishing, web conferencing, and (through FY23) Adobe Advertising Cloud.

Sheet 10QIS
B2: Adobe Inc. (ADBE)
B4: Historic Quarterly Income Statement | C4: Q1'20 | D4: Q2'20 | E4: Q3'20 | F4: Q4'20 | G4: Q1'21 | H4: Q2'21 | I4: Q3'21 | J4: Q4'21 | K4: Q1'22 | L4: Q2'22 | M4: Q3'22 | N4: Q4'22 | O4: Q1'23 | P4: Q2'23 | Q4: Q3'23 | R4: Q4'23 | S4: Q1'24 | T4: Q2'24 | U4: Q3'24 | V4: Q4'24 | W4: Q1'25 | X4: Q2'25 | Y4: Q3'25 | Z4: Q4'25 | AA4: Q1'26 | AB4: Q2'26 | AC4: Q3'26
B5: Subscription Revenue | C5: 2732 | D5: 2831 | E5: 2948 | F5: =11626-C5-D5-E5 -> 3115 | G5: 3584 | H5: 3520 | I5: 3657 | J5: =14573-G5-H5-I5 -> 3812 | K5: 3958 | L5: 4070 | M5: 4128 | N5: =16388-K5-L5-M5 -> 4232 | O5: 4373 | P5: 4517 | Q5: 4631 | R5: 4763 | S5: 4916 | T5: 5060 | U5: 5180 | V5: =20521-S5-T5-U5 -> 5365 | W5: 5483 | X5: 5641 | Y5: 5791 | Z5: =22904-W5-X5-Y5 -> 5989 | AA5: 6198 | AB5: 6416 | AC5: 6582
B6: Product Revenue | C6: 143 | D6: 128 | E6: 109 | F6: =507-C6-D6-E6 -> 127 | G6: 155 | H6: 153 | I6: 119 | J6: =555-G6-H6-I6 -> 128 | K6: 145 | L6: 146 | M6: 126 | N6: =532-K6-L6-M6 -> 115 | O6: 120 | P6: 130 | Q6: 96 | R6: 114 | S6: 119 | T6: 104 | U6: 82 | V6: =386-S6-T6-U6 -> 81 | W6: 95 | X6: 88 | Y6: 68 | Z6: =325-W6-X6-Y6 -> 74 | AA6: 90 | AB6: 89 | AC6: 67
B7: Services and Other Revenue | C7: 216 | D7: 169 | E7: 168 | F7: =735-C7-D7-E7 -> 182 | G7: 166 | H7: 162 | I7: 159 | J7: =657-G7-H7-I7 -> 170 | K7: 159 | L7: 170 | M7: 179 | N7: =686-K7-L7-M7 -> 178 | O7: 162 | P7: 169 | Q7: 163 | R7: 171 | S7: 147 | T7: 145 | U7: 146 | V7: =598-S7-T7-U7 -> 160 | W7: 136 | X7: 144 | Y7: 129 | Z7: =540-W7-X7-Y7 -> 131 | AA7: 110 | AB7: 113 | AC7: 111
B8: Total Revenue | C8: =C5+C6+C7 -> 3091 | D8: =D5+D6+D7 -> 3128 | E8: =E5+E6+E7 -> 3225 | F8: =F5+F6+F7 -> 3424 | G8: =G5+G6+G7 -> 3905 | H8: =H5+H6+H7 -> 3835 | I8: =I5+I6+I7 -> 3935 | J8: =J5+J6+J7 -> 4110 | ... AC8: =AC5+AC6+AC7 -> 6760
B9: Total Cost of Revenue | C9: 452 | D9: 415 | E9: 427 | F9: =1722-C9-D9-E9 -> 428 | G9: 447 | H9: 444 | I9: 467 | J9: =1865-G9-H9-I9 -> 507 | K9: 512 | L9: 539 | M9: 546 | N9: =2165-K9-L9-M9 -> 568 | O9: 568 | P9: 572 | Q9: 580 | R9: 634 | S9: 590 | T9: 598 | U9: 554 | V9: =2358-S9-T9-U9 -> 616 | W9: 622 | X9: 638 | Y9: 642 | Z9: =2551-W9-X9-Y9 -> 649 | AA9: 664 | AB9: 715 | AC9: 763
B10: Gross Profit | C10: =C8-C9 -> 2639 | D10: =D8-D9 -> 2713 | E10: =E8-E9 -> 2798 | F10: =F8-F9 -> 2996 | G10: =G8-G9 -> 3458 | H10: =H8-H9 -> 3391 | I10: =I8-I9 -> 3468 | J10: =J8-J9 -> 3603 | ... AC10: =AC8-AC9 -> 5997
B11: Research and Development | C11: 532 | D11: 532 | E11: 566 | F11: =2188-C11-D11-E11 -> 558 | G11: 620 | H11: 612 | I11: 651 | J11: =2540-G11-H11-I11 -> 657 | K11: 701 | L11: 738 | M11: 775 | N11: =2987-K11-L11-M11 -> 773 | O11: 827 | P11: 876 | Q11: 881 | R11: 889 | S11: 939 | T11: 984 | U11: 1022 | V11: =3944-S11-T11-U11 -> 999 | W11: 1026 | X11: 1082 | Y11: 1088 | Z11: =4294-W11-X11-Y11 -> 1098 | AA11: 1110 | AB11: 1198 | AC11: 1288
B12: Sales and Marketing | C12: 857 | D12: 901 | E12: 892 | F12: =3591-C12-D12-E12 -> 941 | G12: 1049 | H12: 1073 | I12: 1068 | J12: =4321-G12-H12-I12 -> 1131 | K12: 1158 | L12: 1247 | M12: 1266 | N12: =4968-K12-L12-M12 -> 1297 | O12: 1301 | P12: 1345 | Q12: 1337 | R12: 1368 | S12: 1352 | T12: 1445 | U12: 1431 | V12: =5764-S12-T12-U12 -> 1536 | W12: 1495 | X12: 1626 | Y12: 1639 | Z12: =6488-W12-X12-Y12 -> 1728 | AA12: 1708 | AB12: 1884 | AC12: 1827
B13: General and Administrative | C13: 271 | D13: 224 | E13: 230 | F13: =968-C13-D13-E13 -> 243 | G13: 290 | H13: 256 | I13: 265 | J13: =1085-G13-H13-I13 -> 274 | K13: 269 | L13: 291 | M13: 319 | N13: =1219-K13-L13-M13 -> 340 | O13: 331 | P13: 357 | Q13: 353 | R13: 372 | S13: 352 | T13: 355 | U13: 366 | V13: =1529-S13-T13-U13 -> 456 | W13: 367 | X13: 377 | Y13: 408 | Z13: =1573-W13-X13-Y13 -> 421 | AA13: 463 | AB13: 546 | AC13: 488
B14: Acquisition Termination Fee | C14: 0 | D14: 0 | E14: 0 | F14: =0-C14-D14-E14 -> 0 | G14: 0 | H14: 0 | I14: 0 | J14: =0-G14-H14-I14 -> 0 | K14: 0 | L14: 0 | M14: 0 | N14: =0-K14-L14-M14 -> 0 | O14: 0 | P14: 0 | Q14: 0 | R14: 0 | S14: 1000 | T14: 0 | U14: 0 | V14: =1000-S14-T14-U14 -> 0 | W14: 0 | X14: 0 | Y14: 0 | Z14: =0-W14-X14-Y14 -> 0 | AA14: 0 | AB14: 0 | AC14: 0
B15: Amortization of Intangibles | C15: 42 | D15: 40 | E15: 41 | F15: =162-C15-D15-E15 -> 39 | G15: 45 | H15: 44 | I15: 43 | J15: =172-G15-H15-I15 -> 40 | K15: 42 | L15: 42 | M15: 43 | N15: =169-K15-L15-M15 -> 42 | O15: 42 | P15: 42 | Q15: 42 | R15: 42 | S15: 42 | T15: 42 | U15: 43 | V15: =169-S15-T15-U15 -> 42 | W15: 41 | X15: 41 | Y15: 38 | Z15: =157-W15-X15-Y15 -> 37 | AA15: 35 | AB15: 37 | AC15: 40
B16: Total Operating Expenses | C16: =SUM(C11:C15) -> 1702 | D16: =SUM(D11:D15) -> 1697 | E16: =SUM(E11:E15) -> 1729 | F16: =SUM(F11:F15) -> 1781 | G16: =SUM(G11:G15) -> 2004 | H16: =SUM(H11:H15) -> 1985 | I16: =SUM(I11:I15) -> 2027 | J16: =SUM(J11:J15) -> 2102 | ... AC16: =SUM(AC11:AC15) -> 3643
B17: Operating Income | C17: =C10-C16 -> 937 | D17: =D10-D16 -> 1016 | E17: =E10-E16 -> 1069 | F17: =F10-F16 -> 1215 | G17: =G10-G16 -> 1454 | H17: =H10-H16 -> 1406 | I17: =I10-I16 -> 1441 | J17: =J10-J16 -> 1501 | ... AC17: =AC10-AC16 -> 2354
B18: Total Non-Operating Income (Expense), net | C18: -18 | D18: -16 | E18: -9 | F18: =-61-C18-D18-E18 -> -18 | G18: -21 | H18: -20 | I18: -23 | J18: =-97-G18-H18-I18 -> -33 | K18: -37 | L18: -37 | M18: -28 | N18: =-90-K18-L18-M18 -> 12 | O18: 12 | P18: 26 | Q18: 46 | R18: 65 | S18: 61 | T18: 45 | U18: 50 | V18: =190-S18-T18-U18 -> 34 | W18: 19 | X18: -8 | Y18: 14 | Z18: =28-W18-X18-Y18 -> 3 | AA18: 4 | AB18: 0 | AC18: 3
B19: Income Before Income Taxes | C19: =C17+C18 -> 919 | D19: =D17+D18 -> 1000 | E19: =E17+E18 -> 1060 | F19: =F17+F18 -> 1197 | G19: =G17+G18 -> 1433 | H19: =H17+H18 -> 1386 | I19: =I17+I18 -> 1418 | J19: =J17+J18 -> 1468 | ... AC19: =AC17+AC18 -> 2357
B20: Provision for Income Taxes | C20: -36 | D20: -100 | E20: 105 | F20: =-1084-C20-D20-E20 -> -1053 | G20: 172 | H20: 270 | I20: 206 | J20: =883-G20-H20-I20 -> 235 | K20: 277 | L20: 314 | M20: 320 | N20: =1252-K20-L20-M20 -> 341 | O20: 351 | P20: 355 | Q20: 340 | R20: 325 | S20: 348 | T20: 357 | U20: 358 | V20: =1371-S20-T20-U20 -> 308 | W20: 371 | X20: 410 | Y20: 415 | Z20: =1604-W20-X20-Y20 -> 408 | AA20: 533 | AB20: 526 | AC20: 530
B21: Net Income | C21: =C19-C20 -> 955 | D21: =D19-D20 -> 1100 | E21: =E19-E20 -> 955 | F21: =F19-F20 -> 2250 | G21: =G19-G20 -> 1261 | H21: =H19-H20 -> 1116 | I21: =I19-I20 -> 1212 | J21: =J19-J20 -> 1233 | ... AC21: =AC19-AC20 -> 1827
B22: Diluted Shares | C22: 488 | D22: 485 | E22: 485 | F22: 484 | G22: 483 | H22: 481 | I22: 481 | J22: 480 | K22: 475 | L22: 473 | M22: 469 | N22: 466 | O22: 460 | P22: 459 | Q22: 459 | R22: 459 | S22: 456 | T22: 451 | U22: 448 | V22: 443 | W22: 438 | X22: 429 | Y22: 424 | Z22: 417 | AA22: 411 | AB22: 402 | AC22: 395
B23: Diluted EPS | C23: 1.96 | D23: 2.27 | E23: 1.97 | F23: 4.64 | G23: 2.61 | H23: 2.32 | I23: 2.52 | J23: 2.57 | K23: 2.66 | L23: 2.49 | M23: 2.42 | N23: 2.53 | O23: 2.71 | P23: 2.82 | Q23: 3.05 | R23: 3.23 | S23: 1.36 | T23: 3.49 | U23: 3.76 | V23: 3.79 | W23: 4.14 | X23: 3.94 | Y23: 4.18 | Z23: 4.45 | AA23: 4.6 | AB23: 4.25 | AC23: 4.62
B25: Historic Drivers
B26: Subscription Revenue Growth Rate | G26: =IFERROR(G5/C5-1,"") -> 0.31185944 | H26: =IFERROR(H5/D5-1,"") -> 0.2433769 | I26: =IFERROR(I5/E5-1,"") -> 0.24050204 | J26: =IFERROR(J5/F5-1,"") -> 0.22375602 | K26: =IFERROR(K5/G5-1,"") -> 0.10435268 | L26: =IFERROR(L5/H5-1,"") -> 0.15625 | M26: =IFERROR(M5/I5-1,"") -> 0.12879409 | N26: =IFERROR(N5/J5-1,"") -> 0.11017838 | ... AC26: =IFERROR(AC5/Y5-1,"") -> 0.13659126
B27: Product Revenue Growth Rate | G27: =IFERROR(G6/C6-1,"") -> 0.083916084 | H27: =IFERROR(H6/D6-1,"") -> 0.1953125 | I27: =IFERROR(I6/E6-1,"") -> 0.091743119 | J27: =IFERROR(J6/F6-1,"") -> 0.0078740157 | K27: =IFERROR(K6/G6-1,"") -> -0.064516129 | L27: =IFERROR(L6/H6-1,"") -> -0.045751634 | M27: =IFERROR(M6/I6-1,"") -> 0.058823529 | N27: =IFERROR(N6/J6-1,"") -> -0.1015625 | ... AC27: =IFERROR(AC6/Y6-1,"") -> -0.014705882
B28: Service and Other Revenue Growth Rate | G28: =IFERROR(G7/C7-1,"") -> -0.23148148 | H28: =IFERROR(H7/D7-1,"") -> -0.041420118 | I28: =IFERROR(I7/E7-1,"") -> -0.053571429 | J28: =IFERROR(J7/F7-1,"") -> -0.065934066 | K28: =IFERROR(K7/G7-1,"") -> -0.042168675 | L28: =IFERROR(L7/H7-1,"") -> 0.049382716 | M28: =IFERROR(M7/I7-1,"") -> 0.12578616 | N28: =IFERROR(N7/J7-1,"") -> 0.047058824 | ... AC28: =IFERROR(AC7/Y7-1,"") -> -0.13953488
B29: Total Revenue Growth Rate (YoY) | G29: =IFERROR(G8/C8-1,"") -> 0.2633452 | H29: =IFERROR(H8/D8-1,"") -> 0.22602302 | I29: =IFERROR(I8/E8-1,"") -> 0.22015504 | J29: =IFERROR(J8/F8-1,"") -> 0.20035047 | K29: =IFERROR(K8/G8-1,"") -> 0.091421255 | L29: =IFERROR(L8/H8-1,"") -> 0.14367666 | M29: =IFERROR(M8/I8-1,"") -> 0.12655654 | N29: =IFERROR(N8/J8-1,"") -> 0.10097324 | ... AC29: =IFERROR(AC8/Y8-1,"") -> 0.12892452
B30: Gross Margin % | C30: =IFERROR(C10/C8,"") -> 0.85376901 | D30: =IFERROR(D10/D8,"") -> 0.86732737 | E30: =IFERROR(E10/E8,"") -> 0.8675969 | F30: =IFERROR(F10/F8,"") -> 0.875 | G30: =IFERROR(G10/G8,"") -> 0.88553137 | H30: =IFERROR(H10/H8,"") -> 0.88422425 | I30: =IFERROR(I10/I8,"") -> 0.88132147 | J30: =IFERROR(J10/J8,"") -> 0.87664234 | ... AC30: =IFERROR(AC10/AC8,"") -> 0.88713018
B31: R&D % of Revenue | C31: =IFERROR(C11/C8,"") -> 0.17211258 | D31: =IFERROR(D11/D8,"") -> 0.17007673 | E31: =IFERROR(E11/E8,"") -> 0.17550388 | F31: =IFERROR(F11/F8,"") -> 0.16296729 | G31: =IFERROR(G11/G8,"") -> 0.15877081 | H31: =IFERROR(H11/H8,"") -> 0.15958279 | I31: =IFERROR(I11/I8,"") -> 0.16543837 | J31: =IFERROR(J11/J8,"") -> 0.15985401 | ... AC31: =IFERROR(AC11/AC8,"") -> 0.19053254
B32: S&M % of Revenue | C32: =IFERROR(C12/C8,"") -> 0.27725655 | D32: =IFERROR(D12/D8,"") -> 0.28804348 | E32: =IFERROR(E12/E8,"") -> 0.27658915 | F32: =IFERROR(F12/F8,"") -> 0.27482477 | G32: =IFERROR(G12/G8,"") -> 0.26862996 | H32: =IFERROR(H12/H8,"") -> 0.2797914 | I32: =IFERROR(I12/I8,"") -> 0.27141042 | J32: =IFERROR(J12/J8,"") -> 0.27518248 | ... AC32: =IFERROR(AC12/AC8,"") -> 0.27026627
B33: G&A % of Revenue | C33: =IFERROR(C13/C8,"") -> 0.087673892 | D33: =IFERROR(D13/D8,"") -> 0.071611253 | E33: =IFERROR(E13/E8,"") -> 0.071317829 | F33: =IFERROR(F13/F8,"") -> 0.070969626 | G33: =IFERROR(G13/G8,"") -> 0.074263764 | H33: =IFERROR(H13/H8,"") -> 0.066753585 | I33: =IFERROR(I13/I8,"") -> 0.067344346 | J33: =IFERROR(J13/J8,"") -> 0.066666667 | ... AC33: =IFERROR(AC13/AC8,"") -> 0.072189349
B34: Effective Tax Rate | C34: =IFERROR(C20/C19,"") -> -0.039173014 | D34: =IFERROR(D20/D19,"") -> -0.1 | E34: =IFERROR(E20/E19,"") -> 0.099056604 | F34: =IFERROR(F20/F19,"") -> -0.87969925 | G34: =IFERROR(G20/G19,"") -> 0.12002791 | H34: =IFERROR(H20/H19,"") -> 0.19480519 | I34: =IFERROR(I20/I19,"") -> 0.14527504 | J34: =IFERROR(J20/J19,"") -> 0.16008174 | ... AC34: =IFERROR(AC20/AC19,"") -> 0.22486211

Sheet IS
B2: IS Assumptions | C2: =C15 -> FY'19 | D2: =D15 -> FY'20 | E2: =E15 -> FY'21 | F2: =F15 -> FY'22 | G2: =G15 -> FY'23 | H2: =H15 -> FY'24 | I2: =I15 -> FY'25 | J2: =J15 -> FY'26 | ... N2: =N15 -> FY'30
B3: Subscription Revenue Growth Rate | D3: =(D16-C16)/C16 -> 0.2067677 | E3: =(E16-D16)/D16 -> 0.25348357 | F3: =(F16-E16)/E16 -> 0.12454539 | G3: =(G16-F16)/F16 -> 0.11569441 | H3: =(H16-G16)/G16 -> 0.12234741 | I3: =(I16-H16)/H16 -> 0.11612495 | J3: 0.11 | K3: =J3 -> 0.11 | L3: =K3 -> 0.11 | M3: =L3 -> 0.11 | N3: =M3 -> 0.11
B4: Product Revenue Growth Rate | D4: =(D17-C17)/C17 -> -0.21759259 | E4: =(E17-D17)/D17 -> 0.094674556 | F4: =(F17-E17)/E17 -> -0.041441441 | G4: =(G17-F17)/F17 -> -0.13533835 | H4: =(H17-G17)/G17 -> -0.16086957 | I4: =(I17-H17)/H17 -> -0.15803109 | J4: -0.15 | K4: =J4 -> -0.15 | L4: =K4 -> -0.15 | M4: =L4 -> -0.15 | N4: =M4 -> -0.15
B5: Services and Other Revenue Growth Rate | D5: =(D18-C18)/C18 -> -0.17322835 | E5: =(E18-D18)/D18 -> -0.10612245 | F5: =(F18-E18)/E18 -> 0.04414003 | G5: =(G18-F18)/F18 -> -0.030612245 | H5: =(H18-G18)/G18 -> -0.10075188 | I5: =(I18-H18)/H18 -> -0.096989967 | J5: -0.1 | K5: =J5 -> -0.1 | L5: =K5 -> -0.1 | M5: =L5 -> -0.1 | N5: =M5 -> -0.1
B6: Total Revenue Growth Rate | D6: =(D19-C19)/C19 -> 0.1519112 | E6: =(E19-D19)/D19 -> 0.22668635 | F6: =(F19-E19)/E19 -> 0.11536269 | G6: =(G19-F19)/F19 -> 0.10240827 | H6: =(H19-G19)/G19 -> 0.10799114 | I6: =(I19-H19)/H19 -> 0.10527784
B7: Gross Margin % | C7: =C21/C19 -> 0.85023722 | D7: =D21/D19 -> 0.86617967 | E7: =E21/E19 -> 0.88184986 | F7: =F21/F19 -> 0.87703056 | G7: =G21/G19 -> 0.87871606 | H7: =H21/H19 -> 0.89035108 | I7: =I21/I19 -> 0.89267533 | J7: 0.895 | K7: 0.8975 | L7: 0.9 | M7: 0.9 | N7: 0.9
B8: R&D % of Revenue | C8: =C22/C19 -> 0.17276878 | D8: =D22/D19 -> 0.17003419 | E8: =E22/E19 -> 0.16091226 | F8: =F22/F19 -> 0.16965807 | G8: =G22/G19 -> 0.17893761 | H8: =H22/H19 -> 0.18339921 | I8: =I22/I19 -> 0.18065548 | J8: 0.18 | K8: =J8 -> 0.18 | L8: =K8 -> 0.18 | M8: =L8 -> 0.18 | N8: =M8 -> 0.18
B9: S&M % of Revenue | C9: =C23/C19 -> 0.29039477 | D9: =D23/D19 -> 0.27906435 | E9: =E23/E19 -> 0.27374089 | F9: =F23/F19 -> 0.28217653 | G9: =G23/G19 -> 0.27569684 | H9: =H23/H19 -> 0.26803069 | I9: =I23/I19 -> 0.27296058 | J9: 0.275 | K9: =J9 -> 0.275 | L9: =K9 -> 0.275 | M9: =L9 -> 0.275 | N9: =M9 -> 0.275
B10: G&A % of Revenue | C10: =C24/C19 -> 0.078864918 | D10: =D24/D19 -> 0.075225365 | E10: =E24/E19 -> 0.068736142 | F10: =F24/F19 -> 0.06923776 | G10: =G24/G19 -> 0.072801278 | H10: =H24/H19 -> 0.071099744 | I10: =I24/I19 -> 0.066178636 | J10: 0.065 | K10: =J10 -> 0.065 | L10: =K10 -> 0.065 | M10: =L10 -> 0.065 | N10: =M10 -> 0.065
B11: Amortization of Intangibles % of Revenue | C11: =C26/C19 -> 0.015665563 | D11: =D26/D19 -> 0.012589369 | E11: =E26/E19 -> 0.010896421 | F11: =F26/F19 -> 0.0095990003 | G11: =G26/G19 -> 0.0086557782 | H11: =H26/H19 -> 0.0078586375 | I11: =I26/I19 -> 0.0066052421 | J11: 0.07 | K11: =J11 -> 0.07 | L11: 0.06 | M11: 0.05 | N11: 0.04
B12: Effective Tax Rate | C12: =C31/C30 -> 0.07925117 | D12: =D31/D30 -> -0.25957854 | E12: =E31/E30 -> 0.15477651 | F12: =F31/F30 -> 0.20838881 | G12: =G31/G30 -> 0.2016473 | H12: =H31/H30 -> 0.19780695 | I12: =I31/I30 -> 0.1836501 | J12: 0.213 | K12: =J12 -> 0.213 | L12: =K12 -> 0.213 | M12: =L12 -> 0.213 | N12: =M12 -> 0.213
B15: Annual Income Statement | C15: FY'19 | D15: FY'20 | E15: FY'21 | F15: FY'22 | G15: FY'23 | H15: FY'24 | I15: FY'25 | J15: FY'26 | K15: FY'27 | L15: FY'28 | M15: FY'29 | N15: FY'30
B16: Subscription Revenue | C16: 9634 | D16: =SUM('10QIS'!C5:F5) -> 11626 | E16: =SUM('10QIS'!G5:J5) -> 14573 | F16: =SUM('10QIS'!K5:N5) -> 16388 | G16: =SUM('10QIS'!O5:R5) -> 18284 | H16: =SUM('10QIS'!S5:V5) -> 20521 | I16: =SUM('10QIS'!W5:Z5) -> 22904 | J16: =I16*(1+J3) -> 25423.44 | K16: =J16*(1+K3) -> 28220.018 | L16: =K16*(1+L3) -> 31324.22 | M16: =L16*(1+M3) -> 34769.885 | N16: =M16*(1+N3) -> 38594.572
B17: Product Revenue | C17: 648 | D17: =SUM('10QIS'!C6:F6) -> 507 | E17: =SUM('10QIS'!G6:J6) -> 555 | F17: =SUM('10QIS'!K6:N6) -> 532 | G17: =SUM('10QIS'!O6:R6) -> 460 | H17: =SUM('10QIS'!S6:V6) -> 386 | I17: =SUM('10QIS'!W6:Z6) -> 325 | J17: =I17*(1+J4) -> 276.25 | K17: =J17*(1+K4) -> 234.8125 | L17: =K17*(1+L4) -> 199.59062 | M17: =L17*(1+M4) -> 169.65203 | N17: =M17*(1+N4) -> 144.20423
B18: Services and Other Revenue | C18: 889 | D18: =SUM('10QIS'!C7:F7) -> 735 | E18: =SUM('10QIS'!G7:J7) -> 657 | F18: =SUM('10QIS'!K7:N7) -> 686 | G18: =SUM('10QIS'!O7:R7) -> 665 | H18: =SUM('10QIS'!S7:V7) -> 598 | I18: =SUM('10QIS'!W7:Z7) -> 540 | J18: =I18*(1+J5) -> 486 | K18: =J18*(1+K5) -> 437.4 | L18: =K18*(1+L5) -> 393.66 | M18: =L18*(1+M5) -> 354.294 | N18: =M18*(1+N5) -> 318.8646
B19: Total Revenue | C19: =SUM(C16:C18) -> 11171 | D19: =SUM(D16:D18) -> 12868 | E19: =SUM(E16:E18) -> 15785 | F19: =SUM(F16:F18) -> 17606 | G19: =SUM(G16:G18) -> 19409 | H19: =SUM(H16:H18) -> 21505 | I19: =SUM(I16:I18) -> 23769 | J19: =SUM(J16:J18) -> 26185.69 | ... N19: =SUM(N16:N18) -> 39057.641
B20: Total Cost of Revenue | C20: 1673 | D20: =SUM('10QIS'!C9:F9) -> 1722 | E20: =SUM('10QIS'!G9:J9) -> 1865 | F20: =SUM('10QIS'!K9:N9) -> 2165 | G20: =SUM('10QIS'!O9:R9) -> 2354 | H20: =SUM('10QIS'!S9:V9) -> 2358 | I20: =SUM('10QIS'!W9:Z9) -> 2551 | J20: =J19-J21 -> 2749.4974 | K20: =K19-K21 -> 2961.4537 | L20: =L19-L21 -> 3191.7471 | M20: =M19-M21 -> 3529.3831 | N20: =N19-N21 -> 3905.7641
B21: Gross Profit | C21: =C19-C20 -> 9498 | D21: =D19-D20 -> 11146 | E21: =E19-E20 -> 13920 | F21: =F19-F20 -> 15441 | G21: =G19-G20 -> 17055 | H21: =H19-H20 -> 19147 | I21: =I19-I20 -> 21218 | J21: =J19*J7 -> 23436.193 | K21: =K19*K7 -> 25930.777 | L21: =L19*L7 -> 28725.724 | M21: =M19*M7 -> 31764.448 | N21: =N19*N7 -> 35151.877
B22: Research and Development | C22: 1930 | D22: =SUM('10QIS'!C11:F11) -> 2188 | E22: =SUM('10QIS'!G11:J11) -> 2540 | F22: =SUM('10QIS'!K11:N11) -> 2987 | G22: =SUM('10QIS'!O11:R11) -> 3473 | H22: =SUM('10QIS'!S11:V11) -> 3944 | I22: =SUM('10QIS'!W11:Z11) -> 4294 | J22: =J19*J8 -> 4713.4242 | K22: =K19*K8 -> 5200.6016 | L22: =L19*L8 -> 5745.1448 | M22: =M19*M8 -> 6352.8895 | N22: =N19*N8 -> 7030.3753
B23: Sales and Marketing | C23: 3244 | D23: =SUM('10QIS'!C12:F12) -> 3591 | E23: =SUM('10QIS'!G12:J12) -> 4321 | F23: =SUM('10QIS'!K12:N12) -> 4968 | G23: =SUM('10QIS'!O12:R12) -> 5351 | H23: =SUM('10QIS'!S12:V12) -> 5764 | I23: =SUM('10QIS'!W12:Z12) -> 6488 | J23: =J19*J9 -> 7201.0648 | K23: =K19*K9 -> 7945.3635 | L23: =L19*L9 -> 8777.3045 | M23: =M19*M9 -> 9705.8034 | N23: =N19*N9 -> 10740.851
B24: General and Administrative | C24: 881 | D24: =SUM('10QIS'!C13:F13) -> 968 | E24: =SUM('10QIS'!G13:J13) -> 1085 | F24: =SUM('10QIS'!K13:N13) -> 1219 | G24: =SUM('10QIS'!O13:R13) -> 1413 | H24: =SUM('10QIS'!S13:V13) -> 1529 | I24: =SUM('10QIS'!W13:Z13) -> 1573 | J24: =J19*J10 -> 1702.0699 | K24: =K19*K10 -> 1877.995 | L24: =L19*L10 -> 2074.6356 | M24: =M19*M10 -> 2294.099 | N24: =N19*N10 -> 2538.7467
B25: Acquisition Termination Fee | C25: 0 | D25: =SUM('10QIS'!C14:F14) -> 0 | E25: =SUM('10QIS'!G14:J14) -> 0 | F25: =SUM('10QIS'!K14:N14) -> 0 | G25: =SUM('10QIS'!O14:R14) -> 0 | H25: =SUM('10QIS'!S14:V14) -> 1000 | I25: =SUM('10QIS'!W14:Z14) -> 0 | J25: 0 | K25: 0 | L25: 0 | M25: 0 | N25: 0
B26: Amortization of Intangibles | C26: 175 | D26: =SUM('10QIS'!C15:F15) -> 162 | E26: =SUM('10QIS'!G15:J15) -> 172 | F26: =SUM('10QIS'!K15:N15) -> 169 | G26: =SUM('10QIS'!O15:R15) -> 168 | H26: =SUM('10QIS'!S15:V15) -> 169 | I26: =SUM('10QIS'!W15:Z15) -> 157 | J26: =J19*J11 -> 1832.9983 | K26: =K19*K11 -> 2022.4562 | L26: =L19*L11 -> 1915.0483 | M26: =M19*M11 -> 1764.6915 | N26: =N19*N11 -> 1562.3056
B27: Total Operating Expenses | C27: =SUM(C22:C26) -> 6230 | D27: =SUM(D22:D26) -> 6909 | E27: =SUM(E22:E26) -> 8118 | F27: =SUM(F22:F26) -> 9343 | G27: =SUM(G22:G26) -> 10405 | H27: =SUM(H22:H26) -> 12406 | I27: =SUM(I22:I26) -> 12512 | J27: =SUM(J22:J26) -> 15449.557 | ... N27: =SUM(N22:N26) -> 21872.279
B28: Operating Income | C28: =C21-C27 -> 3268 | D28: =D21-D27 -> 4237 | E28: =E21-E27 -> 5802 | F28: =F21-F27 -> 6098 | G28: =G21-G27 -> 6650 | H28: =H21-H27 -> 6741 | I28: =I21-I27 -> 8706 | J28: =J21-J27 -> 7986.6354 | ... N28: =N21-N27 -> 13279.598
B29: Total Non-Operating Income (Expense), net | C29: -63 | D29: =SUM('10QIS'!C18:F18) -> -61 | E29: =SUM('10QIS'!G18:J18) -> -97 | F29: =SUM('10QIS'!K18:N18) -> -90 | G29: =SUM('10QIS'!O18:R18) -> 149 | H29: =SUM('10QIS'!S18:V18) -> 190 | I29: =SUM('10QIS'!W18:Z18) -> 28 | J29: 0 | K29: 0 | L29: 0 | M29: 0 | N29: 0
B30: Income Before Income Taxes | C30: =C28+C29 -> 3205 | D30: =D28+D29 -> 4176 | E30: =E28+E29 -> 5705 | F30: =F28+F29 -> 6008 | G30: =G28+G29 -> 6799 | H30: =H28+H29 -> 6931 | I30: =I28+I29 -> 8734 | J30: =J28+J29 -> 7986.6354 | ... N30: =N28+N29 -> 13279.598
B31: Provision for Income Taxes | C31: 254 | D31: =SUM('10QIS'!C20:F20) -> -1084 | E31: =SUM('10QIS'!G20:J20) -> 883 | F31: =SUM('10QIS'!K20:N20) -> 1252 | G31: =SUM('10QIS'!O20:R20) -> 1371 | H31: =SUM('10QIS'!S20:V20) -> 1371 | I31: =SUM('10QIS'!W20:Z20) -> 1604 | J31: =J30*J12 -> 1701.1534 | K31: =K30*K12 -> 1892.3689 | L31: =L30*L12 -> 2175.4948 | M31: =M30*M12 -> 2480.8034 | N31: =N30*N12 -> 2828.5543
B32: Net Income | C32: =C30-C31 -> 2951 | D32: =D30-D31 -> 5260 | E32: =E30-E31 -> 4822 | F32: =F30-F31 -> 4756 | G32: =G30-G31 -> 5428 | H32: =H30-H31 -> 5560 | I32: =I30-I31 -> 7130 | J32: =J30-J31 -> 6285.4821 | ... N32: =N30-N31 -> 10451.044
B33: Diluted EPS | C33: =IFERROR(C32/C34,"") -> 5.9979675 | D33: =IFERROR(D32/D34,"") -> 10.845361 | E33: =IFERROR(E32/E34,"") -> 10.024948 | F33: =IFERROR(F32/F34,"") -> 10.097665 | G33: =IFERROR(G32/G34,"") -> 11.825708 | H33: =IFERROR(H32/H34,"") -> 12.355556 | I33: =IFERROR(I32/I34,"") -> 16.697892 | J33: =IFERROR(J32/J34,"") -> 15.912613 | ... N33: =IFERROR(N32/N34,"") -> 26.458338
B34: Diluted Shares | C34: 492 | D34: 485 | E34: 481 | F34: 471 | G34: 459 | H34: 450 | I34: 427 | J34: =Main!$C$4 -> 395 | K34: =Main!$C$4 -> 395 | L34: =Main!$C$4 -> 395 | M34: =Main!$C$4 -> 395 | N34: =Main!$C$4 -> 395

Sheet BS
B2: Balance Sheet | C2: FY'20 | D2: FY'21 | E2: FY'22 | F2: FY'23 | G2: FY'24 | H2: FY'25
B3: Cash and cash equivalents | C3: 4478 | D3: 3844 | E3: 4236 | F3: 7141 | G3: 7613 | H3: 5431
B4: Short-term investments | C4: 1514 | D4: 1954 | E4: 1860 | F4: 701 | G4: 273 | H4: 1164
B5: Trade receivables, net | C5: 1398 | D5: 1878 | E5: 2065 | F5: 2224 | G5: 2072 | H5: 2344
B6: Prepaid expenses and other current assets | C6: 756 | D6: 993 | E6: 835 | F6: 1018 | G6: 1274 | H6: 1224
B7: Total current assets | C7: =SUM(C3:C6) -> 8146 | D7: =SUM(D3:D6) -> 8669 | E7: =SUM(E3:E6) -> 8996 | F7: =SUM(F3:F6) -> 11084 | G7: =SUM(G3:G6) -> 11232 | H7: =SUM(H3:H6) -> 10163
B8: Property and equipment, net | C8: 1517 | D8: 1673 | E8: 1908 | F8: 2030 | G8: 1936 | H8: 1873
B9: Operating lease right-of-use assets, net | C9: 487 | D9: 443 | E9: 407 | F9: 358 | G9: 281 | H9: 312
B10: Goodwill | C10: 10742 | D10: 12668 | E10: 12787 | F10: 12805 | G10: 12788 | H10: 12857
B11: Other intangibles, net | C11: 1359 | D11: 1820 | E11: 1449 | F11: 1088 | G11: 782 | H11: 495
B12: Deferred income taxes (asset) | C12: 1370 | D12: 1085 | E12: 777 | F12: 1191 | G12: 1657 | H12: 2186
B13: Other assets | C13: 663 | D13: 883 | E13: 841 | F13: 1223 | G13: 1554 | H13: 1610
B14: Total assets | C14: =C7+SUM(C8:C13) -> 24284 | D14: =D7+SUM(D8:D13) -> 27241 | E14: =E7+SUM(E8:E13) -> 27165 | F14: =F7+SUM(F8:F13) -> 29779 | G14: =G7+SUM(G8:G13) -> 30230 | H14: =H7+SUM(H8:H13) -> 29496
B16: Trade payables | C16: 306 | D16: 312 | E16: 379 | F16: 314 | G16: 361 | H16: 417
B17: Accrued expenses | C17: 1422 | D17: 1736 | E17: 1790 | F17: 1942 | G17: 2336 | H17: 2648
B18: Debt (current) | C18: 0 | D18: 0 | E18: 500 | F18: 0 | G18: 1499 | H18: 0
B19: Deferred revenue (current) | C19: 3629 | D19: 4733 | E19: 5297 | F19: 5837 | G19: 6131 | H19: 6905
B20: Income taxes payable (current) | C20: 63 | D20: 54 | E20: 75 | F20: 85 | G20: 119 | H20: 153
B21: Operating lease liabilities (current) | C21: 92 | D21: 97 | E21: 87 | F21: 73 | G21: 75 | H21: 77
B22: Total current liabilities | C22: =SUM(C16:C21) -> 5512 | D22: =SUM(D16:D21) -> 6932 | E22: =SUM(E16:E21) -> 8128 | F22: =SUM(F16:F21) -> 8251 | G22: =SUM(G16:G21) -> 10521 | H22: =SUM(H16:H21) -> 10200
B23: Debt (long-term) | C23: 4117 | D23: 4123 | E23: 3629 | F23: 3634 | G23: 4129 | H23: 6210
B24: Deferred revenue (long-term) | C24: 130 | D24: 145 | E24: 117 | F24: 113 | G24: 128 | H24: 125
B25: Income taxes payable (long-term) | C25: 529 | D25: 534 | E25: 530 | F25: 514 | G25: 548 | H25: 469
B26: Deferred income taxes (long-term liability) | C26: 10 | D26: 5 | E26: 0 | F26: 0 | G26: 0 | H26: 0
B27: Operating lease liabilities (long-term) | C27: 499 | D27: 453 | E27: 417 | F27: 373 | G27: 353 | H27: 361
B28: Other liabilities | C28: 223 | D28: 252 | E28: 293 | F28: 376 | G28: 446 | H28: 508
B29: Total liabilities | C29: =C22+SUM(C23:C28) -> 11020 | D29: =D22+SUM(D23:D28) -> 12444 | E29: =E22+SUM(E23:E28) -> 13114 | F29: =F22+SUM(F23:F28) -> 13261 | G29: =G22+SUM(G23:G28) -> 16125 | H29: =H22+SUM(H23:H28) -> 17873
B31: Additional paid-in capital | C31: 7357 | D31: 8428 | E31: 9868 | F31: 11586 | G31: 13419 | H31: 15361
B32: Retained earnings | C32: 19611 | D32: 23905 | E32: 28319 | F32: 33346 | G32: 38470 | H32: 45354
B33: Accumulated other comprehensive income (loss) | C33: -158 | D33: -137 | E33: -293 | F33: -285 | G33: -201 | H33: -245
B34: Treasury stock, at cost | C34: -13546 | D34: -17399 | E34: -23843 | F34: -28129 | G34: -37583 | H34: -48847
B35: Total stockholders' equity | C35: =SUM(C31:C34) -> 13264 | D35: =SUM(D31:D34) -> 14797 | E35: =SUM(E31:E34) -> 14051 | F35: =SUM(F31:F34) -> 16518 | G35: =SUM(G31:G34) -> 14105 | H35: =SUM(H31:H34) -> 11623
B36: Total liabilities and stockholders' equity | C36: =C29+C35 -> 24284 | D36: =D29+D35 -> 27241 | E36: =E29+E35 -> 27165 | F36: =F29+F35 -> 29779 | G36: =G29+G35 -> 30230 | H36: =H29+H35 -> 29496
B37: Check (Assets less Liab. & Equity) | C37: =C14-C36 -> 0 | D37: =D14-D36 -> 0 | E37: =E14-E36 -> 0 | F37: =F14-F36 -> 0 | G37: =G14-G36 -> 0 | H37: =H14-H36 -> 0

Sheet CFS
B2: Cash Flow Statement | C2: FY'19 | D2: FY'20 | E2: FY'21 | F2: FY'22 | G2: FY'23 | H2: FY'24 | I2: FY'25
B3: Net income | C3: 2951 | D3: 5260 | E3: 4822 | F3: 4756 | G3: 5428 | H3: 5560 | I3: 7130
B4: Depreciation, amortization and accretion | C4: 757 | D4: 757 | E4: 788 | F4: 856 | G4: 872 | H4: 857 | I4: 818
B5: Stock-based compensation | C5: 788 | D5: 909 | E5: 1069 | F5: 1440 | G5: 1718 | H5: 1833 | I5: 1942
B6: Reduction of operating lease right-of-use assets | C6: 0 | D6: 87 | E6: 73 | F6: 83 | G6: 72 | H6: 77 | I6: 0
B7: Lease-related asset impairments | C7: 0 | D7: 0 | E7: 0 | F7: 0 | G7: 0 | H7: 78 | I7: 0
B8: Deferred income taxes | C8: 3 | D8: -1501 | E8: 183 | F8: 328 | G8: -426 | H8: -468 | I8: -512
B9: Unrealized losses (gains) on investments, net | C9: -48 | D9: -11 | E9: -4 | F9: 29 | G9: -10 | H9: -35 | I9: 0
B10: Other non-cash items | C10: 14 | D10: 40 | E10: 7 | F10: 10 | G10: 3 | H10: 10 | I10: 48
B11: Trade receivables, net | C11: -188 | D11: 106 | E11: -430 | F11: -198 | G11: -159 | H11: 143 | I11: -275
B12: Prepaid expenses and other assets | C12: -551 | D12: -288 | E12: -475 | F12: -94 | G12: -818 | H12: -616 | I12: -90
B13: Trade payables | C13: 23 | D13: 96 | E13: -20 | F13: 66 | G13: -49 | H13: 44 | I13: 64
B14: Accrued expenses and other liabilities | C14: 172 | D14: 86 | E14: 162 | F14: 7 | G14: 146 | H14: 196 | I14: 180
... B16: Deferred revenue | C16: 497 | D16: 258 | E16: 1053 | F16: 536 | G16: 536 | H16: 309 | I16: 771
B17: Net cash provided by operating activities | C17: =SUM(C3:C16) -> 4422 | D17: =SUM(D3:D16) -> 5727 | E17: =SUM(E3:E16) -> 7230 | F17: =SUM(F3:F16) -> 7838 | G17: =SUM(G3:G16) -> 7302 | H17: =SUM(H3:H16) -> 8056 | I17: =SUM(I3:I16) -> 10031
B19: Purchases of short-term investments | C19: -700 | D19: -1071 | E19: -1533 | F19: -909 | G19: 0 | H19: -59 | I19: -2034
B20: Maturities of short-term investments | C20: 700 | D20: 915 | E20: 877 | F20: 683 | G20: 965 | H20: 486 | I20: 1168
B21: Proceeds from sales of short-term investments | C21: 86 | D21: 167 | E21: 191 | F21: 270 | G21: 223 | H21: 11 | I21: 6
B22: Acquisitions, net of cash acquired | C22: -101 | D22: 0 | E22: -2682 | F22: -126 | G22: 0 | H22: 0 | I22: -17
B23: Purchases of property and equipment | C23: -395 | D23: -419 | E23: -348 | F23: -442 | G23: -360 | H23: -183 | I23: -179
B24: Purchases of long-term investments, intangibles and other assets | C24: -49 | D24: -15 | E24: -42 | F24: -46 | G24: -53 | H24: -108 | I24: -134
B25: Proceeds from sales of long-term investments and other assets | C25: 3 | D25: 9 | E25: 0 | F25: 0 | G25: 1 | H25: 2 | I25: 3
B26: Net cash provided by (used for) investing activities | C26: =SUM(C19:C25) -> -456 | D26: =SUM(D19:D25) -> -414 | E26: =SUM(E19:E25) -> -3537 | F26: =SUM(F19:F25) -> -570 | G26: =SUM(G19:G25) -> 776 | H26: =SUM(H19:H25) -> 149 | I26: =SUM(I19:I25) -> -1187
B28: Repurchases of common stock | C28: -2750 | D28: -3050 | E28: -3950 | F28: -6550 | G28: -4400 | H28: -9500 | I28: -11281
B29: Proceeds from re-issuance of treasury stock | C29: 233 | D29: 270 | E29: 291 | F29: 278 | G29: 314 | H29: 361 | I29: 348
B30: Taxes paid related to net share settlement of equity awards | C30: -440 | D30: -681 | E30: -719 | F30: -518 | G30: -589 | H30: -677 | I30: -475
B31: Proceeds from issuance of debt | C31: 0 | D31: 3144 | E31: 0 | F31: 0 | G31: 0 | H31: 1997 | I31: 1997
B32: Repayment of debt | C32: 0 | D32: -3150 | E32: 0 | F32: 0 | G32: -500 | H32: 0 | I32: -1500
B33: Other financing activities, net | C33: 11 | D33: -21 | E33: 77 | F33: -35 | G33: -7 | H33: 95 | I33: -149
B34: Net cash used for financing activities | C34: =SUM(C28:C33) -> -2946 | D34: =SUM(D28:D33) -> -3488 | E34: =SUM(E28:E33) -> -4301 | F34: =SUM(F28:F33) -> -6825 | G34: =SUM(G28:G33) -> -5182 | H34: =SUM(H28:H33) -> -7724 | I34: =SUM(I28:I33) -> -11060
B36: Effect of foreign currency exchange rates on cash | C36: -13 | D36: 3 | E36: -26 | F36: -51 | G36: 9 | H36: -9 | I36: 34
B37: Net increase (decrease) in cash and cash equivalents | C37: =C17+C26+C34+C36 -> 1007 | D37: =D17+D26+D34+D36 -> 1828 | E37: =E17+E26+E34+E36 -> -634 | F37: =F17+F26+F34+F36 -> 392 | G37: =G17+G26+G34+G36 -> 2905 | H37: =H17+H26+H34+H36 -> 472 | I37: =I17+I26+I34+I36 -> -2182
B38: Cash and cash equivalents at beginning of year | C38: 1643 | D38: 2650 | E38: 4478 | F38: 3844 | G38: 4236 | H38: 7141 | I38: 7613
B39: Cash and cash equivalents at end of year | C39: =C38+C37 -> 2650 | D39: =D38+D37 -> 4478 | E39: =E38+E37 -> 3844 | F39: =F38+F37 -> 4236 | G39: =G38+G37 -> 7141 | H39: =H38+H37 -> 7613 | I39: =I38+I37 -> 5431

Sheet DCF
B2: Adobe Inc. (ADBE)
B4: Valuation Date: | F4: =TODAY() -> 46287
B5: Share Price on Valuation Date: | F5: =Main!C3 -> 293.12
B6: Diluted Shares Outstanding | F6: =Main!C4 -> 395
B7: Stub Period to FY26 Year-End (yrs) | F7: =(DATE(YEAR(F4),11,27)-F4)/365 -> 0.18082192
B8: Select Operating Data
I9: Projected Annual Forecast
C10: FY'20 | D10: FY'21 | E10: FY'22 | F10: FY'23 | G10: FY'24 | H10: FY'25 | I10: FY'26 | J10: FY'27 | K10: FY'28 | L10: FY'29 | M10: FY'30
B11: Revenue | C11: =IS!D19 -> 12868 | D11: =IS!E19 -> 15785 | E11: =IS!F19 -> 17606 | F11: =IS!G19 -> 19409 | G11: =IS!H19 -> 21505 | H11: =IS!I19 -> 23769 | I11: =IS!J19 -> 26185.69 | J11: =IS!K19 -> 28892.231 | ... M11: =IS!N19 -> 39057.641
B13: EBIT (Operating Income) | C13: =IS!D28 -> 4237 | D13: =IS!E28 -> 5802 | E13: =IS!F28 -> 6098 | F13: =IS!G28 -> 6650 | G13: =IS!H28 -> 6741 | H13: =IS!I28 -> 8706 | I13: =IS!J28 -> 7986.6354 | J13: =IS!K28 -> 8884.361 | ... M13: =IS!N28 -> 13279.598
B15: Depreciation & Amortization (total, incl. PP&E) | C15: =CFS!D4 -> 757 | D15: =CFS!E4 -> 788 | E15: =CFS!F4 -> 856 | F15: =CFS!G4 -> 872 | G15: =CFS!H4 -> 857 | H15: =CFS!I4 -> 818 | I15: =I11*I16 -> 901.16936 | J15: =J11*J16 -> 965.42158 | K15: =K11*K16 -> 1034.5912 | L15: =L11*L16 -> 1108.7406 | M15: =M11*M16 -> 1187.9215 | O15: Arithmetic Avg | P15: Geometric Avg
B16: D&A as % of Revenue | C16: =C15/C11 -> 0.058828101 | D16: =D15/D11 -> 0.049920811 | E16: =E15/E11 -> 0.048619789 | F16: =F15/F11 -> 0.044927611 | G16: =G15/G11 -> 0.039851197 | H16: =H15/H11 -> 0.034414574 | I16: =H16 -> 0.034414574 | J16: =I16-0.001 -> 0.033414574 | K16: =J16-0.001 -> 0.032414574 | L16: =K16-0.001 -> 0.031414574 | M16: =L16-0.001 -> 0.030414574 | O16: =AVERAGE(C16:H16) -> 0.04609368 | P16: =GEOMEAN(C16:H16) -> 0.045435583
B18: Select Balance Sheet And Other Data
I19: Projected Annual Forecast
C20: FY'20 | D20: FY'21 | E20: FY'22 | F20: FY'23 | G20: FY'24 | H20: FY'25 | I20: FY'26 | J20: FY'27 | K20: FY'28 | L20: FY'29 | M20: FY'30
B21: Trade Receivables | C21: =BS!C5 -> 1398 | D21: =BS!D5 -> 1878 | E21: =BS!E5 -> 2065 | F21: =BS!F5 -> 2224 | G21: =BS!G5 -> 2072 | H21: =BS!H5 -> 2344 | I21: =I30*I11 -> 2917.3403 | J21: =J30*J11 -> 3218.8753 | K21: =K30*K11 -> 3555.9164 | L21: =L30*L11 -> 3932.0757 | M21: =M30*M11 -> 4351.4007
B22: Prepaid Expenses and Other Current Assets | C22: =BS!C6 -> 756 | D22: =BS!D6 -> 993 | E22: =BS!E6 -> 835 | F22: =BS!F6 -> 1018 | G22: =BS!G6 -> 1274 | H22: =BS!H6 -> 1224 | I22: =I31*I11 -> 1444.9083 | J22: =J31*J11 -> 1594.2533 | K22: =K31*K11 -> 1761.184 | L22: =L31*L11 -> 1947.4892 | M22: =M31*M11 -> 2155.1736
B24: Trade Payables and Accrued Expenses | C24: =BS!C16+BS!C17 -> 1728 | D24: =BS!D16+BS!D17 -> 2048 | E24: =BS!E16+BS!E17 -> 2169 | F24: =BS!F16+BS!F17 -> 2256 | G24: =BS!G16+BS!G17 -> 2697 | H24: =BS!H16+BS!H17 -> 3065 | I24: =I32*I11 -> 3235.2246 | J24: =J32*J11 -> 3569.6159 | K24: =K32*K11 -> 3943.3823 | L24: =L32*L11 -> 4360.5293 | M24: =M32*M11 -> 4825.5456
B26: Debt | C26: =BS!C18+BS!C23 -> 4117 | D26: =BS!D18+BS!D23 -> 4123 | E26: =BS!E18+BS!E23 -> 4129 | F26: =BS!F18+BS!F23 -> 3634 | G26: =BS!G18+BS!G23 -> 5628 | H26: =BS!H18+BS!H23 -> 6210
B28: Capital Expenditures | C28: =CFS!D23 -> -419 | D28: =CFS!E23 -> -348 | E28: =CFS!F23 -> -442 | F28: =CFS!G23 -> -360 | G28: =CFS!H23 -> -183 | H28: =CFS!I23 -> -179 | I28: =I33*I11 -> -197.19965 | J28: =J33*J11 -> -188.68989 | K28: =K33*K11 -> -176.52971 | L28: =L33*L11 -> -159.9099 | M28: =M33*M11 -> -137.9054
O29: Arithmetic Mean | P29: Geometric Mean
B30: Trade Receivables as a % of revenue | C30: =C21/C11 -> 0.10864159 | D30: =D21/D11 -> 0.11897371 | E30: =E21/E11 -> 0.11728956 | F30: =F21/F11 -> 0.11458602 | G30: =G21/G11 -> 0.096349686 | H30: =$P$30 -> 0.11140972 | I30: =$P$30 -> 0.11140972 | J30: =$P$30 -> 0.11140972 | K30: =$P$30 -> 0.11140972 | L30: =$P$30 -> 0.11140972 | M30: =$P$30 -> 0.11140972 | O30: =AVERAGE(D30:G30) -> 0.11179974 | P30: =IFERROR(GEOMEAN(D30:G30),"n/a") -> 0.11140972
B31: Prepaid Expenses as a % of revenue | C31: =C22/C11 -> 0.058750389 | D31: =D22/D11 -> 0.062907824 | E31: =E22/E11 -> 0.047427014 | F31: =F22/F11 -> 0.052449894 | G31: =G22/G11 -> 0.059242037 | H31: =$P$31 -> 0.055179309 | I31: =$P$31 -> 0.055179309 | J31: =$P$31 -> 0.055179309 | K31: =$P$31 -> 0.055179309 | L31: =$P$31 -> 0.055179309 | M31: =$P$31 -> 0.055179309 | O31: =AVERAGE(D31:G31) -> 0.055506692 | P31: =IFERROR(GEOMEAN(D31:G31),"n/a") -> 0.055179309
B32: Trade Payables/Accrued as a % of revenue | C32: =C24/C11 -> 0.1342866 | D32: =D24/D11 -> 0.12974343 | E32: =E24/E11 -> 0.12319664 | F32: =F24/F11 -> 0.11623474 | G32: =G24/G11 -> 0.12541269 | H32: =$P$32 -> 0.12354934 | I32: =$P$32 -> 0.12354934 | J32: =$P$32 -> 0.12354934 | K32: =$P$32 -> 0.12354934 | L32: =$P$32 -> 0.12354934 | M32: =$P$32 -> 0.12354934 | O32: =AVERAGE(D32:G32) -> 0.12364687 | P32: =IFERROR(GEOMEAN(D32:G32),"n/a") -> 0.12354934
B33: Capital Expenditures as a % of revenue | C33: =C28/C11 -> -0.032561393 | D33: =D28/D11 -> -0.022046246 | E33: =E28/E11 -> -0.025105078 | F33: =F28/F11 -> -0.018548096 | G33: =G28/G11 -> -0.0085096489 | H33: =H28/H11 -> -0.0075308175 | I33: =H33 -> -0.0075308175 | J33: =I33+0.001 -> -0.0065308175 | K33: =J33+0.001 -> -0.0055308175 | L33: =K33+0.001 -> -0.0045308175 | M33: =L33+0.001 -> -0.0035308175 | O33: =AVERAGE(D33:H33) -> -0.016347977 | P33: =IFERROR(GEOMEAN(D33:H33),0) -> 0
B34: Trade Receivables Growth (%) | D34: =IFERROR((D21/C21)-1,"") -> 0.34334764 | E34: =IFERROR((E21/D21)-1,"") -> 0.099574015 | F34: =IFERROR((F21/E21)-1,"") -> 0.076997579 | G34: =IFERROR((G21/F21)-1,"") -> -0.068345324 | H34: =IFERROR((H21/G21)-1,"") -> 0.13127413
B35: Prepaid Expenses Growth (%) | D35: =IFERROR((D22/C22)-1,"") -> 0.31349206 | E35: =IFERROR((E22/D22)-1,"") -> -0.1591138 | F35: =IFERROR((F22/E22)-1,"") -> 0.21916168 | G35: =IFERROR((G22/F22)-1,"") -> 0.25147348 | H35: =IFERROR((H22/G22)-1,"") -> -0.039246468
B36: Trade Payables/Accrued Growth (%) | D36: =IFERROR((D24/C24)-1,"") -> 0.18518519 | E36: =IFERROR((E24/D24)-1,"") -> 0.059082031 | F36: =IFERROR((F24/E24)-1,"") -> 0.04011065 | G36: =IFERROR((G24/F24)-1,"") -> 0.19547872 | H36: =IFERROR((H24/G24)-1,"") -> 0.13644791
B38: Capital Expenditures Growth (%) | D38: =IFERROR((D28/C28)-1,"") -> -0.16945107 | E38: =IFERROR((E28/D28)-1,"") -> 0.27011494 | F38: =IFERROR((F28/E28)-1,"") -> -0.18552036 | G38: =IFERROR((G28/F28)-1,"") -> -0.49166667 | H38: =IFERROR((H28/G28)-1,"") -> -0.021857923
B40: Free Cash Flow Buildup
B41: $mm | I41: Projected Annual Forecast
C42: FY'20 | D42: FY'21 | E42: FY'22 | F42: FY'23 | G42: FY'24 | H42: FY'25 | I42: FY'26 | J42: FY'27 | K42: FY'28 | L42: FY'29 | M42: FY'30
B43: Period | I43: =$F$7/2 -> 0.090410959 | J43: =$F$7+0.5 -> 0.68082192 | K43: =$F$7+1.5 -> 1.6808219 | L43: =$F$7+2.5 -> 2.6808219 | M43: =$F$7+3.5 -> 3.6808219
B44: Total Revenues | C44: =C11 -> 12868 | D44: =D11 -> 15785 | E44: =E11 -> 17606 | F44: =F11 -> 19409 | G44: =G11 -> 21505 | H44: =H11 -> 23769 | I44: =I11 -> 26185.69 | J44: =J11 -> 28892.231 | ... M44: =M11 -> 39057.641
B45: EBIT | C45: =C13 -> 4237 | D45: =D13 -> 5802 | E45: =E13 -> 6098 | F45: =F13 -> 6650 | G45: =G13 -> 6741 | H45: =H13 -> 8706 | I45: =I13 -> 7986.6354 | J45: =J13 -> 8884.361 | ... M45: =M13 -> 13279.598
B46: Effective Tax Rate | C46: =IS!D12 -> -0.25957854 | D46: =IS!E12 -> 0.15477651 | E46: =IS!F12 -> 0.20838881 | F46: =IS!G12 -> 0.2016473 | G46: =IS!H12 -> 0.19780695 | H46: =IS!I12 -> 0.1836501 | I46: =$H$46 -> 0.1836501 | J46: =$H$46 -> 0.1836501 | K46: =$H$46 -> 0.1836501 | L46: =$H$46 -> 0.1836501 | M46: =$H$46 -> 0.1836501
B47: EBIAT = EBIT x (1-T) = NOPAT | C47: =C45*(1-C46) -> 5336.8343 | D47: =D45*(1-D46) -> 4903.9867 | E47: =E45*(1-E46) -> 4827.245 | F47: =F45*(1-F46) -> 5309.0454 | G47: =G45*(1-G46) -> 5407.5833 | H47: =H45*(1-H46) -> 7107.1422 | I47: =I45*(1-I46) -> 6519.889 | J47: =J45*(1-J46) -> 7252.7472 | ... M47: =M45*(1-M46) -> 10840.798
B48: Depreciation & Amortization | C48: =C15 -> 757 | D48: =D15 -> 788 | E48: =E15 -> 856 | F48: =F15 -> 872 | G48: =G15 -> 857 | H48: =H15 -> 818 | I48: =I15 -> 901.16936 | J48: =J15 -> 965.42158 | ... M48: =M15 -> 1187.9215
B49: Chg in Trade Receivables | C49: 0 | D49: =(D21-C21)*-1 -> -480 | E49: =(E21-D21)*-1 -> -187 | F49: =(F21-E21)*-1 -> -159 | G49: =(G21-F21)*-1 -> 152 | H49: =(H21-G21)*-1 -> -272 | I49: =(I21-H21)*-1 -> -573.34032 | J49: =(J21-I21)*-1 -> -301.53496 | K49: =(K21-J21)*-1 -> -337.04115 | ... M49: =(M21-L21)*-1 -> -419.32502
B50: Chg in Prepaid Expenses | C50: 0 | D50: =(D22-C22)*-1 -> -237 | E50: =(E22-D22)*-1 -> 158 | F50: =(F22-E22)*-1 -> -183 | G50: =(G22-F22)*-1 -> -256 | H50: =(H22-G22)*-1 -> 50 | I50: =(I22-H22)*-1 -> -220.90829 | J50: =(J22-I22)*-1 -> -149.34506 | K50: =(K22-J22)*-1 -> -166.93066 | ... M50: =(M22-L22)*-1 -> -207.68444
...

Sheet Digital Media
B2: Segment | C2: Digital Media
B3: Description | C3: Adobe's largest segment: Creative Cloud (Photoshop, Illustrator, Premiere Pro, Firefly, etc.) and Document Cloud (Acrobat, Acrobat Sign).

Sheet Digital Experience
B2: Segment | C2: Digital Experience
B3: Description | C3: Adobe Experience Cloud: enterprise platform and applications for customer experience management, analytics, and commerce.

Sheet Publishing and Advertising
B2: Segment | C2: Publishing and Advertising
B3: Description | C3: Legacy products/services: eLearning, technical document publishing, web conferencing, and (through FY23) Adobe Advertising Cloud.
