Workbook

Sheet IS Quarterly
B1: AutoZone, Inc. | Income Statement (Quarterly)
B2: $mm except per share
C4: Q1 FY2023 | D4: Q2 FY2023 | E4: Q3 FY2023 | F4: Q4 FY2023 | G4: Q1 FY2024 | H4: Q2 FY2024 | I4: Q3 FY2024 | J4: Q4 FY2024 | K4: Q1 FY2025 | L4: Q2 FY2025 | M4: Q3 FY2025 | N4: Q4 FY2025 | O4: Q1 FY2026 | P4: Q2 FY2026 | Q4: Q3 FY2026 | R4: Q4 FY2026
B6: Net sales | C6: 3985.067 | D6: 3690.982 | E6: 4090.541 | F6: ='IS Annual'!C6-SUM(C6:E6) -> 5690.619 | G6: 4190.277 | H6: 3859.126 | I6: 4235.485 | J6: ='IS Annual'!D6-SUM(G6:I6) -> 6205.38 | K6: 4279.641 | L6: 3952.012 | M6: 4464.339 | N6: ='IS Annual'!E6-SUM(K6:M6) -> 6242.725 | O6: 4628.63 | P6: 4274.098 | Q6: 4840.95 | R6: ='IS Annual'!F6-SUM(O6:Q6) -> 6594.877
B7: Cost of sales, including warehouse and delivery expenses | C7: 1990.445 | D7: 1760.979 | E7: 1944.415 | F7: ='IS Annual'!C7-SUM(C7:E7) -> 2690.948 | G7: 1976.261 | H7: 1779.474 | I7: 1969.963 | J7: ='IS Annual'!D7-SUM(G7:I7) -> 2947.518 | K7: 2011.584 | L7: 1823.611 | M7: 2110.816 | N7: ='IS Annual'!E7-SUM(K7:M7) -> 3026.232 | O7: 2269.317 | P7: 2030.74 | Q7: 2316.376 | R7: ='IS Annual'!F7-SUM(O7:Q7) -> 3077.148
B8: Gross profit | C8: 1994.622 | D8: 1930.003 | E8: 2146.126 | F8: ='IS Annual'!C8-SUM(C8:E8) -> 2999.671 | G8: 2214.016 | H8: 2079.652 | I8: 2265.522 | J8: ='IS Annual'!D8-SUM(G8:I8) -> 3257.862 | K8: 2268.057 | L8: 2128.401 | M8: 2353.523 | N8: ='IS Annual'!E8-SUM(K8:M8) -> 3216.493 | O8: 2359.313 | P8: 2243.358 | Q8: 2524.574 | R8: ='IS Annual'!F8-SUM(O8:Q8) -> 3517.729
B9: Operating, selling, general and administrative expenses | C9: 1271.589 | D9: 1260.026 | E9: 1287.645 | F9: ='IS Annual'!C9-SUM(C9:E9) -> 1777.176 | G9: 1365.412 | H9: 1336.41 | I9: 1365.341 | J9: ='IS Annual'!D9-SUM(G9:I9) -> 1961.181 | K9: 1426.908 | L9: 1421.634 | M9: 1487.349 | N9: ='IS Annual'!E9-SUM(K9:M9) -> 2020.427 | O9: 1575.108 | P9: 1544.902 | Q9: 1600.818 | R9: ='IS Annual'!F9-SUM(O9:Q9) -> 2200.832
B10: Operating profit | C10: 723.033 | D10: 669.977 | E10: 858.481 | F10: ='IS Annual'!C10-SUM(C10:E10) -> 1222.495 | G10: 848.604 | H10: 743.242 | I10: 900.181 | J10: ='IS Annual'!D10-SUM(G10:I10) -> 1296.681 | K10: 841.149 | L10: 706.767 | M10: 866.174 | N10: ='IS Annual'!E10-SUM(K10:M10) -> 1196.066 | O10: 784.205 | P10: 698.456 | Q10: 923.756 | R10: ='IS Annual'!F10-SUM(O10:Q10) -> 1316.897
B11: Interest expense, net | C11: 57.723 | D11: 65.609 | E11: 74.313 | F11: ='IS Annual'!C11-SUM(C11:E11) -> 108.727 | G11: 91.384 | H11: 102.619 | I11: 104.422 | J11: ='IS Annual'!D11-SUM(G11:I11) -> 153.153 | K11: 107.629 | L11: 108.822 | M11: 111.285 | N11: ='IS Annual'!E11-SUM(K11:M11) -> 148.088 | O11: 106.27 | P11: 107.205 | Q11: 110.49 | R11: ='IS Annual'!F11-SUM(O11:Q11) -> 148.649
B12: Income before income taxes | C12: 665.31 | D12: 604.368 | E12: 784.168 | F12: ='IS Annual'!C12-SUM(C12:E12) -> 1113.768 | G12: 757.22 | H12: 640.623 | I12: 795.759 | J12: ='IS Annual'!D12-SUM(G12:I12) -> 1143.528 | K12: 733.52 | L12: 597.945 | M12: 754.889 | N12: ='IS Annual'!E12-SUM(K12:M12) -> 1047.978 | O12: 677.935 | P12: 591.251 | Q12: 813.266 | R12: ='IS Annual'!F12-SUM(O12:Q12) -> 1168.248
B13: Income tax expense | C13: 125.992 | D13: 127.824 | E13: 136.445 | F13: ='IS Annual'!C13-SUM(C13:E13) -> 248.927 | G13: 163.757 | H13: 125.593 | I13: 144.033 | J13: ='IS Annual'!D13-SUM(G13:I13) -> 241.32 | K13: 168.587 | L13: 110.022 | M13: 146.449 | N13: ='IS Annual'!E13-SUM(K13:M13) -> 211.027 | O13: 147.112 | P13: 122.391 | Q13: 171.775 | R13: ='IS Annual'!F13-SUM(O13:Q13) -> 236.645
B14: Net income | C14: 539.318 | D14: 476.544 | E14: 647.723 | F14: ='IS Annual'!C14-SUM(C14:E14) -> 864.841 | G14: 593.463 | H14: 515.03 | I14: 651.726 | J14: ='IS Annual'!D14-SUM(G14:I14) -> 902.208 | K14: 564.933 | L14: 487.923 | M14: 608.44 | N14: ='IS Annual'!E14-SUM(K14:M14) -> 836.951 | O14: 530.823 | P14: 468.86 | Q14: 641.491 | R14: ='IS Annual'!F14-SUM(O14:Q14) -> 931.603
B16: Weighted average shares for basic earnings per share | C16: 19.007 | D16: 18.705 | E16: 18.389 | F16: 18.08 | G16: 17.709 | H16: 17.319 | I16: 17.273 | J16: 17.03 | K16: 16.913 | L16: 16.788 | M16: 16.746 | N16: 16.731 | O16: 16.652 | P16: 16.573 | Q16: 16.468 | R16: 16.294
B17: Weighted average shares for diluted earnings per share | C17: 19.645 | D17: 19.337 | E17: 18.983 | F17: 18.613 | G17: 18.234 | H17: 17.828 | I17: 17.761 | J17: 17.491 | K17: 17.37 | L17: 17.245 | M17: 17.207 | N17: 17.181 | O17: 17.102 | P17: 16.969 | Q17: 16.852 | R17: 16.62
B18: Basic earnings per share | C18: 28.37 | D18: 25.48 | E18: 35.22 | F18: 47.83 | G18: 33.51 | H18: 29.74 | I18: 37.73 | J18: 52.98 | K18: 33.4 | L18: 29.06 | M18: 36.33 | N18: 50.02 | O18: 31.88 | P18: 28.29 | Q18: 38.95 | R18: 57.17
B19: Diluted earnings per share | C19: 27.45 | D19: 24.64 | E19: 34.12 | F19: 46.46 | G19: 32.55 | H19: 28.89 | I19: 36.69 | J19: 51.58 | K19: 32.52 | L19: 28.29 | M19: 35.36 | N19: 48.71 | O19: 31.04 | P19: 27.63 | Q19: 38.07 | R19: 56.05

Sheet IS Annual
B1: AutoZone, Inc. | Income Statement (Annual)
B2: $mm except per share
C4: FY2023 | D4: FY2024 | E4: FY2025 | F4: FY 2026
C5: 45164 | D5: 45535 | E5: 45899 | F5: 46151
B6: Net sales | C6: 17457.209 | D6: 18490.268 | E6: 18938.717 | F6: 20338.555
B7: Cost of sales, including warehouse and delivery expenses | C7: 8386.787 | D7: 8673.216 | E7: 8972.243 | F7: 9693.581
B8: Gross profit | C8: 9070.422 | D8: 9817.052 | E8: 9966.474 | F8: 10644.974
B9: Operating, selling, general and administrative expenses | C9: 5596.436 | D9: 6028.344 | E9: 6356.318 | F9: 6921.66
B10: Operating profit | C10: 3473.986 | D10: 3788.708 | E10: 3610.156 | F10: 3723.314
B11: Interest expense, net | C11: 306.372 | D11: 451.578 | E11: 475.824 | F11: 472.614
B12: Income before income taxes | C12: 3167.614 | D12: 3337.13 | E12: 3134.332 | F12: 3250.7
B13: Income tax expense | C13: 639.188 | D13: 674.703 | E13: 636.085 | F13: 677.923
B14: Net income | C14: 2528.426 | D14: 2662.427 | E14: 2498.247 | F14: 2572.777
B15: Weighted average shares for basic earnings per share | C15: 18.51 | D15: 17.309 | E15: 16.789 | F15: 16.481
B16: Weighted average shares for diluted earnings per share | C16: 19.103 | D16: 17.803 | E16: 17.245 | F16: 16.865
B17: Basic earnings per share | C17: 136.6 | D17: 153.82 | E17: 148.8 | F17: 156.11
B18: Diluted earnings per share | C18: 132.36 | D18: 149.55 | E18: 144.87 | F18: 152.55

Sheet BS Annual
B1: AutoZone, Inc. | Balance Sheet (Annual)
B2: $mm except per share
C4: FY2023 | D4: FY2024 | E4: FY2025 | F4: TTM Q3 FY2026
C5: 45164 | D5: 45535 | E5: 45899 | F5: 46151
B6: Cash and cash equivalents | C6: 277.054 | D6: 298.172 | E6: 271.803 | F6: 253.729
B7: Accounts receivable | C7: 520.385 | D7: 545.575 | E7: 670.137 | F7: 764.924
B8: Merchandise inventories | C8: 5764.143 | D8: 6155.218 | E8: 7025.688 | F8: 7559.056
B9: Other current assets | C9: 217.844 | D9: 307.794 | E9: 373.751 | F9: 356.86
B10: Total current assets | C10: 6779.426 | D10: 7306.759 | E10: 8341.379 | F10: 8934.569
B11: Property and equipment, net | C11: 5596.548 | D11: 6183.539 | E11: 7062.509 | F11: 7796.988
B12: Operating lease right-of-use assets | C12: 2998.097 | D12: 3057.78 | E12: 3194.666 | F12: 3413.97
B13: Goodwill | C13: 302.645 | D13: 302.645 | E13: 302.645 | F13: 302.645
B14: Deferred income taxes (asset) | C14: 86.002 | D14: 83.689 | E14: 118.433 | F14: 132.109
B15: Other long-term assets | C15: 223.16 | D15: 242.126 | E15: 335.692 | F15: 336.182
B16: Total long-term assets | C16: 3609.904 | D16: 3686.24 | E16: 3951.436 | F16: 11981.894
B17: Total assets | C17: 15985.878 | D17: 17176.538 | E17: 19355.324 | F17: 20916.463
... B33: Total liabilities and stockholders' deficit | C33: 15985.878 | D33: 17176.538 | E33: 19355.324 | F33: 20916.463

Sheet CF Quarterly
B1: AutoZone, Inc. | Cash Flow Statement (Quarterly)
B2: $mm except per share
C4: Q1 FY2023 | D4: Q2 FY2023 | E4: Q3 FY2023 | F4: Q4 FY2023 | G4: Q1 FY2024 | H4: Q2 FY2024 | I4: Q3 FY2024 | J4: Q4 FY2024 | K4: Q1 FY2025 | L4: Q2 FY2025 | M4: Q3 FY2025 | N4: Q4 FY2025 | O4: Q1 FY2026 | P4: Q2 FY2026 | Q4: Q3 FY2026 | R4: Q4 FY2026
B6: Net income | C6: =C42 -> 539.318 | D6: =D42-C42 -> 476.544 | E6: =E42-D42 -> 647.723 | F6: ='CF Annual'!C6-E42 -> 864.841 | G6: =F42 -> 593.463 | H6: =G42-F42 -> 515.03 | I6: =H42-G42 -> 651.726 | J6: ='CF Annual'!D6-H42 -> 902.208 | K6: =I42 -> 564.933 | L6: =J42-I42 -> 487.923 | M6: =K42-J42 -> 608.441 | N6: ='CF Annual'!E6-K42 -> 836.95 | O6: =L42 -> 530.823 | P6: =M42-L42 -> 468.86 | Q6: =N42-M42 -> 641.491 | R6: ='CF Annual'!F6-N42 -> 836.95
B7: Depreciation and amortization of property and equipment | C7: =C43 -> 109.253 | D7: =D43-C43 -> 113.711 | E7: =E43-D43 -> 116.123 | F7: ='CF Annual'!C7-E43 -> 158.49 | G7: =F43 -> 120.224 | H7: =G43-F43 -> 124.968 | I7: =H43-G43 -> 129.224 | J7: ='CF Annual'!D7-H43 -> 175.339 | K7: =I43 -> 133.173 | L7: =J43-I43 -> 137.918 | M7: =K43-J43 -> 144.696 | N7: ='CF Annual'!E7-K43 -> 197.412 | O7: =L43 -> 148.194 | P7: =M43-L43 -> 155.64 | Q7: =N43-M43 -> 160.292 | R7: ='CF Annual'!F7-N43 -> 197.412
B8: Other non-cash charges (income) | C8: =C44 -> 81 | D8: =D44-C44 -> 10 | E8: =E44-D44 -> -17 | F8: ='CF Annual'!C8-E44 -> -30 | G8: =F44 -> -2 | H8: =G44-F44 -> -14 | I8: =H44-G44 -> -24 | J8: ='CF Annual'!D8-H44 -> 0 | K8: =I44 -> 0 | L8: =J44-I44 -> 0 | M8: =K44-J44 -> -16 | N8: ='CF Annual'!E8-K44 -> 80 | O8: =L44 -> 98 | P8: =M44-L44 -> 59 | Q8: =N44-M44 -> 20 | R8: ='CF Annual'!F8-N44 -> 80
B9: Amortization of debt origination fees | C9: =C45 -> 1.905 | D9: =D45-C45 -> 2.017 | E9: =E45-D45 -> 2.143 | F9: ='CF Annual'!C9-E45 -> 3.199 | G9: =F45 -> 2.81 | H9: =G45-F45 -> 2.741 | I9: =H45-G45 -> 2.604 | J9: ='CF Annual'!D9-H45 -> 3.833 | K9: =I45 -> 3.018 | L9: =J45-I45 -> 3.043 | M9: =K45-J45 -> 3.022 | N9: ='CF Annual'!E9-K45 -> 3.757 | O9: =L45 -> 3.21 | P9: =M45-L45 -> 2.768 | Q9: =N45-M45 -> 2.795 | R9: ='CF Annual'!F9-N45 -> 3.757
B10: Deferred income taxes | C10: =C46 -> 13.816 | D10: =D46-C46 -> -18.513 | E10: =E46-D46 -> 1.273 | F10: ='CF Annual'!C10-E46 -> -22.283 | G10: =F46 -> 0.882 | H10: =G46-F46 -> 5.116 | I10: =H46-G46 -> 3.018 | J10: ='CF Annual'!D10-H46 -> -263.409 | K10: =I46 -> -4.831 | L10: =J46-I46 -> -38.903 | M10: =K46-J46 -> -15.586 | N10: ='CF Annual'!E10-K46 -> 174.709 | O10: =L46 -> -41.724 | P10: =M46-L46 -> -95.352 | Q10: =N46-M46 -> -20.658 | R10: ='CF Annual'!F10-N46 -> 174.709
B11: Share-based compensation expense | C11: =C47 -> 19.005 | D11: =D47-C47 -> 23.374 | E11: =E47-D47 -> 20.01 | F11: ='CF Annual'!C11-E47 -> 30.698 | G11: =F47 -> 22.913 | H11: =G47-F47 -> 23.048 | I11: =H47-G47 -> 25.353 | J11: ='CF Annual'!D11-H47 -> 34.932 | K11: =I47 -> 26.117 | L11: =J47-I47 -> 30.446 | M11: =K47-J47 -> 29.021 | N11: ='CF Annual'!E11-K47 -> 39.133 | O11: =L47 -> 30.727 | P11: =M47-L47 -> 36.742 | Q11: =N47-M47 -> 30.172 | R11: ='CF Annual'!F11-N47 -> 39.133
B12: Accounts receivable | C12: =C48 -> 4.1 | D12: =D48-C48 -> 18.173 | E12: =E48-D48 -> 16.044 | F12: ='CF Annual'!C12-E48 -> -44.991 | G12: =F48 -> 6.856 | H12: =G48-F48 -> 11.508 | I12: =H48-G48 -> -84.914 | J12: ='CF Annual'!D12-H48 -> 28.268 | K12: =I48 -> 9.873 | L12: =J48-I48 -> -64.448 | M12: =K48-J48 -> 12.755 | N12: ='CF Annual'!E12-K48 -> -76.786 | O12: =L48 -> 36.7 | P12: =M48-L48 -> -57.041 | Q12: =N48-M48 -> -66.266 | R12: ='CF Annual'!F12-N48 -> -76.786
B13: Merchandise inventories | C13: =C49 -> -39.308 | D13: =D49-C49 -> -122.238 | E13: =E49-D49 -> 68.383 | F13: ='CF Annual'!C13-E49 -> 3.983 | G13: =F49 -> -21.899 | H13: =G49-F49 -> -176.526 | I13: =H49-G49 -> -155.388 | J13: ='CF Annual'!D13-H49 -> -99.288 | K13: =I49 -> -136.181 | L13: =J49-I49 -> -317.928 | M13: =K49-J49 -> -188.208 | N13: ='CF Annual'!E13-K49 -> -251.591 | O13: =L49 -> -205.335 | P13: =M49-L49 -> -347.038 | Q13: =N49-M49 -> -104.135 | R13: ='CF Annual'!F13-N49 -> -251.591
B14: Accounts payable and accrued expenses | C14: =C50 -> 6.574 | D14: =D50-C50 -> -117.885 | E14: =E50-D50 -> -128.589 | F14: ='CF Annual'!C14-E50 -> 56.221 | G14: =F50 -> 33.762 | H14: =G50-F50 -> -50.824 | I14: =H50-G50 -> 143.55 | J14: ='CF Annual'!D14-H50 -> 117.646 | K14: =I50 -> 170.032 | L14: =J50-I50 -> 279.755 | M14: =K50-J50 -> 153.826 | N14: ='CF Annual'!E14-K50 -> 53.795 | O14: =L50 -> 243.49 | P14: =M50-L50 -> -7.734 | Q14: =N50-M50 -> 111.712 | R14: ='CF Annual'!F14-N50 -> 53.795
B15: Income taxes | C15: =C51 -> 73.954 | D15: =D51-C51 -> 13.446 | E15: =E51-D51 -> -23.359 | F15: ='CF Annual'!C15-E51 -> 28.791 | G15: =F51 -> 96.793 | H15: =G51-F51 -> -0.511 | I15: =H51-G51 -> -26.536 | J15: ='CF Annual'!D15-H51 -> 226.652 | K15: =I51 -> 103.019 | L15: =J51-I51 -> 67.571 | M15: =K51-J51 -> -34.637 | N15: ='CF Annual'!E15-K51 -> -67.506 | O15: =L51 -> 114.578 | P15: =M51-L51 -> 70.596 | Q15: =N51-M51 -> 21.035 | R15: ='CF Annual'!F15-N51 -> -67.506
B16: Other, net (operating) | C16: =C52 -> -16.03 | D16: =D52-C52 -> -44.155 | E16: =E52-D52 -> 21.964 | F16: ='CF Annual'!C16-E52 -> 19.063 | G16: =F52 -> -23.545 | H16: =G52-F52 -> -6.423 | I16: =H52-G52 -> 4.843 | J16: ='CF Annual'!D16-H52 -> -55.931 | K16: =I52 -> -57.35 | L16: =J52-I52 -> -1.628 | M16: =K52-J52 -> 71.7 | N16: ='CF Annual'!E16-K52 -> -37.118 | O16: =L52 -> -14.492 | P16: =M52-L52 -> 86.988 | Q16: =N52-M52 -> 5.549 | R16: ='CF Annual'!F16-N52 -> -37.118
B17: Net cash provided by operating activities | C17: =C53 -> 793.587 | D17: =D53-C53 -> 354.474 | E17: =E53-D53 -> 724.715 | F17: ='CF Annual'!C17-E53 -> 1068.012 | G17: =F53 -> 830.259 | H17: =G53-F53 -> 434.127 | I17: =H53-G53 -> 669.48 | J17: ='CF Annual'!D17-H53 -> 1070.25 | K17: =I53 -> 811.803 | L17: =J53-I53 -> 583.749 | M17: =K53-J53 -> 769.03 | N17: ='CF Annual'!E17-K53 -> 952.755 | O17: =L53 -> 944.171 | P17: =M53-L53 -> 373.429 | Q17: =N53-M53 -> 801.987 | R17: ='CF Annual'!F17-N53 -> 952.755
... B35: Cash and cash equivalents at end of period | C35: =C71 -> 269.79 | D35: =D71-C71 -> 31.496 | E35: =E71-D71 -> -26.37 | F35: ='CF Annual'!C35-E71 -> 2.138 | G35: =F71 -> 282.981 | H35: =G71-F71 -> 21.115 | I35: =H71-G71 -> -28.738 | J35: ='CF Annual'!D35-H71 -> 22.814 | K35: =I71 -> 304.018 | L35: =J71-I71 -> -3.113 | M35: =K71-J71 -> -32.28 | N35: ='CF Annual'!E35-K71 -> 3.178 | O35: =L71 -> 287.639 | P35: =M71-L71 -> -2.147 | Q35: =N71-M71 -> -31.763 | R35: ='CF Annual'!F35-N71 -> 0
B40: Year to Date, as Reported
C41: 3M FY2023 | D41: 6M FY2023 | E41: 9M FY2023 | F41: 3M FY2024 | G41: 6M FY2024 | H41: 9M FY2024 | I41: 3M FY2025 | J41: 6M FY2025 | K41: 9M FY2025 | L41: 3M TTM Q3 FY2026 | M41: 6M TTM Q3 FY2026 | N41: 9M TTM Q3 FY2026
B42: Net income | C42: 539.318 | D42: 1015.862 | E42: 1663.585 | F42: 593.463 | G42: 1108.493 | H42: 1760.219 | I42: 564.933 | J42: 1052.856 | K42: 1661.297 | L42: 530.823 | M42: 999.683 | N42: 1641.174
B43: Depreciation and amortization of property and equipment | C43: 109.253 | D43: 222.964 | E43: 339.087 | F43: 120.224 | G43: 245.192 | H43: 374.416 | I43: 133.173 | J43: 271.091 | K43: 415.787 | L43: 148.194 | M43: 303.834 | N43: 464.126
B44: Other non-cash charges (income) | C44: 81 | D44: 91 | E44: 74 | F44: -2 | G44: -16 | H44: -40 | I44: 0 | J44: 0 | K44: -16 | L44: 98 | M44: 157 | N44: 177
B45: Amortization of debt origination fees | C45: 1.905 | D45: 3.922 | E45: 6.065 | F45: 2.81 | G45: 5.551 | H45: 8.155 | I45: 3.018 | J45: 6.061 | K45: 9.083 | L45: 3.21 | M45: 5.978 | N45: 8.773
B46: Deferred income taxes | C46: 13.816 | D46: -4.697 | E46: -3.424 | F46: 0.882 | G46: 5.998 | H46: 9.016 | I46: -4.831 | J46: -43.734 | K46: -59.32 | L46: -41.724 | M46: -137.076 | N46: -157.734
B47: Share-based compensation expense | C47: 19.005 | D47: 42.379 | E47: 62.389 | F47: 22.913 | G47: 45.961 | H47: 71.314 | I47: 26.117 | J47: 56.563 | K47: 85.584 | L47: 30.727 | M47: 67.469 | N47: 97.641
B48: Accounts receivable | C48: 4.1 | D48: 22.273 | E48: 38.317 | F48: 6.856 | G48: 18.364 | H48: -66.55 | I48: 9.873 | J48: -54.575 | K48: -41.82 | L48: 36.7 | M48: -20.341 | N48: -86.607
B49: Merchandise inventories | C49: -39.308 | D49: -161.546 | E49: -93.163 | F49: -21.899 | G49: -198.425 | H49: -353.813 | I49: -136.181 | J49: -454.109 | K49: -642.317 | L49: -205.335 | M49: -552.373 | N49: -656.508
B50: Accounts payable and accrued expenses | C50: 6.574 | D50: -111.311 | E50: -239.9 | F50: 33.762 | G50: -17.062 | H50: 126.488 | I50: 170.032 | J50: 449.787 | K50: 603.613 | L50: 243.49 | M50: 235.756 | N50: 347.468
B51: Income taxes | C51: 73.954 | D51: 87.4 | E51: 64.041 | F51: 96.793 | G51: 96.282 | H51: 69.746 | I51: 103.019 | J51: 170.59 | K51: 135.953 | L51: 114.578 | M51: 185.174 | N51: 206.209
B52: Other, net (operating) | C52: -16.03 | D52: -60.185 | E52: -38.221 | F52: -23.545 | G52: -29.968 | H52: -25.125 | I52: -57.35 | J52: -58.978 | K52: 12.722 | L52: -14.492 | M52: 72.496 | N52: 78.045
B53: Net cash provided by operating activities | C53: 793.587 | D53: 1148.061 | E53: 1872.776 | F53: 830.259 | G53: 1264.386 | H53: 1933.866 | I53: 811.803 | J53: 1395.552 | K53: 2164.582 | L53: 944.171 | M53: 1317.6 | N53: 2119.587
... B71: Cash and cash equivalents at end of period | C71: 269.79 | D71: 301.286 | E71: 274.916 | F71: 282.981 | G71: 304.096 | H71: 275.358 | I71: 304.018 | J71: 300.905 | K71: 268.625 | L71: 287.639 | M71: 285.492 | N71: 253.729

Sheet CF Annual
B1: AutoZone, Inc. | Cash Flow Statement (Annual)
B2: $mm except per share
C4: FY2023 | D4: FY2024 | E4: FY2025 | F4: TTM Q3 FY2026
C5: 45164 | D5: 45535 | E5: 45899 | F5: 46151
B6: Net income | C6: 2528.426 | D6: 2662.427 | E6: 2498.247 | F6: 2478.124
B7: Depreciation and amortization of property and equipment | C7: 497.577 | D7: 549.755 | E7: 613.199 | F7: 661.538
B8: Other non-cash charges (income) | C8: 44 | D8: -40 | E8: 64 | F8: 257
B9: Amortization of debt origination fees | C9: 9.264 | D9: 11.988 | E9: 12.84 | F9: 12.53
B10: Deferred income taxes | C10: -25.707 | D10: -254.393 | E10: 115.389 | F10: 16.975
B11: Share-based compensation expense | C11: 93.087 | D11: 106.246 | E11: 124.717 | F11: 136.774
B12: Accounts receivable | C12: -6.674 | D12: -38.282 | E12: -118.606 | F12: -163.393
B13: Merchandise inventories | C13: -89.18 | D13: -453.101 | E13: -893.908 | F13: -908.099
B14: Accounts payable and accrued expenses | C14: -183.679 | D14: 244.134 | E14: 657.408 | F14: 401.263
B15: Income taxes | C15: 92.832 | D15: 296.398 | E15: 68.447 | F15: 138.703
B16: Other, net (operating) | C16: -19.158 | D16: -81.056 | E16: -24.396 | F16: 40.927
B17: Net cash provided by operating activities | C17: 2940.788 | D17: 3004.116 | E17: 3117.337 | F17: 3072.342
... B35: Cash and cash equivalents at end of period | C35: 277.054 | D35: 298.172 | E35: 271.803 | F35: 253.729
B36: Interest paid, net of interest cost capitalized | C36: 260.866 | D36: 353.819 | E36: 413.026
B37: Income taxes paid | C37: 570.25 | D37: 437.552 | E37: 313.488
B38: Leased assets obtained in exchange for new finance lease liabilities | C38: 58.316 | D38: 196.112 | E38: 95.759
B39: Leased assets obtained in exchange for new operating lease liabilities | C39: 428.15 | D39: 415.212 | E39: 533.197

Sheet DCF Model
C1: #VALUE!
C3: Valuation Date: | I3: =TODAY() -> 46289 | V3: Scenario Assumptions | W3: Bear | X3: Base | Y3: Bull | AA3: Selected
C4: Share Price on Valuation Date: | I4: {=_FV(C1,"Price")} -> 2864.49 | V4: Revenue Growth Rate (%) | W4: 0.02 | X4: =$R$11 -> 0.052240696 | Y4: 0 | AA4: =INDEX(W4:Y4,MATCH($I$6,$W$3:$Y$3,0)) -> 0.052240696
C5: Diluted Shares Outstanding | I5: ='IS Quarterly'!R17 -> 16.62 | J5: mm | V5: EBIT Margin (%) | W5: 0.15 | X5: 0.18 | Y5: 0 | AA5: =INDEX(W5:Y5,MATCH($I$6,$W$3:$Y$3,0)) -> 0.18
C6: Scenario: | I6: Base | V6: D&A as a % of Revenue | W6: 0.04 | X6: 0.035 | Y6: 0 | AA6: =INDEX(W6:Y6,MATCH($I$6,$W$3:$Y$3,0)) -> 0.035
C7: Select Operating Data
K8: Projected Annual Forecast | V8: Accounts Receivable as a % of Revenue | W8: 0.05 | X8: 0.04 | Y8: 0 | AA8: =INDEX(W8:Y8,MATCH($I$6,$W$3:$Y$3,0)) -> 0.04
G9: 45164 | H9: 45535 | I9: 45899 | J9: 46263 | K9: =EDATE(J9,12) -> 46628 | L9: =EDATE(K9,12) -> 46994 | M9: =EDATE(L9,12) -> 47359 | N9: =EDATE(M9,12) -> 47724 | O9: =EDATE(N9,12) -> 48089 | V9: Inventories as a % of Revenue | W9: 0.4 | X9: 0.38 | Y9: 0 | AA9: =INDEX(W9:Y9,MATCH($I$6,$W$3:$Y$3,0)) -> 0.38
C10: Revenue | G10: ='IS Annual'!C6 -> 17457.209 | H10: ='IS Annual'!D6 -> 18490.268 | I10: ='IS Annual'!E6 -> 18938.717 | J10: ='IS Annual'!F6 -> 20338.555 | K10: =J10*(1+K11)*$I$103 -> 19876.597 | L10: =(K10/$I$103)*(1+L11) -> 22519.061 | M10: =L10*(1+M11) -> 23695.473 | N10: =M10*(1+N11) -> 24933.341 | O10: =N10*(1+O11) -> 26235.876 | Q10: Arithmetic Avg | R10: Geometric Avg | S10: Harmean | V10: Prepaid Expenses as a % of Revenue | W10: 0.02 | X10: =$R$36 -> 0.016376622 | Y10: 0 | AA10: =INDEX(W10:Y10,MATCH($I$6,$W$3:$Y$3,0)) -> 0.016376622
C11: Revenue Growth Rate (%) | H11: =(H10/G10)-1 -> 0.059176642 | I11: =(I10/H10)-1 -> 0.024253245 | J11: =(J10/I10)-1 -> 0.073914088 | K11: =$AA$4 -> 0.052240696 | L11: =+K11 -> 0.052240696 | M11: =+L11 -> 0.052240696 | N11: =+M11 -> 0.052240696 | O11: =+N11 -> 0.052240696 | Q11: =AVERAGE(H11:J11) -> 0.052447992 | R11: =GEOMEAN(H12:J12)-1 -> 0.052240696 | S11: =HARMEAN(H12:J12)-1 -> 0.052032175 | V11: Accounts Payable/Accruals as a % of Revenue | W11: =R37 -> 0.41168672 | X11: =$R$37 -> 0.41168672 | Y11: 0 | AA11: =INDEX(W11:Y11,MATCH($I$6,$W$3:$Y$3,0)) -> 0.41168672
C12: Revenue Growth Rate (%) +1 | H12: =H11+1 -> 1.0591766 | I12: =I11+1 -> 1.0242532 | J12: =J11+1 -> 1.0739141 | V12: Accrued Expenses as a % of Revenue | W12: 0.08 | X12: 0.075 | Y12: 0 | AA12: =INDEX(W12:Y12,MATCH($I$6,$W$3:$Y$3,0)) -> 0.075
C14: EBIT | G14: ='IS Annual'!C10 -> 3473.986 | H14: ='IS Annual'!D10 -> 3788.708 | I14: ='IS Annual'!E10 -> 3610.156 | J14: ='IS Annual'!F10 -> 3723.314 | K14: =K15*K10 -> 3577.7874 | L14: =L15*L10 -> 4053.431 | M14: =M15*M10 -> 4265.1851 | N14: =N15*N10 -> 4488.0013 | O14: =O15*O10 -> 4722.4576 | Q14: Arithmetic Avg | R14: Geometric Avg | S14: Harmean | V14: Capital Expenditures as a % of Revenue | W14: 0.08 | X14: 0.073 | Y14: 0 | AA14: =INDEX(W14:Y14,MATCH($I$6,$W$3:$Y$3,0)) -> 0.073
C15: EBIT Margin (%) | G15: =IFERROR(G14/G10,"") -> 0.19900008 | H15: =IFERROR(H14/H10,"") -> 0.20490282 | I15: =IFERROR(I14/I10,"") -> 0.19062305 | J15: =IFERROR(J14/J10,"") -> 0.18306679 | K15: =$AA$5 -> 0.18 | L15: =+K15 -> 0.18 | M15: =+L15 -> 0.18 | N15: =+M15 -> 0.18 | O15: =+N15 -> 0.18 | Q15: =AVERAGE(G15:J15) -> 0.19439818 | R15: =IFERROR(GEOMEAN(G15:J15),"") -> 0.19422116 | S15: =IFERROR(HARMEAN(G15:J15),"") -> 0.19404356 | V15: Effective Tax Rate (%) | W15: 0.213 | X15: =IFERROR($R$52+0,$Q$52) -> 0.20384609 | Y15: 0 | AA15: =INDEX(W15:Y15,MATCH($I$6,$W$3:$Y$3,0)) -> 0.20384609
C17: Depreciation & Amortization | G17: ='CF Annual'!C7 -> 497.577 | H17: ='CF Annual'!D7 -> 549.755 | I17: ='CF Annual'!E7 -> 613.199 | J17: ='CF Annual'!F7 -> 661.538 | K17: =K18*K10 -> 695.68088 | L17: =L18*L10 -> 788.16714 | M17: =M18*M10 -> 829.34154 | N17: =N18*N10 -> 872.66692 | O17: =O18*O10 -> 918.25565 | Q17: Arithmetic Avg | R17: Geometric Avg | S17: Harmean | V17: Long-Term (Terminal) Growth Rate (%) | W17: 0.01 | X17: 0.02 | Y17: 0.025 | AA17: =INDEX(W17:Y17,MATCH($I$6,$W$3:$Y$3,0)) -> 0.02
C18: D&A as a % of revenue | G18: =IFERROR(G17/G10,"") -> 0.028502666 | H18: =IFERROR(H17/H10,"") -> 0.029732127 | I18: =IFERROR(I17/I10,"") -> 0.032378064 | J18: =IFERROR(J17/J10,"") -> 0.032526303 | K18: =$AA$6 -> 0.035 | L18: =+K18 -> 0.035 | M18: =+L18 -> 0.035 | N18: =+M18 -> 0.035 | O18: =+N18 -> 0.035 | Q18: =AVERAGE(G18:J18) -> 0.03078479 | R18: =IFERROR(GEOMEAN(G18:J18),"") -> 0.030736136 | S18: =IFERROR(HARMEAN(G18:J18),"") -> 0.030687191
C20: Select Balance Sheet And Other Data
K21: Projected Annual Forecast
G22: 45164 | H22: 45535 | I22: 45899 | J22: 46263 | K22: =EDATE(J22,12) -> 46628 | L22: =EDATE(K22,12) -> 46994 | M22: =EDATE(L22,12) -> 47359 | N22: =EDATE(M22,12) -> 47724 | O22: =EDATE(N22,12) -> 48089
C23: Accounts Receivable | G23: ='BS Annual'!C7 -> 520.385 | H23: ='BS Annual'!D7 -> 545.575 | I23: ='BS Annual'!E7 -> 670.137 | J23: ='BS Annual'!F7 -> 764.924 | K23: =K34*(K10/$I$103) -> 856.04221 | L23: =L34*L10 -> 900.76245 | M23: =M34*M10 -> 947.81891 | N23: =N34*N10 -> 997.33363 | O23: =O34*O10 -> 1049.435
C24: Inventories | G24: ='BS Annual'!C8 -> 5764.143 | H24: ='BS Annual'!D8 -> 6155.218 | I24: ='BS Annual'!E8 -> 7025.688 | J24: ='BS Annual'!F8 -> 7559.056 | K24: =K35*(K10/$I$103) -> 8132.401 | L24: =L35*L10 -> 8557.2433 | M24: =M35*M10 -> 9004.2796 | N24: =N35*N10 -> 9474.6695 | O24: =O35*O10 -> 9969.6328
C25: Prepaid Expenses | G25: ='BS Annual'!C9 -> 217.844 | H25: ='BS Annual'!D9 -> 307.794 | I25: ='BS Annual'!E9 -> 373.751 | J25: ='BS Annual'!F9 -> 356.86 | K25: =K36*(K10/$I$103) -> 350.477 | L25: =L36*L10 -> 368.78616 | M25: =M36*M10 -> 388.0518 | N25: =N36*N10 -> 408.3239 | O25: =O36*O10 -> 429.65503
C27: Accounts Payable and Accruals | G27: ='BS Annual'!C18 -> 7201.281 | H27: ='BS Annual'!D18 -> 7355.701 | I27: ='BS Annual'!E18 -> 8025.59 | J27: ='BS Annual'!F18 -> 8401.277 | K27: =K37*(K10/$I$103) -> 8810.5303 | L27: =L37*L10 -> 9270.7985 | M27: =M37*M10 -> 9755.1114 | N27: =N37*N10 -> 10264.725 | O27: =O37*O10 -> 10800.962
C28: Accrued Expenses | G28: ='BS Annual'!C20 -> 1000.841 | H28: ='BS Annual'!D20 -> 1060.746 | I28: ='BS Annual'!E20 -> 1151.536 | J28: ='BS Annual'!F20 -> 1226.757 | K28: =K38*(K10/$I$103) -> 1605.0791 | L28: =L38*L10 -> 1688.9296 | M28: =M38*M10 -> 1777.1605 | N28: =N38*N10 -> 1870.0006 | O28: =O38*O10 -> 1967.6907
C30: Debt | G30: =0+'BS Annual'!C23 -> 7668.549 | H30: =0+'BS Annual'!D23 -> 9024.381 | I30: =0+'BS Annual'!E23 -> 8799.775 | J30: =0+'BS Annual'!F23 -> 9016.477
C32: Capital Expenditures | G32: =-('CF Annual'!C18) -> 796.657 | H32: =-('CF Annual'!D18) -> 1072.696 | I32: =-('CF Annual'!E18) -> 1327.257 | J32: =-('CF Annual'!F18) -> 1439.12 | K32: =K39*K10 -> 1450.9915 | L32: =L39*L10 -> 1643.8915 | M32: =M39*M10 -> 1729.7695 | N32: =N39*N10 -> 1820.1339 | O32: =O39*O10 -> 1915.2189
Q33: Arithmetic Avg | R33: Geometric Avg | S33: Harmean
C34: Accounts Receivable as a % of revenue | G34: =IFERROR(G23/G10,"") -> 0.029809175 | H34: =IFERROR(H23/H10,"") -> 0.029506062 | I34: =IFERROR(I23/I10,"") -> 0.035384498 | J34: =IFERROR(J23/J10,"") -> 0.037609555 | K34: =$AA$8 -> 0.04 | L34: =$AA$8 -> 0.04 | M34: =$AA$8 -> 0.04 | N34: =$AA$8 -> 0.04 | O34: =$AA$8 -> 0.04 | Q34: =AVERAGE(G34:J34) -> 0.033077323 | R34: =IFERROR(GEOMEAN(G34:J34),"") -> 0.032892214 | S34: =IFERROR(HARMEAN(G34:J34),"") -> 0.032709666
C35: Inventories as a % of revenue | G35: =IFERROR(G24/G10,"") -> 0.33018697 | H35: =IFERROR(H24/H10,"") -> 0.3328896 | I35: =IFERROR(I24/I10,"") -> 0.37096959 | J35: =IFERROR(J24/J10,"") -> 0.37166141 | K35: =$AA$9 -> 0.38 | L35: =$AA$9 -> 0.38 | M35: =$AA$9 -> 0.38 | N35: =$AA$9 -> 0.38 | O35: =$AA$9 -> 0.38 | Q35: =AVERAGE(G35:J35) -> 0.35142689 | R35: =IFERROR(GEOMEAN(G35:J35),"") -> 0.35086212 | S35: =IFERROR(HARMEAN(G35:J35),"") -> 0.3502981
C36: Prepaid Expenses as a % of revenue | G36: =IFERROR(G25/G10,"") -> 0.012478742 | H36: =IFERROR(H25/H10,"") -> 0.01664627 | I36: =IFERROR(I25/I10,"") -> 0.019734758 | J36: =IFERROR(J25/J10,"") -> 0.017545986 | K36: =$AA$10 -> 0.016376622 | L36: =$AA$10 -> 0.016376622 | M36: =$AA$10 -> 0.016376622 | N36: =$AA$10 -> 0.016376622 | O36: =$AA$10 -> 0.016376622 | Q36: =AVERAGE(G36:J36) -> 0.016601439 | R36: =IFERROR(GEOMEAN(G36:J36),"") -> 0.016376622 | S36: =IFERROR(HARMEAN(G36:J36),"") -> 0.016137172
C37: Accounts Payable/Accruals as a % of revenue | G37: =IFERROR(G27/G10,"") -> 0.41251044 | H37: =IFERROR(H27/H10,"") -> 0.39781473 | I37: =IFERROR(I27/I10,"") -> 0.4237663 | J37: =IFERROR(J27/J10,"") -> 0.41307148 | K37: =$AA$11 -> 0.41168672 | L37: =$AA$11 -> 0.41168672 | M37: =$AA$11 -> 0.41168672 | N37: =$AA$11 -> 0.41168672 | O37: =$AA$11 -> 0.41168672 | Q37: =AVERAGE(G37:J37) -> 0.41179074 | R37: =IFERROR(GEOMEAN(G37:J37),"") -> 0.41168672 | S37: =IFERROR(HARMEAN(G37:J37),"") -> 0.41158218
C38: Accrued Expenses as a % of revenue | G38: =IFERROR(G28/G10,"") -> 0.0573311 | H38: =IFERROR(H28/H10,"") -> 0.0573678 | I38: =IFERROR(I28/I10,"") -> 0.060803274 | J38: =IFERROR(J28/J10,"") -> 0.060316822 | K38: =$AA$12 -> 0.075 | L38: =$AA$12 -> 0.075 | M38: =$AA$12 -> 0.075 | N38: =$AA$12 -> 0.075 | O38: =$AA$12 -> 0.075 | Q38: =AVERAGE(G38:J38) -> 0.058954749 | R38: =IFERROR(GEOMEAN(G38:J38),"") -> 0.05893265 | S38: =IFERROR(HARMEAN(G38:J38),"") -> 0.058910573
C39: Capital Expenditures as a % of revenue | G39: =IFERROR(G32/G10,"") -> 0.045634843 | H39: =IFERROR(H32/H10,"") -> 0.058014086 | I39: =IFERROR(I32/I10,"") -> 0.070081674 | J39: =IFERROR(J32/J10,"") -> 0.070758222 | K39: =$AA$14 -> 0.073 | L39: =$AA$14 -> 0.073 | M39: =$AA$14 -> 0.073 | N39: =$AA$14 -> 0.073 | O39: =$AA$14 -> 0.073 | Q39: =AVERAGE(G39:J39) -> 0.061122207 | R39: =IFERROR(GEOMEAN(G39:J39),"") -> 0.060193951 | S39: =IFERROR(HARMEAN(G39:J39),"") -> 0.059213667
C40: Accounts Receivable Growth (%) | H40: =IFERROR((H23/G23)-1,"") -> 0.048406468 | I40: =IFERROR((I23/H23)-1,"") -> 0.22831325 | J40: =IFERROR((J23/I23)-1,"") -> 0.14144421
C41: Inventories Growth (%) | H41: =IFERROR((H24/G24)-1,"") -> 0.067846166 | I41: =IFERROR((I24/H24)-1,"") -> 0.14141985 | J41: =IFERROR((J24/I24)-1,"") -> 0.075916835
C42: Prepaid Expenses Growth (%) | H42: =IFERROR((H25/G25)-1,"") -> 0.41291016 | I42: =IFERROR((I25/H25)-1,"") -> 0.21428943 | J42: =IFERROR((J25/I25)-1,"") -> -0.04519319
C43: Accounts Payable/Accruals Growth (%) | H43: =IFERROR((H27/G27)-1,"") -> 0.021443407 | I43: =IFERROR((I27/H27)-1,"") -> 0.091070722 | J43: =IFERROR((J27/I27)-1,"") -> 0.046811138
C44: Accrued Expenses Growth (%) | H44: =IFERROR((H28/G28)-1,"") -> 0.059854662 | I44: =IFERROR((I28/H28)-1,"") -> 0.085590707 | J44: =IFERROR((J28/I28)-1,"") -> 0.065322317
C45: Capital Expenditures Growth (%) | H45: =IFERROR((H32/G32)-1,"") -> 0.34649667 | I45: =IFERROR((I32/H32)-1,"") -> 0.23730955 | J45: =IFERROR((J32/I32)-1,"") -> 0.084281341
C46: Free Cash Flow Buildup
C47: $mm | K47: Projected Annual Forecast
...

Sheet Comps
B1: AutoZone, Inc. | Comparable Companies and Precedent Transactions
B2: $mm except per share; blue cells on yellow are inputs
B4: Trading Comparables
B5: Company | C5: Ticker | D5: Share Price | E5: Diluted Shares (mm) | F5: Market Cap | G5: Net Debt | H5: Enterprise Value | I5: EPS (LTM) | J5: EPS Growth (%) | K5: EBITDA (LTM) | L5: EBIT (LTM) | M5: EBITDAR (TTM) | N5: P/E | O5: EV/EBITDA | P5: EV/EBIT | Q5: PEG | R5: EV/EBITDAR
F6: =IF(COUNT(D6,E6)<2,"",D6*E6) | H6: =IF(F6="","",F6+G6) | N6: =IF(COUNT(D6,I6)<2,"",IF(I6<=0,"NM",D6/I6)) | O6: =IF(COUNT(H6,K6)<2,"",IF(K6<=0,"NM",H6/K6)) | P6: =IF(COUNT(H6,L6)<2,"",IF(L6<=0,"NM",H6/L6)) | Q6: =IF(OR(ISNUMBER(N6)=FALSE(),COUNT(J6)=0),"",IF(J6<=0,"NM",N6/(J6*100))) | R6: =IF(COUNT(H6,M6)<2,"",IF(M6<=0,"NM",H6/M6))
F7: =IF(COUNT(D7,E7)<2,"",D7*E7) | H7: =IF(F7="","",F7+G7) | N7: =IF(COUNT(D7,I7)<2,"",IF(I7<=0,"NM",D7/I7)) | O7: =IF(COUNT(H7,K7)<2,"",IF(K7<=0,"NM",H7/K7)) | P7: =IF(COUNT(H7,L7)<2,"",IF(L7<=0,"NM",H7/L7)) | Q7: =IF(OR(ISNUMBER(N7)=FALSE(),COUNT(J7)=0),"",IF(J7<=0,"NM",N7/(J7*100))) | R7: =IF(COUNT(H7,M7)<2,"",IF(M7<=0,"NM",H7/M7))
F8: =IF(COUNT(D8,E8)<2,"",D8*E8) | H8: =IF(F8="","",F8+G8) | N8: =IF(COUNT(D8,I8)<2,"",IF(I8<=0,"NM",D8/I8)) | O8: =IF(COUNT(H8,K8)<2,"",IF(K8<=0,"NM",H8/K8)) | P8: =IF(COUNT(H8,L8)<2,"",IF(L8<=0,"NM",H8/L8)) | Q8: =IF(OR(ISNUMBER(N8)=FALSE(),COUNT(J8)=0),"",IF(J8<=0,"NM",N8/(J8*100))) | R8: =IF(COUNT(H8,M8)<2,"",IF(M8<=0,"NM",H8/M8))
F9: =IF(COUNT(D9,E9)<2,"",D9*E9) | H9: =IF(F9="","",F9+G9) | N9: =IF(COUNT(D9,I9)<2,"",IF(I9<=0,"NM",D9/I9)) | O9: =IF(COUNT(H9,K9)<2,"",IF(K9<=0,"NM",H9/K9)) | P9: =IF(COUNT(H9,L9)<2,"",IF(L9<=0,"NM",H9/L9)) | Q9: =IF(OR(ISNUMBER(N9)=FALSE(),COUNT(J9)=0),"",IF(J9<=0,"NM",N9/(J9*100))) | R9: =IF(COUNT(H9,M9)<2,"",IF(M9<=0,"NM",H9/M9))
F10: =IF(COUNT(D10,E10)<2,"",D10*E10) | H10: =IF(F10="","",F10+G10) | N10: =IF(COUNT(D10,I10)<2,"",IF(I10<=0,"NM",D10/I10)) | O10: =IF(COUNT(H10,K10)<2,"",IF(K10<=0,"NM",H10/K10)) | P10: =IF(COUNT(H10,L10)<2,"",IF(L10<=0,"NM",H10/L10)) | Q10: =IF(OR(ISNUMBER(N10)=FALSE(),COUNT(J10)=0),"",IF(J10<=0,"NM",N10/(J10*100))) | R10: =IF(COUNT(H10,M10)<2,"",IF(M10<=0,"NM",H10/M10))
B12: Mean | N12: =IF(COUNT(N6:N10)=0,"",AVERAGE(N6:N10)) | O12: =IF(COUNT(O6:O10)=0,"",AVERAGE(O6:O10)) | P12: =IF(COUNT(P6:P10)=0,"",AVERAGE(P6:P10)) | Q12: =IF(COUNT(Q6:Q10)=0,"",AVERAGE(Q6:Q10)) | R12: =IF(COUNT(R6:R10)=0,"",AVERAGE(R6:R10))
B13: Median | N13: =IF(COUNT(N6:N10)=0,"",MEDIAN(N6:N10)) | O13: =IF(COUNT(O6:O10)=0,"",MEDIAN(O6:O10)) | P13: =IF(COUNT(P6:P10)=0,"",MEDIAN(P6:P10)) | Q13: =IF(COUNT(Q6:Q10)=0,"",MEDIAN(Q6:Q10)) | R13: =IF(COUNT(R6:R10)=0,"",MEDIAN(R6:R10))
B14: 25th Percentile | N14: =IF(COUNT(N6:N10)=0,"",QUARTILE(N6:N10,1)) | O14: =IF(COUNT(O6:O10)=0,"",QUARTILE(O6:O10,1)) | P14: =IF(COUNT(P6:P10)=0,"",QUARTILE(P6:P10,1)) | Q14: =IF(COUNT(Q6:Q10)=0,"",QUARTILE(Q6:Q10,1)) | R14: =IF(COUNT(R6:R10)=0,"",QUARTILE(R6:R10,1))
B15: 75th Percentile | N15: =IF(COUNT(N6:N10)=0,"",QUARTILE(N6:N10,3)) | O15: =IF(COUNT(O6:O10)=0,"",QUARTILE(O6:O10,3)) | P15: =IF(COUNT(P6:P10)=0,"",QUARTILE(P6:P10,3)) | Q15: =IF(COUNT(Q6:Q10)=0,"",QUARTILE(Q6:Q10,3)) | R15: =IF(COUNT(R6:R10)=0,"",QUARTILE(R6:R10,3))
B16: High | N16: =IF(COUNT(N6:N10)=0,"",MAX(N6:N10)) | O16: =IF(COUNT(O6:O10)=0,"",MAX(O6:O10)) | P16: =IF(COUNT(P6:P10)=0,"",MAX(P6:P10)) | Q16: =IF(COUNT(Q6:Q10)=0,"",MAX(Q6:Q10)) | R16: =IF(COUNT(R6:R10)=0,"",MAX(R6:R10))
B17: Low | N17: =IF(COUNT(N6:N10)=0,"",MIN(N6:N10)) | O17: =IF(COUNT(O6:O10)=0,"",MIN(O6:O10)) | P17: =IF(COUNT(P6:P10)=0,"",MIN(P6:P10)) | Q17: =IF(COUNT(Q6:Q10)=0,"",MIN(Q6:Q10)) | R17: =IF(COUNT(R6:R10)=0,"",MIN(R6:R10))
B19: Precedent Transactions
B20: Target | C20: Acquirer | D20: Date Announced | E20: Enterprise Value | F20: Equity Value | G20: Net Income (LTM) | H20: Net Income Growth (%) | I20: EBITDA (LTM) | J20: EBIT (LTM) | K20: EBITDAR (TTM) | N20: P/E | O20: EV/EBITDA | P20: EV/EBIT | Q20: PEG | R20: EV/EBITDAR
N21: =IF(COUNT(F21,G21)<2,"",IF(G21<=0,"NM",F21/G21)) | O21: =IF(COUNT(E21,I21)<2,"",IF(I21<=0,"NM",E21/I21)) | P21: =IF(COUNT(E21,J21)<2,"",IF(J21<=0,"NM",E21/J21)) | Q21: =IF(OR(ISNUMBER(N21)=FALSE(),COUNT(H21)=0),"",IF(H21<=0,"NM",N21/(H21*100))) | R21: =IF(COUNT(E21,K21)<2,"",IF(K21<=0,"NM",E21/K21))
N22: =IF(COUNT(F22,G22)<2,"",IF(G22<=0,"NM",F22/G22)) | O22: =IF(COUNT(E22,I22)<2,"",IF(I22<=0,"NM",E22/I22)) | P22: =IF(COUNT(E22,J22)<2,"",IF(J22<=0,"NM",E22/J22)) | Q22: =IF(OR(ISNUMBER(N22)=FALSE(),COUNT(H22)=0),"",IF(H22<=0,"NM",N22/(H22*100))) | R22: =IF(COUNT(E22,K22)<2,"",IF(K22<=0,"NM",E22/K22))
N23: =IF(COUNT(F23,G23)<2,"",IF(G23<=0,"NM",F23/G23)) | O23: =IF(COUNT(E23,I23)<2,"",IF(I23<=0,"NM",E23/I23)) | P23: =IF(COUNT(E23,J23)<2,"",IF(J23<=0,"NM",E23/J23)) | Q23: =IF(OR(ISNUMBER(N23)=FALSE(),COUNT(H23)=0),"",IF(H23<=0,"NM",N23/(H23*100))) | R23: =IF(COUNT(E23,K23)<2,"",IF(K23<=0,"NM",E23/K23))
N24: =IF(COUNT(F24,G24)<2,"",IF(G24<=0,"NM",F24/G24)) | O24: =IF(COUNT(E24,I24)<2,"",IF(I24<=0,"NM",E24/I24)) | P24: =IF(COUNT(E24,J24)<2,"",IF(J24<=0,"NM",E24/J24)) | Q24: =IF(OR(ISNUMBER(N24)=FALSE(),COUNT(H24)=0),"",IF(H24<=0,"NM",N24/(H24*100))) | R24: =IF(COUNT(E24,K24)<2,"",IF(K24<=0,"NM",E24/K24))
N25: =IF(COUNT(F25,G25)<2,"",IF(G25<=0,"NM",F25/G25)) | O25: =IF(COUNT(E25,I25)<2,"",IF(I25<=0,"NM",E25/I25)) | P25: =IF(COUNT(E25,J25)<2,"",IF(J25<=0,"NM",E25/J25)) | Q25: =IF(OR(ISNUMBER(N25)=FALSE(),COUNT(H25)=0),"",IF(H25<=0,"NM",N25/(H25*100))) | R25: =IF(COUNT(E25,K25)<2,"",IF(K25<=0,"NM",E25/K25))
B27: Mean | N27: =IF(COUNT(N21:N25)=0,"",AVERAGE(N21:N25)) | O27: =IF(COUNT(O21:O25)=0,"",AVERAGE(O21:O25)) | P27: =IF(COUNT(P21:P25)=0,"",AVERAGE(P21:P25)) | Q27: =IF(COUNT(Q21:Q25)=0,"",AVERAGE(Q21:Q25)) | R27: =IF(COUNT(R21:R25)=0,"",AVERAGE(R21:R25))
B28: Median | N28: =IF(COUNT(N21:N25)=0,"",MEDIAN(N21:N25)) | O28: =IF(COUNT(O21:O25)=0,"",MEDIAN(O21:O25)) | P28: =IF(COUNT(P21:P25)=0,"",MEDIAN(P21:P25)) | Q28: =IF(COUNT(Q21:Q25)=0,"",MEDIAN(Q21:Q25)) | R28: =IF(COUNT(R21:R25)=0,"",MEDIAN(R21:R25))
B29: 25th Percentile | N29: =IF(COUNT(N21:N25)=0,"",QUARTILE(N21:N25,1)) | O29: =IF(COUNT(O21:O25)=0,"",QUARTILE(O21:O25,1)) | P29: =IF(COUNT(P21:P25)=0,"",QUARTILE(P21:P25,1)) | Q29: =IF(COUNT(Q21:Q25)=0,"",QUARTILE(Q21:Q25,1)) | R29: =IF(COUNT(R21:R25)=0,"",QUARTILE(R21:R25,1))
B30: 75th Percentile | N30: =IF(COUNT(N21:N25)=0,"",QUARTILE(N21:N25,3)) | O30: =IF(COUNT(O21:O25)=0,"",QUARTILE(O21:O25,3)) | P30: =IF(COUNT(P21:P25)=0,"",QUARTILE(P21:P25,3)) | Q30: =IF(COUNT(Q21:Q25)=0,"",QUARTILE(Q21:Q25,3)) | R30: =IF(COUNT(R21:R25)=0,"",QUARTILE(R21:R25,3))
B31: High | N31: =IF(COUNT(N21:N25)=0,"",MAX(N21:N25)) | O31: =IF(COUNT(O21:O25)=0,"",MAX(O21:O25)) | P31: =IF(COUNT(P21:P25)=0,"",MAX(P21:P25)) | Q31: =IF(COUNT(Q21:Q25)=0,"",MAX(Q21:Q25)) | R31: =IF(COUNT(R21:R25)=0,"",MAX(R21:R25))
B32: Low | N32: =IF(COUNT(N21:N25)=0,"",MIN(N21:N25)) | O32: =IF(COUNT(O21:O25)=0,"",MIN(O21:O25)) | P32: =IF(COUNT(P21:P25)=0,"",MIN(P21:P25)) | Q32: =IF(COUNT(Q21:Q25)=0,"",MIN(Q21:Q25)) | R32: =IF(COUNT(R21:R25)=0,"",MIN(R21:R25))
B34: AutoZone, Inc. Metrics (TTM Q3 FY2026)
B35: EPS (Diluted) | C35: ='IS Annual'!F18 -> 152.55
B36: EPS Growth (%) | C36: 0
B37: EBITDA | C37: ='IS Annual'!F10+'CF Annual'!F7 -> 4384.852
B38: EBIT | C38: ='IS Annual'!F10 -> 3723.314
B39: EBITDAR (TTM) | C39: 4727.016
B40: Net Debt | C40: ='DCF Model'!I93 -> 8762.748
B41: Diluted Shares (mm) | C41: ='DCF Model'!I5 -> 16.62
B44: Implied Value Per Share: Trading Comps
B45: Multiple | C45: 25th Percentile | D45: Median | E45: 75th Percentile
B46: P/E | C46: =IF(OR(ISNUMBER($N$14)=FALSE(),ISNUMBER($C$35)=FALSE()),"",IF($C$35<=0,"NM",$N$14*$C$35)) | D46: =IF(OR(ISNUMBER($N$13)=FALSE(),ISNUMBER($C$35)=FALSE()),"",IF($C$35<=0,"NM",$N$13*$C$35)) | E46: =IF(OR(ISNUMBER($N$15)=FALSE(),ISNUMBER($C$35)=FALSE()),"",IF($C$35<=0,"NM",$N$15*$C$35))
B47: EV/EBITDA | C47: =IF(OR(ISNUMBER($O$14)=FALSE(),ISNUMBER($C$37)=FALSE()),"",IF($C$37<=0,"NM",($O$14*$C$37-$C$40)/$C$41)) | D47: =IF(OR(ISNUMBER($O$13)=FALSE(),ISNUMBER($C$37)=FALSE()),"",IF($C$37<=0,"NM",($O$13*$C$37-$C$40)/$C$41)) | E47: =IF(OR(ISNUMBER($O$15)=FALSE(),ISNUMBER($C$37)=FALSE()),"",IF($C$37<=0,"NM",($O$15*$C$37-$C$40)/$C$41))
...

Sheet Liquidation
B1: AutoZone, Inc. | Liquidation Value (TTM Q3 FY2026 Balance Sheet)
B2: $mm except per share
B4: Asset | C4: Book Value | D4: Orderly Recovery | E4: Orderly Value | F4: Fire Sale Recovery | G4: Fire Sale Value
B5: Cash and cash equivalents | C5: ='BS Annual'!F6 -> 253.729 | D5: 1 | E5: =C5*D5 -> 253.729 | F5: 1 | G5: =C5*F5 -> 253.729
B6: Accounts receivable | C6: ='BS Annual'!F7 -> 764.924 | D6: 0.85 | E6: =C6*D6 -> 650.1854 | F6: 0.6 | G6: =C6*F6 -> 458.9544
B7: Merchandise inventories | C7: ='BS Annual'!F8 -> 7559.056 | D7: 0.65 | E7: =C7*D7 -> 4913.3864 | F7: 0.4 | G7: =C7*F7 -> 3023.6224
B8: Other current assets | C8: ='BS Annual'!F9 -> 356.86 | D8: 0.25 | E8: =C8*D8 -> 89.215 | F8: 0 | G8: =C8*F8 -> 0
B9: Property and equipment, net | C9: ='BS Annual'!F11 -> 7796.988 | D9: 0.4 | E9: =C9*D9 -> 3118.7952 | F9: 0.15 | G9: =C9*F9 -> 1169.5482
B10: Operating lease right-of-use assets | C10: ='BS Annual'!F12 -> 3413.97 | D10: 0 | E10: =C10*D10 -> 0 | F10: 0 | G10: =C10*F10 -> 0
B11: Goodwill | C11: ='BS Annual'!F13 -> 302.645 | D11: 0 | E11: =C11*D11 -> 0 | F11: 0 | G11: =C11*F11 -> 0
B12: Deferred income taxes (asset) | C12: ='BS Annual'!F14 -> 132.109 | D12: 0.1 | E12: =C12*D12 -> 13.2109 | F12: 0 | G12: =C12*F12 -> 0
B13: Other long-term assets | C13: ='BS Annual'!F15 -> 336.182 | D13: 0.1 | E13: =C13*D13 -> 33.6182 | F13: 0 | G13: =C13*F13 -> 0
B14: Gross Proceeds | C14: =SUM(C5:C13) -> 20916.463 | E14: =SUM(E5:E13) -> 9072.1401 | G14: =SUM(G5:G13) -> 4905.854
B15: Less: Wind-Down Costs | D15: 0.05 | E15: =-E14*D15 -> -453.60701 | F15: 0.1 | G15: =-G14*F15 -> -490.5854
B16: Less: Total Liabilities | C16: =-('BS Annual'!F22+'BS Annual'!F23+'BS Annual'!F24+'BS Annual'!F25+'BS Annual'!F26) -> -23701.015 | E16: =C16 -> -23701.015 | G16: =C16 -> -23701.015
B17: Net Liquidation Value | E17: =E14+E15+E16 -> -15082.482 | G17: =G14+G15+G16 -> -19285.746
B18: Diluted Shares (mm) | E18: ='DCF Model'!I5 -> 16.62 | G18: ='DCF Model'!I5 -> 16.62
B19: Liquidation Value Per Share | E19: =E17/E18 -> -907.48989 | G19: =G17/G18 -> -1160.3939

Sheet Summary
B1: AutoZone, Inc. | Valuation Summary
B2: $ per share
B4: Current Share Price | C4: ='DCF Model'!I4 -> 2864.49
B6: Method | C6: Low | D6: Base | E6: High | F6: Base vs. Price
B7: DCF (WACC +/- 1%) | C7: ='DCF Model'!K101 -> 2497.692 | D7: ='DCF Model'!I96 -> 3235.5371 | E7: ='DCF Model'!I101 -> 4443.2035 | F7: =IF(ISNUMBER(D7),D7/$C$4-1,"") -> 0.12953339 | H7: =IF(AND(ISNUMBER(C7),ISNUMBER(E7)),MAX(0,MIN(C7,E7)),0) -> 2497.692 | I7: =IF(AND(ISNUMBER(C7),ISNUMBER(E7)),MAX(0,MAX(C7,E7))-H7,0) -> 1945.5115
B8: Trading Comps: P/E | C8: =Comps!C46 | D8: =Comps!D46 | E8: =Comps!E46 | F8: =IF(ISNUMBER(D8),D8/$C$4-1,"") | H8: =IF(AND(ISNUMBER(C8),ISNUMBER(E8)),MAX(0,MIN(C8,E8)),0) -> 0 | I8: =IF(AND(ISNUMBER(C8),ISNUMBER(E8)),MAX(0,MAX(C8,E8))-H8,0) -> 0
B9: Trading Comps: EV/EBITDA | C9: =Comps!C47 | D9: =Comps!D47 | E9: =Comps!E47 | F9: =IF(ISNUMBER(D9),D9/$C$4-1,"") | H9: =IF(AND(ISNUMBER(C9),ISNUMBER(E9)),MAX(0,MIN(C9,E9)),0) -> 0 | I9: =IF(AND(ISNUMBER(C9),ISNUMBER(E9)),MAX(0,MAX(C9,E9))-H9,0) -> 0
B10: Trading Comps: EV/EBIT | C10: =Comps!C48 | D10: =Comps!D48 | E10: =Comps!E48 | F10: =IF(ISNUMBER(D10),D10/$C$4-1,"") | H10: =IF(AND(ISNUMBER(C10),ISNUMBER(E10)),MAX(0,MIN(C10,E10)),0) -> 0 | I10: =IF(AND(ISNUMBER(C10),ISNUMBER(E10)),MAX(0,MAX(C10,E10))-H10,0) -> 0
B11: Trading Comps: PEG | C11: =Comps!C49 | D11: =Comps!D49 | E11: =Comps!E49 | F11: =IF(ISNUMBER(D11),D11/$C$4-1,"") | H11: =IF(AND(ISNUMBER(C11),ISNUMBER(E11)),MAX(0,MIN(C11,E11)),0) -> 0 | I11: =IF(AND(ISNUMBER(C11),ISNUMBER(E11)),MAX(0,MAX(C11,E11))-H11,0) -> 0
B12: Trading Comps: EV/EBITDAR | C12: =Comps!C50 | D12: =Comps!D50 | E12: =Comps!E50 | F12: =IF(ISNUMBER(D12),D12/$C$4-1,"") | H12: =IF(AND(ISNUMBER(C12),ISNUMBER(E12)),MAX(0,MIN(C12,E12)),0) -> 0 | I12: =IF(AND(ISNUMBER(C12),ISNUMBER(E12)),MAX(0,MAX(C12,E12))-H12,0) -> 0
B13: Precedent Transactions: P/E | C13: =Comps!C55 | D13: =Comps!D55 | E13: =Comps!E55 | F13: =IF(ISNUMBER(D13),D13/$C$4-1,"") | H13: =IF(AND(ISNUMBER(C13),ISNUMBER(E13)),MAX(0,MIN(C13,E13)),0) -> 0 | I13: =IF(AND(ISNUMBER(C13),ISNUMBER(E13)),MAX(0,MAX(C13,E13))-H13,0) -> 0
B14: Precedent Transactions: EV/EBITDA | C14: =Comps!C56 | D14: =Comps!D56 | E14: =Comps!E56 | F14: =IF(ISNUMBER(D14),D14/$C$4-1,"") | H14: =IF(AND(ISNUMBER(C14),ISNUMBER(E14)),MAX(0,MIN(C14,E14)),0) -> 0 | I14: =IF(AND(ISNUMBER(C14),ISNUMBER(E14)),MAX(0,MAX(C14,E14))-H14,0) -> 0
B15: Precedent Transactions: EV/EBIT | C15: =Comps!C57 | D15: =Comps!D57 | E15: =Comps!E57 | F15: =IF(ISNUMBER(D15),D15/$C$4-1,"") | H15: =IF(AND(ISNUMBER(C15),ISNUMBER(E15)),MAX(0,MIN(C15,E15)),0) -> 0 | I15: =IF(AND(ISNUMBER(C15),ISNUMBER(E15)),MAX(0,MAX(C15,E15))-H15,0) -> 0
B16: Precedent Transactions: PEG | C16: =Comps!C58 | D16: =Comps!D58 | E16: =Comps!E58 | F16: =IF(ISNUMBER(D16),D16/$C$4-1,"") | H16: =IF(AND(ISNUMBER(C16),ISNUMBER(E16)),MAX(0,MIN(C16,E16)),0) -> 0 | I16: =IF(AND(ISNUMBER(C16),ISNUMBER(E16)),MAX(0,MAX(C16,E16))-H16,0) -> 0
B17: Precedent Transactions: EV/EBITDAR | C17: =Comps!C59 | D17: =Comps!D59 | E17: =Comps!E59 | F17: =IF(ISNUMBER(D17),D17/$C$4-1,"") | H17: =IF(AND(ISNUMBER(C17),ISNUMBER(E17)),MAX(0,MIN(C17,E17)),0) -> 0 | I17: =IF(AND(ISNUMBER(C17),ISNUMBER(E17)),MAX(0,MAX(C17,E17))-H17,0) -> 0
B18: Liquidation (Fire Sale to Orderly) | C18: =Liquidation!G19 -> -1160.3939 | E18: =Liquidation!E19 -> -907.48989 | F18: =IF(ISNUMBER(D18),D18/$C$4-1,"") | H18: =IF(AND(ISNUMBER(C18),ISNUMBER(E18)),MAX(0,MIN(C18,E18)),0) -> 0 | I18: =IF(AND(ISNUMBER(C18),ISNUMBER(E18)),MAX(0,MAX(C18,E18))-H18,0) -> 0
