Workbook

Sheet Main
B2: CASY | C2: Statements as of FY2026 10-K (period ended 4/30/26)
B3: Price | C3: 824
B4: Diluted Shares Outstanding (millions) | C4: 37.241037
B5: Market Cap | C5: =C3*C4 -> 30686.614
B6: Cash | C6: =BS!H3/1000 -> 522.991
B7: Debt | C7: =(BS!H22+BS!H30)/1000 -> 2431.594
B8: EV | C8: =C5+C7-C6 -> 32595.217
B10: CEO:
B11: CFO:
B12: Founder/exec chairman:
B14: Revenue Categories
B15: Category | C15: FY2026 Revenue | D15: FY2026 Margin %
B16: Fuel | C16: =Fuel!H8 -> 10615407 | D16: =Fuel!H10 -> 0.14098291
B17: Grocery & General Merchandise | C17: ='Grocery & General Merchandise'!H8 -> 4563614 | D17: ='Grocery & General Merchandise'!H10 -> 0.35835743
B18: Prepared Food & Beverage | C18: ='Prepared Food & Beverage'!H8 -> 1776828 | D18: ='Prepared Food & Beverage'!H10 -> 0.58584342

Sheet 10QIS
B2: Casey's General Stores, Inc. (CASY)
B4: Historic Quarterly Income Statement | C4: Q1'21 | D4: Q2'21 | E4: Q3'21 | F4: Q4'21 | G4: Q1'22 | H4: Q2'22 | I4: Q3'22 | J4: Q4'22 | K4: Q1'23 | L4: Q2'23 | M4: Q3'23 | N4: Q4'23 | O4: Q1'24 | P4: Q2'24 | Q4: Q3'24 | R4: Q4'24 | S4: Q1'25 | T4: Q2'25 | U4: Q3'25 | V4: Q4'25 | W4: Q1'26 | X4: Q2'26 | Y4: Q3'26 | Z4: Q4'26
B5: Total Revenue | C5: 2105021 | D5: 2215905 | E5: 2008028 | F5: 2378235 | G5: 3181994 | H5: 3262942 | I5: 3048717 | J5: =12952594-(3181994+3262942+3048717) -> 3458941 | K5: 4454644 | L5: 3978575 | M5: 3332555 | N5: =15094475-(4454644+3978575+3332555) -> 3328701 | O5: 3869251 | P5: 4064400 | Q5: 3329247 | R5: =14862913-(3869251+4064400+3329247) -> 3600015 | S5: 4097737 | T5: 3946771 | U5: 3903633 | V5: =15940899-(4097737+3946771+3903633) -> 3992758 | W5: 4567106 | X5: 4506084 | Y5: 3916132 | Z5: =17561101-(4567106+4506084+3916132) -> 4571779
B6: Cost of goods sold | C6: 1481518 | D6: 1584145 | E6: 1467847 | F6: 1817244 | G6: 2458107 | H6: 2545352 | I6: 2384222 | J6: =10189880-(2458107+2545352+2384222) -> 2802199 | K6: 3618394 | L6: 3167633 | M6: 2595093 | N6: =12022069-(3618394+3167633+2595093) -> 2640949 | O6: 2991497 | P6: 3178839 | Q6: 2542724 | R6: =11515002-(2991497+3178839+2542724) -> 2801942 | S6: 3142481 | T6: 2988212 | U6: 2991065 | V6: =12188496-(3142481+2988212+2991065) -> 3066738 | W6: 3454660 | X6: 3384398 | Y6: 2909580 | Z6: =13240060-(3454660+3384398+2909580) -> 3491422
B7: Gross Margin | C7: =C5-C6 -> 623503 | D7: =D5-D6 -> 631760 | E7: =E5-E6 -> 540181 | F7: =F5-F6 -> 560991 | G7: =G5-G6 -> 723887 | H7: =H5-H6 -> 717590 | I7: =I5-I6 -> 664495 | J7: =J5-J6 -> 656742 | ... Z7: =Z5-Z6 -> 1080357
B8: Operating expenses | C8: 386088 | D8: 410348 | E8: 414448 | F8: 426307 | G8: 478928 | H8: 500644 | I8: 490997 | J8: =1961473-(478928+500644+490997) -> 490904 | K8: 543271 | L8: 539207 | M8: 515735 | N8: =2119942-(543271+539207+515735) -> 521729 | O8: 560855 | P8: 579703 | Q8: 568908 | R8: =2288513-(560855+579703+568908) -> 579047 | S8: 609474 | T8: 609679 | U8: 670200 | V8: =2552356-(609474+609679+670200) -> 663003 | W8: 698176 | X8: 711587 | Y8: 697640 | Z8: =2837426-(698176+711587+697640) -> 730023
B9: Depreciation and amortization | C9: 65820 | D9: 64294 | E9: 65185 | F9: 69896 | G9: 75888 | H9: 74258 | I9: 75529 | J9: =303541-(75888+74258+75529) -> 77866 | K9: 76295 | L9: 78117 | M9: 78088 | N9: =313131-(76295+78117+78088) -> 80631 | O9: 82905 | P9: 85598 | Q9: 88950 | R9: =349797-(82905+85598+88950) -> 92344 | S9: 94409 | T9: 96592 | U9: 105203 | V9: =403647-(94409+96592+105203) -> 107443 | W9: 108963 | X9: 111416 | Y9: 114084 | Z9: =449958-(108963+111416+114084) -> 115495
B10: Interest, net | C10: 13407 | D10: 10634 | E10: 11469 | F10: 11169 | G10: 13730 | H10: 13520 | I10: 14431 | J10: =56972-(13730+13520+14431) -> 15291 | K10: 13816 | L10: 13502 | M10: 11697 | N10: =51815-(13816+13502+11697) -> 12800 | O10: 12495 | P10: 12306 | Q10: 14146 | R10: =53441-(12495+12306+14146) -> 14494 | S10: 14067 | T10: 12553 | U10: 29415 | V10: =83951-(14067+12553+29415) -> 27916 | W10: 26850 | X10: 24690 | Y10: 23381 | Z10: =96634-(26850+24690+23381) -> 21713
B11: Income before income taxes | C11: =C7-C8-C9-C10 -> 158188 | D11: =D7-D8-D9-D10 -> 146484 | E11: =E7-E8-E9-E10 -> 49079 | F11: =F7-F8-F9-F10 -> 53619 | G11: =G7-G8-G9-G10 -> 155341 | H11: =H7-H8-H9-H10 -> 129168 | I11: =I7-I8-I9-I10 -> 83538 | J11: =J7-J8-J9-J10 -> 72681 | ... Z11: =Z7-Z8-Z9-Z10 -> 213126
B12: Federal and state income taxes | C12: 37596 | D12: 34501 | E12: 10452 | F12: 11921 | G12: 36182 | H12: 32337 | I12: 19514 | J12: =100938-(36182+32337+19514) -> 12905 | K12: 49936 | L12: 42561 | M12: 31830 | N12: =140827-(49936+42561+31830) -> 16500 | O12: 52262 | P12: 49172 | Q12: 27586 | R12: =154188-(52262+49172+27586) -> 25168 | S12: 57108 | T12: 58817 | U12: 20653 | V12: =165929-(57108+58817+20653) -> 29351 | W12: 63102 | X12: 67657 | Y12: 41374 | Z12: =222575-(63102+67657+41374) -> 50442
B13: Net income | C13: =C11-C12 -> 120592 | D13: =D11-D12 -> 111983 | E13: =E11-E12 -> 38627 | F13: =F11-F12 -> 41698 | G13: =G11-G12 -> 119159 | H13: =H11-H12 -> 96831 | I13: =I11-I12 -> 64024 | J13: =J11-J12 -> 59776 | ... Z13: =Z11-Z12 -> 162684
B14: Diluted EPS | C14: =(C13/1000)/C15 -> 3.2380495 | D14: =(D13/1000)/D15 -> 3.004087 | E14: =(E13/1000)/E15 -> 1.0360322 | F14: =(F13/1000)/F15 -> 1.1188823 | G14: =(G13/1000)/G15 -> 3.1915791 | H14: =(H13/1000)/H15 -> 2.591236 | I14: =(I13/1000)/I15 -> 1.7134026 | J14: =(J13/1000)/J15 -> 1.6001332 | ... Z14: =(Z13/1000)/Z15 -> 4.3623493
B15: Diluted weighted average shares outstanding (millions) | C15: 37.242173 | D15: 37.276883 | E15: 37.283591 | F15: 37.267549 | G15: 37.335437 | H15: 37.368653 | I15: 37.366583 | J15: 37.356891 | K15: 37.409705 | L15: 37.523759 | M15: 37.564551 | N15: 37.499338 | O15: 37.456139 | P15: 37.431075 | Q15: 37.336083 | R15: 37.407766 | S15: 37.277694 | T15: 37.311479 | U15: 37.362056 | V15: 37.317076 | W15: 37.35208 | X15: 37.285133 | Y15: 37.241037 | Z15: 37.29275
B18: Historic Drivers
B19: Revenue Growth Rate (YoY) | G19: =(G5-C5)/C5 -> 0.51162102 | H19: =(H5-D5)/D5 -> 0.47250988 | I19: =(I5-E5)/E5 -> 0.51826419 | J19: =(J5-F5)/F5 -> 0.45441514 | K19: =(K5-G5)/G5 -> 0.39995361 | L19: =(L5-H5)/H5 -> 0.2193214 | M19: =(M5-I5)/I5 -> 0.093100803 | N19: =(N5-J5)/J5 -> -0.037653143 | ... Z19: =(Z5-V5)/V5 -> 0.1450178
B20: Gross Margin % | C20: =C7/C5 -> 0.296198 | D20: =D7/D5 -> 0.28510248 | E20: =E7/E5 -> 0.26901069 | F20: =F7/F5 -> 0.23588544 | G20: =G7/G5 -> 0.22749477 | H20: =H7/H5 -> 0.21992116 | I20: =I7/I5 -> 0.2179589 | J20: =J7/J5 -> 0.18986794 | ... Z20: =Z7/Z5 -> 0.23630998
B21: Operating Expenses % of Revenue | C21: =C8/C5 -> 0.1834129 | D21: =D8/D5 -> 0.18518303 | E21: =E8/E5 -> 0.20639553 | F21: =F8/F5 -> 0.17925352 | G21: =G8/G5 -> 0.15051191 | H21: =H8/H5 -> 0.15343331 | I21: =I8/I5 -> 0.16105037 | J21: =J8/J5 -> 0.14192321 | ... Z21: =Z8/Z5 -> 0.15968029
B22: D&A % of Revenue | C22: =C9/C5 -> 0.031268097 | D22: =D9/D5 -> 0.029014782 | E22: =E9/E5 -> 0.032462197 | F22: =F9/F5 -> 0.029389863 | G22: =G9/G5 -> 0.023849196 | H22: =H9/H5 -> 0.02275799 | I22: =I9/I5 -> 0.024774028 | J22: =J9/J5 -> 0.022511514 | ... Z22: =Z9/Z5 -> 0.025262595
B23: Effective Tax Rate | C23: =C12/C11 -> 0.23766657 | D23: =D12/D11 -> 0.23552743 | E23: =E12/E11 -> 0.21296277 | F23: =F12/F11 -> 0.22232791 | G23: =G12/G11 -> 0.23291983 | H23: =H12/H11 -> 0.25034838 | I23: =I12/I11 -> 0.23359429 | J23: =J12/J11 -> 0.17755672 | ... Z23: =Z12/Z11 -> 0.2366769

Sheet IS
B2: IS Assumptions (historical, computed)
B3: Revenue Growth Rate | D3: =(D10-C10)/C10 -> 0.48757469 | E3: =(E10-D10)/D10 -> 0.16536309 | F3: =(F10-E10)/E10 -> -0.015340845 | G3: =(G10-F10)/F10 -> 0.072528582 | H3: =(H10-G10)/G10 -> 0.10163806 | I3: 0.15 | J3: =I3 -> 0.15 | K3: =J3 -> 0.15 | L3: =K3 -> 0.15 | M3: =L3 -> 0.15
B4: Gross Margin % | C4: =C12/C10 -> 0.27063097 | D4: =D12/D10 -> 0.21329426 | E4: =E12/E10 -> 0.20354507 | F4: =F12/F10 -> 0.22525268 | G4: =G12/G10 -> 0.23539469 | H4: =H12/H10 -> 0.24605752 | I4: 0.25 | J4: =I4 -> 0.25 | K4: =J4 -> 0.25 | L4: =K4 -> 0.25 | M4: =L4 -> 0.25
B5: Operating Expenses % | C5: =C13/C10 -> 0.1880275 | D5: =D13/D10 -> 0.15143476 | E5: =E13/E10 -> 0.1404449 | F5: =F13/F10 -> 0.15397473 | G5: =G13/G10 -> 0.16011368 | H5: =H13/H10 -> 0.16157449 | I5: =H5 -> 0.16157449 | J5: =I5 -> 0.16157449 | K5: =J5 -> 0.16157449 | L5: =K5 -> 0.16157449 | M5: =L5 -> 0.16157449
B6: D&A % | C6: =C14/C10 -> 0.030457017 | D6: =D14/D10 -> 0.023434765 | E6: =E14/E10 -> 0.020744743 | F6: =F14/F10 -> 0.023534888 | G6: =G14/G10 -> 0.02532147 | H6: =H14/H10 -> 0.025622425 | I6: 0.025 | J6: =I6 -> 0.025 | K6: =J6 -> 0.025 | L6: =K6 -> 0.025 | M6: =L6 -> 0.025
B7: Effective Tax Rate | C7: =C17/C16 -> 0.2319022 | D7: =D17/D16 -> 0.22902561 | E7: =E17/E16 -> 0.23969819 | F7: =F17/F16 -> 0.23498537 | G7: =G17/G16 -> 0.23289948 | H7: =H17/H16 -> 0.23753419 | I7: =AVERAGE(C7:H7) -> 0.23434084 | J7: =I7 -> 0.23434084 | K7: =J7 -> 0.23434084 | L7: =K7 -> 0.23434084 | M7: =L7 -> 0.23434084
B9: Annual Income Statement ($000s) | C9: FY'21 | D9: FY'22 | E9: FY'23 | F9: FY'24 | G9: FY'25 | H9: FY'26 | I9: FY'27 | J9: FY'28 | K9: FY'29 | L9: FY'30 | M9: FY'31
B10: Total Revenue | C10: =SUM('10QIS'!C5:F5) -> 8707189 | D10: =SUM('10QIS'!G5:J5) -> 12952594 | E10: =SUM('10QIS'!K5:N5) -> 15094475 | F10: =SUM('10QIS'!O5:R5) -> 14862913 | G10: =SUM('10QIS'!S5:V5) -> 15940899 | H10: =SUM('10QIS'!W5:Z5) -> 17561101
B11: Cost of goods sold | C11: =SUM('10QIS'!C6:F6) -> 6350754 | D11: =SUM('10QIS'!G6:J6) -> 10189880 | E11: =SUM('10QIS'!K6:N6) -> 12022069 | F11: =SUM('10QIS'!O6:R6) -> 11515002 | G11: =SUM('10QIS'!S6:V6) -> 12188496 | H11: =SUM('10QIS'!W6:Z6) -> 13240060
B12: Gross Margin | C12: =C10-C11 -> 2356435 | D12: =D10-D11 -> 2762714 | E12: =E10-E11 -> 3072406 | F12: =F10-F11 -> 3347911 | G12: =G10-G11 -> 3752403 | H12: =H10-H11 -> 4321041 | I12: =I10-I11 -> 0 | J12: =J10-J11 -> 0 | ... M12: =M10-M11 -> 0
B13: Operating expenses | C13: =SUM('10QIS'!C8:F8) -> 1637191 | D13: =SUM('10QIS'!G8:J8) -> 1961473 | E13: =SUM('10QIS'!K8:N8) -> 2119942 | F13: =SUM('10QIS'!O8:R8) -> 2288513 | G13: =SUM('10QIS'!S8:V8) -> 2552356 | H13: =SUM('10QIS'!W8:Z8) -> 2837426
B14: Depreciation and amortization | C14: =SUM('10QIS'!C9:F9) -> 265195 | D14: =SUM('10QIS'!G9:J9) -> 303541 | E14: =SUM('10QIS'!K9:N9) -> 313131 | F14: =SUM('10QIS'!O9:R9) -> 349797 | G14: =SUM('10QIS'!S9:V9) -> 403647 | H14: =SUM('10QIS'!W9:Z9) -> 449958
B15: Interest, net | C15: =SUM('10QIS'!C10:F10) -> 46679 | D15: =SUM('10QIS'!G10:J10) -> 56972 | E15: =SUM('10QIS'!K10:N10) -> 51815 | F15: =SUM('10QIS'!O10:R10) -> 53441 | G15: =SUM('10QIS'!S10:V10) -> 83951 | H15: =SUM('10QIS'!W10:Z10) -> 96634
B16: Income before income taxes | C16: =C12-C13-C14-C15 -> 407370 | D16: =D12-D13-D14-D15 -> 440728 | E16: =E12-E13-E14-E15 -> 587518 | F16: =F12-F13-F14-F15 -> 656160 | G16: =G12-G13-G14-G15 -> 712449 | H16: =H12-H13-H14-H15 -> 937023 | I16: =I12-I13-I14-I15 -> 0 | J16: =J12-J13-J14-J15 -> 0 | ... M16: =M12-M13-M14-M15 -> 0
B17: Federal and state income taxes | C17: =SUM('10QIS'!C12:F12) -> 94470 | D17: =SUM('10QIS'!G12:J12) -> 100938 | E17: =SUM('10QIS'!K12:N12) -> 140827 | F17: =SUM('10QIS'!O12:R12) -> 154188 | G17: =SUM('10QIS'!S12:V12) -> 165929 | H17: =SUM('10QIS'!W12:Z12) -> 222575
B18: Net income | C18: =C16-C17 -> 312900 | D18: =D16-D17 -> 339790 | E18: =E16-E17 -> 446691 | F18: =F16-F17 -> 501972 | G18: =G16-G17 -> 546520 | H18: =H16-H17 -> 714448 | I18: =I16-I17 -> 0 | J18: =J16-J17 -> 0 | ... M18: =M16-M17 -> 0
B19: Diluted EPS | C19: 8.38 | D19: 9.1 | E19: 11.91 | F19: 13.43 | G19: 14.64 | H19: 19.16

Sheet BS
B2: Balance Sheet ($000s) | C2: FY'21 | D2: FY'22 | E2: FY'23 | F2: FY'24 | G2: FY'25 | H2: FY'26
B3: Cash and cash equivalents | C3: 336545 | D3: 158878 | E3: 378869 | F3: 206482 | G3: 326662 | H3: 522991
B4: Receivables | C4: 79698 | D4: 108028 | E4: 120547 | F4: 151793 | G4: 180746 | H4: 243502
B5: Inventories | C5: 286598 | D5: 396199 | E5: 376085 | F5: 428722 | G5: 480034 | H5: 557151
B6: Prepaid expenses and other current assets | C6: 11214 | D6: 17859 | E6: 22107 | F6: 25791 | G6: 24641 | H6: 29783
B7: Income taxes receivable | C7: 9578 | D7: 44071 | E7: 23347 | F7: 17066 | G7: 770 | H7: 10585
B8: Total current assets | C8: =SUM(C3:C7) -> 723633 | D8: =SUM(D3:D7) -> 725035 | E8: =SUM(E3:E7) -> 920955 | F8: =SUM(F3:F7) -> 829854 | G8: =SUM(G3:G7) -> 1012853 | H8: =SUM(H3:H7) -> 1364012
B9: Land | C9: 938199 | D9: 1097985 | E9: 1151812 | F9: 1281408 | G9: 1429673 | H9: 1496529
B10: Buildings and leasehold improvements | C10: 2162261 | D10: 2445509 | E10: 2629795 | F10: 3003191 | G10: 3539550 | H10: 3829703
B11: Machinery and equipment | C11: 2478404 | D11: 2695366 | E11: 2783802 | F11: 3052798 | G11: 3314403 | H11: 3561976
B12: Finance lease right-of-use assets | C12: 22413 | D12: 75060 | E12: 99764 | F12: 106837 | G12: 120670 | H12: 134388
B13: Construction in process | C13: 98587 | D13: 92331 | E13: 169796 | F13: 109048 | G13: 131151 | H13: 171314
B14: Property and equipment, at cost | C14: =SUM(C9:C13) -> 5699864 | D14: =SUM(D9:D13) -> 6406251 | E14: =SUM(E9:E13) -> 6834969 | F14: =SUM(F9:F13) -> 7553282 | G14: =SUM(G9:G13) -> 8535447 | H14: =SUM(H9:H13) -> 9193910
B15: Less accumulated depreciation and amortization | C15: 2206405 | D15: 2425709 | E15: 2620149 | F15: 2883925 | G15: 3122203 | H15: 3444442
B16: Net property and equipment | C16: =C14-C15 -> 3493459 | D16: =D14-D15 -> 3980542 | E16: =E14-E15 -> 4214820 | F16: =F14-F15 -> 4669357 | G16: =G14-G15 -> 5413244 | H16: =H14-H15 -> 5749468
B17: Other assets, net | C17: 82147 | D17: 187219 | E17: 192153 | F17: 195559 | G17: 120082 | H17: 121249
B18: Operating lease right-of-use assets, net | G18: 417046 | H18: 432640
B19: Goodwill | C19: 161075 | D19: 612934 | E19: 615342 | F19: 652663 | G19: 1244893 | H19: 1268686
B20: Total assets | C20: =C8+C16+C17+C18+C19 -> 4460314 | D20: =D8+D16+D17+D18+D19 -> 5505730 | E20: =E8+E16+E17+E18+E19 -> 5943270 | F20: =F8+F16+F17+F18+F19 -> 6347433 | G20: =G8+G16+G17+G18+G19 -> 8208118 | H20: =H8+H16+H17+H18+H19 -> 8936055
B22: Current maturities of long-term debt and finance lease obligations | C22: 2354 | D22: 24466 | E22: 52861 | F22: 53181 | G22: 94925 | H22: 101357
B23: Accounts payable | C23: 355471 | D23: 588783 | E23: 560546 | F23: 569527 | G23: 620447 | H23: 823804
B24: Wages and related taxes | C24: 69226 | D24: 87022 | E24: 78791 | F24: 95821 | G24: 80633 | H24: 105119
B25: Property taxes | C25: 39399 | D25: 47556 | E25: 51109 | F25: 54009 | G25: 59843 | H25: 62263
B26: Insurance accruals (current) | C26: 24287 | D26: 25795 | E26: 28856 | F26: 27323 | G26: 41328 | H26: 35100
B27: Operating lease liabilities, current | G27: 14647 | H27: 14197
B28: Other accrued expenses | C28: 122012 | D28: 131056 | E28: 154962 | F28: 153605 | G28: 189870 | H28: 208766
B29: Total current liabilities | C29: =SUM(C22:C28) -> 612749 | D29: =SUM(D22:D28) -> 904678 | E29: =SUM(E22:E28) -> 927125 | F29: =SUM(F22:F28) -> 953466 | G29: =SUM(G22:G28) -> 1101693 | H29: =SUM(H22:H28) -> 1350606
B30: Long-term debt and finance lease obligations, net of current | C30: 1361395 | D30: 1663403 | E30: 1620513 | F30: 1582758 | G30: 2413620 | H30: 2330237
B31: Deferred income taxes | C31: 439721 | D31: 520472 | E31: 543598 | F31: 596850 | G31: 646905 | H31: 739843
B32: Deferred compensation | C32: 15094 | D32: 12746
B33: Operating lease liabilities, non-current | G33: 434707 | H33: 459284
B34: Insurance accruals, net of current portion | C34: 26239 | D34: 27957 | E34: 32312 | F34: 30046 | G34: 33143 | H34: 32140
B35: Other long-term liabilities | C35: 72437 | D35: 135636 | E35: 159056 | F35: 168932 | G35: 69380 | H35: 72226
B36: Total liabilities | C36: =C29+SUM(C30:C35) -> 2527635 | D36: =D29+SUM(D30:D35) -> 3264892 | E36: =E29+SUM(E30:E35) -> 3282604 | F36: =F29+SUM(F30:F35) -> 3332052 | G36: =G29+SUM(G30:G35) -> 4699448 | H36: =H29+SUM(H30:H35) -> 4984336
B38: Common stock | C38: 58951 | D38: 79412 | E38: 110037 | F38: 27453 | G38: 49605 | H38: 0
B39: Retained earnings | C39: 1873728 | D39: 2161426 | E39: 2550629 | F39: 2987928 | G39: 3459065 | H39: 3951719
B40: Total shareholders’ equity | C40: =SUM(C38:C39) -> 1932679 | D40: =SUM(D38:D39) -> 2240838 | E40: =SUM(E38:E39) -> 2660666 | F40: =SUM(F38:F39) -> 3015381 | G40: =SUM(G38:G39) -> 3508670 | H40: =SUM(H38:H39) -> 3951719
B41: Total liabilities and shareholders’ equity | C41: =C36+C40 -> 4460314 | D41: =D36+D40 -> 5505730 | E41: =E36+E40 -> 5943270 | F41: =F36+F40 -> 6347433 | G41: =G36+G40 -> 8208118 | H41: =H36+H40 -> 8936055
B43: Check (Assets less Liab. & Equity) | C43: =C20-C41 -> 0 | D43: =D20-D41 -> 0 | E43: =E20-E41 -> 0 | F43: =F20-F41 -> 0 | G43: =G20-G41 -> 0 | H43: =H20-H41 -> 0
B45: Source: FY2021 and FY2022 figures from the FY2022 10-K (current + comparative column); FY2023-FY2026 each from that year’s 10-K. Blank cells indicate the line item was not separately disclosed that year (e.g., operating lease ROU assets/liabilities only broken out starting FY2025; deferred compensation only shown FY2021-FY2022).

Sheet CFS
B2: Cash Flow Statement ($000s) | C2: FY'21 | D2: FY'22 | E2: FY'23 | F2: FY'24 | G2: FY'25 | H2: FY'26
B3: Net income | C3: 312900 | D3: 339790 | E3: 446691 | F3: 501972 | G3: 546520 | H3: 714448
B4: Depreciation and amortization | C4: 265195 | D4: 303541 | E4: 313131 | F4: 349797 | G4: 403647 | H4: 449958
B5: Amortization of debt (issuance) related costs | C5: 1603 | D5: 2527 | E5: 1789 | F5: 1111 | G5: 2312 | H5: 2065
B6: Change in excess replacement cost over LIFO inventory valuation | F6: 12499 | G6: 11530 | H6: 17455
B7: Share-based compensation | C7: 31986 | D7: 37976 | E7: 47024 | F7: 41379 | G7: 47732 | H7: 63407
B8: Loss (gain) on disposal of assets and impairment charges | C8: 9680 | D8: -1201 | E8: 6871 | F8: 6414 | G8: 12401 | H8: 13517
B9: Deferred income taxes | C9: 4123 | D9: 82721 | E9: 23126 | F9: 53252 | G9: 59958 | H9: 94772
B10: Receivables | C10: -26278 | D10: -33025 | E10: -12519 | F10: -31246 | G10: -1297 | H10: -60075
B11: Inventories | C11: -50342 | D11: -76730 | E11: 24090 | F11: -51785 | G11: -7756 | H11: -90084
B12: Prepaid expenses | C12: -1413 | D12: -6376 | E12: -4248 | F12: -3684 | G12: 3658 | H12: -5142
B13: Accounts payable | C13: 166546 | D13: 165893 | E13: -9483 | F13: -8731 | G13: -20782 | H13: 159172
B14: Accrued expenses | C14: 65497 | D14: 23574 | E14: 20292 | F14: 14387 | G14: 21525 | H14: 35609
B15: Income taxes | C15: 5714 | D15: -35716 | E15: 20652 | F15: 5112 | G15: 15460 | H15: -11444
B16: Other, net | C16: 18877 | D16: -14233 | E16: 4535 | F16: 2476 | G16: -4054 | H16: -6118
B17: Net cash provided by operating activities | C17: =SUM(C3:C16) -> 804088 | D17: =SUM(D3:D16) -> 788741 | E17: =SUM(E3:E16) -> 881951 | F17: =SUM(F3:F16) -> 892953 | G17: =SUM(G3:G16) -> 1090854 | H17: =SUM(H3:H16) -> 1377540
B19: Purchase of property and equipment | C19: -441252 | D19: -326475 | E19: -476568 | F19: -522004 | G19: -506224 | H19: -655920
B20: Payments for acquisitions of businesses, net of cash acquired | C20: -9356 | D20: -901638 | E20: -85569 | F20: -330032 | G20: -1239249 | H20: -141583
B21: Proceeds from sales of property and equipment | C21: 6268 | D21: 70118 | E21: 17103 | F21: 26680 | G21: 18805 | H21: 42072
B22: Net cash used in investing activities | C22: =SUM(C19:C21) -> -444340 | D22: =SUM(D19:D21) -> -1157995 | E22: =SUM(E19:E21) -> -545034 | F22: =SUM(F19:F21) -> -825356 | G22: =SUM(G19:G21) -> -1726668 | H22: =SUM(H19:H21) -> -755431
B24: Proceeds from long-term debt | C24: 650000 | D24: 450000 | E24: 0 | F24: 0 | G24: 1100000 | H24: 0
B25: Repayments of long-term debt and finance lease obligations | C25: -571661 | D25: -188537 | E25: -40970 | F25: -53656 | G25: -239492 | H25: -94895
B26: Net (payments) borrowings of short-term debt | C26: -120000 | D26: 0 | E26: 0 | F26: 0 | G26: 0 | H26: 0
B27: Payment of debt issuance/related costs | C27: -5525 | D27: -1149 | E27: -3940 | F27: 0 | G27: -5891 | H27: 0
B28: Proceeds from exercise of stock options | C28: 1784 | D28: 133 | E28: 0 | F28: 0 | G28: 0 | H28: 0
B29: Payments of cash dividends | C29: -47971 | D29: -51212 | E29: -55617 | F29: -62918 | G29: -72309 | H29: -83136
B30: Tax withholdings on employee share-based awards | C30: -8105 | D30: -17648 | E30: -16399 | F30: -18512 | G30: -25580 | H30: -47244
B31: Repurchase of common stock | F31: -104898 | G31: -734 | H31: -200505
B32: Net cash provided by (used in) financing activities | C32: =SUM(C24:C31) -> -101478 | D32: =SUM(D24:D31) -> 191587 | E32: =SUM(E24:E31) -> -116926 | F32: =SUM(F24:F31) -> -239984 | G32: =SUM(G24:G31) -> 755994 | H32: =SUM(H24:H31) -> -425780
B34: Net increase (decrease) in cash and cash equivalents | C34: =C17+C22+C32 -> 258270 | D34: =D17+D22+D32 -> -177667 | E34: =E17+E22+E32 -> 219991 | F34: =F17+F22+F32 -> -172387 | G34: =G17+G22+G32 -> 120180 | H34: =H17+H22+H32 -> 196329
B35: Cash and cash equivalents at beginning of year | C35: 78275 | D35: =C36 -> 336545 | E35: =D36 -> 158878 | F35: =E36 -> 378869 | G35: =F36 -> 206482 | H35: =G36 -> 326662
B36: Cash and cash equivalents at end of year | C36: =C34+C35 -> 336545 | D36: =D34+D35 -> 158878 | E36: =E34+E35 -> 378869 | F36: =F34+F35 -> 206482 | G36: =G34+G35 -> 326662 | H36: =H34+H35 -> 522991
B38: Source: FY2021-FY2022 from FY2022 10-K; FY2023 from FY2023 10-K; FY2024 from FY2024 10-K; FY2025 from FY2025 10-K; FY2026 from FY2026 10-K. Blank cells = line item not disclosed that year (e.g. share repurchases only began FY2024; the LIFO inventory valuation line was first broken out separately in the FY2024 10-K, so FY2021-FY2023 as originally filed do not show it — those years bundle it into other adjustment lines).

Sheet DCF
B2: Casey's General Stores, Inc. (CASY)
B4: Valuation Date: | F4: =TODAY() -> 46259
B5: Share Price on Valuation Date:
B6: Diluted Shares Outstanding | F6: =Main!C4 -> 37.241037
B7: Stub Period to FY Year-End (yrs) [Casey's FYE = 4/30] | F7: =(IF(F4>DATE(YEAR(F4),4,30),DATE(YEAR(F4)+1,4,30),DATE(YEAR(F4),4,30))-F4)/365 -> 0.67945205
B9: Select Operating Data
C10: FY'21 | D10: FY'22 | E10: FY'23 | F10: FY'24 | G10: FY'25 | H10: FY'26 | I10: FY'27 | J10: FY'28 | K10: FY'29 | L10: FY'30 | M10: FY'31
B11: Revenue | C11: =IS!C10 -> 8707189 | D11: =IS!D10 -> 12952594 | E11: =IS!E10 -> 15094475 | F11: =IS!F10 -> 14862913 | G11: =IS!G10 -> 15940899 | H11: =IS!H10 -> 17561101
B13: EBIT | C13: =IS!C16+IS!C15 -> 454049 | D13: =IS!D16+IS!D15 -> 497700 | E13: =IS!E16+IS!E15 -> 639333 | F13: =IS!F16+IS!F15 -> 709601 | G13: =IS!G16+IS!G15 -> 796400 | H13: =IS!H16+IS!H15 -> 1033657
B15: Depreciation & Amortization | C15: =IS!C14 -> 265195 | D15: =IS!D14 -> 303541 | E15: =IS!E14 -> 313131 | F15: =IS!F14 -> 349797 | G15: =IS!G14 -> 403647 | H15: =IS!H14 -> 449958 | N15: Arithmetic Avg | O15: Geometric Avg
B16: % of revenue | C16: =C15/C11 -> 0.030457017 | D16: =D15/D11 -> 0.023434765 | E16: =E15/E11 -> 0.020744743 | F16: =F15/F11 -> 0.023534888 | G16: =G15/G11 -> 0.02532147 | H16: =H15/H11 -> 0.025622425 | N16: =AVERAGE(C16:H16) -> 0.024852551 | O16: =AVERAGE(C16:H16) -> 0.024852551
B19: Select Balance Sheet And Other Data
C20: FY'21 | D20: FY'22 | E20: FY'23 | F20: FY'24 | G20: FY'25 | H20: FY'26 | I20: FY'27 | J20: FY'28 | K20: FY'29 | L20: FY'30 | M20: FY'31
B21: Accounts Receivable | C21: =BS!C4 -> 79698 | D21: =BS!D4 -> 108028 | E21: =BS!E4 -> 120547 | F21: =BS!F4 -> 151793 | G21: =BS!G4 -> 180746 | H21: =BS!H4 -> 243502 | I21: =I32*I11 -> 0 | J21: =J32*J11 -> 0 | K21: =K32*K11 -> 0 | L21: =L32*L11 -> 0 | M21: =M32*M11 -> 0
B22: Inventories | C22: =BS!C5 -> 286598 | D22: =BS!D5 -> 396199 | E22: =BS!E5 -> 376085 | F22: =BS!F5 -> 428722 | G22: =BS!G5 -> 480034 | H22: =BS!H5 -> 557151 | I22: =I33*I11 -> 0 | J22: =J33*J11 -> 0 | K22: =K33*K11 -> 0 | L22: =L33*L11 -> 0 | M22: =M33*M11 -> 0
B23: Prepaid Expenses | C23: =BS!C6 -> 11214 | D23: =BS!D6 -> 17859 | E23: =BS!E6 -> 22107 | F23: =BS!F6 -> 25791 | G23: =BS!G6 -> 24641 | H23: =BS!H6 -> 29783 | I23: =I34*I11 -> 0 | J23: =J34*J11 -> 0 | K23: =K34*K11 -> 0 | L23: =L34*L11 -> 0 | M23: =M34*M11 -> 0
B25: Accounts Payable | C25: =BS!C23 -> 355471 | D25: =BS!D23 -> 588783 | E25: =BS!E23 -> 560546 | F25: =BS!F23 -> 569527 | G25: =BS!G23 -> 620447 | H25: =BS!H23 -> 823804 | I25: =I35*I11 -> 0 | J25: =J35*J11 -> 0 | K25: =K35*K11 -> 0 | L25: =L35*L11 -> 0 | M25: =M35*M11 -> 0
B26: Accrued Expenses (wages+property tax+insurance+other) | C26: =BS!C24+BS!C25+BS!C26+BS!C28 -> 254924 | D26: =BS!D24+BS!D25+BS!D26+BS!D28 -> 291429 | E26: =BS!E24+BS!E25+BS!E26+BS!E28 -> 313718 | F26: =BS!F24+BS!F25+BS!F26+BS!F28 -> 330758 | G26: =BS!G24+BS!G25+BS!G26+BS!G28 -> 371674 | H26: =BS!H24+BS!H25+BS!H26+BS!H28 -> 411248 | I26: =I36*I11 -> 0 | J26: =J36*J11 -> 0 | K26: =K36*K11 -> 0 | L26: =L36*L11 -> 0 | M26: =M36*M11 -> 0
B28: Debt (current + long-term) | C28: =BS!C22+BS!C30 -> 1363749 | D28: =BS!D22+BS!D30 -> 1687869 | E28: =BS!E22+BS!E30 -> 1673374 | F28: =BS!F22+BS!F30 -> 1635939 | G28: =BS!G22+BS!G30 -> 2508545 | H28: =BS!H22+BS!H30 -> 2431594
B30: Capital Expenditures | C30: =CFS!C19 -> -441252 | D30: =CFS!D19 -> -326475 | E30: =CFS!E19 -> -476568 | F30: =CFS!F19 -> -522004 | G30: =CFS!G19 -> -506224 | H30: =CFS!H19 -> -655920 | I30: =I37*I11 -> 0 | J30: =J37*J11 -> 0 | K30: =K37*K11 -> 0 | L30: =L37*L11 -> 0 | M30: =M37*M11 -> 0
B32: Accounts Receivable as a % of revenue | C32: =C21/C11 -> 0.0091531262 | D32: =D21/D11 -> 0.0083402599 | E32: =E21/E11 -> 0.0079861671 | F32: =F21/F11 -> 0.01021287 | G32: =G21/G11 -> 0.011338507 | H32: =H21/H11 -> 0.013865987 | I32: =$N$32 -> 0.010149486 | J32: =$N$32 -> 0.010149486 | K32: =$N$32 -> 0.010149486 | L32: =$N$32 -> 0.010149486 | M32: =$N$32 -> 0.010149486 | N32: =AVERAGE(C32:H32) -> 0.010149486 | O32: Geometric Avg →
B33: Inventories as a % of revenue | C33: =C22/C11 -> 0.0329151 | D33: =D22/D11 -> 0.03058839 | E33: =E22/E11 -> 0.024915408 | F33: =F22/F11 -> 0.028845086 | G33: =G22/G11 -> 0.030113358 | H33: =H22/H11 -> 0.031726428 | I33: =$N$33 -> 0.029850628 | J33: =$N$33 -> 0.029850628 | K33: =$N$33 -> 0.029850628 | L33: =$N$33 -> 0.029850628 | M33: =$N$33 -> 0.029850628 | N33: =AVERAGE(C33:H33) -> 0.029850628 | O33: Geometric Avg →
B34: Prepaid Expenses as a % of revenue | C34: =C23/C11 -> 0.0012879013 | D34: =D23/D11 -> 0.0013787972 | E34: =E23/E11 -> 0.0014645756 | F34: =F23/F11 -> 0.0017352588 | G34: =G23/G11 -> 0.0015457723 | H34: =H23/H11 -> 0.0016959643 | I34: =$N$34 -> 0.0015180449 | J34: =$N$34 -> 0.0015180449 | K34: =$N$34 -> 0.0015180449 | L34: =$N$34 -> 0.0015180449 | M34: =$N$34 -> 0.0015180449 | N34: =AVERAGE(C34:H34) -> 0.0015180449 | O34: Geometric Avg →
B35: Accounts Payable as a % of revenue | C35: =C25/C11 -> 0.040825001 | D35: =D25/D11 -> 0.045456763 | E35: =E25/E11 -> 0.037135839 | F35: =F25/F11 -> 0.038318666 | G35: =G25/G11 -> 0.038921707 | H35: =H25/H11 -> 0.046910726 | I35: =$N$35 -> 0.041261451 | J35: =$N$35 -> 0.041261451 | K35: =$N$35 -> 0.041261451 | L35: =$N$35 -> 0.041261451 | M35: =$N$35 -> 0.041261451 | N35: =AVERAGE(C35:H35) -> 0.041261451 | O35: Geometric Avg →
B36: Accrued Expenses as a % of revenue | C36: =C26/C11 -> 0.029277417 | D36: =D26/D11 -> 0.022499663 | E36: =E26/E11 -> 0.020783631 | F36: =F26/F11 -> 0.022253915 | G36: =G26/G11 -> 0.023315749 | H36: =H26/H11 -> 0.023418122 | I36: =$N$36 -> 0.023591416 | J36: =$N$36 -> 0.023591416 | K36: =$N$36 -> 0.023591416 | L36: =$N$36 -> 0.023591416 | M36: =$N$36 -> 0.023591416 | N36: =AVERAGE(C36:H36) -> 0.023591416 | O36: Geometric Avg →
B37: Capital Expenditures as a % of revenue | C37: =C30/C11 -> -0.050676745 | D37: =D30/D11 -> -0.025205376 | E37: =E30/E11 -> -0.031572347 | F37: =F30/F11 -> -0.035121244 | G37: =G30/G11 -> -0.031756302 | H37: =H30/H11 -> -0.037350733 | I37: =$N$37 -> -0.035280458 | J37: =$N$37 -> -0.035280458 | K37: =$N$37 -> -0.035280458 | L37: =$N$37 -> -0.035280458 | M37: =$N$37 -> -0.035280458 | N37: =AVERAGE(C37:H37) -> -0.035280458 | O37: Geometric Avg →
B39: Accounts Receivable Growth (%) | D39: =IFERROR((D21/C21)-1,0) -> 0.35546689 | E39: =IFERROR((E21/D21)-1,0) -> 0.11588662 | F39: =IFERROR((F21/E21)-1,0) -> 0.25920181 | G39: =IFERROR((G21/F21)-1,0) -> 0.19074002 | H39: =IFERROR((H21/G21)-1,0) -> 0.34720547
B40: Inventories Growth (%) | D40: =IFERROR((D22/C22)-1,0) -> 0.38242067 | E40: =IFERROR((E22/D22)-1,0) -> -0.050767417 | F40: =IFERROR((F22/E22)-1,0) -> 0.13996038 | G40: =IFERROR((G22/F22)-1,0) -> 0.11968595 | H40: =IFERROR((H22/G22)-1,0) -> 0.16064904
B41: Prepaid Expenses Growth (%) | D41: =IFERROR((D23/C23)-1,0) -> 0.59256287 | E41: =IFERROR((E23/D23)-1,0) -> 0.23786326 | F41: =IFERROR((F23/E23)-1,0) -> 0.16664405 | G41: =IFERROR((G23/F23)-1,0) -> -0.044589198 | H41: =IFERROR((H23/G23)-1,0) -> 0.2086766
B42: Accounts Payable Growth (%) | D42: =IFERROR((D25/C25)-1,0) -> 0.65634609 | E42: =IFERROR((E25/D25)-1,0) -> -0.047958246 | F42: =IFERROR((F25/E25)-1,0) -> 0.016021879 | G42: =IFERROR((G25/F25)-1,0) -> 0.089407526 | H42: =IFERROR((H25/G25)-1,0) -> 0.32775886
B43: Accrued Expenses Growth (%) | D43: =IFERROR((D26/C26)-1,0) -> 0.14319954 | E43: =IFERROR((E26/D26)-1,0) -> 0.07648175 | F43: =IFERROR((F26/E26)-1,0) -> 0.054316297 | G43: =IFERROR((G26/F26)-1,0) -> 0.12370374 | H43: =IFERROR((H26/G26)-1,0) -> 0.10647503
B44: Capital Expenditures Growth (%) | D44: =IFERROR((D30/C30)-1,0) -> -0.26011667 | E44: =IFERROR((E30/D30)-1,0) -> 0.45973811 | F44: =IFERROR((F30/E30)-1,0) -> 0.095340014 | G44: =IFERROR((G30/F30)-1,0) -> -0.030229653 | H44: =IFERROR((H30/G30)-1,0) -> 0.29571099
B46: Free Cash Flow Buildup | I46: Projected Annual Forecast
B47: $000s | C47: FY'21 | D47: FY'22 | E47: FY'23 | F47: FY'24 | G47: FY'25 | H47: FY'26 | I47: FY'27 | J47: FY'28 | K47: FY'29 | L47: FY'30 | M47: FY'31
B48: Period | I48: =$F$7/2 -> 0.33972603 | J48: =I48+1 -> 1.339726 | K48: =J48+1 -> 2.339726 | L48: =K48+1 -> 3.339726 | M48: =L48+1 -> 4.339726
B49: Total Revenues | C49: =C11 -> 8707189 | D49: =D11 -> 12952594 | E49: =E11 -> 15094475 | F49: =F11 -> 14862913 | G49: =G11 -> 15940899 | H49: =H11 -> 17561101 | I49: =I11 -> 0 | J49: =J11 -> 0 | ... M49: =M11 -> 0
B50: EBIT | C50: =C13 -> 454049 | D50: =D13 -> 497700 | E50: =E13 -> 639333 | F50: =F13 -> 709601 | G50: =G13 -> 796400 | H50: =H13 -> 1033657 | I50: =I13 -> 0 | J50: =J13 -> 0 | ... M50: =M13 -> 0
B51: Effective Tax Rate | C51: =IS!C7 -> 0.2319022 | D51: =IS!D7 -> 0.22902561 | E51: =IS!E7 -> 0.23969819 | F51: =IS!F7 -> 0.23498537 | G51: =IS!G7 -> 0.23289948 | H51: =IS!H7 -> 0.23753419 | J51: =I51 -> 0 | K51: =J51 -> 0 | L51: =K51 -> 0 | M51: =L51 -> 0
B52: EBIAT = EBIT(1-T) = NOPAT | C52: =C50*(1-C51) -> 348754.04 | D52: =D50*(1-D51) -> 383713.95 | E52: =E50*(1-E51) -> 486086.04 | F52: =F50*(1-F51) -> 542855.15 | G52: =G50*(1-G51) -> 610918.86 | H52: =H50*(1-H51) -> 788128.12 | I52: =I50*(1-I51) -> 0 | J52: =J50*(1-J51) -> 0 | ... M52: =M50*(1-M51) -> 0
B53: Depreciation & Amortization | C53: =C15 -> 265195 | D53: =D15 -> 303541 | E53: =E15 -> 313131 | F53: =F15 -> 349797 | G53: =G15 -> 403647 | H53: =H15 -> 449958 | I53: =I15 -> 0 | J53: =J15 -> 0 | ... M53: =M15 -> 0
...

Sheet Fuel
B2: Fuel
B3: Category | C3: Fuel
B4: Description | C4: Retail motor fuel sold at Casey’s convenience stores.
B5: Reporting basis | C5: Revenue category within Casey’s single reportable segment (not a separate GAAP operating segment)
B7: Revenue and Margin ($000s) | C7: FY'21 | D7: FY'22 | E7: FY'23 | F7: FY'24 | G7: FY'25 | H7: FY'26
B8: Revenue | C8: 4825466 | D8: 8312038 | E8: 10027310 | F8: 9402071 | G8: 9776033 | H8: 10615407
B9: Revenue less COGS (excl. D&A) | C9: 761247 | D9: 928868 | E9: 1074913 | F9: 1116671 | G9: 1236694 | H9: 1496591
B10: Margin % | C10: =C9/C8 -> 0.15775616 | D10: =D9/D8 -> 0.11174973 | E10: =E9/E8 -> 0.10719854 | F10: =F9/F8 -> 0.11876862 | G10: =G9/G8 -> 0.12650264 | H10: =H9/H8 -> 0.14098291
B12: Note: figures per Casey’s MD&A "Revenue and Revenue less Cost of Goods Sold by Category" table in each 10-K. Casey’s reports as a single operating segment; these are revenue categories, not GAAP segments.

Sheet Grocery & General Merchandise
B2: Grocery & General Merchandise
B3: Category | C3: Grocery & General Merchandise
B4: Description | C4: Packaged grocery, tobacco/nicotine, beverages, and general merchandise sold in-store.
B5: Reporting basis | C5: Revenue category within Casey’s single reportable segment (not a separate GAAP operating segment)
B7: Revenue and Margin ($000s) | C7: FY'21 | D7: FY'22 | E7: FY'23 | F7: FY'24 | G7: FY'25 | H7: FY'26
B8: Revenue | C8: 2724374 | D8: 3141527 | E8: 3445777 | F8: 3727394 | G8: 4143887 | H8: 4563614
B9: Revenue less COGS (excl. D&A) | C9: 872573 | D9: 1027477 | E9: 1156451 | F9: 1270527 | G9: 1452008 | H9: 1635405
B10: Margin % | C10: =C9/C8 -> 0.32028385 | D10: =D9/D8 -> 0.32706292 | E10: =E9/E8 -> 0.335614 | F10: =F9/F8 -> 0.34086201 | G10: =G9/G8 -> 0.35039759 | H10: =H9/H8 -> 0.35835743
B12: Note: figures per Casey’s MD&A "Revenue and Revenue less Cost of Goods Sold by Category" table in each 10-K. Casey’s reports as a single operating segment; these are revenue categories, not GAAP segments.

Sheet Prepared Food & Beverage
B2: Prepared Food & Dispensed Beverage
B3: Category | C3: Prepared Food & Dispensed Beverage
B4: Description | C4: Made-to-order and prepared food (pizza, sandwiches, bakery) and dispensed/fountain beverages.
B5: Reporting basis | C5: Revenue category within Casey’s single reportable segment (not a separate GAAP operating segment)
B7: Revenue and Margin ($000s) | C7: FY'21 | D7: FY'22 | E7: FY'23 | F7: FY'24 | G7: FY'25 | H7: FY'26
B8: Revenue | C8: 1087147 | D8: 1204100 | E8: 1322560 | F8: 1461600 | G8: 1611762 | H8: 1776828
B9: Revenue less COGS (excl. D&A) | C9: 653689 | D9: 712352 | E9: 748405 | F9: 858295 | G9: 937440 | H9: 1040943
B10: Margin % | C10: =C9/C8 -> 0.60128851 | D10: =D9/D8 -> 0.59160535 | E10: =E9/E8 -> 0.56587603 | F10: =F9/F8 -> 0.58722975 | G10: =G9/G8 -> 0.58162433 | H10: =H9/H8 -> 0.58584342
B12: Note: figures per Casey’s MD&A "Revenue and Revenue less Cost of Goods Sold by Category" table in each 10-K. Casey’s reports as a single operating segment; these are revenue categories, not GAAP segments.
