Workbook

Sheet Quarterly Financials
A1: Quarterly Financial Statements, Last 12 Quarters
B2: $ in thousands except per share.
A4: INCOME STATEMENT
C5: Q3 2023 | D5: Q4 2023 | E5: Q1 2024 | F5: Q2 2024 | G5: Q3 2024 | H5: Q4 2024 | I5: Q1 2025 | J5: Q2 2025 | K5: Q3 2025 | L5: Q4 2025 | M5: Q1 2026 | N5: Q2 2026 | O5: LTM
B6: Net revenues | C6: ='Qtr Source Data'!C6 -> 157854 | D6: ='Qtr Source Data'!E6-'Qtr Source Data'!D6 -> 187987 | E6: ='Qtr Source Data'!F6 -> 174350 | F6: ='Qtr Source Data'!G6 -> 163147 | G6: ='Qtr Source Data'!H6 -> 136593 | H6: ='Qtr Source Data'!J6-'Qtr Source Data'!I6 -> 143484 | I6: ='Qtr Source Data'!K6 -> 121387 | J6: ='Qtr Source Data'!L6 -> 105120 | K6: ='Qtr Source Data'!M6 -> 77742 | L6: ='Qtr Source Data'!O6-'Qtr Source Data'!N6 -> 72659 | M6: ='Qtr Source Data'!P6 -> 63262 | N6: ='Qtr Source Data'!Q6 -> 51849 | O6: =SUM(K6:N6) -> 265512
B7: YoY growth | C7: n/a | D7: n/a | E7: n/a | F7: n/a | G7: =IFERROR(G6/C6-1,"") -> -0.13468775 | H7: =IFERROR(H6/D6-1,"") -> -0.23673446 | I7: =IFERROR(I6/E6-1,"") -> -0.30377402 | J7: =IFERROR(J6/F6-1,"") -> -0.3556731 | K7: =IFERROR(K6/G6-1,"") -> -0.43084931 | L7: =IFERROR(L6/H6-1,"") -> -0.49360904 | M7: =IFERROR(M6/I6-1,"") -> -0.4788404 | N7: =IFERROR(N6/J6-1,"") -> -0.5067637
B8: Cost of revenues | C8: ='Qtr Source Data'!C7 -> 83575 | D8: ='Qtr Source Data'!E7-'Qtr Source Data'!D7 -> 45804 | E8: ='Qtr Source Data'!F7 -> 46497 | F8: ='Qtr Source Data'!G7 -> 45411 | G8: ='Qtr Source Data'!H7 -> 43420 | H8: ='Qtr Source Data'!J7-'Qtr Source Data'!I7 -> 45599 | I8: ='Qtr Source Data'!K7 -> 53973 | J8: ='Qtr Source Data'!L7 -> 35478 | K8: ='Qtr Source Data'!M7 -> 31701 | L8: ='Qtr Source Data'!O7-'Qtr Source Data'!N7 -> 30999 | M8: ='Qtr Source Data'!P7 -> 25374 | N8: ='Qtr Source Data'!Q7 -> 23567 | O8: =SUM(K8:N8) -> 111641
B9: Gross profit | C9: =C6-C8 -> 74279 | D9: =D6-D8 -> 142183 | E9: =E6-E8 -> 127853 | F9: =F6-F8 -> 117736 | G9: =G6-G8 -> 93173 | H9: =H6-H8 -> 97885 | I9: =I6-I8 -> 67414 | J9: =J6-J8 -> 69642 | ... O9: =O6-O8 -> 153871
B10: Gross margin | C10: =IFERROR(C9/C6,"") -> 0.47055507 | D10: =IFERROR(D9/D6,"") -> 0.75634485 | E10: =IFERROR(E9/E6,"") -> 0.7333123 | F10: =IFERROR(F9/F6,"") -> 0.72165593 | G10: =IFERROR(G9/G6,"") -> 0.68212134 | H10: =IFERROR(H9/H6,"") -> 0.6822015 | I10: =IFERROR(I9/I6,"") -> 0.55536425 | J10: =IFERROR(J9/J6,"") -> 0.6625 | ... O10: =IFERROR(O9/O6,"") -> 0.5795256
B11: Research and development | C11: ='Qtr Source Data'!C8 -> 46202 | D11: ='Qtr Source Data'!E8-'Qtr Source Data'!D8 -> 45724 | E11: ='Qtr Source Data'!F8 -> 44435 | F11: ='Qtr Source Data'!G8 -> 43651 | G11: ='Qtr Source Data'!H8 -> 41337 | H11: ='Qtr Source Data'!J8-'Qtr Source Data'!I8 -> 41008 | I11: ='Qtr Source Data'!K8 -> 29428 | J11: ='Qtr Source Data'!L8 -> 28717 | K11: ='Qtr Source Data'!M8 -> 18350 | L11: ='Qtr Source Data'!O8-'Qtr Source Data'!N8 -> 16958 | M11: ='Qtr Source Data'!P8 -> 9139 | N11: ='Qtr Source Data'!Q8 -> 7398 | O11: =SUM(K11:N11) -> 51845
B12: Sales and marketing | C12: ='Qtr Source Data'!C9 -> 28872 | D12: ='Qtr Source Data'!E9-'Qtr Source Data'!D9 -> 29746 | E12: ='Qtr Source Data'!F9 -> 30375 | F12: ='Qtr Source Data'!G9 -> 23545 | G12: ='Qtr Source Data'!H9 -> 26508 | H12: ='Qtr Source Data'!J9-'Qtr Source Data'!I9 -> 27901 | I12: ='Qtr Source Data'!K9 -> 25614 | J12: ='Qtr Source Data'!L9 -> 17417 | K12: ='Qtr Source Data'!M9 -> 11583 | L12: ='Qtr Source Data'!O9-'Qtr Source Data'!N9 -> 14140 | M12: ='Qtr Source Data'!P9 -> 10606 | N12: ='Qtr Source Data'!Q9 -> 9468 | O12: =SUM(K12:N12) -> 45797
B13: General and administrative | C13: ='Qtr Source Data'!C10 -> 53475 | D13: ='Qtr Source Data'!E10-'Qtr Source Data'!D10 -> 53426 | E13: ='Qtr Source Data'!F10 -> 55534 | F13: ='Qtr Source Data'!G10 -> 54016 | G13: ='Qtr Source Data'!H10 -> 51910 | H13: ='Qtr Source Data'!J10-'Qtr Source Data'!I10 -> 56296 | I13: ='Qtr Source Data'!K10 -> 39374 | J13: ='Qtr Source Data'!L10 -> 59966 | K13: ='Qtr Source Data'!M10 -> 33232 | L13: ='Qtr Source Data'!O10-'Qtr Source Data'!N10 -> 44834 | M13: ='Qtr Source Data'!P10 -> 19180 | N13: ='Qtr Source Data'!Q10 -> 14591 | O13: =SUM(K13:N13) -> 111837
B14: Impairment expense | C14: ='Qtr Source Data'!C11 -> 3600 | D14: ='Qtr Source Data'!E11-'Qtr Source Data'!D11 -> 0 | E14: ='Qtr Source Data'!F11 -> 0 | F14: ='Qtr Source Data'!G11 -> 481531 | G14: ='Qtr Source Data'!H11 -> 195708 | H14: ='Qtr Source Data'!J11-'Qtr Source Data'!I11 -> 0 | I14: ='Qtr Source Data'!K11 -> 2000 | J14: ='Qtr Source Data'!L11 -> 0 | K14: ='Qtr Source Data'!M11 -> 0 | L14: ='Qtr Source Data'!O11-'Qtr Source Data'!N11 -> 0 | M14: ='Qtr Source Data'!P11 -> 0 | N14: ='Qtr Source Data'!Q11 -> 0 | O14: =SUM(K14:N14) -> 0
B15: Total operating expenses | C15: =SUM(C11:C14) -> 132149 | D15: =SUM(D11:D14) -> 128896 | E15: =SUM(E11:E14) -> 130344 | F15: =SUM(F11:F14) -> 602743 | G15: =SUM(G11:G14) -> 315463 | H15: =SUM(H11:H14) -> 125205 | I15: =SUM(I11:I14) -> 96416 | J15: =SUM(J11:J14) -> 106100 | ... O15: =SUM(O11:O14) -> 209479
B16: Operating income (loss) | C16: =C9-C15 -> -57870 | D16: =D9-D15 -> 13287 | E16: =E9-E15 -> -2491 | F16: =F9-F15 -> -485007 | G16: =G9-G15 -> -222290 | H16: =H9-H15 -> -27320 | I16: =I9-I15 -> -29002 | J16: =J9-J15 -> -36458 | ... O16: =O9-O15 -> -55608
B17: Operating margin | C17: =IFERROR(C16/C6,"") -> -0.36660458 | D17: =IFERROR(D16/D6,"") -> 0.070680419 | E17: =IFERROR(E16/E6,"") -> -0.014287353 | F17: =IFERROR(F16/F6,"") -> -2.9728221 | G17: =IFERROR(G16/G6,"") -> -1.6273894 | H17: =IFERROR(H16/H6,"") -> -0.19040451 | I17: =IFERROR(I16/I6,"") -> -0.2389218 | J17: =IFERROR(J16/J6,"") -> -0.34682268 | ... O17: =IFERROR(O16/O6,"") -> -0.20943686
B18: Interest expense, net | C18: ='Qtr Source Data'!C12 -> -733 | D18: ='Qtr Source Data'!E12-'Qtr Source Data'!D12 -> -658 | E18: ='Qtr Source Data'!F12 -> -650 | F18: ='Qtr Source Data'!G12 -> -651 | G18: ='Qtr Source Data'!H12 -> -658 | H18: ='Qtr Source Data'!J12-'Qtr Source Data'!I12 -> -631 | I18: ='Qtr Source Data'!K12 -> -467 | J18: ='Qtr Source Data'!L12 -> -41 | K18: ='Qtr Source Data'!M12 -> -41 | L18: ='Qtr Source Data'!O12-'Qtr Source Data'!N12 -> -41 | M18: ='Qtr Source Data'!P12 -> -31 | N18: ='Qtr Source Data'!Q12 -> -22 | O18: =SUM(K18:N18) -> -135
B19: Other income, net | C19: ='Qtr Source Data'!C13 -> 40492 | D19: ='Qtr Source Data'!E13-'Qtr Source Data'!D13 -> 5139 | E19: ='Qtr Source Data'!F13 -> 10780 | F19: ='Qtr Source Data'!G13 -> 7119 | G19: ='Qtr Source Data'!H13 -> 7586 | H19: ='Qtr Source Data'!J13-'Qtr Source Data'!I13 -> 25847 | I19: ='Qtr Source Data'!K13 -> 12997 | J19: ='Qtr Source Data'!L13 -> 2059 | K19: ='Qtr Source Data'!M13 -> 1377 | L19: ='Qtr Source Data'!O13-'Qtr Source Data'!N13 -> 871 | M19: ='Qtr Source Data'!P13 -> 1156 | N19: ='Qtr Source Data'!Q13 -> 638 | O19: =SUM(K19:N19) -> 4042
B20: Income (loss) before income taxes | C20: =C16+C18+C19 -> -18111 | D20: =D16+D18+D19 -> 17768 | E20: =E16+E18+E19 -> 7639 | F20: =F16+F18+F19 -> -478539 | G20: =G16+G18+G19 -> -215362 | H20: =H16+H18+H19 -> -2104 | I20: =I16+I18+I19 -> -16472 | J20: =J16+J18+J19 -> -34440 | ... O20: =O16+O18+O19 -> -51701
B21: (Provision for) benefit from income taxes | C21: ='Qtr Source Data'!C14 -> -172 | D21: ='Qtr Source Data'!E14-'Qtr Source Data'!D14 -> -8103 | E21: ='Qtr Source Data'!F14 -> -9059 | F21: ='Qtr Source Data'!G14 -> -138345 | G21: ='Qtr Source Data'!H14 -> 2723 | H21: ='Qtr Source Data'!J14-'Qtr Source Data'!I14 -> -4021 | I21: ='Qtr Source Data'!K14 -> -1012 | J21: ='Qtr Source Data'!L14 -> -1223 | K21: ='Qtr Source Data'!M14 -> -1683 | L21: ='Qtr Source Data'!O14-'Qtr Source Data'!N14 -> 639 | M21: ='Qtr Source Data'!P14 -> 140 | N21: ='Qtr Source Data'!Q14 -> -392 | O21: =SUM(K21:N21) -> -1296
B22: Net income (loss) | C22: =C20+C21 -> -18283 | D22: =D20+D21 -> 9665 | E22: =E20+E21 -> -1420 | F22: =F20+F21 -> -616884 | G22: =G20+G21 -> -212639 | H22: =H20+H21 -> -6125 | I22: =I20+I21 -> -17484 | J22: =J20+J21 -> -35663 | ... O22: =O20+O21 -> -52997
B23: Net margin | C23: =IFERROR(C22/C6,"") -> -0.11582222 | D23: =IFERROR(D22/D6,"") -> 0.05141313 | E23: =IFERROR(E22/E6,"") -> -0.0081445369 | F23: =IFERROR(F22/F6,"") -> -3.7811544 | G23: =IFERROR(G22/G6,"") -> -1.5567342 | H23: =IFERROR(H22/H6,"") -> -0.042687686 | I23: =IFERROR(I22/I6,"") -> -0.14403519 | J23: =IFERROR(J22/J6,"") -> -0.33925989 | ... O23: =IFERROR(O22/O6,"") -> -0.19960303
B24: EPS, basic | C24: ='Qtr Source Data'!C16 -> -0.16 | D24: n/a | E24: ='Qtr Source Data'!F16 -> -0.01 | F24: ='Qtr Source Data'!G16 -> -6.01 | G24: ='Qtr Source Data'!H16 -> -2.05 | H24: n/a | I24: ='Qtr Source Data'!K16 -> -0.17 | J24: ='Qtr Source Data'!L16 -> -0.33 | K24: ='Qtr Source Data'!M16 -> -0.16 | L24: n/a | M24: ='Qtr Source Data'!P16 -> 0 | N24: ='Qtr Source Data'!Q16 -> -0.03
B25: EPS, diluted | C25: ='Qtr Source Data'!C17 -> -0.16 | D25: n/a | E25: ='Qtr Source Data'!F17 -> -0.01 | F25: ='Qtr Source Data'!G17 -> -6.01 | G25: ='Qtr Source Data'!H17 -> -2.05 | H25: n/a | I25: ='Qtr Source Data'!K17 -> -0.17 | J25: ='Qtr Source Data'!L17 -> -0.33 | K25: ='Qtr Source Data'!M17 -> -0.16 | L25: n/a | M25: ='Qtr Source Data'!P17 -> 0 | N25: ='Qtr Source Data'!Q17 -> -0.03
B26: Weighted avg shares, basic (000s) | C26: ='Qtr Source Data'!C18 -> 115407 | D26: n/a | E26: ='Qtr Source Data'!F18 -> 102343 | F26: ='Qtr Source Data'!G18 -> 102604 | G26: ='Qtr Source Data'!H18 -> 103723 | H26: n/a | I26: ='Qtr Source Data'!K18 -> 105159 | J26: ='Qtr Source Data'!L18 -> 106908 | K26: ='Qtr Source Data'!M18 -> 108450 | L26: n/a | M26: ='Qtr Source Data'!P18 -> 111726 | N26: ='Qtr Source Data'!Q18 -> 111422
B27: Weighted avg shares, diluted (000s) | C27: ='Qtr Source Data'!C19 -> 115407 | D27: n/a | E27: ='Qtr Source Data'!F19 -> 102343 | F27: ='Qtr Source Data'!G19 -> 102604 | G27: ='Qtr Source Data'!H19 -> 103723 | H27: n/a | I27: ='Qtr Source Data'!K19 -> 105159 | J27: ='Qtr Source Data'!L19 -> 106908 | K27: ='Qtr Source Data'!M19 -> 108450 | L27: n/a | M27: ='Qtr Source Data'!P19 -> 112130 | N27: ='Qtr Source Data'!Q19 -> 111422
A29: BALANCE SHEET (period end)
C30: Q3 2023 | D30: Q4 2023 | E30: Q1 2024 | F30: Q2 2024 | G30: Q3 2024 | H30: Q4 2024 | I30: Q1 2025 | J30: Q2 2025 | K30: Q3 2025 | L30: Q4 2025 | M30: Q1 2026 | N30: Q2 2026
B31: Cash and cash equivalents | C31: ='Qtr Source Data'!C24 -> 94419 | D31: ='Qtr Source Data'!D24 -> 135757 | E31: ='Qtr Source Data'!E24 -> 143747 | F31: ='Qtr Source Data'!F24 -> 133068 | G31: ='Qtr Source Data'!G24 -> 152073 | H31: ='Qtr Source Data'!H24 -> 161475 | I31: ='Qtr Source Data'!I24 -> 44105 | J31: ='Qtr Source Data'!J24 -> 36825 | ... N31: ='Qtr Source Data'!N24 -> 44623
B32: Short-term investments | C32: ='Qtr Source Data'!C25 -> 166841 | D32: ='Qtr Source Data'!D25 -> 194257 | E32: ='Qtr Source Data'!E25 -> 247013 | F32: ='Qtr Source Data'!F25 -> 212396 | G32: ='Qtr Source Data'!G25 -> 209003 | H32: ='Qtr Source Data'!H25 -> 154249 | I32: ='Qtr Source Data'!I25 -> 44188 | J32: ='Qtr Source Data'!J25 -> 48815 | ... N32: ='Qtr Source Data'!N25 -> 27691
B33: Accounts receivable, net | C33: ='Qtr Source Data'!C26 -> 30480 | D33: ='Qtr Source Data'!D26 -> 31404 | E33: ='Qtr Source Data'!E26 -> 24741 | F33: ='Qtr Source Data'!F26 -> 20964 | G33: ='Qtr Source Data'!G26 -> 23749 | H33: ='Qtr Source Data'!H26 -> 23641 | I33: ='Qtr Source Data'!I26 -> 28549 | J33: ='Qtr Source Data'!J26 -> 18055 | ... N33: ='Qtr Source Data'!N26 -> 10734
B34: Prepaid expenses | C34: ='Qtr Source Data'!C27 -> 30761 | D34: ='Qtr Source Data'!D27 -> 20980 | E34: ='Qtr Source Data'!E27 -> 20429 | F34: ='Qtr Source Data'!F27 -> 30841 | G34: ='Qtr Source Data'!G27 -> 24706 | H34: ='Qtr Source Data'!H27 -> 17100 | I34: ='Qtr Source Data'!I27 -> 14514 | J34: ='Qtr Source Data'!J27 -> 23683 | ... N34: ='Qtr Source Data'!N27 -> 11352
B35: Other current assets | C35: ='Qtr Source Data'!C28 -> 25195 | D35: ='Qtr Source Data'!D28 -> 32437 | E35: ='Qtr Source Data'!E28 -> 30010 | F35: ='Qtr Source Data'!F28 -> 36279 | G35: ='Qtr Source Data'!G28 -> 86980 | H35: ='Qtr Source Data'!H28 -> 81094 | I35: ='Qtr Source Data'!I28 -> 78395 | J35: ='Qtr Source Data'!J28 -> 76548 | ... N35: ='Qtr Source Data'!N28 -> 14301
B36: Total current assets | C36: =SUM(C31:C35) -> 347696 | D36: =SUM(D31:D35) -> 414835 | E36: =SUM(E31:E35) -> 465940 | F36: =SUM(F31:F35) -> 433548 | G36: =SUM(G31:G35) -> 496511 | H36: =SUM(H31:H35) -> 437559 | I36: =SUM(I31:I35) -> 209751 | J36: =SUM(J31:J35) -> 203926 | ... N36: =SUM(N31:N35) -> 108701
B37: Long-term investments | C37: ='Qtr Source Data'!C29 -> 412541 | D37: ='Qtr Source Data'!D29 -> 249547 | E37: ='Qtr Source Data'!E29 -> 221665 | F37: ='Qtr Source Data'!F29 -> 259925 | G37: ='Qtr Source Data'!G29 -> 270161 | H37: ='Qtr Source Data'!H29 -> 212650 | I37: ='Qtr Source Data'!I29 -> 38093 | J37: ='Qtr Source Data'!J29 -> 28474 | ... N37: ='Qtr Source Data'!N29 -> 0
B38: Property and equipment, net | C38: ='Qtr Source Data'!C30 -> 168735 | D38: ='Qtr Source Data'!D30 -> 183073 | E38: ='Qtr Source Data'!E30 -> 188430 | F38: ='Qtr Source Data'!F30 -> 179278 | G38: ='Qtr Source Data'!G30 -> 177882 | H38: ='Qtr Source Data'!H30 -> 170648 | I38: ='Qtr Source Data'!I30 -> 144971 | J38: ='Qtr Source Data'!J30 -> 135491 | ... N38: ='Qtr Source Data'!N30 -> 94948
B39: Goodwill | C39: ='Qtr Source Data'!C31 -> 617690 | D39: ='Qtr Source Data'!D31 -> 631995 | E39: ='Qtr Source Data'!E31 -> 628784 | F39: ='Qtr Source Data'!F31 -> 189769 | G39: ='Qtr Source Data'!G31 -> 0 | H39: ='Qtr Source Data'!H31 -> 0 | I39: ='Qtr Source Data'!I31 -> 0 | J39: ='Qtr Source Data'!J31 -> 0 | ... N39: ='Qtr Source Data'!N31 -> 0
B40: Intangible assets, net | C40: ='Qtr Source Data'!C32 -> 56638 | D40: ='Qtr Source Data'!D32 -> 52430 | E40: ='Qtr Source Data'!E32 -> 48143 | F40: ='Qtr Source Data'!F32 -> 12848 | G40: ='Qtr Source Data'!G32 -> 11424 | H40: ='Qtr Source Data'!H32 -> 10347 | I40: ='Qtr Source Data'!I32 -> 9271 | J40: ='Qtr Source Data'!J32 -> 8194 | ... N40: ='Qtr Source Data'!N32 -> 3957
B41: Right of use assets | C41: ='Qtr Source Data'!C33 -> 26568 | D41: ='Qtr Source Data'!D33 -> 25130 | E41: ='Qtr Source Data'!E33 -> 23521 | F41: ='Qtr Source Data'!F33 -> 21508 | G41: ='Qtr Source Data'!G33 -> 29071 | H41: ='Qtr Source Data'!H33 -> 22256 | I41: ='Qtr Source Data'!I33 -> 21479 | J41: ='Qtr Source Data'!J33 -> 19418 | ... N41: ='Qtr Source Data'!N33 -> 11505
B42: Deferred tax assets | C42: ='Qtr Source Data'!C34 -> 145807 | D42: ='Qtr Source Data'!D34 -> 141843 | E42: ='Qtr Source Data'!E34 -> 140200 | F42: ='Qtr Source Data'!F34 -> 2287 | G42: ='Qtr Source Data'!G34 -> 2308 | H42: ='Qtr Source Data'!H34 -> 0 | I42: ='Qtr Source Data'!I34 -> 0 | J42: ='Qtr Source Data'!J34 -> 0 | ... N42: ='Qtr Source Data'!N34 -> 0
...

Sheet Assumptions
A1: Assumptions & Inputs
A3: COMPANY
B4: Company name | C4: Chegg, Inc.
B5: Ticker | C5: #VALUE!
B6: Current share price ($) | C6: {=_FV(C5,"Price")} -> 0.72
B7: Shares outstanding (millions) | C7: {=(_FV(C5,"Shares outstanding",TRUE)+10322706)/1000000} -> 121.35021
B8: Market capitalization ($mm) | C8: =C6*C7 -> 87.372148
A10: FREE CASH FLOW & GROWTH
B11: CFO | C11: 14.161
B12: Minus CapEx | C12: -4.7
B13: Minus SBC | C13: -5.035
B14: Current normalized FCF | C14: =SUM(C11:C13) -> 4.426
B15: Current normalized FCF per share ($) | C15: {=SUM(C11:C13/C7)*2} -> 0.0729459
B16: Conservative case — annual FCF growth, Yrs 1-10 | C16: 0 | D16: Book's worst-realistic-case default: results never improve from here
B17: Moderate case — annual FCF growth, Yrs 1-10 | C17: 0.1 | D17: A modest, non-heroic growth assumption (still meant to be defensible, not optimistic)
B18: Terminal growth rate (in perpetuity after Yr 10) | C18: 0 | D18: 0% is the conservative default
A20: DISCOUNT RATE
B21: Current risk-free rate | C21: 0.04965 | D21: 10-yr Treasury yield
B22: Discount rate — Low | C22: 0.1
B23: Discount rate — Base | C23: =C21+(2*(0.0414)) -> 0.13245 | D23: WACC (CAPM)
B24: Discount rate — High | C24: 0.15
A26: BALANCE SHEET, $ MILLIONS
B27: Cash & equivalents | C27: 44.623
B28: Marketable securities (at market) | C28: 27.691
B29: Accounts receivable | C29: 10.734
B30: Inventory | C30: 0
B31: Other current assets | C31: =14.301+11.352 -> 25.653
B32: Net PP&E (book value) | C32: 94.948
B33: Total current liabilities | C33: 92.96
B34: Long-term debt | C34: 0
B35: Other long-term liabilities | C35: 16.051
B36: Off-balance-sheet / contingent liabilities | C36: 0 | D36: Underfunded pensions, environmental or lease exposure
A38: LIQUIDATION RECOVERY ASSUMPTIONS
B39: Securities — transaction cost % | C39: 0.02
B40: Receivables recovery — orderly liquidation | C40: 0.9
B41: Receivables recovery — fire sale | C41: 0.7
B42: Inventory recovery — orderly liquidation | C42: 0.7
B43: Inventory recovery — fire sale | C43: 0.4
B44: PP&E — estimated liquidation value ($mm) | C44: =C32*0.01 -> 0.94948 | D44: This is the hardest line to estimate and genuinely case-by-case
A46: COMPARABLE MULTIPLES
...

Sheet DCF NPV
A1: NPV / Discounted Cash Flow Analysis
B3: Company: | C3: =Assumptions!C4 -> Chegg, Inc.
A5: CONSERVATIVE CASE
C6: Year 1 | D6: Year 2 | E6: Year 3 | F6: Year 4 | G6: Year 5 | H6: Year 6 | I6: Year 7 | J6: Year 8 | K6: Year 9 | L6: Year 10
B7: FCF | C7: =Assumptions!$C$14*(1+Assumptions!$C$16)^(COLUMN()-2) -> 4.426 | D7: =Assumptions!$C$14*(1+Assumptions!$C$16)^(COLUMN()-2) -> 4.426 | E7: =Assumptions!$C$14*(1+Assumptions!$C$16)^(COLUMN()-2) -> 4.426 | F7: =Assumptions!$C$14*(1+Assumptions!$C$16)^(COLUMN()-2) -> 4.426 | G7: =Assumptions!$C$14*(1+Assumptions!$C$16)^(COLUMN()-2) -> 4.426 | H7: =Assumptions!$C$14*(1+Assumptions!$C$16)^(COLUMN()-2) -> 4.426 | I7: =Assumptions!$C$14*(1+Assumptions!$C$16)^(COLUMN()-2) -> 4.426 | J7: =Assumptions!$C$14*(1+Assumptions!$C$16)^(COLUMN()-2) -> 4.426 | ... L7: =Assumptions!$C$14*(1+Assumptions!$C$16)^(COLUMN()-2) -> 4.426
B8: FCF per share | C8: =Assumptions!$C$15*(1+Assumptions!$C$16)^(COLUMN()-2) -> 0.0729459 | D8: =Assumptions!$C$15*(1+Assumptions!$C$16)^(COLUMN()-2) -> 0.0729459 | E8: =Assumptions!$C$15*(1+Assumptions!$C$16)^(COLUMN()-2) -> 0.0729459 | F8: =Assumptions!$C$15*(1+Assumptions!$C$16)^(COLUMN()-2) -> 0.0729459 | G8: =Assumptions!$C$15*(1+Assumptions!$C$16)^(COLUMN()-2) -> 0.0729459 | H8: =Assumptions!$C$15*(1+Assumptions!$C$16)^(COLUMN()-2) -> 0.0729459 | I8: =Assumptions!$C$15*(1+Assumptions!$C$16)^(COLUMN()-2) -> 0.0729459 | J8: =Assumptions!$C$15*(1+Assumptions!$C$16)^(COLUMN()-2) -> 0.0729459 | ... L8: =Assumptions!$C$15*(1+Assumptions!$C$16)^(COLUMN()-2) -> 0.0729459
A10: MODERATE CASE
C11: Year 1 | D11: Year 2 | E11: Year 3 | F11: Year 4 | G11: Year 5 | H11: Year 6 | I11: Year 7 | J11: Year 8 | K11: Year 9 | L11: Year 10
B12: FCF | C12: =Assumptions!$C$14*(1+Assumptions!$C$17)^(COLUMN()-2) -> 4.8686 | D12: =Assumptions!$C$14*(1+Assumptions!$C$17)^(COLUMN()-2) -> 5.35546 | E12: =Assumptions!$C$14*(1+Assumptions!$C$17)^(COLUMN()-2) -> 5.891006 | F12: =Assumptions!$C$14*(1+Assumptions!$C$17)^(COLUMN()-2) -> 6.4801066 | G12: =Assumptions!$C$14*(1+Assumptions!$C$17)^(COLUMN()-2) -> 7.1281173 | H12: =Assumptions!$C$14*(1+Assumptions!$C$17)^(COLUMN()-2) -> 7.840929 | I12: =Assumptions!$C$14*(1+Assumptions!$C$17)^(COLUMN()-2) -> 8.6250219 | J12: =Assumptions!$C$14*(1+Assumptions!$C$17)^(COLUMN()-2) -> 9.4875241 | ... L12: =Assumptions!$C$14*(1+Assumptions!$C$17)^(COLUMN()-2) -> 11.479904
B13: FCF per share | C13: =Assumptions!$C$15*(1+Assumptions!$C$17)^(COLUMN()-2) -> 0.08024049 | D13: =Assumptions!$C$15*(1+Assumptions!$C$17)^(COLUMN()-2) -> 0.088264539 | E13: =Assumptions!$C$15*(1+Assumptions!$C$17)^(COLUMN()-2) -> 0.097090993 | F13: =Assumptions!$C$15*(1+Assumptions!$C$17)^(COLUMN()-2) -> 0.10680009 | G13: =Assumptions!$C$15*(1+Assumptions!$C$17)^(COLUMN()-2) -> 0.1174801 | H13: =Assumptions!$C$15*(1+Assumptions!$C$17)^(COLUMN()-2) -> 0.12922811 | I13: =Assumptions!$C$15*(1+Assumptions!$C$17)^(COLUMN()-2) -> 0.14215092 | J13: =Assumptions!$C$15*(1+Assumptions!$C$17)^(COLUMN()-2) -> 0.15636602 | ... L13: =Assumptions!$C$15*(1+Assumptions!$C$17)^(COLUMN()-2) -> 0.18920288
A15: CONSERVATIVE CASE
B16: Discount Rate | C16: Rate | D16: PV of Yrs 1-10 FCF | E16: Terminal Value (Yr 10) | F16: PV of Terminal Value | G16: Total NPV / Share
B17: Low | C17: =Assumptions!C22 -> 0.1 | D17: =NPV(C17,C8:L8) -> 0.44822098 | E17: =L8*(1+Assumptions!$C$18)/(C17-Assumptions!$C$18) -> 0.729459 | F17: =E17/(1+C17)^10 -> 0.28123802 | G17: =D17+F17 -> 0.729459
B18: Base | C18: =Assumptions!C23 -> 0.13245 | D18: =NPV(C18,C8:L8) -> 0.39197653 | E18: =L8*(1+Assumptions!$C$18)/(C18-Assumptions!$C$18) -> 0.55074292 | F18: =E18/(1+C18)^10 -> 0.15876639 | G18: =D18+F18 -> 0.55074292
B19: High | C19: =Assumptions!C24 -> 0.15 | D19: =NPV(C19,C8:L8) -> 0.36609859 | E19: =L8*(1+Assumptions!$C$18)/(C19-Assumptions!$C$18) -> 0.486306 | F19: =E19/(1+C19)^10 -> 0.12020741 | G19: =D19+F19 -> 0.486306
A21: MODERATE CASE
B22: Discount Rate | C22: Rate | D22: PV of Yrs 1-10 FCF | E22: Terminal Value (Yr 10) | F22: PV of Terminal Value | G22: Total NPV / Share
B23: Low | C23: =Assumptions!C22 -> 0.1 | D23: =NPV(C23,C13:L13) -> 0.729459 | E23: =L13*(1+Assumptions!$C$18)/(C23-Assumptions!$C$18) -> 1.8920288 | F23: =E23/(1+C23)^10 -> 0.729459 | G23: =D23+F23 -> 1.458918
B24: Base | C24: =Assumptions!C23 -> 0.13245 | D24: =NPV(C24,C13:L13) -> 0.62383412 | E24: =L13*(1+Assumptions!$C$18)/(C24-Assumptions!$C$18) -> 1.4284853 | F24: =E24/(1+C24)^10 -> 0.41179912 | G24: =D24+F24 -> 1.0356332
B25: High | C25: =Assumptions!C24 -> 0.15 | D25: =NPV(C25,C13:L13) -> 0.57591253 | E25: =L13*(1+Assumptions!$C$18)/(C25-Assumptions!$C$18) -> 1.2613525 | F25: =E25/(1+C25)^10 -> 0.31178705 | G25: =D25+F25 -> 0.88769958
A27: SUMMARY
C28: Conservative Case | D28: Moderate Case
B29: Low discount rate | C29: =G17 -> 0.729459 | D29: =G23 -> 1.458918
B30: Base discount rate | C30: =G18 -> 0.55074292 | D30: =G24 -> 1.0356332
B31: High discount rate | C31: =G19 -> 0.486306 | D31: =G25 -> 0.88769958
B32: Range across all scenarios | C32: =MIN(C29:D31) -> 0.486306 | D32: =MAX(C29:D31) -> 1.458918

Sheet Liquidation
A1: Liquidation Value
B3: Company: | C3: =Assumptions!C4 -> Chegg, Inc.
A5: NET-NET WORKING CAPITAL
C6: $mm
B7: Cash & equivalents | C7: =Assumptions!C27 -> 44.623
B8: Marketable securities | C8: =Assumptions!C28 -> 27.691
B9: Accounts receivable | C9: =Assumptions!C29 -> 10.734
B10: Inventory | C10: =Assumptions!C30 -> 0
B11: Other current assets | C11: =Assumptions!C31 -> 25.653
B12: Total current assets (undiscounted) | C12: =SUM(C7:C11) -> 108.701
B13: Less: total current liabilities | C13: =-Assumptions!C33 -> -92.96
B14: Less: long-term debt | C14: =-Assumptions!C34 -> 0
B15: Less: other long-term liabilities | C15: =-Assumptions!C35 -> -16.051
B16: Less: contingent/off-balance-sheet liabilities | C16: =-Assumptions!C36 -> 0
B17: Net-net working capital ($mm) | C17: =C12+SUM(C13:C16) -> -0.31
B18: Net-net working capital per share | C18: =C17/Assumptions!C7 -> -0.0025545898
B19: Net working capital (current assets less current liabilities) minus all long-term liabilities, a genuine worst-case floor
A21: ORDERLY vs. FIRE-SALE LIQUIDATION VALUE (pp. 143-144)
C22: Orderly | D22: Fire Sale
B23: Cash & equivalents (100% both cases) | C23: =Assumptions!C27 -> 44.623 | D23: =Assumptions!C27 -> 44.623
B24: Marketable securities, net of transaction cost | C24: =Assumptions!C28*(1-Assumptions!C39) -> 27.13718 | D24: =Assumptions!C28*(1-Assumptions!C39) -> 27.13718
B25: Accounts receivable, at recovery % | C25: =Assumptions!C29*Assumptions!C40 -> 9.6606 | D25: =Assumptions!C29*Assumptions!C41 -> 7.5138
B26: Inventory, at recovery % | C26: =Assumptions!C30*Assumptions!C42 -> 0 | D26: =Assumptions!C30*Assumptions!C43 -> 0
B27: Other current assets (assume orderly recovery %, both cases) | C27: =Assumptions!C31*Assumptions!C40 -> 23.0877 | D27: =Assumptions!C31*Assumptions!C41 -> 17.9571
B28: PP&E, at estimated liquidation value (your judgment) | C28: =Assumptions!C44 -> 0.94948 | D28: =Assumptions!C44*0.7 -> 0.664636
B29: Gross liquidation proceeds | C29: =SUM(C23:C28) -> 105.45796 | D29: =SUM(D23:D28) -> 97.895716
B30: Less: total liabilities (current + LT + contingent) | C30: =-(Assumptions!C33+Assumptions!C34+Assumptions!C35+Assumptions!C36) -> -109.011 | D30: =-(Assumptions!C33+Assumptions!C34+Assumptions!C35+Assumptions!C36) -> -109.011
B31: Net liquidation value ($mm) | C31: =C29+C30 -> -3.55304 | D31: =D29+D30 -> -11.115284
B32: Net liquidation value per share | C32: =C31/Assumptions!C7 -> -0.029279225 | D32: =D31/Assumptions!C7 -> -0.091596746

Sheet Market Multiples
A1: Private-Market Value & Stock Market Value
B3: Company: | C3: =Assumptions!C4 -> Chegg, Inc.
B4: Subject pretax cash flow ($mm): | C4: =Assumptions!C47 -> 49.2
A6: PRIVATE-MARKET VALUE
B7: Average multiple | C7: =AVERAGEIF(Assumptions!$D$50:$D$54,"Transaction",Assumptions!$C$50:$C$54) -> 14.6
B8: Number of comps in that average | C8: =COUNTIF(Assumptions!$D$50:$D$54,"Transaction") -> 1
B9: Implied enterprise value ($mm) | C9: =C4*C7 -> 718.32
B10: Less: total debt | C10: =-(Assumptions!C34) -> 0
B11: Plus: cash & equivalents | C11: =Assumptions!C27 -> 44.623
B12: Implied equity value ($mm) | C12: =C9-Assumptions!C34+Assumptions!C27 -> 762.943
B13: Implied value per share | C13: =C12/Assumptions!C7 -> 6.2871175
B14: Multiples paid by sophisticated private buyers for comparable whole businesses. These multiples drift with credit availability and buyer discipline.
A16: STOCK MARKET VALUE
B17: Average multiple | C17: =AVERAGEIF(Assumptions!$D$50:$D$54,"Trading",Assumptions!$C$50:$C$54) -> 8.15
B18: Number of comps in that average | C18: =COUNTIF(Assumptions!$D$50:$D$54,"Trading") -> 2
B19: Implied enterprise value ($mm) | C19: =C4*C17 -> 400.98
B20: Less: total debt | C20: =-(Assumptions!C34) -> 0
B21: Plus: cash & equivalents | C21: =Assumptions!C27 -> 44.623
B22: Implied equity value ($mm) | C22: =C19-Assumptions!C34+Assumptions!C27 -> 445.603
B23: Implied value per share | C23: =C22/Assumptions!C7 -> 3.6720416
B24: What comparable public companies trade for. Book calls this the least reliable of the three core methods, most useful for closed-end funds, holding companies, or spin-offs.

Sheet Summary
A1: Summary — Range of Value & Margin of Safety
B3: Company: | C3: =Assumptions!C4 -> Chegg, Inc.
B4: Current share price: | C4: =Assumptions!C6 -> 0.72
A6: VALUE ESTIMATES PER SHARE
C7: Value / Share | D7: Source / Note
B8: NPV / DCF — Conservative case, low end | C8: ='DCF NPV'!C32 -> 0.486306 | D8: Lowest of 6 DCF scenarios on DCF_NPV.
B9: NPV / DCF — Moderate case, high end | C9: ='DCF NPV'!D32 -> 1.458918 | D9: Highest of 6 DCF scenarios on DCF_NPV.
B10: Net-net working capital (Graham floor) | C10: =Liquidation!C18 -> -0.0025545898 | D10: Undiscounted current assets less every liability (pp. 144-145).
B11: Liquidation value — orderly wind-down | C11: =Liquidation!C32 -> -0.029279225 | D11: From the Liquidation tab.
B12: Liquidation value — fire sale | C12: =Liquidation!D32 -> -0.091596746 | D12: From the Liquidation tab.
B13: Private-market value | C13: ='Market Multiples'!C13 -> 6.2871175 | D13: Transaction-multiple comps (pp. 140-142).
B14: Stock market value | C14: ='Market Multiples'!C23 -> 3.6720416 | D14: Trading-multiple comps (pp. 145-147).
A16: RANGE & MARGIN OF SAFETY
B17: Lowest value estimate (most conservative) | C17: =MIN(C8:C14) -> -0.091596746
B18: Highest value estimate | C18: =MAX(C8:C14) -> 6.2871175
B19: Current share price | C19: =C4 -> 0.72
B20: Discount of price to lowest value estimate | C20: =IF(C17<=0,"n/a - lowest estimate is zero or negative",1-C4/C17) -> n/a - lowest estimate is zero or negative
B21: Your required margin of safety | C21: =Assumptions!C63 -> 0.33
B22: Price at which required margin of safety is met | C22: =C17*(1-C21) -> -0.06136982
B23: Meets your required margin of safety? | C23: =IF(ISNUMBER(C20),IF(C20>=C21,"Yes - price is at/below your target","No - price is above your target"),"n/a - see note above") -> n/a - see note above
B25: Reminder: the book does not prescribe a single required discount — margin of safety is defined as buying cheap enough to absorb your own forecasting error, bad luck, or market decline (Glossary, p. 244). Set the required-margin cell on the Assumptions tab to whatever discount you actually need to sleep at night, and revisit it if your conviction in the inputs above changes.
B27: Also revisit the range itself, not just the price: if the seven estimates above disagree sharply, that is itself information (p. 147) — it usually means one or more of your inputs (growth, discount rate, recovery %) deserves more scrutiny before you rely on the average.

Sheet Qtr Source Data
A1: Quarterly Source Data (as reported in Chegg SEC filings)
B2: $ in thousands, except per share.
A4: INCOME STATEMENT, AS REPORTED
B5: Period | C5: 3M Sep-23 | D5: 9M Sep-23 | E5: FY 2023 | F5: 3M Mar-24 | G5: 3M Jun-24 | H5: 3M Sep-24 | I5: 9M Sep-24 | J5: FY 2024 | K5: 3M Mar-25 | L5: 3M Jun-25 | M5: 3M Sep-25 | N5: 9M Sep-25 | O5: FY 2025 | P5: 3M Mar-26 | Q5: 3M Jun-26
B6: Net revenues | C6: 157854 | D6: 528308 | E6: 716295 | F6: 174350 | G6: 163147 | H6: 136593 | I6: 474090 | J6: 617574 | K6: 121387 | L6: 105120 | M6: 77742 | N6: 304249 | O6: 376908 | P6: 63262 | Q6: 51849
B7: Cost of revenues (positive = expense) | C7: 83575 | D7: 180137 | E7: 225941 | F7: 46497 | G7: 45411 | H7: 43420 | I7: 135328 | J7: 180927 | K7: 53973 | L7: 35478 | M7: 31701 | N7: 121152 | O7: 152151 | P7: 25374 | Q7: 23567
B8: Research and development | C8: 46202 | D8: 145981 | E8: 191705 | F8: 44435 | G8: 43651 | H8: 41337 | I8: 129423 | J8: 170431 | K8: 29428 | L8: 28717 | M8: 18350 | N8: 76495 | O8: 93453 | P8: 9139 | Q8: 7398
B9: Sales and marketing | C9: 28872 | D9: 96845 | E9: 126591 | F9: 30375 | G9: 23545 | H9: 26508 | I9: 80428 | J9: 108329 | K9: 25614 | L9: 17417 | M9: 11583 | N9: 54614 | O9: 68754 | P9: 10606 | Q9: 9468
B10: General and administrative | C10: 53475 | D10: 182757 | E10: 236183 | F10: 55534 | G10: 54016 | H10: 51910 | I10: 161460 | J10: 217756 | K10: 39374 | L10: 59966 | M10: 33232 | N10: 132572 | O10: 177406 | P10: 19180 | Q10: 14591
B11: Impairment expense | C11: 3600 | D11: 3600 | E11: 3600 | F11: 0 | G11: 481531 | H11: 195708 | I11: 677239 | J11: 677239 | K11: 2000 | L11: 0 | M11: 0 | N11: 2000 | O11: 2000 | P11: 0 | Q11: 0
B12: Interest expense, net | C12: -733 | D12: -3115 | E12: -3773 | F12: -650 | G12: -651 | H12: -658 | I12: -1959 | J12: -2590 | K12: -467 | L12: -41 | M12: -41 | N12: -549 | O12: -590 | P12: -31 | Q12: -22
B13: Other income, net | C13: 40492 | D13: 116671 | E13: 121810 | F13: 10780 | G13: 7119 | H13: 7586 | I13: 25485 | J13: 51332 | K13: 12997 | L13: 2059 | M13: 1377 | N13: 16433 | O13: 17304 | P13: 1156 | Q13: 638
B14: (Provision for) benefit from income taxes | C14: -172 | D14: -24029 | E14: -32132 | F14: -9059 | G14: -138345 | H14: 2723 | I14: -144681 | J14: -148702 | K14: -1012 | L14: -1223 | M14: -1683 | N14: -3918 | O14: -3279 | P14: 140 | Q14: -392
B15: Net income (loss), as reported | C15: -18283 | D15: 8515 | E15: 18180 | F15: -1420 | G15: -616884 | H15: -212639 | I15: -830943 | J15: -837068 | K15: -17484 | L15: -35663 | M15: -17471 | N15: -70618 | O15: -103421 | P15: 228 | Q15: -2951
B16: EPS, basic ($) | C16: -0.16 | F16: -0.01 | G16: -6.01 | H16: -2.05 | K16: -0.17 | L16: -0.33 | M16: -0.16 | P16: 0 | Q16: -0.03
B17: EPS, diluted ($) | C17: -0.16 | F17: -0.01 | G17: -6.01 | H17: -2.05 | K17: -0.17 | L17: -0.33 | M17: -0.16 | P17: 0 | Q17: -0.03
B18: Weighted avg shares, basic (000s) | C18: 115407 | F18: 102343 | G18: 102604 | H18: 103723 | K18: 105159 | L18: 106908 | M18: 108450 | P18: 111726 | Q18: 111422
B19: Weighted avg shares, diluted (000s) | C19: 115407 | F19: 102343 | G19: 102604 | H19: 103723 | K19: 105159 | L19: 106908 | M19: 108450 | P19: 112130 | Q19: 111422
A22: BALANCE SHEET, AS REPORTED
B23: Period end | C23: Sep 30, 2023 | D23: Dec 31, 2023 | E23: Mar 31, 2024 | F23: Jun 30, 2024 | G23: Sep 30, 2024 | H23: Dec 31, 2024 | I23: Mar 31, 2025 | J23: Jun 30, 2025 | K23: Sep 30, 2025 | L23: Dec 31, 2025 | M23: Mar 31, 2026 | N23: Jun 30, 2026
B24: Cash and cash equivalents | C24: 94419 | D24: 135757 | E24: 143747 | F24: 133068 | G24: 152073 | H24: 161475 | I24: 44105 | J24: 36825 | K24: 38180 | L24: 31146 | M24: 33526 | N24: 44623
B25: Short-term investments | C25: 166841 | D25: 194257 | E25: 247013 | F25: 212396 | G25: 209003 | H25: 154249 | I25: 44188 | J25: 48815 | K25: 58209 | L25: 41674 | M25: 32388 | N25: 27691
B26: Accounts receivable, net | C26: 30480 | D26: 31404 | E26: 24741 | F26: 20964 | G26: 23749 | H26: 23641 | I26: 28549 | J26: 18055 | K26: 15440 | L26: 15604 | M26: 17795 | N26: 10734
B27: Prepaid expenses | C27: 30761 | D27: 20980 | E27: 20429 | F27: 30841 | G27: 24706 | H27: 17100 | I27: 14514 | J27: 23683 | K27: 18742 | L27: 16331 | M27: 12128 | N27: 11352
B28: Other current assets | C28: 25195 | D28: 32437 | E28: 30010 | F28: 36279 | G28: 86980 | H28: 81094 | I28: 78395 | J28: 76548 | K28: 72788 | L28: 16857 | M28: 14948 | N28: 14301
B29: Long-term investments | C29: 412541 | D29: 249547 | E29: 221665 | F29: 259925 | G29: 270161 | H29: 212650 | I29: 38093 | J29: 28474 | K29: 15277 | L29: 12392 | M29: 1984 | N29: 0
B30: Property and equipment, net | C30: 168735 | D30: 183073 | E30: 188430 | F30: 179278 | G30: 177882 | H30: 170648 | I30: 144971 | J30: 135491 | K30: 125598 | L30: 115168 | M30: 105127 | N30: 94948
B31: Goodwill | C31: 617690 | D31: 631995 | E31: 628784 | F31: 189769 | G31: 0 | H31: 0 | I31: 0 | J31: 0 | K31: 0 | L31: 0 | M31: 0 | N31: 0
B32: Intangible assets, net | C32: 56638 | D32: 52430 | E32: 48143 | F32: 12848 | G32: 11424 | H32: 10347 | I32: 9271 | J32: 8194 | K32: 7117 | L32: 6041 | M32: 4964 | N32: 3957
B33: Right of use assets | C33: 26568 | D33: 25130 | E33: 23521 | F33: 21508 | G33: 29071 | H33: 22256 | I33: 21479 | J33: 19418 | K33: 18088 | L33: 13188 | M33: 12113 | N33: 11505
B34: Deferred tax assets | C34: 145807 | D34: 141843 | E34: 140200 | F34: 2287 | G34: 2308 | H34: 0 | I34: 0 | J34: 0 | K34: 0 | L34: 0 | M34: 0 | N34: 0
B35: Other assets | C35: 28964 | D35: 28382 | E35: 15961 | F35: 15167 | G35: 15315 | H35: 15491 | I35: 15204 | J35: 8950 | K35: 8832 | L35: 9613 | M35: 9129 | N35: 8514
... B49: Total stockholders' equity, as reported | C49: 1033349 | D49: 944618 | E49: 963474 | F49: 365500 | G49: 184981 | H49: 192981 | I49: 185671 | J49: 157856 | K49: 146053 | L49: 119623 | M49: 121143 | N49: 118614
A52: CASH FLOW STATEMENT, AS REPORTED YEAR-TO-DATE
B53: Period (year-to-date) | C53: 6M Jun-23 | D53: 9M Sep-23 | E53: FY 2023 | F53: 3M Mar-24 | G53: 6M Jun-24 | H53: 9M Sep-24 | I53: FY 2024 | J53: 3M Mar-25 | K53: 6M Jun-25 | L53: 9M Sep-25 | M53: FY 2025 | N53: 3M Mar-26 | O53: 6M Jun-26
B54: Net income (loss) | C54: 26798 | D54: 8515 | E54: 18180 | F54: -1420 | G54: -618304 | H54: -830943 | I54: -837068 | J54: -17484 | K54: -53147 | L54: -70618 | M54: -103421 | N54: 228 | O54: -2723
B55: Share-based compensation expense | C55: 69666 | D55: 101596 | E55: 133502 | F55: 29289 | G55: 47336 | H55: 69267 | I55: 84614 | J55: 11257 | K55: 19169 | L55: 25094 | M55: 31864 | N55: 2711 | O55: 5035
B56: Depreciation and amortization expense | C56: 52027 | D56: 108945 | E56: 129718 | F56: 19687 | G56: 39393 | H56: 58966 | I56: 78344 | J56: 32094 | K56: 48320 | L56: 63641 | M56: 78637 | N56: 13947 | O56: 26992
B57: Deferred income taxes | C57: 20142 | D57: 20929 | E57: 26575 | F57: 2877 | G57: 141032 | H57: 141103 | I57: 143319 | J57: 15 | K57: 149 | L57: 319 | M57: 1348 | N57: -95 | O57: -11
B58: Operating lease expense, net of accretion | C58: 3009 | D58: 4535 | E58: 6079 | F58: 1567 | G58: 3141 | H58: 4647 | I58: 5864 | J58: 1089 | K58: 2019 | L58: 2883 | M58: 3641 | N58: 545 | O58: 1076
...
