Workbook

Sheet Main
B2: CRM | C2: Statements as of 1/31/26 (FY26 fiscal year-end)
B3: Price | C3: 247.29
B4: Shares Outstanding (mm) | C4: 929
B5: Market Cap | C5: =C3*C4 -> 229732.41
B6: Cash | C6: 7327
B7: Debt | C7: =4000+10439 -> 14439
B8: EV | C8: =C5+C7-C6 -> 236844.41
B10: Founder/Exec Chairman:
B11: CEO:
B12: CFO:

Sheet 10QIS
B2: Salesforce, Inc. (CRM)
B4: Historic Quarterly Income Statement | C4: Q1'21 | D4: Q2'21 | E4: Q3'21 | F4: Q4'21 | G4: Q1'22 | H4: Q2'22 | I4: Q3'22 | J4: Q4'22 | K4: Q1'23 | L4: Q2'23 | M4: Q3'23 | N4: Q4'23 | O4: Q1'24 | P4: Q2'24 | Q4: Q3'24 | R4: Q4'24 | S4: Q1'25 | T4: Q2'25 | U4: Q3'25 | V4: Q4'25 | W4: Q1'26 | X4: Q2'26 | Y4: Q3'26 | Z4: Q4'26 | AA4: Q1'27
B5: Subscription and Support Revenue | C5: 4575 | D5: 4840 | E5: 5085 | F5: 5476 | G5: 5536 | H5: 5914 | I5: 6379 | J5: 6828 | K5: 6856 | L5: 7143 | M5: 7233 | N5: 7789 | O5: 7642 | P5: 8006 | Q5: 8141 | R5: 8748 | S5: 8585 | T5: 8764 | U5: 8879 | V5: 9451 | W5: 9297 | X5: 9690 | Y5: 9726 | Z5: 10675 | AA5: 10593
B6: Professional Services and Other Revenue | C6: 290 | D6: 311 | E6: 334 | F6: 341 | G6: 427 | H6: 426 | I6: 484 | J6: 498 | K6: 555 | L6: 577 | M6: 604 | N6: 595 | O6: 605 | P6: 597 | Q6: 579 | R6: 539 | S6: 548 | T6: 561 | U6: 565 | V6: 542 | W6: 532 | X6: 546 | Y6: 533 | Z6: 526 | AA6: 540
B7: Total Revenue | C7: =SUM(C5:C6) -> 4865 | D7: =SUM(D5:D6) -> 5151 | E7: =SUM(E5:E6) -> 5419 | F7: =SUM(F5:F6) -> 5817 | G7: =SUM(G5:G6) -> 5963 | H7: =SUM(H5:H6) -> 6340 | I7: =SUM(I5:I6) -> 6863 | J7: =SUM(J5:J6) -> 7326 | ... AA7: =SUM(AA5:AA6) -> 11133
B8: Subscription and Support Cost of Revenue | C8: 966 | D8: 1013 | E8: 1060 | F8: 1115 | G8: 1122 | H8: 1146 | I8: 1335 | J8: 1456 | K8: 1440 | L8: 1490 | M8: 1451 | N8: 1440 | O8: 1510 | P8: 1515 | Q8: 1571 | R8: 1581 | S8: 1560 | T8: 1556 | U8: 1501 | V8: 1581 | W8: 1611 | X8: 1645 | Y8: 1665 | Z8: 1875 | AA8: 1953
B9: Professional Services and Other Cost of Revenue | C9: 288 | D9: 298 | E9: 334 | F9: 364 | G9: 433 | H9: 467 | I9: 509 | J9: 558 | K9: 605 | L9: 637 | M9: 637 | N9: 660 | O9: 615 | P9: 598 | Q9: 584 | R9: 567 | S9: 602 | T9: 603 | U9: 604 | V9: 636 | W9: 654 | X9: 597 | Y9: 590 | Z9: 633 | AA9: 617
B10: Total Cost of Revenue | C10: =SUM(C8:C9) -> 1254 | D10: =SUM(D8:D9) -> 1311 | E10: =SUM(E8:E9) -> 1394 | F10: =SUM(F8:F9) -> 1479 | G10: =SUM(G8:G9) -> 1555 | H10: =SUM(H8:H9) -> 1613 | I10: =SUM(I8:I9) -> 1844 | J10: =SUM(J8:J9) -> 2014 | ... AA10: =SUM(AA8:AA9) -> 2570
B11: Gross Profit | C11: =C7-C10 -> 3611 | D11: =D7-D10 -> 3840 | E11: =E7-E10 -> 4025 | F11: =F7-F10 -> 4338 | G11: =G7-G10 -> 4408 | H11: =H7-H10 -> 4727 | I11: =I7-I10 -> 5019 | J11: =J7-J10 -> 5312 | ... AA11: =AA7-AA10 -> 8563
B12: Research and Development | C12: 859 | D12: 898 | E12: 902 | F12: 939 | G12: 951 | H12: 1020 | I12: 1203 | J12: 1291 | K12: 1318 | L12: 1329 | M12: 1280 | N12: 1128 | O12: 1207 | P12: 1220 | Q12: 1204 | R12: 1275 | S12: 1368 | T12: 1349 | U12: 1356 | V12: 1420 | W12: 1460 | X12: 1481 | Y12: 1433 | Z12: 1619 | AA12: 1627
B13: Sales and Marketing | C13: 2390 | D13: 2275 | E13: 2377 | F13: 2632 | G13: 2544 | H13: 2736 | I13: 3111 | J13: 3464 | K13: 3372 | L13: 3424 | M13: 3345 | N13: 3385 | O13: 3154 | P13: 3113 | Q13: 3173 | R13: 3437 | S13: 3239 | T13: 3224 | U13: 3323 | V13: 3471 | W13: 3429 | X13: 3443 | Y13: 3456 | Z13: 4017 | AA13: 3769
B14: General and Administrative | C14: 502 | D14: 489 | E14: 522 | F14: 574 | G14: 559 | H14: 639 | I14: 667 | J14: 733 | K14: 656 | L14: 647 | M14: 664 | N14: 586 | O14: 638 | P14: 632 | Q14: 632 | R14: 632 | S14: 647 | T14: 711 | U14: 711 | V14: 767 | W14: 697 | X14: 734 | Y14: 667 | Z14: 902 | AA14: 740
B15: Restructuring | N15: 828 | O15: 711 | P15: 49 | Q15: 55 | R15: 173 | S15: 8 | T15: 99 | U15: 56 | V15: 298 | W15: 36 | X15: 4 | Y15: 260 | Z15: 286 | AA15: 80
B16: Total Operating Expenses | C16: 3751 | D16: 3662 | E16: 3801 | F16: =15359-3751-3662-3801 -> 4145 | G16: 4054 | H16: 4395 | I16: 4981 | J16: =18918-4054-4395-4981 -> 5488 | K16: 5346 | L16: 5400 | M16: 5289 | N16: =21962-5346-5400-5289 -> 5927 | O16: 5710 | P16: 5014 | Q16: 5064 | R16: =21305-5710-5014-5064 -> 5517 | S16: 5262 | T16: 5383 | U16: 5446 | V16: =22047-5262-5383-5446 -> 5956 | W16: 5622 | X16: 5662 | Y16: 5816 | Z16: =23924-5622-5662-5816 -> 6824 | AA16: 6216
B17: Income from Operations | C17: -140 | D17: 178 | E17: 224 | F17: =455--140-178-224 -> 193 | G17: 354 | H17: 332 | I17: 38 | J17: =548-354-332-38 -> -176 | K17: 20 | L17: 193 | M17: 460 | N17: =1030-20-193-460 -> 357 | O17: 412 | P17: 1476 | Q17: 1501 | R17: =5011-412-1476-1501 -> 1622 | S17: 1709 | T17: 1783 | U17: 1893 | V17: =7205-1709-1783-1893 -> 1820 | W17: 1942 | X17: 2332 | Y17: 2188 | Z17: =8331-1942-2332-2188 -> 1869 | AA17: 2347
B18: Interest Expense | AA18: -317
B19: Gains (Losses) on Strategic Investments, net | C19: 192 | D19: 682 | E19: 1036 | F19: 260 | G19: 288 | H19: 526 | I19: 363 | J19: 34 | K19: 7 | L19: 45 | M19: 23 | N19: -314 | O19: -141 | P19: -29 | Q19: -72 | R19: -35 | S19: 37 | T19: -37 | U19: -217 | V19: 96 | W19: -63 | X19: 6 | Y19: 263 | Z19: 811 | AA19: 558
B20: Other Income | C20: -5 | D20: -21 | E20: -10 | F20: -28 | G20: -38 | H20: -32 | I20: -102 | J20: -55 | K20: -56 | L20: -57 | M20: -8 | N20: -10 | O20: 55 | P20: 45 | Q20: 58 | R20: 58 | S20: 121 | T20: 91 | U20: 70 | V20: 72 | W20: 95 | X20: 68 | Y20: 61 | Z20: -52 | AA20: 133
B21: Income Before Income Taxes | C21: =SUM(C17:C20) -> 47 | D21: =SUM(D17:D20) -> 839 | E21: =SUM(E17:E20) -> 1250 | F21: =SUM(F17:F20) -> 425 | G21: =SUM(G17:G20) -> 604 | H21: =SUM(H17:H20) -> 826 | I21: =SUM(I17:I20) -> 299 | J21: =SUM(J17:J20) -> -197 | ... AA21: =SUM(AA17:AA20) -> 2721
B22: Provision for Income Taxes | C22: 52 | D22: 1786 | E22: -169 | F22: -158 | G22: -135 | H22: -291 | I22: 169 | J22: 169 | K22: 57 | L22: -113 | M22: -265 | N22: -131 | O22: -127 | P22: -225 | Q22: -263 | R22: -199 | S22: -334 | T22: -408 | U22: -219 | V22: -280 | W22: -433 | X22: -519 | Y22: -426 | Z22: -685 | AA22: -614
B23: Net Income | C23: =C21+C22 -> 99 | D23: =D21+D22 -> 2625 | E23: =E21+E22 -> 1081 | F23: =F21+F22 -> 267 | G23: =G21+G22 -> 469 | H23: =H21+H22 -> 535 | I23: =I21+I22 -> 468 | J23: =J21+J22 -> -28 | ... AA23: =AA21+AA22 -> 2107
B24: Diluted EPS | C24: =IFERROR(C23/C25,"") -> 0.10843373 | D24: =IFERROR(D23/D25,"") -> 2.8470716 | E24: =IFERROR(E23/E25,"") -> 1.1512247 | F24: =IFERROR(F23/F25,"") -> 0.28224101 | G24: =IFERROR(G23/G25,"") -> 0.49893617 | H24: =IFERROR(H23/H25,"") -> 0.56315789 | I24: =IFERROR(I23/I25,"") -> 0.46753247 | J24: =IFERROR(J23/J25,"") -> -0.027860697 | ... AA24: =IFERROR(AA23/AA25,"") -> 2.4190586
B25: Diluted Shares | C25: 913 | D25: 922 | E25: 939 | F25: 946 | G25: 940 | H25: 950 | I25: 1001 | J25: 1005 | K25: 1001 | L25: 1001 | M25: 1000 | N25: 986 | O25: 988 | P25: 986 | Q25: 981 | R25: 981 | S25: 985 | T25: 973 | U25: 965 | V25: 973 | W25: 970 | X25: 962 | Y25: 952 | Z25: 940 | AA25: 871
B27: Historic Drivers
B28: Historic Subscription and Support Revenue Growth Rate (YoY) | G28: =IFERROR((G5-C5)/C5,"") -> 0.21005464 | H28: =IFERROR((H5-D5)/D5,"") -> 0.22190083 | I28: =IFERROR((I5-E5)/E5,"") -> 0.25447394 | J28: =IFERROR((J5-F5)/F5,"") -> 0.24689554 | K28: =IFERROR((K5-G5)/G5,"") -> 0.23843931 | L28: =IFERROR((L5-H5)/H5,"") -> 0.20781197 | M28: =IFERROR((M5-I5)/I5,"") -> 0.13387678 | N28: =IFERROR((N5-J5)/J5,"") -> 0.140744 | ... AA28: =IFERROR((AA5-W5)/W5,"") -> 0.13939981
B29: Historic Professional Services Revenue Growth Rate (YoY) | G29: =IFERROR((G6-C6)/C6,"") -> 0.47241379 | H29: =IFERROR((H6-D6)/D6,"") -> 0.36977492 | I29: =IFERROR((I6-E6)/E6,"") -> 0.4491018 | J29: =IFERROR((J6-F6)/F6,"") -> 0.46041056 | K29: =IFERROR((K6-G6)/G6,"") -> 0.29976581 | L29: =IFERROR((L6-H6)/H6,"") -> 0.35446009 | M29: =IFERROR((M6-I6)/I6,"") -> 0.24793388 | N29: =IFERROR((N6-J6)/J6,"") -> 0.19477912 | ... AA29: =IFERROR((AA6-W6)/W6,"") -> 0.015037594
B30: Historic Total Revenue Growth Rate (YoY) | G30: =IFERROR((G7-C7)/C7,"") -> 0.22569373 | H30: =IFERROR((H7-D7)/D7,"") -> 0.23082897 | I30: =IFERROR((I7-E7)/E7,"") -> 0.26646983 | J30: =IFERROR((J7-F7)/F7,"") -> 0.25941207 | K30: =IFERROR((K7-G7)/G7,"") -> 0.24283079 | L30: =IFERROR((L7-H7)/H7,"") -> 0.21766562 | M30: =IFERROR((M7-I7)/I7,"") -> 0.14192044 | N30: =IFERROR((N7-J7)/J7,"") -> 0.14441714 | ... AA30: =IFERROR((AA7-W7)/W7,"") -> 0.13266863
B31: Historic Gross Margin % | C31: =IFERROR(C11/C7,"") -> 0.74224049 | D31: =IFERROR(D11/D7,"") -> 0.74548631 | E31: =IFERROR(E11/E7,"") -> 0.74275697 | F31: =IFERROR(F11/F7,"") -> 0.74574523 | G31: =IFERROR(G11/G7,"") -> 0.73922522 | H31: =IFERROR(H11/H7,"") -> 0.7455836 | I31: =IFERROR(I11/I7,"") -> 0.73131284 | J31: =IFERROR(J11/J7,"") -> 0.72508873 | ... AA31: =IFERROR(AA11/AA7,"") -> 0.76915477
B32: Historic R&D % of Revenue | C32: =IFERROR(C12/C7,"") -> 0.17656732 | D32: =IFERROR(D12/D7,"") -> 0.17433508 | E32: =IFERROR(E12/E7,"") -> 0.16645137 | F32: =IFERROR(F12/F7,"") -> 0.16142341 | G32: =IFERROR(G12/G7,"") -> 0.15948348 | H32: =IFERROR(H12/H7,"") -> 0.16088328 | I32: =IFERROR(I12/I7,"") -> 0.17528778 | J32: =IFERROR(J12/J7,"") -> 0.17622168 | ... AA32: =IFERROR(AA12/AA7,"") -> 0.1461421
B33: Historic Sales and Marketing % of Revenue | C33: =IFERROR(C13/C7,"") -> 0.49126413 | D33: =IFERROR(D13/D7,"") -> 0.44166181 | E33: =IFERROR(E13/E7,"") -> 0.43864182 | F33: =IFERROR(F13/F7,"") -> 0.45246691 | G33: =IFERROR(G13/G7,"") -> 0.42663089 | H33: =IFERROR(H13/H7,"") -> 0.43154574 | I33: =IFERROR(I13/I7,"") -> 0.45330031 | J33: =IFERROR(J13/J7,"") -> 0.47283647 | ... AA33: =IFERROR(AA13/AA7,"") -> 0.33854307
B34: Historic G&A % of Revenue | C34: =IFERROR(C14/C7,"") -> 0.10318602 | D34: =IFERROR(D14/D7,"") -> 0.094933023 | E34: =IFERROR(E14/E7,"") -> 0.096327736 | F34: =IFERROR(F14/F7,"") -> 0.098676294 | G34: =IFERROR(G14/G7,"") -> 0.093744759 | H34: =IFERROR(H14/H7,"") -> 0.10078864 | I34: =IFERROR(I14/I7,"") -> 0.097187819 | J34: =IFERROR(J14/J7,"") -> 0.1000546 | ... AA34: =IFERROR(AA14/AA7,"") -> 0.066469056
B35: Historic Effective Tax Rate | C35: =IFERROR(C22/C21,"") -> 1.106383 | D35: =IFERROR(D22/D21,"") -> 2.1287247 | E35: =IFERROR(E22/E21,"") -> -0.1352 | F35: =IFERROR(F22/F21,"") -> -0.37176471 | G35: =IFERROR(G22/G21,"") -> -0.22350993 | H35: =IFERROR(H22/H21,"") -> -0.35230024 | I35: =IFERROR(I22/I21,"") -> 0.56521739 | J35: =IFERROR(J22/J21,"") -> -0.85786802 | ... AA35: =IFERROR(AA22/AA21,"") -> -0.22565233

Sheet IS
B2: IS Assumptions | C2: =C13 -> FY'21 | D2: =D13 -> FY'22 | E2: =E13 -> FY'23 | F2: =F13 -> FY'24 | G2: =G13 -> FY'25 | H2: =H13 -> FY'26 | I2: =I13 -> FY'27 | J2: =J13 -> FY'28 | ... M2: =M13 -> FY'31
B3: Subscription and Support Revenue Growth Rate | D3: =(D14-C14)/C14 -> 0.2343312 | E3: =(E14-D14)/D14 -> 0.17698828 | F3: =(F14-E14)/E14 -> 0.12115365 | G3: =(G14-F14)/F14 -> 0.096566985 | H3: =(H14-G14)/G14 -> 0.10395471 | I3: 0.15 | J3: =I3 -> 0.15 | K3: =J3 -> 0.15 | L3: 0.1 | M3: 0.08
B4: Professional Services Revenue Growth Rate | D4: =(D15-C15)/C15 -> 0.43808777 | E4: =(E15-D15)/D15 -> 0.27029973 | F4: =(F15-E15)/E15 -> -0.0047190047 | G4: =(G15-F15)/F15 -> -0.044827586 | H4: =(H15-G15)/G15 -> -0.035649819 | I4: 0.01 | J4: 0.01 | K4: 0.01 | L4: 0.01 | M4: 0.01
B5: Total Revenue Growth Rate | D5: =(D16-C16)/C16 -> 0.24656503 | E5: =(E16-D16)/D16 -> 0.18345161 | F5: =(F16-E16)/E16 -> 0.1117951 | G5: =(G16-F16)/F16 -> 0.087156095 | H5: =(H16-G16)/G16 -> 0.095791001
B6: Gross Margin % | C6: =C18/C16 -> 0.7441182 | D6: =D18/D16 -> 0.73478786 | E6: =E18/E16 -> 0.73335034 | F6: =F18/F16 -> 0.75497031 | G6: =G18/G16 -> 0.77192242 | H6: =H18/H16 -> 0.77676099 | I6: =H6+0.001 -> 0.77776099 | J6: =I6+0.001 -> 0.77876099 | K6: =J6+0.001 -> 0.77976099 | L6: =K6+0.001 -> 0.78076099 | M6: =L6+0.001 -> 0.78176099
B7: R&D % | C7: =C19/C16 -> 0.16930171 | D7: =D19/D16 -> 0.16854145 | E7: =E19/E16 -> 0.16123373 | F7: =F19/F16 -> 0.14074648 | G7: =G19/G16 -> 0.14495316 | H7: =H19/H16 -> 0.1443227 | I7: =H7-0.001 -> 0.1433227 | J7: =I7-0.001 -> 0.1423227 | K7: =J7-0.001 -> 0.1413227 | L7: =K7-0.001 -> 0.1403227 | M7: =L7-0.001 -> 0.1393227
B8: Sales and Marketing % | C8: =C20/C16 -> 0.45520422 | D8: =D20/D16 -> 0.44749358 | E8: =E20/E16 -> 0.43142383 | F8: =F20/F16 -> 0.36942365 | G8: =G20/G16 -> 0.34983507 | H8: =H20/H16 -> 0.34545455 | I8: =H8 -> 0.34545455 | J8: =I8-0.005 -> 0.34045455 | K8: =J8-0.005 -> 0.33545455 | L8: =K8-0.005 -> 0.33045455 | M8: =L8-0.005 -> 0.32545455
B9: G&A % | C9: =C21/C16 -> 0.098202522 | D9: =D21/D16 -> 0.098067341 | E9: =E21/E16 -> 0.081430212 | F9: =F21/F16 -> 0.072697019 | G9: =G21/G16 -> 0.074838369 | H9: =H21/H16 -> 0.072245635 | I9: =H9-0.001 -> 0.071245635 | J9: =I9-0.001 -> 0.070245635 | K9: =J9-0.001 -> 0.069245635 | L9: =K9-0.001 -> 0.068245635 | M9: =L9-0.001 -> 0.067245635
B10: Restructuring % | C10: =C22/C16 -> 0 | D10: =D22/D16 -> 0 | E10: =E22/E16 -> 0.026409798 | F10: =F22/F16 -> 0.028344378 | G10: =G22/G16 -> 0.012165193 | H10: =H22/H16 -> 0.014111981 | I10: 0.01 | J10: =I10-0.001 -> 0.009 | K10: =J10-0.001 -> 0.008 | L10: =K10-0.001 -> 0.007 | M10: =L10-0.001 -> 0.006
B11: Tax Rate | C11: =IFERROR(C27/C26,"") -> 0.5900039 | D11: =IFERROR(D27/D26,"") -> -0.057441253 | E11: =IFERROR(E27/E26,"") -> -0.68484848 | F11: =IFERROR(F27/F26,"") -> -0.16444444 | G11: =IFERROR(G27/G26,"") -> -0.16684593 | H11: =IFERROR(H27/H26,"") -> -0.21670168 | I11: 0.213 | J11: =I11 -> 0.213 | K11: =J11 -> 0.213 | L11: =K11 -> 0.213 | M11: =L11 -> 0.213
B13: Annual Income Statement | C13: FY'21 | D13: FY'22 | E13: FY'23 | F13: FY'24 | G13: FY'25 | H13: FY'26 | I13: FY'27 | J13: FY'28 | K13: FY'29 | L13: FY'30 | M13: FY'31
B14: Subscription and Support Revenue | C14: =SUM('10QIS'!C5:F5) -> 19976 | D14: =SUM('10QIS'!G5:J5) -> 24657 | E14: =SUM('10QIS'!K5:N5) -> 29021 | F14: =SUM('10QIS'!O5:R5) -> 32537 | G14: =SUM('10QIS'!S5:V5) -> 35679 | H14: =SUM('10QIS'!W5:Z5) -> 39388 | I14: =H14*(1+I3) -> 45296.2 | J14: =I14*(1+J3) -> 52090.63 | K14: =J14*(1+K3) -> 59904.224 | L14: =K14*(1+L3) -> 65894.647 | M14: =L14*(1+M3) -> 71166.219
B15: Professional Services and Other Revenue | C15: =SUM('10QIS'!C6:F6) -> 1276 | D15: =SUM('10QIS'!G6:J6) -> 1835 | E15: =SUM('10QIS'!K6:N6) -> 2331 | F15: =SUM('10QIS'!O6:R6) -> 2320 | G15: =SUM('10QIS'!S6:V6) -> 2216 | H15: =SUM('10QIS'!W6:Z6) -> 2137 | I15: =H15*(1+I4) -> 2158.37 | J15: =I15*(1+J4) -> 2179.9537 | K15: =J15*(1+K4) -> 2201.7532 | L15: =K15*(1+L4) -> 2223.7708 | M15: =L15*(1+M4) -> 2246.0085
B16: Total Revenue | C16: =C14+C15 -> 21252 | D16: =D14+D15 -> 26492 | E16: =E14+E15 -> 31352 | F16: =F14+F15 -> 34857 | G16: =G14+G15 -> 37895 | H16: =H14+H15 -> 41525 | I16: =I14+I15 -> 47454.57 | J16: =J14+J15 -> 54270.584 | ... M16: =M14+M15 -> 73412.227
B17: Total Cost of Revenue | C17: =SUM('10QIS'!C8:F9) -> 5438 | D17: =SUM('10QIS'!G8:J9) -> 7026 | E17: =SUM('10QIS'!K8:N9) -> 8360 | F17: =SUM('10QIS'!O8:R9) -> 8541 | G17: =SUM('10QIS'!S8:V9) -> 8643 | H17: =SUM('10QIS'!W8:Z9) -> 9270 | I17: =I16-I18 -> 10546.257 | J17: =J16-J18 -> 12006.77 | K17: =K16-K18 -> 13678.159 | L17: =L16-L18 -> 14934.215 | M17: =M16-M18 -> 16021.412
B18: Gross Profit | C18: =C16-C17 -> 15814 | D18: =D16-D17 -> 19466 | E18: =E16-E17 -> 22992 | F18: =F16-F17 -> 26316 | G18: =G16-G17 -> 29252 | H18: =H16-H17 -> 32255 | I18: =I16*I6 -> 36908.313 | J18: =J16*J6 -> 42263.813 | K18: =K16*K6 -> 48427.819 | L18: =L16*L6 -> 53184.203 | M18: =M16*M6 -> 57390.815
B19: Research and Development | C19: =SUM('10QIS'!C12:F12) -> 3598 | D19: =SUM('10QIS'!G12:J12) -> 4465 | E19: =SUM('10QIS'!K12:N12) -> 5055 | F19: =SUM('10QIS'!O12:R12) -> 4906 | G19: =SUM('10QIS'!S12:V12) -> 5493 | H19: =SUM('10QIS'!W12:Z12) -> 5993 | I19: =I16*I7 -> 6801.317 | J19: =J16*J7 -> 7723.9358 | K19: =K16*K7 -> 8776.9843 | L19: =L16*L7 -> 9558.5601 | M19: =M16*M7 -> 10227.989
B20: Sales and Marketing | C20: =SUM('10QIS'!C13:F13) -> 9674 | D20: =SUM('10QIS'!G13:J13) -> 11855 | E20: =SUM('10QIS'!K13:N13) -> 13526 | F20: =SUM('10QIS'!O13:R13) -> 12877 | G20: =SUM('10QIS'!S13:V13) -> 13257 | H20: =SUM('10QIS'!W13:Z13) -> 14345 | I20: =I16*I8 -> 16393.397 | J20: =J16*J8 -> 18476.667 | K20: =K16*K8 -> 20833.733 | L20: =L16*L8 -> 22510.041 | M20: =M16*M8 -> 23892.343
B21: General and Administrative | C21: =SUM('10QIS'!C14:F14) -> 2087 | D21: =SUM('10QIS'!G14:J14) -> 2598 | E21: =SUM('10QIS'!K14:N14) -> 2553 | F21: =SUM('10QIS'!O14:R14) -> 2534 | G21: =SUM('10QIS'!S14:V14) -> 2836 | H21: =SUM('10QIS'!W14:Z14) -> 3000 | I21: =I16*I9 -> 3380.931 | J21: =J16*J9 -> 3812.2716 | K21: =K16*K9 -> 4300.5679 | L21: =L16*L9 -> 4648.7847 | M21: =M16*M9 -> 4936.6518
B22: Restructuring | C22: =SUM('10QIS'!C15:F15) -> 0 | D22: =SUM('10QIS'!G15:J15) -> 0 | E22: =SUM('10QIS'!K15:N15) -> 828 | F22: =SUM('10QIS'!O15:R15) -> 988 | G22: =SUM('10QIS'!S15:V15) -> 461 | H22: =SUM('10QIS'!W15:Z15) -> 586 | I22: =I16*I10 -> 474.5457 | J22: =J16*J10 -> 488.43525 | K22: =K16*K10 -> 496.84782 | L22: =L16*L10 -> 476.82892 | M22: =M16*M10 -> 440.47336
B23: Total Operating Expenses | C23: =SUM(C19:C22) -> 15359 | D23: =SUM(D19:D22) -> 18918 | E23: =SUM(E19:E22) -> 21962 | F23: =SUM(F19:F22) -> 21305 | G23: =SUM(G19:G22) -> 22047 | H23: =SUM(H19:H22) -> 23924 | I23: =SUM(I19:I22) -> 27050.191 | J23: =SUM(J19:J22) -> 30501.31 | ... M23: =SUM(M19:M22) -> 39497.458
B24: Income from Operations | C24: =C18-C23 -> 455 | D24: =D18-D23 -> 548 | E24: =E18-E23 -> 1030 | F24: =F18-F23 -> 5011 | G24: =G18-G23 -> 7205 | H24: =H18-H23 -> 8331 | I24: =I18-I23 -> 9858.1227 | J24: =J18-J23 -> 11762.504 | ... M24: =M18-M23 -> 17893.357
B25: Other Income (Expense), net | C25: =SUM('10QIS'!C18:F20) -> 2106 | D25: =SUM('10QIS'!G18:J20) -> 984 | E25: =SUM('10QIS'!K18:N20) -> -370 | F25: =SUM('10QIS'!O18:R20) -> -61 | G25: =SUM('10QIS'!S18:V20) -> 233 | H25: =SUM('10QIS'!W18:Z20) -> 1189 | I25: 0 | J25: 0 | K25: 0 | L25: 0 | M25: 0
B26: Income Before Income Taxes | C26: =C24+C25 -> 2561 | D26: =D24+D25 -> 1532 | E26: =E24+E25 -> 660 | F26: =F24+F25 -> 4950 | G26: =G24+G25 -> 7438 | H26: =H24+H25 -> 9520 | I26: =I24+I25 -> 9858.1227 | J26: =J24+J25 -> 11762.504 | ... M26: =M24+M25 -> 17893.357
B27: Provision for Income Taxes | C27: =SUM('10QIS'!C22:F22) -> 1511 | D27: =SUM('10QIS'!G22:J22) -> -88 | E27: =SUM('10QIS'!K22:N22) -> -452 | F27: =SUM('10QIS'!O22:R22) -> -814 | G27: =SUM('10QIS'!S22:V22) -> -1241 | H27: =SUM('10QIS'!W22:Z22) -> -2063 | I27: =I26*I11 -> 2099.7801 | J27: =J26*J11 -> 2505.4133 | K27: =K26*K11 -> 2986.1931 | L27: =L26*L11 -> 3405.8676 | M27: =M26*M11 -> 3811.2851
B28: Net Income | C28: =C26+C27 -> 4072 | D28: =D26+D27 -> 1444 | E28: =E26+E27 -> 208 | F28: =F26+F27 -> 4136 | G28: =G26+G27 -> 6197 | H28: =H26+H27 -> 7457 | I28: =I26-I27 -> 7758.3425 | J28: =J26-J27 -> 9257.0904 | K28: =K26-K27 -> 11033.493 | L28: =L26-L27 -> 12584.121 | M28: =M26-M27 -> 14082.072
B29: Diluted EPS | C29: =IFERROR(C28/C30,"") -> 4.3784946 | D29: =IFERROR(D28/D30,"") -> 1.4825462 | E29: =IFERROR(E28/E30,"") -> 0.20862588 | F29: =IFERROR(F28/F30,"") -> 4.203252 | G29: =IFERROR(G28/G30,"") -> 6.362423 | H29: =IFERROR(H28/H30,"") -> 7.8002092 | I29: =IFERROR(I28/I30,"") -> 8.3512837 | J29: =IFERROR(J28/J30,"") -> 9.9645753 | ... M29: =IFERROR(M28/M30,"") -> 15.158313
B30: Diluted Shares | C30: =AVERAGE('10QIS'!C25:F25) -> 930 | D30: =AVERAGE('10QIS'!G25:J25) -> 974 | E30: =AVERAGE('10QIS'!K25:N25) -> 997 | F30: =AVERAGE('10QIS'!O25:R25) -> 984 | G30: =AVERAGE('10QIS'!S25:V25) -> 974 | H30: =AVERAGE('10QIS'!W25:Z25) -> 956 | I30: =Main!C4 -> 929 | J30: =Main!C4 -> 929 | K30: =Main!C4 -> 929 | L30: =Main!C4 -> 929 | M30: =Main!C4 -> 929

Sheet BS
B2: Balance Sheet | C2: FY'21 | D2: FY'22 | E2: FY'23 | F2: FY'24 | G2: FY'25 | H2: FY'26 | I2: FY'27
B3: Cash and Cash Equivalents | C3: 6195 | D3: 5464 | E3: 7016 | F3: 8472 | G3: 8848 | H3: 7327
B4: Marketable Securities | C4: 5771 | D4: 5073 | E4: 5492 | F4: 5722 | G4: 5184 | H4: 2238
B5: Accounts Receivable, net | C5: 7786 | D5: 9739 | E5: 10755 | F5: 11414 | G5: 11945 | H5: 14339
B6: Costs Capitalized to Obtain Revenue Contracts, net (current) | C6: 1146 | D6: 1454 | E6: 1776 | F6: 1905 | G6: 1971 | H6: 2075
B7: Prepaid Expenses and Other Current Assets | C7: 991 | D7: 1120 | E7: 1356 | F7: 1561 | G7: 1779 | H7: 2243
B8: Total Current Assets | C8: =SUM(C3:C7) -> 21889 | D8: =SUM(D3:D7) -> 22850 | E8: =SUM(E3:E7) -> 26395 | F8: =SUM(F3:F7) -> 29074 | G8: =SUM(G3:G7) -> 29727 | H8: =SUM(H3:H7) -> 28222 | I8: =SUM(I3:I7) -> 0
B9: Property and Equipment, net | C9: 2459 | D9: 2815 | E9: 3702 | F9: 3689 | G9: 3236 | H9: 3120
B10: Operating Lease Right-of-Use Assets, net | C10: 3204 | D10: 2880 | E10: 2890 | F10: 2366 | G10: 2157 | H10: 2003
B11: Noncurrent Costs Capitalized to Obtain Revenue Contracts, net | C11: 1715 | D11: 2342 | E11: 2697 | F11: 2515 | G11: 2475 | H11: 2985
B12: Strategic Investments | C12: 3909 | D12: 4784 | E12: 4672 | F12: 4848 | G12: 4852 | H12: 7591
B13: Goodwill | C13: 26318 | D13: 47937 | E13: 48568 | F13: 48620 | G13: 51283 | H13: 57941
B14: Intangible Assets Acquired through Business Combinations, net | C14: 4114 | D14: 8978 | E14: 7125 | F14: 5278 | G14: 4428 | H14: 6815
B15: Deferred Tax Assets and Other Assets, net | C15: 2693 | D15: 2623 | E15: 2800 | F15: 3433 | G15: 4770 | H15: 3628
B16: Total Assets | C16: =C8+SUM(C9:C15) -> 66301 | D16: =D8+SUM(D9:D15) -> 95209 | E16: =E8+SUM(E9:E15) -> 98849 | F16: =F8+SUM(F9:F15) -> 99823 | G16: =G8+SUM(G9:G15) -> 102928 | H16: =H8+SUM(H9:H15) -> 112305 | I16: =I8+SUM(I9:I15) -> 0
B18: Accounts Payable, Accrued Expenses and Other Liabilities | C18: 4355 | D18: 5474 | E18: 6743 | F18: 6111 | G18: 6658 | H18: 8253
B19: Operating Lease Liabilities, current | C19: 766 | D19: 686 | E19: 590 | F19: 518 | G19: 579 | H19: 548
B20: Unearned Revenue | C20: 12607 | D20: 15628 | E20: 17376 | F20: 19003 | G20: 20743 | H20: 24317
B21: Debt, current | C21: 0 | D21: 0 | E21: 1182 | F21: 999 | G21: 0 | H21: 4000
B22: Total Current Liabilities | C22: =SUM(C18:C21) -> 17728 | D22: =SUM(D18:D21) -> 21788 | E22: =SUM(E18:E21) -> 25891 | F22: =SUM(F18:F21) -> 26631 | G22: =SUM(G18:G21) -> 27980 | H22: =SUM(H18:H21) -> 37118 | I22: =SUM(I18:I21) -> 0
B23: Noncurrent Debt | C23: 2673 | D23: 10592 | E23: 9419 | F23: 8427 | G23: 8433 | H23: 10439
B24: Noncurrent Operating Lease Liabilities | C24: 2842 | D24: 2703 | E24: 2897 | F24: 2644 | G24: 2380 | H24: 2189
B25: Other Noncurrent Liabilities | C25: 1565 | D25: 1995 | E25: 2283 | F25: 2475 | G25: 2962 | H25: 3417
B26: Total Liabilities | C26: =C22+SUM(C23:C25) -> 24808 | D26: =D22+SUM(D23:D25) -> 37078 | E26: =E22+SUM(E23:E25) -> 40490 | F26: =F22+SUM(F23:F25) -> 40177 | G26: =G22+SUM(G23:G25) -> 41755 | H26: =H22+SUM(H23:H25) -> 53163 | I26: =I22+SUM(I23:I25) -> 0
B28: Common Stock, par value | C28: 1 | D28: 1 | E28: 1 | F28: 1 | G28: 1 | H28: 1
B29: Treasury Stock, at cost | C29: 0 | D29: 0 | E29: -4000 | F29: -11692 | G29: -19507 | H29: -32228
B30: Additional Paid-in Capital | C30: 35601 | D30: 50919 | E30: 55047 | F30: 59841 | G30: 64576 | H30: 68835
B31: Accumulated Other Comprehensive Income (Loss) | C31: -42 | D31: -166 | E31: -274 | F31: -225 | G31: -266 | H31: 313
B32: Retained Earnings | C32: 5933 | D32: 7377 | E32: 7585 | F32: 11721 | G32: 16369 | H32: 22221
B33: Total Stockholders' Equity | C33: =SUM(C28:C32) -> 41493 | D33: =SUM(D28:D32) -> 58131 | E33: =SUM(E28:E32) -> 58359 | F33: =SUM(F28:F32) -> 59646 | G33: =SUM(G28:G32) -> 61173 | H33: =SUM(H28:H32) -> 59142 | I33: =SUM(I28:I32) -> 0
B34: Total Liabilities and Stockholders' Equity | C34: =C26+C33 -> 66301 | D34: =D26+D33 -> 95209 | E34: =E26+E33 -> 98849 | F34: =F26+F33 -> 99823 | G34: =G26+G33 -> 102928 | H34: =H26+H33 -> 112305 | I34: =I26+I33 -> 0
B35: Check (Assets less Liab. & Equity) | C35: =C16-C34 -> 0 | D35: =D16-D34 -> 0 | E35: =E16-E34 -> 0 | F35: =F16-F34 -> 0 | G35: =G16-G34 -> 0 | H35: =H16-H34 -> 0 | I35: =I16-I34 -> 0

Sheet CFS
B2: Cash Flow Statement | C2: FY'21 | D2: FY'22 | E2: FY'23 | F2: FY'24 | G2: FY'25 | H2: FY'26 | I2: FY'27 (1/4)
B3: Operating Activities:
B4: Net Income | C4: 4072 | D4: 1444 | E4: 208 | F4: 4136 | G4: 6197 | H4: 7457
B5: Depreciation and Amortization | C5: 2846 | D5: 3298 | E5: 3786 | F5: 3959 | G5: 3477 | H5: 3631
B6: Amortization of Costs Capitalized to Obtain Revenue Contracts, net | C6: 1058 | D6: 1348 | E6: 1668 | F6: 1925 | G6: 2095 | H6: 2197
B7: Stock-Based Compensation Expense | C7: 2190 | D7: 2779 | E7: 3279 | F7: 2787 | G7: 3183 | H7: 3509
B8: (Gains) Losses on Strategic Investments, net | C8: -2170 | D8: -1211 | E8: 239 | F8: 277 | G8: 121 | H8: -1017
B9: Tax Benefit from Intra-Entity Transfer of Intangible Property | C9: -2003 | D9: 0 | E9: 0 | F9: 0 | G9: 0 | H9: 0
B10: Change in Accounts Receivable, net | C10: -1556 | D10: -1824 | E10: -995 | F10: -659 | G10: -490 | H10: -2160
B11: Change in Costs Capitalized to Obtain Revenue Contracts, net | C11: -1645 | D11: -2283 | E11: -2345 | F11: -1872 | G11: -2121 | H11: -2811
B12: Change in Prepaid Expenses and Other Assets | C12: -133 | D12: 114 | E12: -302 | F12: -843 | G12: -1495 | H12: 819
B13: Change in Accounts Payable and Accrued Expenses and Other Liabilities | C13: 1100 | D13: 507 | E13: 528 | F13: -478 | G13: 1089 | H13: 1014
B14: Change in Operating Lease Liabilities | C14: -830 | D14: -801 | E14: -699 | F14: -621 | G14: -548 | H14: -567
B15: Change in Unearned Revenue | C15: 1872 | D15: 2629 | E15: 1744 | F15: 1623 | G15: 1584 | H15: 2924
B16: Net Cash Provided by Operating Activities | C16: =SUM(C4:C15) -> 4801 | D16: =SUM(D4:D15) -> 6000 | E16: =SUM(E4:E15) -> 7111 | F16: =SUM(F4:F15) -> 10234 | G16: =SUM(G4:G15) -> 13092 | H16: =SUM(H4:H15) -> 14996 | I16: =SUM(I4:I15) -> 0
B18: Investing Activities:
B19: Business Combinations, net of Cash Acquired | C19: -1281 | D19: -14876 | E19: -439 | F19: -82 | G19: -2734 | H19: -9268
B20: Purchases of Strategic Investments | C20: -1069 | D20: -1718 | E20: -550 | F20: -496 | G20: -539 | H20: -1958
B21: Sales of Strategic Investments | C21: 1051 | D21: 2201 | E21: 355 | F21: 108 | G21: 126 | H21: 184
B22: Purchases of Marketable Securities | C22: -4833 | D22: -5674 | E22: -4777 | F22: -3761 | G22: -6879 | H22: -3763
B23: Sales of Marketable Securities | C23: 1836 | D23: 4179 | E23: 1771 | F23: 1511 | G23: 4143 | H23: 4414
B24: Maturities of Marketable Securities | C24: 1035 | D24: 2069 | E24: 2449 | F24: 2129 | G24: 3378 | H24: 2395
B25: Capital Expenditures | C25: -710 | D25: -717 | E25: -798 | F25: -736 | G25: -658 | H25: -594
B26: Net Cash Used in Investing Activities | C26: =SUM(C19:C25) -> -3971 | D26: =SUM(D19:D25) -> -14536 | E26: =SUM(E19:E25) -> -1989 | F26: =SUM(F19:F25) -> -1327 | G26: =SUM(G19:G25) -> -3163 | H26: =SUM(H19:H25) -> -8590 | I26: =SUM(I19:I25) -> 0
B28: Financing Activities:
B29: Proceeds from Issuance of Debt, net | C29: -20 | D29: 7906 | E29: 0 | F29: 0 | G29: 0 | H29: 6000
B30: Repayments of Slack Convertible Notes, net | C30: 0 | D30: -1197 | E30: 0 | F30: 0 | G30: 0 | H30: 0
B31: Repurchases of Common Stock | C31: 0 | D31: 0 | E31: -4000 | F31: -7620 | G31: -7829 | H31: -12596
B32: Payments for Taxes Related to Net Share Settlement of Equity Awards | C32: 0 | D32: 0 | E32: 0 | F32: 0 | G32: 0 | H32: -351
B33: Proceeds from Employee Stock Plans | C33: 1321 | D33: 1289 | E33: 861 | F33: 1954 | G33: 1540 | H33: 1039
B34: Principal Payments on Financing Obligations | C34: -103 | D34: -156 | E34: -419 | F34: -629 | G34: -603 | H34: -584
B35: Repayments of Debt | C35: -4 | D35: -4 | E35: -4 | F35: -1182 | G35: -1000 | H35: 0
B36: Payments of Dividends | C36: 0 | D36: 0 | E36: 0 | F36: 0 | G36: -1537 | H36: -1587
B37: Net Cash Provided by (Used in) Financing Activities | C37: =SUM(C29:C36) -> 1194 | D37: =SUM(D29:D36) -> 7838 | E37: =SUM(E29:E36) -> -3562 | F37: =SUM(F29:F36) -> -7477 | G37: =SUM(G29:G36) -> -9429 | H37: =SUM(H29:H36) -> -8079 | I37: =SUM(I29:I36) -> 0
B39: Effect of Exchange Rate Changes | C39: 26 | D39: -33 | E39: -8 | F39: 26 | G39: -124 | H39: 152
B40: Net Increase (Decrease) in Cash and Cash Equivalents | C40: =C16+C26+C37+C39 -> 2050 | D40: =D16+D26+D37+D39 -> -731 | E40: =E16+E26+E37+E39 -> 1552 | F40: =F16+F26+F37+F39 -> 1456 | G40: =G16+G26+G37+G39 -> 376 | H40: =H16+H26+H37+H39 -> -1521 | I40: =I16+I26+I37+I39 -> 0
B41: Cash and Cash Equivalents, Beginning of Period | C41: 4145 | D41: 6195 | E41: 5464 | F41: 7016 | G41: 8472 | H41: 8848 | I41: =H42 -> 7327
B42: Cash and Cash Equivalents, End of Period | C42: =C41+C40 -> 6195 | D42: =D41+D40 -> 5464 | E42: =E41+E40 -> 7016 | F42: =F41+F40 -> 8472 | G42: =G41+G40 -> 8848 | H42: =H41+H40 -> 7327 | I42: =I41+I40 -> 7327

Sheet DCF
B2: Salesforce, Inc. (CRM)
B4: Valuation Date: | F4: =TODAY() -> 46261
B5: Share Price on Valuation Date: | F5: =Main!C3 -> 247.29
B6: Diluted Shares Outstanding | F6: =Main!C4 -> 929
B7: Stub Period to Next FY Year-End (yrs) | F7: =(DATE(YEAR(F4)+IF(MONTH(F4)=1,0,1),1,31)-F4)/365 -> 0.43013699
B8: Select Operating Data
I9: Projected Annual Forecast
C10: FY'21 | D10: FY'22 | E10: FY'23 | F10: FY'24 | G10: FY'25 | H10: FY'26 | I10: FY'27 | J10: FY'28 | K10: FY'29 | L10: FY'30 | M10: FY'31
B11: Revenue | C11: =IS!C16 -> 21252 | D11: =IS!D16 -> 26492 | E11: =IS!E16 -> 31352 | F11: =IS!F16 -> 34857 | G11: =IS!G16 -> 37895 | H11: =IS!H16 -> 41525 | I11: =IS!I16 -> 47454.57 | J11: =IS!J16 -> 54270.584 | ... M11: =IS!M16 -> 73412.227
B13: EBIT | C13: =IS!C24 -> 455 | D13: =IS!D24 -> 548 | E13: =IS!E24 -> 1030 | F13: =IS!F24 -> 5011 | G13: =IS!G24 -> 7205 | H13: =IS!H24 -> 8331 | I13: =IS!I24 -> 9858.1227 | J13: =IS!J24 -> 11762.504 | ... M13: =IS!M24 -> 17893.357
B15: Depreciation & Amortization | C15: =CFS!C5 -> 2846 | D15: =CFS!D5 -> 3298 | E15: =CFS!E5 -> 3786 | F15: =CFS!F5 -> 3959 | G15: =CFS!G5 -> 3477 | H15: =CFS!H5 -> 3631 | I15: =I11*I16 -> 5250.4708 | J15: =J11*J16 -> 6004.6085 | K15: =K11*K16 -> 6871.5326 | L15: =L11*L16 -> 7536.7612 | M15: =M11*M16 -> 8122.4792 | O15: Arithmetic Avg | P15: Geometric Avg
B16: % of Revenue | C16: =C15/C11 -> 0.13391681 | D16: =D15/D11 -> 0.12449041 | E16: =E15/E11 -> 0.12075785 | F16: =F15/F11 -> 0.11357833 | G16: =G15/G11 -> 0.091753529 | H16: =H15/H11 -> 0.0874413 | I16: =$P$16 -> 0.11064205 | J16: =$P$16 -> 0.11064205 | K16: =$P$16 -> 0.11064205 | L16: =$P$16 -> 0.11064205 | M16: =$P$16 -> 0.11064205 | O16: =AVERAGE(C16:H16) -> 0.11198971 | P16: =GEOMEAN(C16:H16) -> 0.11064205
B18: Select Balance Sheet And Other Data
I19: Projected Annual Forecast
C20: FY'21 | D20: FY'22 | E20: FY'23 | F20: FY'24 | G20: FY'25 | H20: FY'26 | I20: FY'27 | J20: FY'28 | K20: FY'29 | L20: FY'30 | M20: FY'31
B21: Accounts Receivable | C21: =BS!C5 -> 7786 | D21: =BS!D5 -> 9739 | E21: =BS!E5 -> 10755 | F21: =BS!F5 -> 11414 | G21: =BS!G5 -> 11945 | H21: =BS!H5 -> 14339 | I21: =I31*I11 -> 16307.279 | J21: =J31*J11 -> 18649.532 | K21: =K31*K11 -> 21342.085 | L21: =L31*L11 -> 23408.199 | M21: =M31*M11 -> 25227.363
B22: Prepaid Expenses | C22: =BS!C7 -> 991 | D22: =BS!D7 -> 1120 | E22: =BS!E7 -> 1356 | F22: =BS!F7 -> 1561 | G22: =BS!G7 -> 1779 | H22: =BS!H7 -> 2243 | I22: =I32*I11 -> 2190.842 | J22: =J32*J11 -> 2505.5179 | K22: =K32*K11 -> 2867.2557 | L22: =L32*L11 -> 3144.8329 | M22: =M32*M11 -> 3389.233
B24: Accounts Payable, Accrued Expenses and Other Liabilities | C24: =BS!C18 -> 4355 | D24: =BS!D18 -> 5474 | E24: =BS!E18 -> 6743 | F24: =BS!F18 -> 6111 | G24: =BS!G18 -> 6658 | H24: =BS!H18 -> 8253 | I24: =I33*I11 -> 9275.1332 | J24: =J33*J11 -> 10607.343 | K24: =K33*K11 -> 12138.793 | L24: =L33*L11 -> 13313.942 | M24: =M33*M11 -> 14348.632
B25: Unearned Revenue | C25: =BS!C20 -> 12607 | D25: =BS!D20 -> 15628 | E25: =BS!E20 -> 17376 | F25: =BS!F20 -> 19003 | G25: =BS!G20 -> 20743 | H25: =BS!H20 -> 24317 | I25: =I34*I11 -> 26995.783 | J25: =J34*J11 -> 30873.252 | K25: =K34*K11 -> 35330.623 | L25: =L34*L11 -> 38750.958 | M25: =M34*M11 -> 41762.481
B27: Debt | C27: =BS!C21+BS!C23 -> 2673 | D27: =BS!D21+BS!D23 -> 10592 | E27: =BS!E21+BS!E23 -> 10601 | F27: =BS!F21+BS!F23 -> 9426 | G27: =BS!G21+BS!G23 -> 8433 | H27: =BS!H21+BS!H23 -> 14439
B29: Capital Expenditures | C29: =CFS!C25 -> -710 | D29: =CFS!D25 -> -717 | E29: =CFS!E25 -> -798 | F29: =CFS!F25 -> -736 | G29: =CFS!G25 -> -658 | H29: =CFS!H25 -> -594 | I29: =I35*I11 -> -1097.0671 | J29: =J35*J11 -> -1254.6415 | K29: =K35*K11 -> -1435.7822 | L29: =L35*L11 -> -1574.7793 | M29: =M35*M11 -> -1697.163
O30: Arithmetic Mean | P30: Geometric Mean
B31: Accounts Receivable as a % of Revenue | C31: =C21/C11 -> 0.36636552 | D31: =D21/D11 -> 0.36762041 | E31: =E21/E11 -> 0.34304032 | F31: =F21/F11 -> 0.32745216 | G31: =G21/G11 -> 0.31521309 | H31: =H21/H11 -> 0.34531005 | I31: =$P$31 -> 0.34363979 | J31: =$P$31 -> 0.34363979 | K31: =$P$31 -> 0.34363979 | L31: =$P$31 -> 0.34363979 | M31: =$P$31 -> 0.34363979 | O31: =AVERAGE(C31:H31) -> 0.34416693 | P31: =IFERROR(GEOMEAN(C31:H31),"n/a") -> 0.34363979
B32: Prepaid Expenses as a % of Revenue | C32: =C22/C11 -> 0.046630905 | D32: =D22/D11 -> 0.042276914 | E32: =E22/E11 -> 0.043250829 | F32: =F22/F11 -> 0.04478297 | G32: =G22/G11 -> 0.046945507 | H32: =H22/H11 -> 0.054015653 | I32: =$P$32 -> 0.046167145 | J32: =$P$32 -> 0.046167145 | K32: =$P$32 -> 0.046167145 | L32: =$P$32 -> 0.046167145 | M32: =$P$32 -> 0.046167145 | O32: =AVERAGE(C32:H32) -> 0.04631713 | P32: =IFERROR(GEOMEAN(C32:H32),"n/a") -> 0.046167145
B33: Accounts Payable/Accrued Expenses as a % of Revenue | C33: =C24/C11 -> 0.20492189 | D33: =D24/D11 -> 0.20662842 | E33: =E24/E11 -> 0.215074 | F33: =F24/F11 -> 0.17531629 | G33: =G24/G11 -> 0.175696 | H33: =H24/H11 -> 0.19874774 | I33: =$P$33 -> 0.1954529 | J33: =$P$33 -> 0.1954529 | K33: =$P$33 -> 0.1954529 | L33: =$P$33 -> 0.1954529 | M33: =$P$33 -> 0.1954529 | O33: =AVERAGE(C33:H33) -> 0.19606406 | P33: =IFERROR(GEOMEAN(C33:H33),"n/a") -> 0.1954529
B34: Unearned Revenue as a % of Revenue | C34: =C25/C11 -> 0.59321476 | D34: =D25/D11 -> 0.58991394 | E34: =E25/E11 -> 0.55422302 | F34: =F25/F11 -> 0.54517027 | G34: =G25/G11 -> 0.54738092 | H34: =H25/H11 -> 0.58559904 | I34: =$P$34 -> 0.56887636 | J34: =$P$34 -> 0.56887636 | K34: =$P$34 -> 0.56887636 | L34: =$P$34 -> 0.56887636 | M34: =$P$34 -> 0.56887636 | O34: =AVERAGE(C34:H34) -> 0.56925032 | P34: =IFERROR(GEOMEAN(C34:H34),"n/a") -> 0.56887636
B35: Capital Expenditures as a % of Revenue | C35: =C29/C11 -> -0.03340862 | D35: =D29/D11 -> -0.027064774 | E35: =E29/E11 -> -0.025452922 | F35: =F29/F11 -> -0.021114841 | G35: =G29/G11 -> -0.017363768 | H35: =H29/H11 -> -0.014304636 | I35: =$O$35 -> -0.02311826 | J35: =$O$35 -> -0.02311826 | K35: =$O$35 -> -0.02311826 | L35: =$O$35 -> -0.02311826 | M35: =$O$35 -> -0.02311826 | O35: =AVERAGE(C35:H35) -> -0.02311826 | P35: =IFERROR(GEOMEAN(C35:H35),"n/a") -> n/a
B36: Accounts Receivable Growth (%) | D36: =((D21/C21)-1) -> 0.25083483 | E36: =((E21/D21)-1) -> 0.10432283 | F36: =((F21/E21)-1) -> 0.061273826 | G36: =((G21/F21)-1) -> 0.046521815 | H36: =((H21/G21)-1) -> 0.20041859
B37: Prepaid Expenses Growth (%) | D37: =((D22/C22)-1) -> 0.13017154 | E37: =((E22/D22)-1) -> 0.21071429 | F37: =((F22/E22)-1) -> 0.15117994 | G37: =((G22/F22)-1) -> 0.13965407 | H37: =((H22/G22)-1) -> 0.26082069
B38: Accounts Payable/Accrued Expenses Growth (%) | D38: =((D24/C24)-1) -> 0.25694604 | E38: =((E24/D24)-1) -> 0.23182316 | F38: =((F24/E24)-1) -> -0.093726828 | G38: =((G24/F24)-1) -> 0.089510718 | H38: =((H24/G24)-1) -> 0.23956143
B39: Unearned Revenue Growth (%) | D39: =((D25/C25)-1) -> 0.23962878 | E39: =((E25/D25)-1) -> 0.11185052 | F39: =((F25/E25)-1) -> 0.093634899 | G39: =((G25/F25)-1) -> 0.09156449 | H39: =((H25/G25)-1) -> 0.17229909
B40: Capital Expenditures Growth (%) | D40: =((D29/C29)-1) -> 0.0098591549 | E40: =((E29/D29)-1) -> 0.11297071 | F40: =((F29/E29)-1) -> -0.077694236 | G40: =((G29/F29)-1) -> -0.10597826 | H40: =((H29/G29)-1) -> -0.097264438
B42: Free Cash Flow Buildup
B43: $mm | I43: Projected Annual Forecast
C44: FY'21 | D44: FY'22 | E44: FY'23 | F44: FY'24 | G44: FY'25 | H44: FY'26 | I44: FY'27 | J44: FY'28 | K44: FY'29 | L44: FY'30 | M44: FY'31
B45: Period | I45: =$F$7/2 -> 0.21506849 | J45: =I45+1 -> 1.2150685 | K45: =J45+1 -> 2.2150685 | L45: =K45+1 -> 3.2150685 | M45: =L45+1 -> 4.2150685
B46: Total Revenues | C46: =C11 -> 21252 | D46: =D11 -> 26492 | E46: =E11 -> 31352 | F46: =F11 -> 34857 | G46: =G11 -> 37895 | H46: =H11 -> 41525 | I46: =I11 -> 47454.57 | J46: =J11 -> 54270.584 | ... M46: =M11 -> 73412.227
B47: EBIT | C47: =C13 -> 455 | D47: =D13 -> 548 | E47: =E13 -> 1030 | F47: =F13 -> 5011 | G47: =G13 -> 7205 | H47: =H13 -> 8331 | I47: =I13 -> 9858.1227 | J47: =J13 -> 11762.504 | ... M47: =M13 -> 17893.357
B48: Effective Tax Rate | C48: =IS!C11 -> 0.5900039 | D48: =IS!D11 -> -0.057441253 | E48: =IS!E11 -> -0.68484848 | F48: =IS!F11 -> -0.16444444 | G48: =IS!G11 -> -0.16684593 | H48: =IS!H11 -> -0.21670168 | I48: =-IS!I11 -> -0.213 | J48: =-IS!J11 -> -0.213 | K48: =-IS!K11 -> -0.213 | L48: =-IS!L11 -> -0.213 | M48: =-IS!M11 -> -0.213
B49: EBIAT = EBIT(1-T) = NOPAT | C49: =C47*(1-C48) -> 186.54822 | D49: =D47*(1-D48) -> 579.47781 | E49: =E47*(1-E48) -> 1735.3939 | F49: =F47*(1-F48) -> 5835.0311 | G49: =G47*(1-G48) -> 8407.1249 | H49: =H47*(1-H48) -> 10136.342 | I49: =I47*(1-I48) -> 11957.903 | J49: =J47*(1-J48) -> 14267.917 | ... M49: =M47*(1-M48) -> 21704.643
...

Sheet Subscription and Support
B2: Segment | C2: Subscription and Support
B3: Description | C3: Recurring subscription fees for access to Salesforce’s cloud application suite (Sales, Service, Platform, Marketing and Commerce, Data, Slack, and related products) plus associated support. ~95% of total revenue in FY26.
B4: Pricing Model | C4: Primarily annual/multi-year subscription contracts, recognized ratably over the contract term; some usage-based (consumption) pricing within Data Cloud/AI offerings.
B5: Notes

Sheet Professional Services & Other
B2: Segment | C2: Professional Services & Other
B3: Description | C3: Consulting, implementation, and training services sold alongside the subscription offerings, plus certain other revenue. ~5% of total revenue in FY26.
B4: Pricing Model | C4: Primarily time-and-materials or fixed-fee project engagements, recognized as services are delivered.
B5: Notes
