Workbook

Sheet Main
B2: SAMSARA INC. (IOT) | C2: Balance sheet data as of FY26 year-end (2/1/26); diluted share count as of Q1 FY27 (quarter ended 5/2/26)
B3: Price ($/share) | C3: 40.85
B4: Shares (diluted, thousands) | C4: 581835.92
B5: Market Cap ($000s) | C5: =C3*C4 -> 23767997
B6: Cash & investments ($000s, FY26 year-end) | C6: =318789+515003+403123 -> 1236915
B7: Debt ($000s) | C7: 0
B8: EV ($000s) | C8: =C5+C7-C6 -> 22531082
B11: CEO: | C11: Sanjit Biswas
B12: CFO: | C12: Dominic Phillips

Sheet 10QIS
B2: SAMSARA INC. (IOT)
B4: Historic Quarterly Income Statement | C4: Q1'23 | D4: Q2'23 | E4: Q3'23 | F4: Q4'23 | G4: Q1'24 | H4: Q2'24 | I4: Q3'24 | J4: Q4'24 | K4: Q1'25 | L4: Q2'25 | M4: Q3'25 | N4: Q4'25 | O4: Q1'26 | P4: Q2'26 | Q4: Q3'26 | R4: Q4'26 | S4: Q1'27
B5: Revenue | C5: 142.645 | D5: 153.523 | E5: 169.8 | F5: =652.545-142.645-153.523-169.8 -> 186.577 | G5: 204.32 | H5: 219.257 | I5: 237.534 | J5: =937.385-204.32-219.257-237.534 -> 276.274 | K5: 280.726 | L5: 300.202 | M5: 321.981 | N5: =1249.2-280.726-300.202-321.981 -> 346.291 | O5: 366.884 | P5: 391.48 | Q5: 415.975 | R5: =1618.63-366.884-391.48-415.975 -> 444.291 | S5: 478.844
B6: Cost of revenue | C6: 39.618 | D6: 44.257 | E6: 47.253 | F6: =182.656-39.618-44.257-47.253 -> 51.528 | G6: 57.557 | H6: 58.866 | I6: 61.585 | J6: =247.032-57.557-58.866-61.585 -> 69.024 | K6: 68.625 | L6: 73.365 | M6: 76.027 | N6: =298.321-68.625-73.365-76.027 -> 80.304 | O6: 83.169 | P6: 90.501 | Q6: 96.964 | R6: =376.549-83.169-90.501-96.964 -> 105.915 | S6: 117.701
B7: Gross profit | C7: =C5-C6 -> 103.027 | D7: =D5-D6 -> 109.266 | E7: =E5-E6 -> 122.547 | F7: =F5-F6 -> 135.049 | G7: =G5-G6 -> 146.763 | H7: =H5-H6 -> 160.391 | I7: =I5-I6 -> 175.949 | J7: =J5-J6 -> 207.25 | ... S7: =S5-S6 -> 361.143
B8: Research and development | C8: 40.985 | D8: 41.847 | E8: 49.97 | F8: =187.405-40.985-41.847-49.97 -> 54.603 | G8: 60.366 | H8: 63.969 | I8: 60.82 | J8: =258.581-60.366-63.969-60.82 -> 73.426 | K8: 72.973 | L8: 76.476 | M8: 76.99 | N8: =299.716-72.973-76.476-76.99 -> 73.277 | O8: 83.242 | P8: 85.612 | Q8: 86.219 | R8: =344.589-83.242-85.612-86.219 -> 89.516 | S8: 97.567
B9: Sales and marketing | C9: 87.449 | D9: 91.842 | E9: 94.056 | F9: =370.098-87.449-91.842-94.056 -> 96.751 | G9: 118.955 | H9: 117.908 | I9: 116.78 | J9: =486.649-118.955-117.908-116.78 -> 133.006 | K9: 147.437 | L9: 151.493 | M9: 150.065 | N9: =601.648-147.437-151.493-150.065 -> 152.653 | O9: 165.4 | P9: 174.083 | Q9: 168.392 | R9: =683.78-165.4-174.083-168.392 -> 175.905 | S9: 203.603
B10: General and administrative | C10: 43.742 | D10: 41.359 | E10: 41.997 | F10: =170.785-43.742-41.359-41.997 -> 43.687 | G10: 43.266 | H10: 48.268 | I10: 48.354 | J10: =195.043-43.266-48.268-48.354 -> 55.155 | K10: 57.688 | L10: 57.062 | M10: 62.66 | N10: =234.609-57.688-57.062-62.66 -> 57.199 | O10: 68.328 | P10: 67.903 | Q10: 66.121 | R10: =266.293-68.328-67.903-66.121 -> 63.941 | S10: 52.778
B11: Lease modification, impairment, and related charges | C11: 1.056 | D11: 0 | E11: 0 | F11: =1.056-1.056-0-0 -> 0 | G11: 0 | H11: 0 | I11: 4.762 | J11: =4.762-0-0-4.762 -> 0 | K11: 0 | L11: 0 | M11: 3.609 | N11: =4.028-0-0-3.609 -> 0.419 | O11: 0 | P11: 0 | Q11: 0 | R11: =0-0-0-0 -> 0 | S11: 0
B12: Legal settlement | C12: 0 | D12: 0 | E12: 0 | F12: =0-0-0-0 -> 0 | G12: 0 | H12: 0 | I12: 0 | J12: =68.665-0-0-0 -> 68.665 | K12: 0 | L12: 0 | M12: 0 | N12: =0.85-0-0-0 -> 0.85 | O12: 0 | P12: 0 | Q12: 0 | R12: =0-0-0-0 -> 0 | S12: 0
B13: Total operating expenses | C13: =SUM(C8:C12) -> 173.232 | D13: =SUM(D8:D12) -> 175.048 | E13: =SUM(E8:E12) -> 186.023 | F13: =SUM(F8:F12) -> 195.041 | G13: =SUM(G8:G12) -> 222.587 | H13: =SUM(H8:H12) -> 230.145 | I13: =SUM(I8:I12) -> 230.716 | J13: =SUM(J8:J12) -> 330.252 | ... S13: =SUM(S8:S12) -> 353.948
B14: Loss from operations | C14: =C7-C13 -> -70.205 | D14: =D7-D13 -> -65.782 | E14: =E7-E13 -> -63.476 | F14: =F7-F13 -> -59.992 | G14: =G7-G13 -> -75.824 | H14: =H7-H13 -> -69.754 | I14: =I7-I13 -> -54.767 | J14: =J7-J13 -> -123.002 | ... S14: =S7-S13 -> 7.195
B15: Interest income and other income (expense), net | C15: -0.06 | D15: 1.541 | E15: 5.613 | F15: =15.62--0.06-1.541-5.613 -> 8.526 | G15: 8.895 | H15: 10.22 | I15: 9.378 | J15: =39.964-8.895-10.22-9.378 -> 11.471 | K15: 10.084 | L15: 9.626 | M15: 10.057 | N15: =39.559-10.084-9.626-10.057 -> 9.792 | O15: 12.723 | P15: 11.426 | Q15: 10.816 | R15: =53.482-12.723-11.426-10.816 -> 18.517 | S15: 41.732
B16: Income (loss) before income taxes | C16: =C14+C15 -> -70.265 | D16: =D14+D15 -> -64.241 | E16: =E14+E15 -> -57.863 | F16: =F14+F15 -> -51.466 | G16: =G14+G15 -> -66.929 | H16: =H14+H15 -> -59.534 | I16: =I14+I15 -> -45.389 | J16: =J14+J15 -> -111.531 | ... S16: =S14+S15 -> 48.927
B17: Provision for income taxes | C17: 0.723 | D17: 0.04 | E17: 0.692 | F17: =3.587-0.723-0.04-0.692 -> 2.132 | G17: 0.927 | H17: 0.434 | I17: 0.142 | J17: =3.343-0.927-0.434-0.142 -> 1.84 | K17: 0.376 | L17: 1.042 | M17: 0.493 | N17: =4.493-0.376-1.042-0.493 -> 2.582 | O17: 1.589 | P17: 1.607 | Q17: 1.329 | R17: =10.023-1.589-1.607-1.329 -> 5.498 | S17: 4.419
B18: Net income (loss) | C18: =C16-C17 -> -70.988 | D18: =D16-D17 -> -64.281 | E18: =E16-E17 -> -58.555 | F18: =F16-F17 -> -53.598 | G18: =G16-G17 -> -67.856 | H18: =H16-H17 -> -59.968 | I18: =I16-I17 -> -45.531 | J18: =J16-J17 -> -113.371 | ... S18: =S16-S17 -> 44.508
B19: EPS | C19: -0.14 | D19: -0.13 | E19: -0.11 | G19: -0.13 | H19: -0.11 | I19: -0.08 | K19: -0.1 | L19: -0.09 | M19: -0.07 | O19: -0.04 | P19: -0.03 | Q19: 0.01 | S19: 0.08
B20: Shares (weighted-avg diluted, thousands) | C20: 507295.98 | D20: 511758.44 | E20: 516551.26 | G20: 526403.4 | H20: 531751.68 | I20: 537464.89 | K20: 548652.31 | L20: 553917.93 | M20: 559006.54 | O20: 567740.73 | P20: 571738.08 | Q20: 575474.83 | S20: 581835.92
B23: Historic Drivers
B24: Revenue Growth Rate (QoQ) | G24: =IFERROR((G5-C5)/F5,"n/a") -> 0.33056057 | H24: =IFERROR((H5-D5)/G5,"n/a") -> 0.32172083 | I24: =IFERROR((I5-E5)/H5,"n/a") -> 0.30892514 | J24: =IFERROR((J5-F5)/I5,"n/a") -> 0.37761752 | K24: =IFERROR((K5-G5)/J5,"n/a") -> 0.27655878 | L24: =IFERROR((L5-H5)/K5,"n/a") -> 0.28834166 | M24: =IFERROR((M5-I5)/L5,"n/a") -> 0.28130059 | N24: =IFERROR((N5-J5)/M5,"n/a") -> 0.21745693 | ... S24: =IFERROR((S5-O5)/R5,"n/a") -> 0.251997
B25: Gross Margin % | C25: =C7/C5 -> 0.72226156 | D25: =D7/D5 -> 0.71172398 | E25: =E7/E5 -> 0.72171378 | F25: =F7/F5 -> 0.72382448 | G25: =G7/G5 -> 0.71829973 | H25: =H7/H5 -> 0.73152054 | I25: =I7/I5 -> 0.74073185 | J25: =J7/J5 -> 0.75016107 | ... S25: =S7/S5 -> 0.75419761
B26: R&D % | C26: =C8/C5 -> 0.28732167 | D26: =D8/D5 -> 0.27257805 | E26: =E8/E5 -> 0.2942874 | F26: =F8/F5 -> 0.29265665 | G26: =G8/G5 -> 0.29544832 | H26: =H8/H5 -> 0.29175351 | I26: =I8/I5 -> 0.25604756 | J26: =J8/J5 -> 0.26577239 | ... S26: =S8/S5 -> 0.20375529
B27: S&M % | C27: =C9/C5 -> 0.61305338 | D27: =D9/D5 -> 0.59822958 | E27: =E9/E5 -> 0.55392226 | F27: =F9/F5 -> 0.51855802 | G27: =G9/G5 -> 0.58219949 | H27: =H9/H5 -> 0.53776162 | I27: =I9/I5 -> 0.49163488 | J27: =J9/J5 -> 0.48142786 | ... S27: =S9/S5 -> 0.42519693
B28: G&A % | C28: =C10/C5 -> 0.30664937 | D28: =D10/D5 -> 0.26939937 | E28: =E10/E5 -> 0.24733216 | F28: =F10/F5 -> 0.23414998 | G28: =G10/G5 -> 0.21175607 | H28: =H10/H5 -> 0.22014348 | I28: =I10/I5 -> 0.20356665 | J28: =J10/J5 -> 0.19963876 | ... S28: =S10/S5 -> 0.11021961
B29: Effective Tax Rate | C29: =IFERROR(C17/C16,"n/a") -> -0.010289618 | D29: =IFERROR(D17/D16,"n/a") -> -0.00062265531 | E29: =IFERROR(E17/E16,"n/a") -> -0.011959283 | F29: =IFERROR(F17/F16,"n/a") -> -0.041425407 | G29: =IFERROR(G17/G16,"n/a") -> -0.013850498 | H29: =IFERROR(H17/H16,"n/a") -> -0.007289952 | I29: =IFERROR(I17/I16,"n/a") -> -0.0031285113 | J29: =IFERROR(J17/J16,"n/a") -> -0.016497655 | ... S29: =IFERROR(S17/S16,"n/a") -> 0.090318229

Sheet IS
B2: IS Assumptions | C2: FY'21A | D2: FY'22A | E2: FY'23A | F2: FY'24A | G2: FY'25A | H2: FY'26A | I2: FY'27P | J2: FY'28P | K2: FY'29P | L2: FY'30P | M2: FY'31P | N2: FY'32P | O2: FY'33P | P2: FY'34P | Q2: FY'35P | R2: FY'36P
B3: Revenue Growth Rate | D3: =(D12-C12)/C12 -> 0.71403133 | E3: =(E12-D12)/D12 -> 0.52340987 | F3: =(F12-E12)/E12 -> 0.43650629 | G3: =(G12-F12)/F12 -> 0.33264347 | H3: =(H12-G12)/G12 -> 0.29573327 | I3: 0.25 | J3: 0.25 | K3: 0.25 | L3: 0.2 | M3: 0.2 | N3: 0.16 | O3: 0.13 | P3: 0.1 | Q3: 0.07 | R3: 0.05
B4: Gross Margin % | C4: =C14/C12 -> 0.69831336 | D4: =D14/D12 -> 0.70938379 | E4: =E14/E12 -> 0.72008674 | F4: =F14/F12 -> 0.73646687 | G4: =G14/G12 -> 0.76119036 | H4: =H14/H12 -> 0.76736561 | I4: 0.7675 | J4: =I4 -> 0.7675 | K4: =J4 -> 0.7675 | L4: =K4 -> 0.7675 | M4: =L4 -> 0.7675 | N4: =M4 -> 0.7675 | O4: =N4 -> 0.7675 | P4: =O4 -> 0.7675 | Q4: =P4 -> 0.7675 | R4: =Q4 -> 0.7675
B5: R&D % | C5: =C15/C12 -> 0.39910366 | D5: =D15/D12 -> 0.47887801 | E5: =E15/E12 -> 0.28719092 | F5: =F15/F12 -> 0.27585357 | G5: =G15/G12 -> 0.23992635 | H5: =H15/H12 -> 0.2128893 | I5: 0.2 | J5: =I5 -> 0.2 | K5: =J5 -> 0.2 | L5: =K5 -> 0.2 | M5: =L5 -> 0.2 | N5: 0.19 | O5: 0.185 | P5: 0.18 | Q5: 0.175 | R5: 0.17
B6: S&M % | C6: =C16/C12 -> 0.80935556 | D6: =D16/D12 -> 0.67984685 | E6: =E16/E12 -> 0.56716089 | F6: =F16/F12 -> 0.51915595 | G6: =G16/G12 -> 0.48162664 | H6: =H16/H12 -> 0.42244367 | I6: 0.4 | J6: 0.35 | K6: 0.3 | L6: =K6 -> 0.3 | M6: =L6 -> 0.3 | N6: 0.28 | O6: 0.27 | P6: 0.26 | Q6: 0.25 | R6: 0.24
B7: G&A % | C7: =C17/C12 -> 0.30100638 | D7: =D17/D12 -> 0.37316416 | E7: =E17/E12 -> 0.26172141 | F7: =F17/F12 -> 0.20807139 | G7: =G17/G12 -> 0.1878074 | H7: =H17/H12 -> 0.16451752 | I7: 0.15 | J7: 0.14 | K7: =J7 -> 0.14 | L7: 0.135 | M7: =L7 -> 0.135 | N7: 0.13 | O7: 0.125 | P7: 0.12 | Q7: 0.115 | R7: 0.11
B8: Effective Tax Rate | C8: =IFERROR(IF(OR(C23<=0,C24/C23>1,C24/C23<0),"n/a",C24/C23),"n/a") -> n/a | D8: =IFERROR(IF(OR(D23<=0,D24/D23>1,D24/D23<0),"n/a",D24/D23),"n/a") -> n/a | E8: =IFERROR(IF(OR(E23<=0,E24/E23>1,E24/E23<0),"n/a",E24/E23),"n/a") -> n/a | F8: =IFERROR(IF(OR(F23<=0,F24/F23>1,F24/F23<0),"n/a",F24/F23),"n/a") -> n/a | G8: =IFERROR(IF(OR(G23<=0,G24/G23>1,G24/G23<0),"n/a",G24/G23),"n/a") -> n/a | H8: =IFERROR(IF(OR(H23<=0,H24/H23>1,H24/H23<0),"n/a",H24/H23),"n/a") -> n/a | I8: 0.21 | J8: =I8 -> 0.21 | K8: =J8 -> 0.21 | L8: =K8 -> 0.21 | M8: =L8 -> 0.21 | N8: =M8 -> 0.21 | O8: =N8 -> 0.21 | P8: =O8 -> 0.21 | Q8: =P8 -> 0.21 | R8: =Q8 -> 0.21
B11: Income Statement | C11: FY'21A | D11: FY'22A | E11: FY'23A | F11: FY'24A | G11: FY'25A | H11: FY'26A | I11: FY'27P | J11: FY'28P | K11: FY'29P | L11: FY'30P | M11: FY'31P | N11: FY'32P | O11: FY'33P | P11: FY'34P | Q11: FY'35P | R11: FY'36P
B12: Revenue | C12: 249.905 | D12: 428.345 | E12: =SUM('10QIS'!C5:F5) -> 652.545 | F12: =SUM('10QIS'!G5:J5) -> 937.385 | G12: =SUM('10QIS'!K5:N5) -> 1249.2 | H12: =SUM('10QIS'!O5:R5) -> 1618.63 | I12: =H12*(1+I3) -> 2023.2875 | J12: =I12*(1+J3) -> 2529.1094 | K12: =J12*(1+K3) -> 3161.3867 | L12: =K12*(1+L3) -> 3793.6641 | M12: =L12*(1+M3) -> 4552.3969 | N12: =M12*(1+N3) -> 5280.7804 | O12: =N12*(1+O3) -> 5967.2818 | P12: =O12*(1+P3) -> 6564.01 | ... R12: =Q12*(1+R3) -> 7374.6652
B13: Cost of revenue | C13: 75.393 | D13: 124.484 | E13: =SUM('10QIS'!C6:F6) -> 182.656 | F13: =SUM('10QIS'!G6:J6) -> 247.032 | G13: =SUM('10QIS'!K6:N6) -> 298.321 | H13: =SUM('10QIS'!O6:R6) -> 376.549 | I13: =I12*(1-I4) -> 470.41434 | J13: =J12*(1-J4) -> 588.01793 | K13: =K12*(1-K4) -> 735.02241 | L13: =L12*(1-L4) -> 882.02689 | M13: =M12*(1-M4) -> 1058.4323 | N13: =N12*(1-N4) -> 1227.7814 | O13: =O12*(1-O4) -> 1387.393 | P13: =P12*(1-P4) -> 1526.1323 | ... R13: =R12*(1-R4) -> 1714.6097
B14: Gross profit | C14: =C12-C13 -> 174.512 | D14: =D12-D13 -> 303.861 | E14: =E12-E13 -> 469.889 | F14: =F12-F13 -> 690.353 | G14: =G12-G13 -> 950.879 | H14: =H12-H13 -> 1242.081 | I14: =I12-I13 -> 1552.8732 | J14: =J12-J13 -> 1941.0914 | ... R14: =R12-R13 -> 5660.0556
B15: Research and development | C15: 99.738 | D15: 205.125 | E15: =SUM('10QIS'!C8:F8) -> 187.405 | F15: =SUM('10QIS'!G8:J8) -> 258.581 | G15: =SUM('10QIS'!K8:N8) -> 299.716 | H15: =SUM('10QIS'!O8:R8) -> 344.589 | I15: =I12*I5 -> 404.6575 | J15: =J12*J5 -> 505.82188 | K15: =K12*K5 -> 632.27734 | L15: =L12*L5 -> 758.73281 | M15: =M12*M5 -> 910.47937 | N15: =N12*N5 -> 1003.3483 | O15: =O12*O5 -> 1103.9471 | P15: =P12*P5 -> 1181.5218 | ... R15: =R12*R5 -> 1253.6931
B16: Sales and marketing | C16: 202.262 | D16: 291.209 | E16: =SUM('10QIS'!C9:F9) -> 370.098 | F16: =SUM('10QIS'!G9:J9) -> 486.649 | G16: =SUM('10QIS'!K9:N9) -> 601.648 | H16: =SUM('10QIS'!O9:R9) -> 683.78 | I16: =I12*I6 -> 809.315 | J16: =J12*J6 -> 885.18828 | K16: =K12*K6 -> 948.41602 | L16: =L12*L6 -> 1138.0992 | M16: =M12*M6 -> 1365.7191 | N16: =N12*N6 -> 1478.6185 | O16: =O12*O6 -> 1611.1661 | P16: =P12*P6 -> 1706.6426 | ... R16: =R12*R6 -> 1769.9197
B17: General and administrative | C17: 75.223 | D17: 159.843 | E17: =SUM('10QIS'!C10:F10) -> 170.785 | F17: =SUM('10QIS'!G10:J10) -> 195.043 | G17: =SUM('10QIS'!K10:N10) -> 234.609 | H17: =SUM('10QIS'!O10:R10) -> 266.293 | I17: =I12*I7 -> 303.49313 | J17: =J12*J7 -> 354.07531 | K17: =K12*K7 -> 442.59414 | L17: =L12*L7 -> 512.14465 | M17: =M12*M7 -> 614.57358 | N17: =N12*N7 -> 686.50145 | O17: =O12*O7 -> 745.91023 | P17: =P12*P7 -> 787.6812 | ... R17: =R12*R7 -> 811.21318
B18: Lease modification, impairment, and related charges (& restructuring, FY21) | C18: 6.768 | D18: 1.532 | E18: =SUM('10QIS'!C11:F11) -> 1.056 | F18: =SUM('10QIS'!G11:J11) -> 4.762 | G18: =SUM('10QIS'!K11:N11) -> 4.028 | H18: =SUM('10QIS'!O11:R11) -> 0 | I18: 0 | J18: 0 | K18: 0 | L18: 0 | M18: 0 | N18: 0 | O18: 0 | P18: 0 | Q18: 0 | R18: 0
B19: Legal settlement | C19: 0 | D19: 0 | E19: =SUM('10QIS'!C12:F12) -> 0 | F19: =SUM('10QIS'!G12:J12) -> 68.665 | G19: =SUM('10QIS'!K12:N12) -> 0.85 | H19: =SUM('10QIS'!O12:R12) -> 0 | I19: 0 | J19: 0 | K19: 0 | L19: 0 | M19: 0 | N19: 0 | O19: 0 | P19: 0 | Q19: 0 | R19: 0
B20: Total operating expenses | C20: =SUM(C15:C19) -> 383.991 | D20: =SUM(D15:D19) -> 657.709 | E20: =SUM(E15:E19) -> 729.344 | F20: =SUM(F15:F19) -> 1013.7 | G20: =SUM(G15:G19) -> 1140.851 | H20: =SUM(H15:H19) -> 1294.662 | I20: =SUM(I15:I19) -> 1517.4656 | J20: =SUM(J15:J19) -> 1745.0855 | ... R20: =SUM(R15:R19) -> 3834.8259
B21: Operating income (Loss from operations) | C21: =C14-C20 -> -209.479 | D21: =D14-D20 -> -353.848 | E21: =E14-E20 -> -259.455 | F21: =F14-F20 -> -323.347 | G21: =G14-G20 -> -189.972 | H21: =H14-H20 -> -52.581 | I21: =I14-I20 -> 35.407531 | J21: =J14-J20 -> 196.00598 | ... R21: =R14-R20 -> 1825.2296
B22: Interest income and other income, net | C22: -0.642 | D22: -0.002 | E22: =SUM('10QIS'!C15:F15) -> 15.62 | F22: =SUM('10QIS'!G15:J15) -> 39.964 | G22: =SUM('10QIS'!K15:N15) -> 39.559 | H22: =SUM('10QIS'!O15:R15) -> 53.482 | I22: 55 | J22: 55 | K22: 55 | L22: 55 | M22: 55 | N22: 55 | O22: 55 | P22: 55 | Q22: 55 | R22: 55
B23: Income (loss) before income taxes | C23: =C21+C22 -> -210.121 | D23: =D21+D22 -> -353.85 | E23: =E21+E22 -> -243.835 | F23: =F21+F22 -> -283.383 | G23: =G21+G22 -> -150.413 | H23: =H21+H22 -> 0.901 | I23: =I21+I22 -> 90.407531 | J23: =J21+J22 -> 251.00598 | ... R23: =R21+R22 -> 1880.2296
B24: Provision for income taxes | C24: 0.087 | D24: 1.174 | E24: =SUM('10QIS'!C17:F17) -> 3.587 | F24: =SUM('10QIS'!G17:J17) -> 3.343 | G24: =SUM('10QIS'!K17:N17) -> 4.493 | H24: =SUM('10QIS'!O17:R17) -> 10.023 | I24: =MAX(I23,0)*I8 -> 18.985582 | J24: =MAX(J23,0)*J8 -> 52.711255 | K24: =MAX(K23,0)*K8 -> 96.196129 | L24: =MAX(L23,0)*L8 -> 117.1087 | M24: =MAX(M23,0)*M8 -> 138.22044 | N24: =MAX(N23,0)*N8 -> 197.30145 | O24: =MAX(O23,0)*O8 -> 246.51172 | P24: =MAX(P23,0)*P8 -> 297.57674 | ... R24: =MAX(R23,0)*R8 -> 394.84823
B25: Net income (loss) | C25: =C23-C24 -> -210.208 | D25: =D23-D24 -> -355.024 | E25: =E23-E24 -> -247.422 | F25: =F23-F24 -> -286.726 | G25: =G23-G24 -> -154.906 | H25: =H23-H24 -> -9.122 | I25: =I23-I24 -> 71.42195 | J25: =J23-J24 -> 198.29472 | ... R25: =R23-R24 -> 1485.3814
B26: EPS | C26: =C25/(C27/1000) -> -0.87849595 | D26: =D25/(D27/1000) -> -1.2791654 | E26: =E25/(E27/1000) -> -0.4811044 | F26: =F25/(F27/1000) -> -0.53605819 | G26: =G25/(G27/1000) -> -0.27844894 | H26: =H25/(H27/1000) -> -0.015906309 | I26: =I25/(I27/1000) -> 0.12454062 | J26: =J25/(J27/1000) -> 0.34577253 | ... R26: =R25/(R27/1000) -> 2.5901047
B27: Shares (diluted weighted-average, thousands) | C27: 239281.7 | D27: 277543.47 | E27: 514279.23 | F27: 534878.5 | G27: 556317.44 | H27: 573483.16 | I27: =H27*(1+DCF!$C$48) -> 573483.16 | J27: =I27*(1+DCF!$C$48) -> 573483.16 | K27: =J27*(1+DCF!$C$48) -> 573483.16 | L27: =K27*(1+DCF!$C$48) -> 573483.16 | M27: =L27*(1+DCF!$C$48) -> 573483.16 | N27: =M27*(1+DCF!$C$48) -> 573483.16 | O27: =N27*(1+DCF!$C$48) -> 573483.16 | P27: =O27*(1+DCF!$C$48) -> 573483.16 | ... R27: =Q27*(1+DCF!$C$48) -> 573483.16

Sheet BS
B2: Balance Sheet | C2: FY'21 | D2: FY'22 | E2: FY'23 | F2: FY'24 | G2: FY'25 | H2: FY'26
B3: Cash and cash equivalents | C3: 399.887 | D3: 921.218 | E3: 200.67 | F3: 135.536 | G3: 227.576 | H3: 318.789
B4: Short-term investments | C4: 0 | D4: 0 | E4: 489.192 | F4: 412.126 | G4: 467.222 | H4: 515.003
B5: Restricted cash | C5: 34.422 | D5: 23.092 | E5: 23.096 | F5: 19.202 | G5: 18.218 | H5: 6.054
B6: Accounts receivable, net | C6: 42.248 | D6: 81.987 | E6: 122.867 | F6: 161.829 | G6: 234.016 | H6: 321.442
B7: Inventories | C7: 13.674 | D7: 33.067 | E7: 40.571 | F7: 22.238 | G7: 38.911 | H7: 48.194
B8: Connected device costs, current | C8: 26.059 | D8: 52.519 | E8: 82.046 | F8: 104.008 | G8: 119.323 | H8: 142.904
B9: Prepaid expenses and other current assets | C9: 9.321 | D9: 11.376 | E9: 22.189 | F9: 51.221 | G9: 58.106 | H9: 69.269
B10: Deferred commissions, current | C10: 0 | D10: 0 | E10: 0 | F10: 0 | G10: 0 | H10: 85.463
B11: Total current assets | C11: =SUM(C3:C10) -> 525.611 | D11: =SUM(D3:D10) -> 1123.259 | E11: =SUM(E3:E10) -> 980.631 | F11: =SUM(F3:F10) -> 906.16 | G11: =SUM(G3:G10) -> 1163.372 | H11: =SUM(H3:H10) -> 1507.118
B12: Long-term investments | C12: 0 | D12: 0 | E12: 113.101 | F12: 276.166 | G12: 282.652 | H12: 403.123
B13: Property and equipment, net | C13: 57.655 | D13: 36.772 | E13: 59.278 | F13: 54.969 | G13: 58.151 | H13: 81.607
B14: Operating lease right-of-use assets | C14: 133.121 | D14: 134.427 | E14: 112.624 | F14: 81.974 | G14: 64.864 | H14: 60.303
B15: Connected device costs, non-current | C15: 81.459 | D15: 141.292 | E15: 194.852 | F15: 230.782 | G15: 242.928 | H15: 297.245
B16: Deferred commissions, non-current | C16: 86.937 | D16: 117.757 | E16: 140.166 | F16: 177.562 | G16: 209.341 | H16: 176.415
B17: Other assets, non-current | C17: 1.85 | D17: 14.422 | E17: 16.356 | F17: 7.232 | G17: 2.994 | H17: 14.863
B18: Total assets | C18: =C11+SUM(C12:C17) -> 886.633 | D18: =D11+SUM(D12:D17) -> 1567.929 | E18: =E11+SUM(E12:E17) -> 1617.008 | F18: =F11+SUM(F12:F17) -> 1734.845 | G18: =G11+SUM(G12:G17) -> 2024.302 | H18: =H11+SUM(H12:H17) -> 2540.674
B20: Accounts payable | C20: 19.4 | D20: 54.705 | E20: 30.144 | F20: 46.281 | G20: 64.017 | H20: 47.68
B21: Accrued expenses and other current liabilities | C21: 14.571 | D21: 31.835 | E21: 53.824 | F21: 61.437 | G21: 74.976 | H21: 102.073
B22: Accrued compensation and benefits | C22: 12.549 | D22: 27.107 | E22: 36.03 | F22: 37.068 | G22: 43.443 | H22: 75.403
B23: Deferred revenue, current | C23: 143.109 | D23: 203.185 | E23: 300.113 | F23: 426.369 | G23: 563.254 | H23: 679.316
B24: Operating lease liabilities, current | C24: 22.313 | D24: 21.447 | E24: 22.047 | F24: 20.661 | G24: 15.656 | H24: 12.566
B25: Total current liabilities | C25: =SUM(C20:C24) -> 211.942 | D25: =SUM(D20:D24) -> 338.279 | E25: =SUM(E20:E24) -> 442.158 | F25: =SUM(F20:F24) -> 591.816 | G25: =SUM(G20:G24) -> 761.346 | H25: =SUM(H20:H24) -> 917.038
B26: Deferred revenue, non-current | C26: 106.463 | D26: 110.501 | E26: 126.452 | F26: 139.117 | G26: 122.516 | H26: 129.726
B27: Operating lease liabilities, non-current | C27: 150.961 | D27: 123.513 | E27: 100.873 | F27: 78.83 | G27: 64.622 | H27: 60.202
B28: Other liabilities, non-current | C28: 1.003 | D28: 6.689 | E28: 9.506 | F28: 9.935 | G28: 6.622 | H28: 13.261
B29: Total liabilities | C29: =C25+SUM(C26:C28) -> 470.369 | D29: =D25+SUM(D26:D28) -> 578.982 | E29: =E25+SUM(E26:E28) -> 678.989 | F29: =F25+SUM(F26:F28) -> 819.698 | G29: =G25+SUM(G26:G28) -> 955.106 | H29: =H25+SUM(H26:H28) -> 1120.227
B31: Convertible preferred stock (mezzanine, pre-IPO) | C31: 949.067 | D31: 0 | E31: 0 | F31: 0 | G31: 0 | H31: 0
B32: Total stockholders' equity (deficit) | C32: -532.803 | D32: 988.947 | E32: 938.019 | F32: 915.147 | G32: 1069.196 | H32: 1420.447
B33: Total liabilities, conv. preferred & stockholders' equity | C33: =C29+C31+C32 -> 886.633 | D33: =D29+D31+D32 -> 1567.929 | E33: =E29+E31+E32 -> 1617.008 | F33: =F29+F31+F32 -> 1734.845 | G33: =G29+G31+G32 -> 2024.302 | H33: =H29+H31+H32 -> 2540.674
B35: Check (Assets less Liab., Pref. & Equity) | C35: =C18-C33 -> 0 | D35: =D18-D33 -> 0 | E35: =E18-E33 -> 0 | F35: =F18-F33 -> 0 | G35: =G18-G33 -> 0 | H35: =H18-H33 -> 0

Sheet CFS
B2: Cash Flow Statement | C2: FY'21 | D2: FY'22 | E2: FY'23 | F2: FY'24 | G2: FY'25 | H2: FY'26
B3: Net income (loss) | C3: -210.208 | D3: -355.024 | E3: -247.422 | F3: -286.726 | G3: -154.907 | H3: -9.117
B4: Depreciation and amortization | C4: 10.738 | D4: 10.388 | E4: 11.768 | F4: 15.526 | G4: 20.649 | H4: 24.048
B5: Stock-based compensation expense | C5: 25.564 | D5: 228.723 | E5: 177.473 | F5: 237.082 | G5: 277.87 | H5: 314.983
B6: Lease modification, impairment, and related charges (non-cash) | C6: 0 | D6: 1.532 | E6: 1.056 | F6: 4.762 | G6: 3.529 | H6: 0
B7: Other non-cash adjustments | C7: 16.786 | D7: 6.63 | E7: 2.12 | F7: -3.651 | G7: -13.529 | H7: -7.125
B8: Accounts receivable, net | C8: -14.14 | D8: -47.049 | E8: -47.464 | F8: -46.42 | G8: -75.531 | H8: -144.676
B9: Inventories | C9: 2.843 | D9: -19.393 | E9: -7.504 | F9: 18.332 | G9: -22.416 | H9: -19.095
B10: Prepaid expenses and other current assets | C10: 1.624 | D10: -1.426 | E10: -11.293 | F10: -29.076 | G10: -6.885 | H10: -7.657
B11: Connected device costs | C11: -44.184 | D11: -86.293 | E11: -83.086 | F11: -57.893 | G11: -27.46 | H11: -74.535
B12: Deferred commissions | C12: -21.327 | D12: -30.821 | E12: -22.409 | F12: -37.396 | G12: -31.779 | H12: -51.312
B13: Other assets | C13: 0.11 | D13: -12.327 | E13: -1.862 | F13: 0.509 | G13: 4.438 | H13: -4.347
B14: Accounts payable and other liabilities | C14: 16.25 | D14: 69.926 | E14: 13.485 | F14: 26.596 | G14: 37.283 | H14: 97.723
... B16: Operating lease liabilities | C16: 9.015 | D16: -0.348 | E16: -0.762 | F16: 7.62 | G16: 0.114 | H16: 0.795
B17: Net cash provided by (used in) operating activities | C17: =SUM(C3:C16) -> -171.769 | D17: =SUM(D3:D16) -> -171.481 | E17: =SUM(E3:E16) -> -103.021 | F17: =SUM(F3:F16) -> -11.815 | G17: =SUM(G3:G16) -> 131.659 | H17: =SUM(H3:H16) -> 236.21
B19: Capital expenditures (purchases of property and equipment) | C19: -32.102 | D19: -19.353 | E19: -33.24 | F19: -10.953 | G19: -20.177 | H19: -28.766
B20: Purchases of investments | C20: 0 | D20: 0 | E20: -685.615 | F20: -740.546 | G20: -649.478 | H20: -873.467
B21: Proceeds from sales and maturities of investments | C21: 0 | D21: 0 | E21: 86.625 | F21: 672.862 | G21: 603.234 | H21: 714.05
B22: Other investing activities | C22: -0.1 | D22: -0.682 | E22: 0.382 | F22: -0.05 | G22: -0.2 | H22: -1.35
B23: Net cash used in investing activities | C23: =C19+C20+C21+C22 -> -32.202 | D23: =D19+D20+D21+D22 -> -20.035 | E23: =E19+E20+E21+E22 -> -631.848 | F23: =F19+F20+F21+F22 -> -78.687 | G23: =G19+G20+G21+G22 -> -66.621 | H23: =H19+H20+H21+H22 -> -189.533
B25: Proceeds from equity issuances (IPO / preferred stock / comp plans) | C25: 402.203 | D25: 848.046 | E25: 18.047 | F25: 23.202 | G25: 28.799 | H25: 30.856
B26: Payment of taxes on net share settlement / stock repurchases | C26: -0.061 | D26: -141.752 | E26: 0 | F26: 0 | G26: -0.007 | H26: 0
B27: Other financing activities (offering costs, finance leases, etc.) | C27: -0.168 | D27: -4.65 | E27: -3.835 | F27: -2.205 | G27: -1.691 | H27: -0.928
B28: Net cash provided by financing activities | C28: =SUM(C25:C27) -> 401.974 | D28: =SUM(D25:D27) -> 701.644 | E28: =SUM(E25:E27) -> 14.212 | F28: =SUM(F25:F27) -> 20.997 | G28: =SUM(G25:G27) -> 27.101 | H28: =SUM(H25:H27) -> 29.928
B30: Effect of exchange rate changes on cash | C30: 0 | D30: -0.127 | E30: 0.113 | F30: 0.477 | G30: -1.083 | H30: 2.444
B31: Net increase (decrease) in cash, cash equivalents, and restricted cash | C31: =C17+C23+C28+C30 -> 198.003 | D31: =D17+D23+D28+D30 -> 510.001 | E31: =E17+E23+E28+E30 -> -720.544 | F31: =F17+F23+F28+F30 -> -69.028 | G31: =G17+G23+G28+G30 -> 91.056 | H31: =H17+H23+H28+H30 -> 79.049
B32: Beginning of period | C32: 236.306 | D32: =C33 -> 434.309 | E32: =D33 -> 944.31 | F32: =E33 -> 223.766 | G32: =F33 -> 154.738 | H32: =G33 -> 245.794
B33: End of period | C33: =C32+C31 -> 434.309 | D33: =D32+D31 -> 944.31 | E33: =E32+E31 -> 223.766 | F33: =F32+F31 -> 154.738 | G33: =G32+G31 -> 245.794 | H33: =H32+H31 -> 324.843

Sheet DCF
B2: Samsara Inc. (IOT)
B4: Valuation Date (hardcoded): | F4: 46267
B5: Share Price on Valuation Date: | F5: =Main!C3 -> 40.85
B6: Diluted Shares Outstanding | F6: =Main!C4 -> 581835.92
B7: Stub Period to Fiscal Year-End (yrs) | F7: =(DATE(YEAR(F4)+IF(MONTH(F4)>1,1,0),1,31)-F4)/365 -> 0.41369863
B8: Select Operating Data
I9: Projected Annual Forecast
C10: FY'21 | D10: FY'22 | E10: FY'23 | F10: FY'24 | G10: FY'25 | H10: FY'26 | I10: FY'27 | J10: FY'28 | K10: FY'29 | L10: FY'30 | M10: FY'31 | N10: FY'32 | O10: FY'33 | P10: FY'34 | Q10: FY'35 | R10: FY'36
B11: Revenue | C11: =IS!C12 -> 249.905 | D11: =IS!D12 -> 428.345 | E11: =IS!E12 -> 652.545 | F11: =IS!F12 -> 937.385 | G11: =IS!G12 -> 1249.2 | H11: =IS!H12 -> 1618.63 | I11: =IS!I12 -> 2023.2875 | J11: =IS!J12 -> 2529.1094 | ... R11: =IS!R12 -> 7374.6652
B13: EBIT | C13: =IS!C21 -> -209.479 | D13: =IS!D21 -> -353.848 | E13: =IS!E21 -> -259.455 | F13: =IS!F21 -> -323.347 | G13: =IS!G21 -> -189.972 | H13: =IS!H21 -> -52.581 | I13: =IS!I21 -> 35.407531 | J13: =IS!J21 -> 196.00598 | ... R13: =IS!R21 -> 1825.2296
B15: Depreciation & Amortization | C15: =CFS!C4 -> 10.738 | D15: =CFS!D4 -> 10.388 | E15: =CFS!E4 -> 11.768 | F15: =CFS!F4 -> 15.526 | G15: =CFS!G4 -> 20.649 | H15: =CFS!H4 -> 24.048 | I15: =I11*(I16) -> 35.982529 | J15: =J11*(J16) -> 44.978162 | K15: =K11*(K16) -> 56.222702 | L15: =L11*(L16) -> 67.467242 | M15: =M11*(M16) -> 80.960691 | N15: =N11*(N16) -> 93.914401 | O15: =O11*(O16) -> 106.12327 | P15: =P11*(P16) -> 116.7356 | ... R15: =R11*(R16) -> 131.15245 | T15: Arithmetic Avg | U15: Geometric Avg
C16: =C15/C11 -> 0.042968328 | D16: =D15/D11 -> 0.02425148 | E16: =E15/E11 -> 0.018034005 | F16: =F15/F11 -> 0.016563098 | G16: =G15/G11 -> 0.016529779 | H16: =H15/H11 -> 0.014857009 | I16: =$U$16 -> 0.01778419 | J16: =$U$16 -> 0.01778419 | K16: =$U$16 -> 0.01778419 | L16: =$U$16 -> 0.01778419 | M16: =$U$16 -> 0.01778419 | N16: =$U$16 -> 0.01778419 | O16: =$U$16 -> 0.01778419 | P16: =$U$16 -> 0.01778419 | ... R16: =$U$16 -> 0.01778419 | T16: =AVERAGE(D16:H16) -> 0.018047074 | U16: =IFERROR(GEOMEAN(D16:H16),"n/a") -> 0.01778419
B18: Select Balance Sheet And Other Data
I19: Projected Annual Forecast
C20: FY'21 | D20: FY'22 | E20: FY'23 | F20: FY'24 | G20: FY'25 | H20: FY'26 | I20: FY'27 | J20: FY'28 | K20: FY'29 | L20: FY'30 | M20: FY'31 | N20: FY'32 | O20: FY'33 | P20: FY'34 | Q20: FY'35 | R20: FY'36
B21: Accounts Receivable | C21: =BS!C6 -> 42.248 | D21: =BS!D6 -> 81.987 | E21: =BS!E6 -> 122.867 | F21: =BS!F6 -> 161.829 | G21: =BS!G6 -> 234.016 | H21: =BS!H6 -> 321.442 | I21: =I36*I11 -> 379.27499 | J21: =J36*J11 -> 474.09374 | K21: =K36*K11 -> 592.61717 | L21: =L36*L11 -> 711.14061 | M21: =M36*M11 -> 853.36873 | N21: =N36*N11 -> 989.90773 | O21: =O36*O11 -> 1118.5957 | P21: =P36*P11 -> 1230.4553 | ... R21: =R36*R11 -> 1382.4165
B22: Deferred Commissions (asset) | C22: =BS!C10+BS!C16 -> 86.937 | D22: =BS!D10+BS!D16 -> 117.757 | E22: =BS!E10+BS!E16 -> 140.166 | F22: =BS!F10+BS!F16 -> 177.562 | G22: =BS!G10+BS!G16 -> 209.341 | H22: =BS!H10+BS!H16 -> 261.878 | I22: =I37*I11 -> 323.726 | J22: =J37*J11 -> 404.6575 | K22: =K37*K11 -> 474.20801 | L22: =L37*L11 -> 569.04961 | M22: =M37*M11 -> 637.33556 | N22: =N37*N11 -> 739.30925 | O22: =O37*O11 -> 835.41946 | P22: =P37*P11 -> 918.9614 | ... R22: =R37*R11 -> 1032.4531
B23: Prepaid Expenses | C23: =BS!C9 -> 9.321 | D23: =BS!D9 -> 11.376 | E23: =BS!E9 -> 22.189 | F23: =BS!F9 -> 51.221 | G23: =BS!G9 -> 58.106 | H23: =BS!H9 -> 69.269 | I23: =I38*I11 -> 80.260952 | J23: =J38*J11 -> 100.32619 | K23: =K38*K11 -> 125.40774 | L23: =L38*L11 -> 150.48928 | M23: =M38*M11 -> 180.58714 | N23: =N38*N11 -> 209.48108 | O23: =O38*O11 -> 236.71363 | P23: =P38*P11 -> 260.38499 | ... R23: =R38*R11 -> 292.54253
B24: Inventories | C24: =BS!C7 -> 13.674 | D24: =BS!D7 -> 33.067 | E24: =BS!E7 -> 40.571 | F24: =BS!F7 -> 22.238 | G24: =BS!G7 -> 38.911 | H24: =BS!H7 -> 48.194 | I24: =I43*I11 -> 60.698625 | J24: =J43*J11 -> 75.873281 | K24: =K43*K11 -> 94.841602 | L24: =L43*L11 -> 113.80992 | M24: =M43*M11 -> 136.57191 | N24: =N43*N11 -> 158.42341 | O24: =O43*O11 -> 179.01845 | P24: =P43*P11 -> 196.9203 | ... R24: =R43*R11 -> 221.23996
B25: Connected Device Costs (current + non-current) | C25: =BS!C8+BS!C15 -> 107.518 | D25: =BS!D8+BS!D15 -> 193.811 | E25: =BS!E8+BS!E15 -> 276.898 | F25: =BS!F8+BS!F15 -> 334.79 | G25: =BS!G8+BS!G15 -> 362.251 | H25: =BS!H8+BS!H15 -> 440.149 | I25: =I44*I11 -> 550.3342 | J25: =J44*J11 -> 687.91775 | K25: =K44*K11 -> 859.89719 | L25: =L44*L11 -> 1031.8766 | M25: =M44*M11 -> 1238.2519 | N25: =N44*N11 -> 1436.3723 | O25: =O44*O11 -> 1623.1007 | P25: =P44*P11 -> 1785.4107 | ... R25: =R44*R11 -> 2005.9089
B27: Accounts Payable | C27: =BS!C20 -> 19.4 | D27: =BS!D20 -> 54.705 | E27: =BS!E20 -> 30.144 | F27: =BS!F20 -> 46.281 | G27: =BS!G20 -> 64.017 | H27: =BS!H20 -> 47.68 | I27: =I39*I11 -> 60.698625 | J27: =J39*J11 -> 75.873281 | K27: =K39*K11 -> 94.841602 | L27: =L39*L11 -> 113.80992 | M27: =M39*M11 -> 136.57191 | N27: =N39*N11 -> 158.42341 | O27: =O39*O11 -> 179.01845 | P27: =P39*P11 -> 196.9203 | ... R27: =R39*R11 -> 221.23996
B28: Accrued Expenses & Compensation | C28: =BS!C21+BS!C22 -> 27.12 | D28: =BS!D21+BS!D22 -> 58.942 | E28: =BS!E21+BS!E22 -> 89.854 | F28: =BS!F21+BS!F22 -> 98.505 | G28: =BS!G21+BS!G22 -> 118.419 | H28: =BS!H21+BS!H22 -> 177.476 | I28: =I40*I11 -> 234.00954 | J28: =J40*J11 -> 292.51193 | K28: =K40*K11 -> 365.63991 | L28: =L40*L11 -> 438.76789 | M28: =M40*M11 -> 526.52147 | N28: =N40*N11 -> 610.76491 | O28: =O40*O11 -> 690.16435 | P28: =P40*P11 -> 759.18078 | ... R28: =R40*R11 -> 852.93961
B29: Deferred Revenue (current + non-current) | C29: =BS!C23+BS!C26 -> 249.572 | D29: =BS!D23+BS!D26 -> 313.686 | E29: =BS!E23+BS!E26 -> 426.565 | F29: =BS!F23+BS!F26 -> 565.486 | G29: =BS!G23+BS!G26 -> 685.77 | H29: =BS!H23+BS!H26 -> 809.042 | I29: =I41*I11 -> 991.41088 | J29: =J41*J11 -> 1201.327 | K29: =K41*K11 -> 1501.6587 | L29: =L41*L11 -> 1707.1488 | M29: =M41*M11 -> 2048.5786 | N29: =N41*N11 -> 2376.3512 | O29: =O41*O11 -> 2685.2768 | P29: =P41*P11 -> 2953.8045 | ... R29: =R41*R11 -> 3318.5994
B31: Debt | C31: 0 | D31: 0 | E31: 0 | F31: 0 | G31: 0 | H31: 0
B32: Capital Expenditures | C32: =-CFS!C19 -> 32.102 | D32: =-CFS!D19 -> 19.353 | E32: =-CFS!E19 -> 33.24 | F32: =-CFS!F19 -> 10.953 | G32: =-CFS!G19 -> 20.177 | H32: =-CFS!H19 -> 28.766 | I32: =I42*I11 -> 35.306367 | J32: =J42*J11 -> 44.259414 | K32: =K42*K11 -> 55.324268 | L32: =L42*L11 -> 66.389121 | M32: =M42*M11 -> 79.666945 | N32: =N42*N11 -> 92.413657 | O32: =O42*O11 -> 104.42743 | P32: =P42*P11 -> 114.87018 | ... R32: =R42*R11 -> 129.05664
B34: Stock-Based Compensation ($) | C34: =C45*C11 -> 25.564 | D34: =D45*D11 -> 228.723 | E34: =E45*E11 -> 177.473 | F34: =F45*F11 -> 237.082 | G34: =G45*G11 -> 277.87 | H34: =H45*H11 -> 314.983 | I34: =I45*I11 -> 374.30819 | J34: =J45*J11 -> 455.23969 | ... R34: =R45*R11 -> 1106.1998
T35: Arithmetic Mean | U35: Geometric Mean
B36: Accounts Receivable as a % of revenue | C36: =C21/C11 -> 0.16905624 | D36: =D21/D11 -> 0.19140413 | E36: =E21/E11 -> 0.18828893 | F36: =F21/F11 -> 0.17263878 | G36: =G21/G11 -> 0.18733269 | H36: =H21/H11 -> 0.19858893 | I36: =$U$36 -> 0.18745482 | J36: =$U$36 -> 0.18745482 | K36: =$U$36 -> 0.18745482 | L36: =$U$36 -> 0.18745482 | M36: =$U$36 -> 0.18745482 | N36: =M36 -> 0.18745482 | O36: =N36 -> 0.18745482 | P36: =O36 -> 0.18745482 | Q36: =P36 -> 0.18745482 | R36: =Q36 -> 0.18745482 | T36: =AVERAGE(D36:H36) -> 0.18765069 | U36: =IFERROR(GEOMEAN(D36:H36),"n/a") -> 0.18745482
B37: Deferred Commissions as a % of revenue | C37: =C22/C11 -> 0.34788019 | D37: =D22/D11 -> 0.27491158 | E37: =E22/E11 -> 0.21479898 | F37: =F22/F11 -> 0.1894227 | G37: =G22/G11 -> 0.16758005 | H37: =H22/H11 -> 0.16178991 | I37: 0.16 | J37: 0.16 | K37: 0.15 | L37: 0.15 | M37: 0.14 | N37: =M37 -> 0.14 | O37: =N37 -> 0.14 | P37: =O37 -> 0.14 | Q37: =P37 -> 0.14 | R37: =Q37 -> 0.14 | T37: =AVERAGE(D37:H37) -> 0.20170064 | U37: =IFERROR(GEOMEAN(D37:H37),"n/a") -> 0.19786374
B38: Prepaid Expenses as a % of revenue | C38: =C23/C11 -> 0.037298173 | D38: =D23/D11 -> 0.026558031 | E38: =E23/E11 -> 0.034003785 | F38: =F23/F11 -> 0.054642436 | G38: =G23/G11 -> 0.046514569 | H38: =H23/H11 -> 0.042794833 | I38: =$U$38 -> 0.039668585 | J38: =$U$38 -> 0.039668585 | K38: =$U$38 -> 0.039668585 | L38: =$U$38 -> 0.039668585 | M38: =$U$38 -> 0.039668585 | N38: =M38 -> 0.039668585 | O38: =N38 -> 0.039668585 | P38: =O38 -> 0.039668585 | Q38: =P38 -> 0.039668585 | R38: =Q38 -> 0.039668585 | T38: =AVERAGE(D38:H38) -> 0.040902731 | U38: =IFERROR(GEOMEAN(D38:H38),"n/a") -> 0.039668585
B39: Accounts Payable as a % of revenue | C39: =C27/C11 -> 0.077629499 | D39: =D27/D11 -> 0.12771247 | E39: =E27/E11 -> 0.046194515 | F39: =F27/F11 -> 0.049372456 | G39: =G27/G11 -> 0.051246398 | H39: =H27/H11 -> 0.02945701 | I39: 0.03 | J39: 0.03 | K39: 0.03 | L39: 0.03 | M39: 0.03 | N39: =M39 -> 0.03 | O39: =N39 -> 0.03 | P39: =O39 -> 0.03 | Q39: =P39 -> 0.03 | R39: =Q39 -> 0.03 | T39: =AVERAGE(D39:H39) -> 0.060796571 | U39: =IFERROR(GEOMEAN(D39:H39),"n/a") -> 0.053534296
B40: Accrued Expenses & Comp as a % of revenue | C40: =C28/C11 -> 0.10852124 | D40: =D28/D11 -> 0.13760403 | E40: =E28/E11 -> 0.13769778 | F40: =F28/F11 -> 0.10508489 | G40: =G28/G11 -> 0.094795869 | H40: =H28/H11 -> 0.10964581 | I40: =$U$40 -> 0.11565808 | J40: =$U$40 -> 0.11565808 | K40: =$U$40 -> 0.11565808 | L40: =$U$40 -> 0.11565808 | M40: =$U$40 -> 0.11565808 | N40: =M40 -> 0.11565808 | O40: =N40 -> 0.11565808 | P40: =O40 -> 0.11565808 | Q40: =P40 -> 0.11565808 | R40: =Q40 -> 0.11565808 | T40: =AVERAGE(D40:H40) -> 0.11696568 | U40: =IFERROR(GEOMEAN(D40:H40),"n/a") -> 0.11565808
B41: Deferred Revenue as a % of revenue | C41: =C29/C11 -> 0.99866749 | D41: =D29/D11 -> 0.73232091 | E41: =E29/E11 -> 0.65369438 | F41: =F29/F11 -> 0.60325907 | G41: =G29/G11 -> 0.54896734 | H41: =H29/H11 -> 0.49983134 | I41: 0.49 | J41: 0.475 | K41: 0.475 | L41: 0.45 | M41: 0.45 | N41: =M41 -> 0.45 | O41: =N41 -> 0.45 | P41: =O41 -> 0.45 | Q41: =P41 -> 0.45 | R41: =Q41 -> 0.45 | T41: =AVERAGE(D41:H41) -> 0.60761461 | U41: =IFERROR(GEOMEAN(D41:H41),"n/a") -> 0.6022683
B42: Capital Expenditures as a % of revenue | C42: =C32/C11 -> 0.12845681 | D42: =D32/D11 -> 0.045180871 | E42: =E32/E11 -> 0.050939016 | F42: =F32/F11 -> 0.011684633 | G42: =G32/G11 -> 0.016151937 | H42: =H32/H11 -> 0.017771819 | I42: 0.01745 | J42: 0.0175 | K42: 0.0175 | L42: 0.0175 | M42: 0.0175 | N42: =M42 -> 0.0175 | O42: =N42 -> 0.0175 | P42: =O42 -> 0.0175 | Q42: =P42 -> 0.0175 | R42: =Q42 -> 0.0175 | T42: =AVERAGE(D42:H42) -> 0.028345655 | U42: =IFERROR(GEOMEAN(D42:H42),"n/a") -> 0.023851481
B43: Inventories as a % of revenue | C43: =C24/C11 -> 0.054716792 | D43: =D24/D11 -> 0.077197119 | E43: =E24/E11 -> 0.06217349 | F43: =F24/F11 -> 0.023723443 | G43: =G24/G11 -> 0.031148735 | H43: =H24/H11 -> 0.029774562 | I43: 0.03 | J43: 0.03 | K43: 0.03 | L43: 0.03 | M43: 0.03 | N43: 0.03 | O43: 0.03 | P43: 0.03 | Q43: 0.03 | R43: 0.03 | T43: =AVERAGE(D43:H43) -> 0.04480347 | U43: =IFERROR(GEOMEAN(D43:H43),"n/a") -> 0.040247043 | V43: Input. ~3.0% of revenue, in line with FY24-FY26 actuals (BS!7 / revenue).
B44: Connected Device Costs as a % of revenue | C44: =C25/C11 -> 0.43023549 | D44: =D25/D11 -> 0.45246472 | E44: =E25/E11 -> 0.42433549 | F44: =F25/F11 -> 0.35715314 | G44: =G25/G11 -> 0.28998639 | H44: =H25/H11 -> 0.27192688 | I44: 0.272 | J44: 0.272 | K44: 0.272 | L44: 0.272 | M44: 0.272 | N44: 0.272 | O44: 0.272 | P44: 0.272 | Q44: 0.272 | R44: 0.272 | T44: =AVERAGE(D44:H44) -> 0.35917332 | U44: =IFERROR(GEOMEAN(D44:H44),"n/a") -> 0.35204296 | V44: Input. Held flat at the FY26 actual of 27.2%. Ratio has fallen every year since FY22 (45.2%), so flat is the conservative choice; fade it if you think efficiency continues.
B45: SBC as % of Revenue | C45: =CFS!C5/C11 -> 0.10229487 | D45: =CFS!D5/D11 -> 0.53396911 | E45: =CFS!E5/E11 -> 0.27197052 | F45: =CFS!F5/F11 -> 0.25291849 | G45: =CFS!G5/G11 -> 0.22243836 | H45: =CFS!H5/H11 -> 0.19459852 | I45: 0.185 | J45: 0.18 | K45: 0.17 | L45: 0.165 | M45: 0.16 | N45: 0.155 | O45: 0.15 | P45: 0.15 | Q45: 0.15 | R45: 0.15 | T45: =AVERAGE(D45:H45) -> 0.295179 | U45: =IFERROR(GEOMEAN(D45:H45),"n/a") -> 0.27559641
B47: SBC Add-Back Toggle (1 = add back to FCF, 0 = treat as a real cost) | C47: 1 | D47: <- when 1, SBC is added back AND the share count below is grown to reflect the dilution that pays for it
B48: Diluted Share Growth Rate (if toggle=1) | C48: 0
B49: Free Cash Flow Buildup
...

Sheet Connected Ops Cloud
B2: Segment / Platform | C2: Connected Operations Cloud
B3: Description | C3: IoT platform combining hardware (vehicle gateways, dashcams, sensors) with cloud software for fleet, equipment, and site operations

Sheet Sources & Assumptions
B2: Sources & Assumptions
B4: Item | D4: Value / Location | F4: Source & Rationale
B5: Historical financials (IS, BS, CFS, 10QIS tabs) | D5: FY21-FY26 actuals | F5: Samsara Inc. 10-K filings and quarterly press releases, sec.gov/Archives/edgar/data/1642896. FY26 revenue $1,618.6mm and FY25 revenue $1,249.2mm confirmed against the FY2026 annual report; Q1 FY27 revenue $478.8mm confirmed against the 4-Jun-2026 press release.
B6: CEO / CFO (Main!C11:C12) | D6: Sanjit Biswas (CEO & co-founder), Dominic Phillips (CFO) | F6: Samsara investor relations leadership page and Q4 FY26 earnings call, 5-Mar-2026.
B7: Valuation date (DCF!F4) | D7: 9/2/2026 (hardcoded) | F7: Changed from =TODAY(). A volatile function made the model's output move every time the file was opened.
B8: Stub period (DCF!F7) | D8: 0.414 yrs to 1/31/2027 | F8: Corrected. Formula previously ran to 12/31; Samsara's fiscal year ends in late January, so every discount period was ~0.08 yrs too short.
B9: Risk-free rate (DCF!K86) | D9: 4.79% | F9: 10-year US Treasury yield as of 9/1/2026 per model label. NOT independently verified - re-source before relying on it.
B10: Equity risk premium (DCF!K85) | D10: 4.28% | F10: Damodaran implied ERP as of 9/1/2026 per model label. NOT independently verified - re-source before relying on it.
B11: Beta (DCF!K87) | D11: 1.34 | F11: Model input, 5-yr weekly adjusted beta. NOT independently verified - re-source before relying on it.
B12: WACC (DCF!E97) | D12: 10.53% | F12: Equals cost of equity, since the company carries no debt. Debt weighting is therefore 0 and the capital-structure weighting has no effect.
B13: FY27 revenue growth (IS!I3) | D13: 25.0% | F13: Company raised FY27 guidance to $2.005-2.013bn after the Q1 FY27 print (4-Jun-2026). The model's 25% produces $2,023mm, ~0.5% above the top of guidance. Reasonable but not conservative.
B14: Revenue growth fade, FY28-FY36 (IS!J3:R3) | D14: 25/25/20/20/16/13/10/7/5% | F14: Author's assumption: a glide path toward the 2.5% terminal rate. No external source for the specific shape. This is the single largest judgment call in the model.
B15: Gross margin (IS row 4) | D15: 76.75%, held flat | F15: Consistent with the FY26 actual of ~76.7%.
... B34: KNOWN REMAINING LIMITATION - method | D34: DCF on a 25%-growth company | F34: 62% of enterprise value sits in the terminal value. Treat this as one input among several, not as a precise answer.
