Workbook

Sheet Main
A2: LLY | D2: Name | E2: Indication | F2: Mechanism | G2: Economics | H2: Approved
A3: Price | B3: 1213.4 | D3: Mounjaro | E3: =Mounjaro!C4 -> Type 2 Diabetes | F3: =Mounjaro!C5 -> Dual GIP/GLP-1 Receptor Agonist | G3: 1 | H3: 44694
A4: Shares | B4: 895.9 | D4: Zepbound | E4: =Zepbound!C4 -> Obesity & Obstructive Sleep Apnea | F4: =Zepbound!C5 -> Dual GIP/GLP-1 Receptor Agonist | G4: 1 | H4: 45238
A5: Market Cap | B5: =B3*B4 -> 1087085.1 | D5: Trulicity | E5: =Trulicity!C4 -> Type-2 Diabetes | F5: =Trulicity!C5 -> GLP-1 Agonist | G5: 1 | H5: 41900
A6: Cash | B6: 7268 | D6: Retatrutide | E6: =Retatrutide!C4 -> Obesity & Type 2 Diabetes | F6: =Retatrutide!C5 -> GIP / GLP-1 / Glucagon Triple Receptor Agonist | G6: 1 | H6: TBD
A7: Debt | B7: =1635+40868 -> 42503 | D7: Foundayo | E7: =Foundayo!C4 -> Obesity / Chronic Weight Management | F7: =Foundayo!C5 -> GLP-1 Receptor Agonist (oral, nonpeptide) | G7: 1 | H7: 46113
A8: EV | B8: =B5+B7-B6 -> 1122320.1 | D8: Basaglar | E8: =Basaglar!C4 -> Type 1 and Type 2 Diabetes | F8: =Basaglar!C5 -> Long-Acting Insulin | G8: 1 | H8: =DATE(2015,12,16) -> 42354
D9: Humalog | E9: =Humalog!C4 -> Type 1 and Type 2 Diabetes | F9: =Humalog!C5 -> Rapid-Acting Insulin | G9: 1 | H9: 35230
D10: Humulin | E10: =Humulin!C4 -> Type 1 and Type 2 Diabetes | F10: =Humulin!C5 -> Insulin (short- and intermediate-acting) | G10: 1 | H10: =DATE(1982,10,28) -> 30252
D11: Jardiance | E11: =Jardiance!C4 -> Type 2 Diabetes & Heart Failure | F11: =Jardiance!C5 -> SGLT2 Inhibitors | G11: Royalty only | H11: 41852
D12: Verzenio | E12: =Verzenio!C4 -> Breast Cancer | F12: =Verzenio!C5 -> CDK4/6 inhibitors | G12: 1 | H12: 43006
D13: Cyramza | E13: =Cyramza!C4 -> Gastric, NSCLC, and Colorectal Cancer | F13: =Cyramza!C5 -> VEGFR2 Antagonist (Monoclonal Antibody) | G13: 1 | H13: =DATE(2014,4,21) -> 41750
D14: Erbitux | E14: =Erbitux!C4 -> Colorectal and Head & Neck Cancer | F14: =Erbitux!C5 -> EGFR Inhibitor (Monoclonal Antibody) | G14: Royalty / share | H14: =DATE(2004,2,12) -> 38029
D15: Retevmo | E15: =Retevmo!C4 -> RET-Altered NSCLC and Thyroid Cancer | F15: =Retevmo!C5 -> RET Kinase Inhibitor | G15: 1 | H15: =DATE(2020,5,8) -> 43959
D16: Tyvyt | E16: =Tyvyt!C4 -> Hodgkin Lymphoma, NSCLC & other cancers (approved in China; not FDA-approved) | F16: =Tyvyt!C5 -> PD-1 Inhibitor (Monoclonal Antibody) | G16: Royalty / share | H16: Not FDA approved
D17: Jaypirca | E17: =Jaypirca!C4 -> Non-Hodgkin Lymphoma | F17: =Jaypirca!C5 -> Bruton’s tyrosine kinase (BTK) inhibitor | G17: 1 | H17: 44953
D18: Inluriyo | E18: =Inluriyo!C4 -> Breast Cancer | F18: =Inluriyo!C5 -> Estrogen Antagonist | G18: 1 | H18: 45925
D19: Ebglyss | E19: =Ebglyss!C4 -> Eczema | F19: =Ebglyss!C5 -> interleukin-13 antagonist | G19: 1 | H19: 45548
D20: Olumiant | E20: =Olumiant!C4 -> Rheumatoid Arthritis, Alopecia Areata, COVID-19 | F20: =Olumiant!C5 -> JAK (Janus Kinase) Inhibitor | G20: 1 | H20: =DATE(2018,5,31) -> 43251
D21: Omvoh | E21: =Omvoh!C4 -> Crohn's Disease & Ulcerative Colitis | F21: =Omvoh!C5 -> interleukin-23 antagonist | G21: 1 | H21: 45225
D22: Taltz | E22: =Taltz!C4 -> Plaque Psoriasis & Psoriatic Arthritis | F22: =Taltz!C5 -> interleukin antagonist | G22: 1 | H22: 42451
D23: Emgality | E23: =Emgality!C4 -> Migraine Prevention and Cluster Headache | F23: =Emgality!C5 -> CGRP Antagonist (Monoclonal Antibody) | G23: 1 | H23: =DATE(2018,9,27) -> 43370
D24: Kisunla | E24: =Kisunla!C4 -> Alzheimer's Disease | F24: =Kisunla!C5 -> amyloid beta-directed antibody | G24: 1 | H24: 45475

Sheet Model
B2: Eli Lilly and Company (LLY)
B4: Historic Quarterly IS | C4: Q1'23 | D4: Q2'23 | E4: Q3'23 | F4: Q4'23 | G4: Q1'24 | H4: Q2'24 | I4: Q3'24 | J4: Q4'24 | K4: Q1'25 | L4: Q2'25 | M4: Q3'25 | N4: Q4'25 | O4: Q1'26 | P4: Q2'26
B5: Diabetes | C5: =SUM(C6:C14) -> 4045.3 | D5: =SUM(D6:D14) -> 4260.4 | E5: =SUM(E6:E14) -> 4565.4 | F5: =SUM(F6:F14) -> 5588.7 | G5: =SUM(G6:G14) -> 5369.2 | H5: =SUM(H6:H14) -> 7858.8 | I5: =SUM(I6:I14) -> 7261.6 | J5: =SUM(J6:J14) -> 8962.7 | ... P5: =SUM(P6:P14) -> 14969
B6: Mounjaro | C6: 568.5 | D6: 979.7 | E6: 1409.3 | F6: 2205.6 | G6: 1806.5 | H6: 3090.8 | I6: 3112.7 | J6: 3530 | K6: 3842 | L6: 5198.9 | M6: 6515.1 | N6: 7409 | O6: 8662 | P6: 9943
B7: Zepbound | F7: 175.8 | G7: 517.4 | H7: 1243.2 | I7: 1257.8 | J7: 1907 | K7: 2312 | L7: 3381.4 | M7: 3588 | N7: 4261 | O7: 4160 | P7: 4928
B8: Trulicity | C8: 1977.1 | D8: 1812.5 | E8: 1673.6 | F8: 1669.3 | G8: 1456.3 | H8: 1245.6 | I8: 1301.4 | J8: 1250.2 | K8: 1095 | L8: 1092.2 | M8: 1051.8 | N8: =4276-M8-L8-K8 -> 1037 | O8: 919
B9: Retatrutide
B10: Foundayo | P10: 98
B11: Basaglar | C11: 209.3 | D11: 154.2 | E11: 179.6 | F11: =728.3-E11-D11-C11 -> 185.2 | G11: 157.6 | H11: 180.8 | I11: 161.6 | J11: 176.9 | K11: 173.6 | L11: 145 | M11: 162.2 | N11: =+J11 -> 176.9 | O11: =+K11-10 -> 163.6
B12: Humalog | C12: 460.9 | D12: 440.4 | E12: 395.4 | F12: 366.6 | G12: 538.7 | H12: 631.6 | I12: 534.6 | J12: 619.9 | K12: 537.2 | L12: 503.1 | M12: 599.1 | N12: =+M12-5 -> 594.1 | O12: =+N12--15 -> 609.1
B13: Humulin | C13: 252 | D13: 205.3 | E13: 206.7 | F13: =852.1-E13-D13-C13 -> 188.1 | G13: 206.2 | H13: 223.6 | I13: 207.1 | J13: 280.3 | K13: 173.2 | L13: 175.2 | M13: 176.6 | N13: =+J13 -> 280.3 | O13: =+K13-10 -> 163.2
B14: Jardiance | C14: 577.5 | D14: 668.3 | E14: 700.8 | F14: 798.1 | G14: 686.5 | H14: 1243.2 | I14: 686.4 | J14: 1198.4 | K14: 1014 | L14: 690 | M14: 959 | N14: =3431-K14-L14-M14 -> 768 | O14: 1114
B15: Oncology | C15: =SUM(C16:C22) -> 1230 | D15: =SUM(D16:D22) -> 1518.6 | E15: =SUM(E16:E22) -> 1596.7 | F15: =SUM(F16:F22) -> 1736.2 | G15: =SUM(G16:G22) -> 1660.7 | H15: =SUM(H16:H22) -> 2043.2 | I15: =SUM(I16:I22) -> 2102.6 | J15: =SUM(J16:J22) -> 2328.2 | ... P15: =SUM(P16:P22) -> 267
B16: Verzenio | C16: 750.9 | D16: 926.8 | E16: 1040.2 | F16: 1145.4 | G16: 1050.3 | H16: 1331.9 | I16: 1369.3 | J16: 1555 | K16: 1158.9 | L16: 1489.3 | M16: 1470.2 | N16: 1604 | O16: 1302
B17: Cyramza | C17: 236.8 | D17: 260.3 | E17: 224.1 | F17: 253.6 | G17: 229.9 | H17: 248.9 | I17: 236 | J17: 258.6 | K17: 224.9 | L17: 253.7 | M17: 245.5 | N17: =+J17 -> 258.6 | O17: =+K17+34 -> 258.9
B18: Erbitux | C18: 129.9 | D18: 162.5 | E18: 153.9 | F18: =596.5-E18-D18-C18 -> 150.2 | G18: 144.6 | H18: 155.8 | I18: 152 | J18: 175 | K18: 149 | L18: 183.7 | M18: 198.6 | N18: =+J18 -> 175 | O18: =+K18+34 -> 183
B19: Retevmo | C19: 51.4 | D19: 65.4 | E19: 63.4 | F19: 73.4 | G19: 69.2 | H19: 91.2 | I19: 114 | J19: 90 | K19: 91 | L19: 125.3 | M19: 112 | N19: =+M19+5 -> 117 | O19: =+N19+34 -> 151
B20: Tyvyt | C20: 61 | D20: 103.6 | E20: 115.1 | F20: 113.6 | G20: 116.7 | H20: 123 | I20: 150.2 | J20: 136 | K20: 137.5 | L20: 137.3 | M20: 141.8 | N20: =+J20 -> 136 | O20: =+K20+34+2 -> 173.5
B21: Jaypirca | G21: 50 | H21: 92.4 | I21: 81.1 | J21: 113.6 | K21: 92 | L21: 123.3 | M21: 142.9 | N21: =+M21+10 -> 152.9 | O21: 165 | P21: 192
B22: Inluriyo | L22: =M22-10 -> 5 | M22: =N22-10 -> 15 | N22: =O22-10 -> 25 | O22: 35 | P22: 75
B23: Immunology | C23: =SUM(C24:C27) -> 755.9 | D23: =SUM(D24:D27) -> 922.8 | E23: =SUM(E24:E27) -> 975.6 | F23: =SUM(F24:F27) -> 1028.1 | G23: =SUM(G24:G27) -> 834 | H23: =SUM(H24:H27) -> 1082.3 | I23: =SUM(I24:I27) -> 1185.8 | J23: =SUM(J24:J27) -> 1290.9 | ... P23: =SUM(P24:P27) -> 303
B24: Ebglyss | G24: 3.1 | H24: 4.3 | I24: 14.9 | J24: 20.4 | K24: 60.2 | L24: 86.8 | M24: 127.1 | N24: =+M24+5 -> 132.1 | O24: 145 | P24: 201
B25: Olumiant | C25: 228.9 | D25: 218.9 | E25: 231.4 | F25: 243.5 | G25: 217.4 | H25: 227.7 | I25: 250.8 | J25: 261.6 | K25: 228.7 | L25: 246.4 | M25: 268.9 | N25: =+J25 -> 261.6 | O25: =+K25+16 -> 244.7
B26: Omvoh | G26: 9.4 | H26: 25.6 | I26: 40.5 | J26: 56.9 | K26: 37.2 | L26: 74.8 | M26: 64.9 | N26: =+M26+25 -> 89.9 | O26: 80 | P26: 102
B27: Taltz | C27: 527 | D27: 703.9 | E27: 744.2 | F27: 784.6 | G27: 604.1 | H27: 824.7 | I27: 879.6 | J27: 952 | K27: 762 | L27: 847.6 | M27: 901.5 | N27: =3563-K27-L27-M27 -> 1051.9 | O27: 733
B28: Neuroscience | C28: =SUM(C29:C30) -> 154.3 | D28: =SUM(D29:D30) -> 169.3 | E28: =SUM(E29:E30) -> 168.5 | F28: =SUM(F29:F30) -> 186.1 | G28: =SUM(G29:G30) -> 225.7 | H28: =SUM(H29:H30) -> 192 | I28: =SUM(I29:I30) -> 204.3 | J28: =SUM(J29:J30) -> 257.7 | ... P28: =SUM(P29:P30) -> 167
B29: Emgality | C29: 154.3 | D29: 169.3 | E29: 168.5 | F29: 186.1 | G29: 225.7 | H29: 192 | I29: 202.9 | J29: 249.8 | K29: 124.6 | L29: 201.1 | M29: 175.7 | N29: =+J29*1.1 -> 274.78 | O29: =+K29*1.1 -> 137.06
B30: Kisunla | I30: 1.4 | J30: 7.9 | K30: 21.5 | L30: 48.6 | M30: 70.4 | N30: =+M30+25 -> 95.4 | O30: 124 | P30: 167
B31: Other / Misc | C31: =C32-(C5+C15+C23+C28) -> 774.5 | D31: =D32-(D5+D15+D23+D28) -> 1441 | E31: =E32-(E5+E15+E23+E28) -> 2192.4 | F31: =F32-(F5+F15+F23+F28) -> 814.3 | G31: =G32-(G5+G15+G23+G28) -> 678.4 | H31: =H32-(H5+H15+H23+H28) -> 126.5 | I31: =I32-(I5+I15+I23+I28) -> 684.8 | J31: =J32-(J5+J15+J23+J28) -> 693.3 | ... O31: =O32-(O5+O15+O23+O28) -> 275.94
B32: Total Revenue | C32: 6960 | D32: 8312.1 | E32: 9498.6 | F32: 9353.4 | G32: 8768 | H32: 11302.8 | I32: 11439.1 | J32: 13532.8 | K32: 12729 | L32: 15557.7 | M32: 17600.8 | N32: 19292 | O32: 19799 | P32: 22974
B33: COGS | C33: 1626.7 | D33: 1807.4 | E33: 1860.1 | F33: 1788 | G33: 1673.5 | H33: 2170.2 | I33: 2170.8 | J33: 2403.8 | K33: 2225 | L33: 2447.8 | M33: 3008.3 | N33: 3371.7 | O33: 3577 | P33: 3268
B34: Gross Margin | C34: =C32-C33 -> 5333.3 | D34: =D32-D33 -> 6504.7 | E34: =E32-E33 -> 7638.5 | F34: =F32-F33 -> 7565.4 | G34: =G32-G33 -> 7094.5 | H34: =H32-H33 -> 9132.6 | I34: =I32-I33 -> 9268.3 | J34: =J32-J33 -> 11129 | ... P34: =P32-P33 -> 19706
B35: R&D | C35: 1985.1 | D35: 2356.5 | E35: 2409.1 | F35: 2562.7 | G35: 2522.8 | H35: 2711.2 | I35: 2734.1 | J35: 3022.5 | K35: 2734 | L35: 3336.1 | M35: 3465.7 | N35: 3801.5 | O35: 3510 | P35: 3819
B36: SG&A | C36: 1749.2 | D36: 1925.4 | E36: 1803.9 | F36: 1924.6 | G36: 1952.2 | H36: 2117.3 | I36: 2099.8 | J36: 2424.5 | K36: 2468 | L36: 2753 | M36: 2740.7 | N36: 3131.4 | O36: 2934 | P36: 3430
B37: IPR&D | C37: 105 | D37: 97.1 | E37: 2975.1 | F37: 622.6 | G37: 110.5 | H37: 154.3 | I37: 2826.4 | J37: 189.2 | K37: 1572 | L37: 153 | M37: 655.7 | N37: 528.8 | O37: 584 | P37: 2776
B38: Asset Impairement/Resturcturing | C38: 0 | D38: 0 | E38: 0 | F38: 67.7 | G38: 0 | H38: 435 | I38: 81.6 | J38: 344 | K38: 35 | L38: 0 | M38: 364.9 | N38: 84.1 | O38: 279 | P38: 703
B39: Other expenses | C39: -35.7 | D39: 36.8 | E39: 23.2 | F39: 121 | G39: -27.1 | H39: 197.6 | I39: -62 | J39: 110.2 | K39: 239 | L39: 90.6 | M39: 133.1 | N39: 108.3 | O39: 65 | P39: -269
B40: Pre Tax Income | C40: =C34-(SUM(C35:C39)) -> 1529.7 | D40: =D34-(SUM(D35:D39)) -> 2088.9 | E40: =E34-(SUM(E35:E39)) -> 427.2 | F40: =F34-(SUM(F35:F39)) -> 2266.8 | G40: =G34-(SUM(G35:G39)) -> 2536.1 | H40: =H34-(SUM(H35:H39)) -> 3517.2 | I40: =I34-(SUM(I35:I39)) -> 1588.4 | J40: =J34-(SUM(J35:J39)) -> 5038.6 | ... P40: =P34-(SUM(P35:P39)) -> 9247
B41: Taxes | C41: 184.8 | D41: 325.7 | E41: 484.6 | F41: 319.1 | G41: 293.2 | H41: 550.2 | I41: 618.1 | J41: 628.9 | K41: 697 | L41: 1115.9 | M41: 1649.9 | N41: 1628.5 | O41: 1454 | P41: 2152
B42: Net Income | C42: =C40-C41 -> 1344.9 | D42: =D40-D41 -> 1763.2 | E42: =E40-E41 -> -57.4 | F42: =F40-F41 -> 1947.7 | G42: =G40-G41 -> 2242.9 | H42: =H40-H41 -> 2967 | I42: =I40-I41 -> 970.3 | J42: =J40-J41 -> 4409.7 | ... P42: =P40-P41 -> 7095
...

Sheet Mounjaro
B2: Brand | C2: Mounjaro
B3: Generic | C3: TIRZEPATIDE
B4: Indication | C4: Type 2 Diabetes
B5: MOA | C5: Dual GIP/GLP-1 Receptor Agonist

Sheet Zepbound
B2: Brand | C2: Zepbound
B3: Generic | C3: Tirzepatide
B4: Indication | C4: Obesity & Obstructive Sleep Apnea
B5: MOA | C5: Dual GIP/GLP-1 Receptor Agonist

Sheet Trulicity
B2: Brand | C2: Trulicity
B3: Generic | C3: dulaglutide
B4: Indication | C4: Type-2 Diabetes
B5: MOA | C5: GLP-1 Agonist

Sheet Retatrutide
B2: Brand | C2: None
B3: Generic | C3: Retatrutide
B4: Indication | C4: Obesity & Type 2 Diabetes
B5: MOA | C5: GIP / GLP-1 / Glucagon Triple Receptor Agonist

Sheet Foundayo
B2: Brand | C2: Foundayo
B3: Generic | C3: Orforglipron
B4: Indication | C4: Obesity / Chronic Weight Management
B5: MOA | C5: GLP-1 Receptor Agonist (oral, nonpeptide)

Sheet Basaglar
B2: Brand | C2: Basaglar
B3: Generic | C3: Insulin Glargine
B4: Indication | C4: Type 1 and Type 2 Diabetes
B5: MOA | C5: Long-Acting Insulin

Sheet Humalog
B2: Brand | C2: Humalog
B3: Generic | C3: Insulin Lispro
B4: Indication | C4: Type 1 and Type 2 Diabetes
B5: MOA | C5: Rapid-Acting Insulin

Sheet Humulin
B2: Brand | C2: Humulin
B3: Generic | C3: Human Insulin
B4: Indication | C4: Type 1 and Type 2 Diabetes
B5: MOA | C5: Insulin (short- and intermediate-acting)

Sheet Jardiance
B2: Brand | C2: Jardiance
B3: Generic | C3: empagliflozin
B4: Indication | C4: Type 2 Diabetes & Heart Failure
B5: MOA | C5: SGLT2 Inhibitors

Sheet Verzenio
B2: Brand | C2: Verzenio
B3: Generic | C3: abemaciclib
B4: Indication | C4: Breast Cancer
B5: MOA | C5: CDK4/6 inhibitors

Sheet Cyramza
B2: Brand | C2: Cyramza
B3: Generic | C3: Ramucirumab
B4: Indication | C4: Gastric, NSCLC, and Colorectal Cancer
B5: MOA | C5: VEGFR2 Antagonist (Monoclonal Antibody)

Sheet Erbitux
B2: Brand | C2: Erbitux
B3: Generic | C3: Cetuximab
B4: Indication | C4: Colorectal and Head & Neck Cancer
B5: MOA | C5: EGFR Inhibitor (Monoclonal Antibody)

Sheet Retevmo
B2: Brand | C2: Retevmo
B3: Generic | C3: Selpercatinib
B4: Indication | C4: RET-Altered NSCLC and Thyroid Cancer
B5: MOA | C5: RET Kinase Inhibitor

Sheet Tyvyt
B2: Brand | C2: Tyvyt
B3: Generic | C3: Sintilimab
B4: Indication | C4: Hodgkin Lymphoma, NSCLC & other cancers (approved in China; not FDA-approved)
B5: MOA | C5: PD-1 Inhibitor (Monoclonal Antibody)

Sheet Jaypirca
B2: Brand | C2: Jaypirca
B3: Generic | C3: Pirtobrutinib
B4: Indication | C4: Non-Hodgkin Lymphoma
B5: MOA | C5: Bruton’s tyrosine kinase (BTK) inhibitor

Sheet Inluriyo
B2: Brand | C2: Inluriyo
B3: Generic | C3: Imlunestrant
B4: Indication | C4: Breast Cancer
B5: MOA | C5: Estrogen Antagonist

Sheet Ebglyss
B2: Brand | C2: Ebglyss
B3: Generic | C3: Lebrikizumab
B4: Indication | C4: Eczema
B5: MOA | C5: interleukin-13 antagonist

Sheet Olumiant
B2: Brand | C2: Olumiant
B3: Generic | C3: Baricitinib
B4: Indication | C4: Rheumatoid Arthritis, Alopecia Areata, COVID-19
B5: MOA | C5: JAK (Janus Kinase) Inhibitor

Sheet Omvoh
B2: Brand | C2: Omvoh
B3: Generic | C3: Mirikizumab-Mrkz
B4: Indication | C4: Crohn's Disease & Ulcerative Colitis
B5: MOA | C5: interleukin-23 antagonist

Sheet Taltz
B2: Brand | C2: Taltz
B3: Generic | C3: Ixekizumab
B4: Indication | C4: Plaque Psoriasis & Psoriatic Arthritis
B5: MOA | C5: interleukin antagonist

Sheet Emgality
B2: Brand | C2: Emgality
B3: Generic | C3: Galcanezumab
B4: Indication | C4: Migraine Prevention and Cluster Headache
B5: MOA | C5: CGRP Antagonist (Monoclonal Antibody)

Sheet Kisunla
B2: Brand | C2: Kisunla
B3: Generic | C3: donanemab-azbt
B4: Indication | C4: Alzheimer's Disease
B5: MOA | C5: amyloid beta-directed antibody
