Workbook

Sheet Main
A2: LLY | D2: Name | E2: Indication | F2: Mechanism | G2: Economics | H2: Approved
A3: Price | B3: 1213.4 | D3: Mounjaro | E3: =Mounjaro!C4 -> Type 2 Diabetes | F3: =Mounjaro!C5 -> Dual GIP/GLP-1 Receptor Agonist | G3: 1 | H3: 44694
A4: Shares | B4: 895.9 | D4: Zepbound | E4: =Zepbound!C4 -> Obesity & Obstructive Sleep Apnea | F4: =Zepbound!C5 -> Dual GIP/GLP-1 Receptor Agonist | G4: 1 | H4: 45238
A5: Market Cap | B5: =B3*B4 -> 1087085.1 | D5: Trulicity | E5: =Trulicity!C4 -> Type-2 Diabetes | F5: =Trulicity!C5 -> GLP-1 Agonist | G5: 1 | H5: 41900
A6: Cash | B6: 7268 | D6: Retatrutide | E6: =Retatrutide!C4 -> Obesity & Type 2 Diabetes | F6: =Retatrutide!C5 -> GIP / GLP-1 / Glucagon Triple Receptor Agonist | G6: 1 | H6: TBD
A7: Debt | B7: =1635+40868 -> 42503 | D7: Foundayo | E7: =Foundayo!C4 -> Obesity / Chronic Weight Management | F7: =Foundayo!C5 -> GLP-1 Receptor Agonist (oral, nonpeptide) | G7: 1 | H7: 46113
A8: EV | B8: =B5+B7-B6 -> 1122320.1 | D8: Basaglar | E8: =Basaglar!C4 -> Type 1 and Type 2 Diabetes | F8: =Basaglar!C5 -> Long-Acting Insulin | G8: 1 | H8: =DATE(2015,12,16) -> 42354
D9: Humalog | E9: =Humalog!C4 -> Type 1 and Type 2 Diabetes | F9: =Humalog!C5 -> Rapid-Acting Insulin | G9: 1 | H9: 35230
D10: Humulin | E10: =Humulin!C4 -> Type 1 and Type 2 Diabetes | F10: =Humulin!C5 -> Insulin (short- and intermediate-acting) | G10: 1 | H10: =DATE(1982,10,28) -> 30252
D11: Jardiance | E11: =Jardiance!C4 -> Type 2 Diabetes & Heart Failure | F11: =Jardiance!C5 -> SGLT2 Inhibitors | G11: Royalty only | H11: 41852
D12: Verzenio | E12: =Verzenio!C4 -> Breast Cancer | F12: =Verzenio!C5 -> CDK4/6 inhibitors | G12: 1 | H12: 43006
D13: Cyramza | E13: =Cyramza!C4 -> Gastric, NSCLC, and Colorectal Cancer | F13: =Cyramza!C5 -> VEGFR2 Antagonist (Monoclonal Antibody) | G13: 1 | H13: =DATE(2014,4,21) -> 41750
D14: Erbitux | E14: =Erbitux!C4 -> Colorectal and Head & Neck Cancer | F14: =Erbitux!C5 -> EGFR Inhibitor (Monoclonal Antibody) | G14: Royalty / share | H14: =DATE(2004,2,12) -> 38029
D15: Retevmo | E15: =Retevmo!C4 -> RET-Altered NSCLC and Thyroid Cancer | F15: =Retevmo!C5 -> RET Kinase Inhibitor | G15: 1 | H15: =DATE(2020,5,8) -> 43959
D16: Tyvyt | E16: =Tyvyt!C4 -> Hodgkin Lymphoma, NSCLC & other cancers (approved in China; not FDA-approved) | F16: =Tyvyt!C5 -> PD-1 Inhibitor (Monoclonal Antibody) | G16: Royalty / share | H16: Not FDA approved
D17: Jaypirca | E17: =Jaypirca!C4 -> Non-Hodgkin Lymphoma | F17: =Jaypirca!C5 -> Bruton’s tyrosine kinase (BTK) inhibitor | G17: 1 | H17: 44953
D18: Inluriyo | E18: =Inluriyo!C4 -> Breast Cancer | F18: =Inluriyo!C5 -> Estrogen Antagonist | G18: 1 | H18: 45925
D19: Ebglyss | E19: =Ebglyss!C4 -> Eczema | F19: =Ebglyss!C5 -> interleukin-13 antagonist | G19: 1 | H19: 45548
D20: Olumiant | E20: =Olumiant!C4 -> Rheumatoid Arthritis, Alopecia Areata, COVID-19 | F20: =Olumiant!C5 -> JAK (Janus Kinase) Inhibitor | G20: 1 | H20: =DATE(2018,5,31) -> 43251
D21: Omvoh | E21: =Omvoh!C4 -> Crohn's Disease & Ulcerative Colitis | F21: =Omvoh!C5 -> interleukin-23 antagonist | G21: 1 | H21: 45225
D22: Taltz | E22: =Taltz!C4 -> Plaque Psoriasis & Psoriatic Arthritis | F22: =Taltz!C5 -> interleukin antagonist | G22: 1 | H22: 42451
D23: Emgality | E23: =Emgality!C4 -> Migraine Prevention and Cluster Headache | F23: =Emgality!C5 -> CGRP Antagonist (Monoclonal Antibody) | G23: 1 | H23: =DATE(2018,9,27) -> 43370
D24: Kisunla | E24: =Kisunla!C4 -> Alzheimer's Disease | F24: =Kisunla!C5 -> amyloid beta-directed antibody | G24: 1 | H24: 45475

Sheet Model
B2: Eli Lilly and Company (LLY)
B3: Quarterly Income Statement
C4: Q1'23 | D4: Q2'23 | E4: Q3'23 | F4: Q4'23 | G4: Q1'24 | H4: Q2'24 | I4: Q3'24 | J4: Q4'24 | K4: Q1'25 | L4: Q2'25 | M4: Q3'25 | N4: Q4'25 | O4: Q1'26 | P4: Q2'26 | Q4: Q3'26 | R4: Q4'26 | S4: Q1'27 | T4: Q2'27 | U4: Q3'27 | V4: Q4'27 | W4: Q1'28 | X4: Q2'28 | Y4: Q3'28 | Z4: Q4'28 | AA4: Q1'29 | AB4: Q2'29 | AC4: Q3'29 | AD4: Q4'29 | AE4: Q1'30 | AF4: Q2'30 | AG4: Q3'30 | AH4: Q4'30 | AI4: Q1'31 | AJ4: Q2'31 | AK4: Q3'31 | AL4: Q4'31
B5: Diabetes | C5: =SUM(C6:C14) -> 4045.3 | D5: =SUM(D6:D14) -> 4260.4 | E5: =SUM(E6:E14) -> 4565.4 | F5: =SUM(F6:F14) -> 5588.7 | G5: =SUM(G6:G14) -> 5369.2 | H5: =SUM(H6:H14) -> 7858.8 | I5: =SUM(I6:I14) -> 7261.6 | J5: =SUM(J6:J14) -> 8962.7 | ... AL5: =SUM(AL6:AL14) -> 28580.713
B6: Mounjaro | C6: 568.5 | D6: 979.7 | E6: 1409.3 | F6: 2205.6 | G6: 1806.5 | H6: 3090.8 | I6: 3112.7 | J6: 3530 | K6: 3842 | L6: 5198.9 | M6: 6515.1 | N6: 7409 | O6: 8662 | P6: =O6*(1+0.06) -> 9181.72 | Q6: =P6*(1+0.06) -> 9732.6232 | R6: =Q6*(1+0.06) -> 10316.581 | S6: =R6*(1+0.04) -> 10729.244 | T6: =S6*(1+0.04) -> 11158.414 | U6: =T6*(1+0.04) -> 11604.75 | V6: =U6*(1+0.04) -> 12068.94 | W6: =V6*(1+0.03) -> 12431.008 | X6: =W6*(1+0.03) -> 12803.939 | Y6: =X6*(1+0.03) -> 13188.057 | Z6: =Y6*(1+0.03) -> 13583.698 | AA6: =Z6*(1+0.02) -> 13855.372 | AB6: =AA6*(1+0.02) -> 14132.48 | AC6: =AB6*(1+0.02) -> 14415.129 | AD6: =AC6*(1+0.02) -> 14703.432 | AE6: =AD6*(1+0.013) -> 14894.577 | AF6: =AE6*(1+0.013) -> 15088.206 | AG6: =AF6*(1+0.013) -> 15284.353 | AH6: =AG6*(1+0.013) -> 15483.049 | AI6: =AH6*(1+0.009) -> 15622.397 | AJ6: =AI6*(1+0.009) -> 15762.998 | AK6: =AJ6*(1+0.009) -> 15904.865 | AL6: =AK6*(1+0.009) -> 16048.009
B7: Zepbound | F7: 175.8 | G7: 517.4 | H7: 1243.2 | I7: 1257.8 | J7: 1907 | K7: 2312 | L7: 3381.4 | M7: 3588 | N7: 4261 | O7: 4160 | P7: =O7*(1+0.065) -> 4430.4 | Q7: =P7*(1+0.065) -> 4718.376 | R7: =Q7*(1+0.065) -> 5025.0704 | S7: =R7*(1+0.04) -> 5226.0733 | T7: =S7*(1+0.04) -> 5435.1162 | U7: =T7*(1+0.04) -> 5652.5208 | V7: =U7*(1+0.04) -> 5878.6217 | W7: =V7*(1+0.025) -> 6025.5872 | X7: =W7*(1+0.025) -> 6176.2269 | Y7: =X7*(1+0.025) -> 6330.6326 | Z7: =Y7*(1+0.025) -> 6488.8984 | AA7: =Z7*(1+0.016) -> 6592.7208 | AB7: =AA7*(1+0.016) -> 6698.2043 | AC7: =AB7*(1+0.016) -> 6805.3756 | AD7: =AC7*(1+0.016) -> 6914.2616 | AE7: =AD7*(1+0.009) -> 6976.4899 | AF7: =AE7*(1+0.009) -> 7039.2783 | AG7: =AF7*(1+0.009) -> 7102.6318 | AH7: =AG7*(1+0.009) -> 7166.5555 | AI7: =AH7*(1+0.005) -> 7202.3883 | AJ7: =AI7*(1+0.005) -> 7238.4002 | AK7: =AJ7*(1+0.005) -> 7274.5922 | AL7: =AK7*(1+0.005) -> 7310.9652
B8: Trulicity | C8: 1977.1 | D8: 1812.5 | E8: 1673.6 | F8: 1669.3 | G8: 1456.3 | H8: 1245.6 | I8: 1301.4 | J8: 1250.2 | K8: 1095 | L8: 1092.2 | M8: 1051.8 | N8: =4276-M8-L8-K8 -> 1037 | O8: 919 | P8: =O8*(1+-0.05) -> 873.05 | Q8: =P8*(1+-0.05) -> 829.3975 | R8: =Q8*(1+-0.05) -> 787.92762 | S8: =R8*(1+-0.12) -> 693.37631 | T8: =S8*(1+-0.12) -> 610.17115 | U8: =T8*(1+-0.12) -> 536.95061 | V8: =U8*(1+-0.12) -> 472.51654 | W8: =V8*(1+-0.12) -> 415.81456 | X8: =W8*(1+-0.12) -> 365.91681 | Y8: =X8*(1+-0.12) -> 322.00679 | Z8: =Y8*(1+-0.12) -> 283.36598 | AA8: =Z8*(1+-0.1) -> 255.02938 | AB8: =AA8*(1+-0.1) -> 229.52644 | AC8: =AB8*(1+-0.1) -> 206.5738 | AD8: =AC8*(1+-0.1) -> 185.91642 | AE8: =AD8*(1+-0.08) -> 171.0431 | AF8: =AE8*(1+-0.08) -> 157.35966 | AG8: =AF8*(1+-0.08) -> 144.77088 | AH8: =AG8*(1+-0.08) -> 133.18921 | AI8: =AH8*(1+-0.06) -> 125.19786 | AJ8: =AI8*(1+-0.06) -> 117.68599 | AK8: =AJ8*(1+-0.06) -> 110.62483 | AL8: =AK8*(1+-0.06) -> 103.98734
B9: Retatrutide | P9: 0 | Q9: 0 | R9: 0 | S9: 0 | T9: 0 | U9: 0 | V9: 0 | W9: 150 | X9: =W9*(1+0.35) -> 202.5 | Y9: =X9*(1+0.35) -> 273.375 | Z9: =Y9*(1+0.35) -> 369.05625 | AA9: =Z9*(1+0.22) -> 450.24863 | AB9: =AA9*(1+0.22) -> 549.30332 | AC9: =AB9*(1+0.22) -> 670.15005 | AD9: =AC9*(1+0.22) -> 817.58307 | AE9: =AD9*(1+0.12) -> 915.69303 | AF9: =AE9*(1+0.12) -> 1025.5762 | AG9: =AF9*(1+0.12) -> 1148.6453 | AH9: =AG9*(1+0.12) -> 1286.4828 | AI9: =AH9*(1+0.08) -> 1389.4014 | AJ9: =AI9*(1+0.08) -> 1500.5535 | AK9: =AJ9*(1+0.08) -> 1620.5978 | AL9: =AK9*(1+0.08) -> 1750.2456
B10: Foundayo | P10: 50 | Q10: 300 | R10: 550 | S10: =R10*(1+0.14) -> 627 | T10: =S10*(1+0.14) -> 714.78 | U10: =T10*(1+0.14) -> 814.8492 | V10: =U10*(1+0.14) -> 928.92809 | W10: =V10*(1+0.1) -> 1021.8209 | X10: =W10*(1+0.1) -> 1124.003 | Y10: =X10*(1+0.1) -> 1236.4033 | Z10: =Y10*(1+0.1) -> 1360.0436 | AA10: =Z10*(1+0.07) -> 1455.2467 | AB10: =AA10*(1+0.07) -> 1557.1139 | AC10: =AB10*(1+0.07) -> 1666.1119 | AD10: =AC10*(1+0.07) -> 1782.7397 | AE10: =AD10*(1+0.05) -> 1871.8767 | AF10: =AE10*(1+0.05) -> 1965.4706 | AG10: =AF10*(1+0.05) -> 2063.7441 | AH10: =AG10*(1+0.05) -> 2166.9313 | AI10: =AH10*(1+0.035) -> 2242.7739 | AJ10: =AI10*(1+0.035) -> 2321.271 | AK10: =AJ10*(1+0.035) -> 2402.5155 | AL10: =AK10*(1+0.035) -> 2486.6035
B11: Basaglar | C11: 209.3 | D11: 154.2 | E11: 179.6 | F11: =728.3-E11-D11-C11 -> 185.2 | G11: 157.6 | H11: 180.8 | I11: 161.6 | J11: 176.9 | K11: 173.6 | L11: 145 | M11: 162.2 | N11: =+J11 -> 176.9 | O11: =+K11-10 -> 163.6 | P11: =O11*(1+-0.01) -> 161.964 | Q11: =P11*(1+-0.01) -> 160.34436 | R11: =Q11*(1+-0.01) -> 158.74092 | S11: =R11*(1+-0.01) -> 157.15351 | T11: =S11*(1+-0.01) -> 155.58197 | U11: =T11*(1+-0.01) -> 154.02615 | V11: =U11*(1+-0.01) -> 152.48589 | W11: =V11*(1+-0.01) -> 150.96103 | ... AL11: =AK11*(1+-0.01) -> 129.8353
B12: Humalog | C12: 460.9 | D12: 440.4 | E12: 395.4 | F12: 366.6 | G12: 538.7 | H12: 631.6 | I12: 534.6 | J12: 619.9 | K12: 537.2 | L12: 503.1 | M12: 599.1 | N12: =+M12-5 -> 594.1 | O12: =+N12--15 -> 609.1 | P12: =O12*(1+-0.0075) -> 604.53175 | Q12: =P12*(1+-0.0075) -> 599.99776 | R12: =Q12*(1+-0.0075) -> 595.49778 | S12: =R12*(1+-0.0075) -> 591.03155 | T12: =S12*(1+-0.0075) -> 586.59881 | U12: =T12*(1+-0.0075) -> 582.19932 | V12: =U12*(1+-0.0075) -> 577.83282 | W12: =V12*(1+-0.0075) -> 573.49908 | ... AL12: =AK12*(1+-0.0075) -> 512.26001
B13: Humulin | C13: 252 | D13: 205.3 | E13: 206.7 | F13: =852.1-E13-D13-C13 -> 188.1 | G13: 206.2 | H13: 223.6 | I13: 207.1 | J13: 280.3 | K13: 173.2 | L13: 175.2 | M13: 176.6 | N13: =+J13 -> 280.3 | O13: =+K13-10 -> 163.2 | P13: =O13*(1+-0.013) -> 161.0784 | Q13: =P13*(1+-0.013) -> 158.98438 | R13: =Q13*(1+-0.013) -> 156.91758 | S13: =R13*(1+-0.013) -> 154.87766 | T13: =S13*(1+-0.013) -> 152.86425 | U13: =T13*(1+-0.013) -> 150.87701 | V13: =U13*(1+-0.013) -> 148.91561 | W13: =V13*(1+-0.013) -> 146.97971 | ... AL13: =AK13*(1+-0.013) -> 120.78546
B14: Jardiance | C14: 577.5 | D14: 668.3 | E14: 700.8 | F14: 798.1 | G14: 686.5 | H14: 1243.2 | I14: 686.4 | J14: 1198.4 | K14: 1014 | L14: 690 | M14: 959 | N14: =3431-K14-L14-M14 -> 768 | O14: 1114 | P14: 864 | Q14: =P14*(1+-0.02) -> 846.72 | R14: =Q14*(1+-0.02) -> 829.7856 | S14: =R14*(1+-0.03) -> 804.89203 | T14: =S14*(1+-0.03) -> 780.74527 | U14: =T14*(1+-0.03) -> 757.32291 | V14: =U14*(1+-0.03) -> 734.60323 | W14: =V14*(1+-0.08) -> 675.83497 | X14: =W14*(1+-0.08) -> 621.76817 | Y14: =X14*(1+-0.08) -> 572.02672 | Z14: =Y14*(1+-0.08) -> 526.26458 | AA14: =Z14*(1+-0.15) -> 447.32489 | AB14: =AA14*(1+-0.15) -> 380.22616 | AC14: =AB14*(1+-0.15) -> 323.19223 | AD14: =AC14*(1+-0.15) -> 274.7134 | AE14: =AD14*(1+-0.12) -> 241.74779 | AF14: =AE14*(1+-0.12) -> 212.73806 | AG14: =AF14*(1+-0.12) -> 187.20949 | AH14: =AG14*(1+-0.12) -> 164.74435 | AI14: =AH14*(1+-0.08) -> 151.5648 | AJ14: =AI14*(1+-0.08) -> 139.43962 | AK14: =AJ14*(1+-0.08) -> 128.28445 | AL14: =AK14*(1+-0.08) -> 118.02169
B15: Oncology | C15: =SUM(C16:C22) -> 1230 | D15: =SUM(D16:D22) -> 1518.6 | E15: =SUM(E16:E22) -> 1596.7 | F15: =SUM(F16:F22) -> 1736.2 | G15: =SUM(G16:G22) -> 1660.7 | H15: =SUM(H16:H22) -> 2043.2 | I15: =SUM(I16:I22) -> 2102.6 | J15: =SUM(J16:J22) -> 2328.2 | ... AL15: =SUM(AL16:AL22) -> 2247.361
B16: Verzenio | C16: 750.9 | D16: 926.8 | E16: 1040.2 | F16: 1145.4 | G16: 1050.3 | H16: 1331.9 | I16: 1369.3 | J16: 1555 | K16: 1158.9 | L16: 1489.3 | M16: 1470.2 | N16: 1604 | O16: 1302 | P16: =O16*(1+0.022) -> 1330.644 | Q16: =P16*(1+0.022) -> 1359.9182 | R16: =Q16*(1+0.022) -> 1389.8364 | S16: =R16*(1+0.015) -> 1410.6839 | T16: =S16*(1+0.015) -> 1431.8442 | U16: =T16*(1+0.015) -> 1453.3218 | V16: =U16*(1+0.015) -> 1475.1217 | W16: =V16*(1+0.005) -> 1482.4973 | X16: =W16*(1+0.005) -> 1489.9098 | Y16: =X16*(1+0.005) -> 1497.3593 | Z16: =Y16*(1+0.005) -> 1504.8461 | AA16: =Z16*(1+-0.0075) -> 1493.5598 | AB16: =AA16*(1+-0.0075) -> 1482.3581 | AC16: =AB16*(1+-0.0075) -> 1471.2404 | AD16: =AC16*(1+-0.0075) -> 1460.2061 | AE16: =AD16*(1+-0.04) -> 1401.7978 | AF16: =AE16*(1+-0.04) -> 1345.7259 | AG16: =AF16*(1+-0.04) -> 1291.8969 | AH16: =AG16*(1+-0.04) -> 1240.221 | AI16: =AH16*(1+-0.07) -> 1153.4055 | AJ16: =AI16*(1+-0.07) -> 1072.6671 | AK16: =AJ16*(1+-0.07) -> 997.58044 | AL16: =AK16*(1+-0.07) -> 927.74981
B17: Cyramza | C17: 236.8 | D17: 260.3 | E17: 224.1 | F17: 253.6 | G17: 229.9 | H17: 248.9 | I17: 236 | J17: 258.6 | K17: 224.9 | L17: 253.7 | M17: 245.5 | N17: =+J17 -> 258.6 | O17: =+K17+34 -> 258.9 | P17: =O17*(1+-0.005) -> 257.6055 | Q17: =P17*(1+-0.005) -> 256.31747 | R17: =Q17*(1+-0.005) -> 255.03589 | S17: =R17*(1+-0.005) -> 253.76071 | T17: =S17*(1+-0.005) -> 252.4919 | U17: =T17*(1+-0.005) -> 251.22944 | V17: =U17*(1+-0.005) -> 249.9733 | W17: =V17*(1+-0.005) -> 248.72343 | ... AL17: =AK17*(1+-0.005) -> 230.70813
B18: Erbitux | C18: 129.9 | D18: 162.5 | E18: 153.9 | F18: =596.5-E18-D18-C18 -> 150.2 | G18: 144.6 | H18: 155.8 | I18: 152 | J18: 175 | K18: 149 | L18: 183.7 | M18: 198.6 | N18: =+J18 -> 175 | O18: =+K18+34 -> 183 | P18: =O18*(1+-0.0075) -> 181.6275 | Q18: =P18*(1+-0.0075) -> 180.26529 | R18: =Q18*(1+-0.0075) -> 178.9133 | S18: =R18*(1+-0.0075) -> 177.57145 | T18: =S18*(1+-0.0075) -> 176.23967 | U18: =T18*(1+-0.0075) -> 174.91787 | V18: =U18*(1+-0.0075) -> 173.60599 | W18: =V18*(1+-0.0075) -> 172.30394 | ... AL18: =AK18*(1+-0.0075) -> 153.90508
B19: Retevmo | C19: 51.4 | D19: 65.4 | E19: 63.4 | F19: 73.4 | G19: 69.2 | H19: 91.2 | I19: 114 | J19: 90 | K19: 91 | L19: 125.3 | M19: 112 | N19: =+M19+5 -> 117 | O19: =+N19+34 -> 151 | P19: =O19*(1+0.02) -> 154.02 | Q19: =P19*(1+0.02) -> 157.1004 | R19: =Q19*(1+0.02) -> 160.24241 | S19: =R19*(1+0.015) -> 162.64604 | T19: =S19*(1+0.015) -> 165.08573 | U19: =T19*(1+0.015) -> 167.56202 | V19: =U19*(1+0.015) -> 170.07545 | W19: =V19*(1+0.01) -> 171.77621 | X19: =W19*(1+0.01) -> 173.49397 | Y19: =X19*(1+0.01) -> 175.22891 | Z19: =Y19*(1+0.01) -> 176.9812 | AA19: =Z19*(1+0.005) -> 177.8661 | AB19: =AA19*(1+0.005) -> 178.75543 | AC19: =AB19*(1+0.005) -> 179.64921 | AD19: =AC19*(1+0.005) -> 180.54746 | AE19: =AD19*(1+0) -> 180.54746 | AF19: =AE19*(1+0) -> 180.54746 | AG19: =AF19*(1+0) -> 180.54746 | AH19: =AG19*(1+0) -> 180.54746 | AI19: =AH19*(1+0) -> 180.54746 | AJ19: =AI19*(1+0) -> 180.54746 | AK19: =AJ19*(1+0) -> 180.54746 | AL19: =AK19*(1+0) -> 180.54746
B20: Tyvyt | C20: 61 | D20: 103.6 | E20: 115.1 | F20: 113.6 | G20: 116.7 | H20: 123 | I20: 150.2 | J20: 136 | K20: 137.5 | L20: 137.3 | M20: 141.8 | N20: =+J20 -> 136 | O20: =+K20+34+2 -> 173.5 | P20: =O20*(1+0.024) -> 177.664 | Q20: =P20*(1+0.024) -> 181.92794 | R20: =Q20*(1+0.024) -> 186.29421 | S20: =R20*(1+0.02) -> 190.02009 | T20: =S20*(1+0.02) -> 193.82049 | U20: =T20*(1+0.02) -> 197.6969 | V20: =U20*(1+0.02) -> 201.65084 | W20: =V20*(1+0.015) -> 204.6756 | X20: =W20*(1+0.015) -> 207.74574 | Y20: =X20*(1+0.015) -> 210.86192 | Z20: =Y20*(1+0.015) -> 214.02485 | AA20: =Z20*(1+0.01) -> 216.1651 | AB20: =AA20*(1+0.01) -> 218.32675 | AC20: =AB20*(1+0.01) -> 220.51002 | AD20: =AC20*(1+0.01) -> 222.71512 | AE20: =AD20*(1+0.005) -> 223.82869 | AF20: =AE20*(1+0.005) -> 224.94784 | AG20: =AF20*(1+0.005) -> 226.07258 | AH20: =AG20*(1+0.005) -> 227.20294 | AI20: =AH20*(1+0) -> 227.20294 | AJ20: =AI20*(1+0) -> 227.20294 | AK20: =AJ20*(1+0) -> 227.20294 | AL20: =AK20*(1+0) -> 227.20294
B21: Jaypirca | G21: 50 | H21: 92.4 | I21: 81.1 | J21: 113.6 | K21: 92 | L21: 123.3 | M21: 142.9 | N21: =+M21+10 -> 152.9 | O21: 165 | P21: =O21*(1+0.068) -> 176.22 | Q21: =P21*(1+0.068) -> 188.20296 | R21: =Q21*(1+0.068) -> 201.00076 | S21: =R21*(1+0.063) -> 213.66381 | T21: =S21*(1+0.063) -> 227.12463 | U21: =T21*(1+0.063) -> 241.43348 | V21: =U21*(1+0.063) -> 256.64379 | W21: =V21*(1+0.051) -> 269.73262 | X21: =W21*(1+0.051) -> 283.48899 | Y21: =X21*(1+0.051) -> 297.94693 | Z21: =Y21*(1+0.051) -> 313.14222 | AA21: =Z21*(1+0.036) -> 324.41534 | AB21: =AA21*(1+0.036) -> 336.09429 | AC21: =AB21*(1+0.036) -> 348.19369 | AD21: =AC21*(1+0.036) -> 360.72866 | AE21: =AD21*(1+0.024) -> 369.38615 | AF21: =AE21*(1+0.024) -> 378.25141 | AG21: =AF21*(1+0.024) -> 387.32945 | AH21: =AG21*(1+0.024) -> 396.62535 | AI21: =AH21*(1+0.017) -> 403.36798 | AJ21: =AI21*(1+0.017) -> 410.22524 | AK21: =AJ21*(1+0.017) -> 417.19907 | AL21: =AK21*(1+0.017) -> 424.29145
B22: Inluriyo | L22: =M22-10 -> 5 | M22: =N22-10 -> 15 | N22: =O22-10 -> 25 | O22: 35 | P22: =O22*(1+0.088) -> 38.08 | Q22: =P22*(1+0.088) -> 41.43104 | R22: =Q22*(1+0.088) -> 45.076972 | S22: =R22*(1+0.078) -> 48.592975 | T22: =S22*(1+0.078) -> 52.383227 | U22: =T22*(1+0.078) -> 56.469119 | V22: =U22*(1+0.078) -> 60.87371 | W22: =V22*(1+0.057) -> 64.343512 | X22: =W22*(1+0.057) -> 68.011092 | Y22: =X22*(1+0.057) -> 71.887724 | Z22: =Y22*(1+0.057) -> 75.985325 | AA22: =Z22*(1+0.036) -> 78.720796 | AB22: =AA22*(1+0.036) -> 81.554745 | AC22: =AB22*(1+0.036) -> 84.490716 | AD22: =AC22*(1+0.036) -> 87.532382 | AE22: =AD22*(1+0.024) -> 89.633159 | AF22: =AE22*(1+0.024) -> 91.784355 | AG22: =AF22*(1+0.024) -> 93.987179 | AH22: =AG22*(1+0.024) -> 96.242871 | AI22: =AH22*(1+0.017) -> 97.879 | AJ22: =AI22*(1+0.017) -> 99.542943 | AK22: =AJ22*(1+0.017) -> 101.23517 | AL22: =AK22*(1+0.017) -> 102.95617
B23: Immunology | C23: =SUM(C24:C27) -> 755.9 | D23: =SUM(D24:D27) -> 922.8 | E23: =SUM(E24:E27) -> 975.6 | F23: =SUM(F24:F27) -> 1028.1 | G23: =SUM(G24:G27) -> 834 | H23: =SUM(H24:H27) -> 1082.3 | I23: =SUM(I24:I27) -> 1185.8 | J23: =SUM(J24:J27) -> 1290.9 | ... AL23: =SUM(AL24:AL27) -> 1373.375
B24: Ebglyss | G24: 3.1 | H24: 4.3 | I24: 14.9 | J24: 20.4 | K24: 60.2 | L24: 86.8 | M24: 127.1 | N24: =+M24+5 -> 132.1 | O24: 145 | P24: =O24*(1+0.078) -> 156.31 | Q24: =P24*(1+0.078) -> 168.50218 | R24: =Q24*(1+0.078) -> 181.64535 | S24: =R24*(1+0.068) -> 193.99723 | T24: =S24*(1+0.068) -> 207.18905 | U24: =T24*(1+0.068) -> 221.2779 | V24: =U24*(1+0.068) -> 236.3248 | W24: =V24*(1+0.051) -> 248.37736 | X24: =W24*(1+0.051) -> 261.04461 | Y24: =X24*(1+0.051) -> 274.35788 | Z24: =Y24*(1+0.051) -> 288.35014 | AA24: =Z24*(1+0.036) -> 298.73074 | AB24: =AA24*(1+0.036) -> 309.48505 | AC24: =AB24*(1+0.036) -> 320.62651 | AD24: =AC24*(1+0.036) -> 332.16906 | AE24: =AD24*(1+0.024) -> 340.14112 | AF24: =AE24*(1+0.024) -> 348.30451 | AG24: =AF24*(1+0.024) -> 356.66382 | AH24: =AG24*(1+0.024) -> 365.22375 | AI24: =AH24*(1+0.017) -> 371.43255 | AJ24: =AI24*(1+0.017) -> 377.7469 | AK24: =AJ24*(1+0.017) -> 384.1686 | AL24: =AK24*(1+0.017) -> 390.69947
B25: Olumiant | C25: 228.9 | D25: 218.9 | E25: 231.4 | F25: 243.5 | G25: 217.4 | H25: 227.7 | I25: 250.8 | J25: 261.6 | K25: 228.7 | L25: 246.4 | M25: 268.9 | N25: =+J25 -> 261.6 | O25: =+K25+16 -> 244.7 | P25: =O25*(1+-0.005) -> 243.4765 | Q25: =P25*(1+-0.005) -> 242.25912 | R25: =Q25*(1+-0.005) -> 241.04782 | S25: =R25*(1+-0.005) -> 239.84258 | T25: =S25*(1+-0.005) -> 238.64337 | U25: =T25*(1+-0.005) -> 237.45015 | V25: =U25*(1+-0.005) -> 236.2629 | W25: =V25*(1+-0.005) -> 235.08159 | ... AL25: =AK25*(1+-0.005) -> 218.05439
B26: Omvoh | G26: 9.4 | H26: 25.6 | I26: 40.5 | J26: 56.9 | K26: 37.2 | L26: 74.8 | M26: 64.9 | N26: =+M26+25 -> 89.9 | O26: 80 | P26: =O26*(1+0.068) -> 85.44 | Q26: =P26*(1+0.068) -> 91.24992 | R26: =Q26*(1+0.068) -> 97.454915 | S26: =R26*(1+0.063) -> 103.59457 | T26: =S26*(1+0.063) -> 110.12103 | U26: =T26*(1+0.063) -> 117.05866 | V26: =U26*(1+0.063) -> 124.43335 | W26: =V26*(1+0.051) -> 130.77945 | X26: =W26*(1+0.051) -> 137.44921 | Y26: =X26*(1+0.051) -> 144.45912 | Z26: =Y26*(1+0.051) -> 151.82653 | AA26: =Z26*(1+0.036) -> 157.29229 | AB26: =AA26*(1+0.036) -> 162.95481 | AC26: =AB26*(1+0.036) -> 168.82118 | AD26: =AC26*(1+0.036) -> 174.89874 | AE26: =AD26*(1+0.024) -> 179.09631 | AF26: =AE26*(1+0.024) -> 183.39462 | AG26: =AF26*(1+0.024) -> 187.7961 | AH26: =AG26*(1+0.024) -> 192.3032 | AI26: =AH26*(1+0.017) -> 195.57236 | AJ26: =AI26*(1+0.017) -> 198.89709 | AK26: =AJ26*(1+0.017) -> 202.27834 | AL26: =AK26*(1+0.017) -> 205.71707
B27: Taltz | C27: 527 | D27: 703.9 | E27: 744.2 | F27: 784.6 | G27: 604.1 | H27: 824.7 | I27: 879.6 | J27: 952 | K27: 762 | L27: 847.6 | M27: 901.5 | N27: =3563-K27-L27-M27 -> 1051.9 | O27: 733 | P27: =O27*(1+0.015) -> 743.995 | Q27: =P27*(1+0.015) -> 755.15492 | R27: =Q27*(1+0.015) -> 766.48225 | S27: =R27*(1+0.0075) -> 772.23087 | T27: =S27*(1+0.0075) -> 778.0226 | U27: =T27*(1+0.0075) -> 783.85777 | V27: =U27*(1+0.0075) -> 789.7367 | W27: =V27*(1+0) -> 789.7367 | X27: =W27*(1+0) -> 789.7367 | Y27: =X27*(1+0) -> 789.7367 | Z27: =Y27*(1+0) -> 789.7367 | AA27: =Z27*(1+-0.013) -> 779.47012 | AB27: =AA27*(1+-0.013) -> 769.33701 | AC27: =AB27*(1+-0.013) -> 759.33563 | AD27: =AC27*(1+-0.013) -> 749.46427 | AE27: =AD27*(1+-0.032) -> 725.48141 | AF27: =AE27*(1+-0.032) -> 702.26601 | AG27: =AF27*(1+-0.032) -> 679.79349 | AH27: =AG27*(1+-0.032) -> 658.0401 | AI27: =AH27*(1+-0.04) -> 631.7185 | AJ27: =AI27*(1+-0.04) -> 606.44976 | AK27: =AJ27*(1+-0.04) -> 582.19177 | AL27: =AK27*(1+-0.04) -> 558.9041
B28: Neuroscience | C28: =SUM(C29:C30) -> 154.3 | D28: =SUM(D29:D30) -> 169.3 | E28: =SUM(E29:E30) -> 168.5 | F28: =SUM(F29:F30) -> 186.1 | G28: =SUM(G29:G30) -> 225.7 | H28: =SUM(H29:H30) -> 192 | I28: =SUM(I29:I30) -> 204.3 | J28: =SUM(J29:J30) -> 257.7 | ... AL28: =SUM(AL29:AL30) -> 555.63343
B29: Emgality | C29: 154.3 | D29: 169.3 | E29: 168.5 | F29: 186.1 | G29: 225.7 | H29: 192 | I29: 202.9 | J29: 249.8 | K29: 124.6 | L29: 201.1 | M29: 175.7 | N29: =+J29*1.1 -> 274.78 | O29: =+K29*1.1 -> 137.06 | P29: =O29*(1+-0.005) -> 136.3747 | Q29: =P29*(1+-0.005) -> 135.69283 | R29: =Q29*(1+-0.005) -> 135.01436 | S29: =R29*(1+-0.005) -> 134.33929 | T29: =S29*(1+-0.005) -> 133.66759 | U29: =T29*(1+-0.005) -> 132.99926 | V29: =U29*(1+-0.005) -> 132.33426 | W29: =V29*(1+-0.005) -> 131.67259 | ... AL29: =AK29*(1+-0.005) -> 122.13541
B30: Kisunla | I30: 1.4 | J30: 7.9 | K30: 21.5 | L30: 48.6 | M30: 70.4 | N30: =+M30+25 -> 95.4 | O30: 124 | P30: =O30*(1+0.097) -> 136.028 | Q30: =P30*(1+0.097) -> 149.22272 | R30: =Q30*(1+0.097) -> 163.69732 | S30: =R30*(1+0.088) -> 178.10268 | T30: =S30*(1+0.088) -> 193.77572 | U30: =T30*(1+0.088) -> 210.82798 | V30: =U30*(1+0.088) -> 229.38085 | W30: =V30*(1+0.068) -> 244.97874 | X30: =W30*(1+0.068) -> 261.6373 | Y30: =X30*(1+0.068) -> 279.42863 | Z30: =Y30*(1+0.068) -> 298.42978 | AA30: =Z30*(1+0.047) -> 312.45598 | AB30: =AA30*(1+0.047) -> 327.14141 | AC30: =AB30*(1+0.047) -> 342.51706 | AD30: =AC30*(1+0.047) -> 358.61536 | AE30: =AD30*(1+0.029) -> 369.01521 | AF30: =AE30*(1+0.029) -> 379.71665 | AG30: =AF30*(1+0.029) -> 390.72843 | AH30: =AG30*(1+0.029) -> 402.05955 | AI30: =AH30*(1+0.019) -> 409.69868 | AJ30: =AI30*(1+0.019) -> 417.48296 | AK30: =AJ30*(1+0.019) -> 425.41514 | AL30: =AK30*(1+0.019) -> 433.49802
B31: Other / Misc | C31: =C35-(C5+C15+C23+C28) -> 774.5 | D31: =D35-(D5+D15+D23+D28) -> 1441 | E31: =E35-(E5+E15+E23+E28) -> 2192.4 | F31: =F35-(F5+F15+F23+F28) -> 814.3 | G31: =G35-(G5+G15+G23+G28) -> 678.4 | H31: =H35-(H5+H15+H23+H28) -> 126.5 | I31: =I35-(I5+I15+I23+I28) -> 684.8 | J31: =J35-(J5+J15+J23+J28) -> 693.3 | ... O31: =O35-(O5+O15+O23+O28) -> 275.94 | P31: =O31*(1+0.0075) -> 278.00955 | Q31: =P31*(1+0.0075) -> 280.09462 | R31: =Q31*(1+0.0075) -> 282.19533 | S31: =R31*(1+0.0075) -> 284.3118 | T31: =S31*(1+0.0075) -> 286.44413 | U31: =T31*(1+0.0075) -> 288.59247 | V31: =U31*(1+0.0075) -> 290.75691 | W31: =V31*(1+0.0075) -> 292.93759 | ... AL31: =AK31*(1+0.0075) -> 327.68074
B35: Total Revenue | C35: 6960 | D35: 8312.1 | E35: 9498.6 | F35: 9353.4 | G35: 8768 | H35: 11302.8 | I35: 11439.1 | J35: 13532.8 | K35: 12729 | L35: 15557.7 | M35: 17600.8 | N35: 19292 | O35: 19799 | P35: =L35*(1+P49) -> 21812.846 | Q35: =M35*(1+Q49) -> 24641.12 | R35: =N35*(1+R49) -> 27008.8 | S35: =O35*(1+S49) -> 27718.6 | T35: =P35*(1+T49) -> 29447.342 | U35: =Q35*(1+U49) -> 33265.512 | V35: =R35*(1+V49) -> 36461.88 | W35: =S35*(1+W49) -> 36034.18 | ... AL35: =AH35*(1+AL49) -> 78757.661
B36: COGS | C36: 1626.7 | D36: 1807.4 | E36: 1860.1 | F36: 1788 | G36: 1673.5 | H36: 2170.2 | I36: 2170.8 | J36: 2403.8 | K36: 2225 | L36: 2447.8 | M36: 3008.3 | N36: 3371.7 | O36: 3577 | P36: =P37*(1-P50) -> 3332.9086 | Q36: =Q37*(1-Q50) -> 3765.0567 | R36: =R37*(1-R50) -> 4126.828 | S36: =S37*(1-S50) -> 4235.2824 | T36: =T37*(1-T50) -> 4499.4266 | U36: =U37*(1-U50) -> 5082.8266 | V36: =V37*(1-V50) -> 5571.2178 | W36: =W37*(1-W50) -> 5505.8671 | ... AL36: =AL37*(1-AL50) -> 12033.83
B37: Gross Margin | C37: =C35-C36 -> 5333.3 | D37: =D35-D36 -> 6504.7 | E37: =E35-E36 -> 7638.5 | F37: =F35-F36 -> 7565.4 | G37: =G35-G36 -> 7094.5 | H37: =H35-H36 -> 9132.6 | I37: =I35-I36 -> 9268.3 | J37: =J35-J36 -> 11129 | ... O37: =O35-O36 -> 16222 | P37: =P35*P50 -> 17707.146 | Q37: =Q35*Q50 -> 20003.072 | R37: =R35*R50 -> 21925.098 | S37: =S35*S50 -> 22501.296 | T37: =T35*T50 -> 23904.648 | U37: =U35*U50 -> 27004.147 | V37: =V35*V50 -> 29598.882 | W37: =W35*W50 -> 29251.685 | ... AL37: =AL35*AL50 -> 63933.585
B38: R&D | C38: 1985.1 | D38: 2356.5 | E38: 2409.1 | F38: 2562.7 | G38: 2522.8 | H38: 2711.2 | I38: 2734.1 | J38: 3022.5 | K38: 2734 | L38: 3336.1 | M38: 3465.7 | N38: 3801.5 | O38: 3510 | P38: =P$37*P51 -> 3831.3453 | Q38: =Q$37*Q51 -> 4328.1212 | R38: =R$37*R51 -> 4743.9953 | S38: =S$37*S51 -> 4868.6691 | T38: =T$37*T51 -> 5172.3162 | U38: =U$37*U51 -> 5842.9636 | V38: =V$37*V51 -> 6404.3937 | W38: =W$37*W51 -> 6329.2698 | ... AL38: =AL$37*AL51 -> 13833.49
B39: SG&A | C39: 1749.2 | D39: 1925.4 | E39: 1803.9 | F39: 1924.6 | G39: 1952.2 | H39: 2117.3 | I39: 2099.8 | J39: 2424.5 | K39: 2468 | L39: 2753 | M39: 2740.7 | N39: 3131.4 | O39: 2934 | P39: =P$37*P52 -> 3202.6117 | Q39: =Q$37*Q52 -> 3600.5529 | R39: =R$37*R52 -> 3946.5176 | S39: =S$37*S52 -> 4050.2333 | T39: =T$37*T52 -> 4302.8366 | U39: =U$37*U52 -> 4860.7464 | V39: =V$37*V52 -> 5327.7987 | W39: =W$37*W52 -> 5265.3033 | ... AL39: =AL$37*AL52 -> 11508.045
B40: IPR&D | C40: 105 | D40: 97.1 | E40: 2975.1 | F40: 622.6 | G40: 110.5 | H40: 154.3 | I40: 2826.4 | J40: 189.2 | K40: 1572 | L40: 153 | M40: 655.7 | N40: 528.8 | O40: 584 | P40: =P$37*P53 -> 637.466 | Q40: =Q$37*Q53 -> 800.12286 | R40: =R$37*R53 -> 877.0039 | S40: =S$37*S53 -> 900.05185 | T40: =T$37*T53 -> 956.1859 | U40: =U$37*U53 -> 1080.1659 | V40: =V$37*V53 -> 1183.9553 | W40: =W$37*W53 -> 1170.0674 | ... AL40: =AL$37*AL53 -> 2557.3434
B41: Asset Impairement/Resturcturing | C41: 0 | D41: 0 | E41: 0 | F41: 67.7 | G41: 0 | H41: 435 | I41: 81.6 | J41: 344 | K41: 35 | L41: 0 | M41: 364.9 | N41: 84.1 | O41: 279 | P41: =AVERAGE(C41:O41) -> 130.1 | Q41: 130 | R41: 130 | S41: 130 | T41: 130 | U41: 130 | V41: 130 | W41: 130 | X41: 130 | Y41: 130 | Z41: 130 | AA41: 130 | AB41: 130 | AC41: 130 | AD41: 130 | AE41: 130 | AF41: 130 | AG41: 130 | AH41: 130 | AI41: 130 | AJ41: 130 | AK41: 130 | AL41: 130
B42: Other expenses | C42: -35.7 | D42: 36.8 | E42: 23.2 | F42: 121 | G42: -27.1 | H42: 197.6 | I42: -62 | J42: 110.2 | K42: 239 | L42: 90.6 | M42: 133.1 | N42: 108.3 | O42: 65 | P42: =AVERAGE(C42:O42) -> 76.923077 | Q42: 77 | R42: 77 | S42: 77 | T42: 77 | U42: 77 | V42: 77 | W42: 77 | X42: 77 | Y42: 77 | Z42: 77 | AA42: 77 | AB42: 77 | AC42: 77 | AD42: 77 | AE42: 77 | AF42: 77 | AG42: 77 | AH42: 77 | AI42: 77 | AJ42: 77 | AK42: 77 | AL42: 77
B43: Pre Tax Income | C43: =C37-(SUM(C38:C42)) -> 1529.7 | D43: =D37-(SUM(D38:D42)) -> 2088.9 | E43: =E37-(SUM(E38:E42)) -> 427.2 | F43: =F37-(SUM(F38:F42)) -> 2266.8 | G43: =G37-(SUM(G38:G42)) -> 2536.1 | H43: =H37-(SUM(H38:H42)) -> 3517.2 | I43: =I37-(SUM(I38:I42)) -> 1588.4 | J43: =J37-(SUM(J38:J42)) -> 5038.6 | ... AL43: =AL37-(SUM(AL38:AL42)) -> 35827.706
B44: Taxes | C44: 184.8 | D44: 325.7 | E44: 484.6 | F44: 319.1 | G44: 293.2 | H44: 550.2 | I44: 618.1 | J44: 628.9 | K44: 697 | L44: 1115.9 | M44: 1649.9 | N44: 1628.5 | O44: 1454 | P44: =P54*P43 -> 2490.1497 | Q44: =Q54*Q43 -> 2766.8187 | R44: =R54*R43 -> 3037.6452 | S44: =S54*S43 -> 3118.8355 | T44: =T54*T43 -> 3316.5772 | U44: =U54*U43 -> 3753.3177 | V44: =V54*V43 -> 4118.9335 | W44: =W54*W43 -> 4070.0111 | ... AL44: =AL54*AL43 -> 8956.9264
...

Sheet Mounjaro
B2: Brand | C2: Mounjaro
B3: Generic | C3: TIRZEPATIDE
B4: Indication | C4: Type 2 Diabetes
B5: MOA | C5: Dual GIP/GLP-1 Receptor Agonist

Sheet Zepbound
B2: Brand | C2: Zepbound
B3: Generic | C3: Tirzepatide
B4: Indication | C4: Obesity & Obstructive Sleep Apnea
B5: MOA | C5: Dual GIP/GLP-1 Receptor Agonist

Sheet Trulicity
B2: Brand | C2: Trulicity
B3: Generic | C3: dulaglutide
B4: Indication | C4: Type-2 Diabetes
B5: MOA | C5: GLP-1 Agonist

Sheet Retatrutide
B2: Brand | C2: None
B3: Generic | C3: Retatrutide
B4: Indication | C4: Obesity & Type 2 Diabetes
B5: MOA | C5: GIP / GLP-1 / Glucagon Triple Receptor Agonist

Sheet Foundayo
B2: Brand | C2: Foundayo
B3: Generic | C3: Orforglipron
B4: Indication | C4: Obesity / Chronic Weight Management
B5: MOA | C5: GLP-1 Receptor Agonist (oral, nonpeptide)

Sheet Basaglar
B2: Brand | C2: Basaglar
B3: Generic | C3: Insulin Glargine
B4: Indication | C4: Type 1 and Type 2 Diabetes
B5: MOA | C5: Long-Acting Insulin

Sheet Humalog
B2: Brand | C2: Humalog
B3: Generic | C3: Insulin Lispro
B4: Indication | C4: Type 1 and Type 2 Diabetes
B5: MOA | C5: Rapid-Acting Insulin

Sheet Humulin
B2: Brand | C2: Humulin
B3: Generic | C3: Human Insulin
B4: Indication | C4: Type 1 and Type 2 Diabetes
B5: MOA | C5: Insulin (short- and intermediate-acting)

Sheet Jardiance
B2: Brand | C2: Jardiance
B3: Generic | C3: empagliflozin
B4: Indication | C4: Type 2 Diabetes & Heart Failure
B5: MOA | C5: SGLT2 Inhibitors

Sheet Verzenio
B2: Brand | C2: Verzenio
B3: Generic | C3: abemaciclib
B4: Indication | C4: Breast Cancer
B5: MOA | C5: CDK4/6 inhibitors

Sheet Cyramza
B2: Brand | C2: Cyramza
B3: Generic | C3: Ramucirumab
B4: Indication | C4: Gastric, NSCLC, and Colorectal Cancer
B5: MOA | C5: VEGFR2 Antagonist (Monoclonal Antibody)

Sheet Erbitux
B2: Brand | C2: Erbitux
B3: Generic | C3: Cetuximab
B4: Indication | C4: Colorectal and Head & Neck Cancer
B5: MOA | C5: EGFR Inhibitor (Monoclonal Antibody)

Sheet Retevmo
B2: Brand | C2: Retevmo
B3: Generic | C3: Selpercatinib
B4: Indication | C4: RET-Altered NSCLC and Thyroid Cancer
B5: MOA | C5: RET Kinase Inhibitor

Sheet Tyvyt
B2: Brand | C2: Tyvyt
B3: Generic | C3: Sintilimab
B4: Indication | C4: Hodgkin Lymphoma, NSCLC & other cancers (approved in China; not FDA-approved)
B5: MOA | C5: PD-1 Inhibitor (Monoclonal Antibody)

Sheet Jaypirca
B2: Brand | C2: Jaypirca
B3: Generic | C3: Pirtobrutinib
B4: Indication | C4: Non-Hodgkin Lymphoma
B5: MOA | C5: Bruton’s tyrosine kinase (BTK) inhibitor

Sheet Inluriyo
B2: Brand | C2: Inluriyo
B3: Generic | C3: Imlunestrant
B4: Indication | C4: Breast Cancer
B5: MOA | C5: Estrogen Antagonist

Sheet Ebglyss
B2: Brand | C2: Ebglyss
B3: Generic | C3: Lebrikizumab
B4: Indication | C4: Eczema
B5: MOA | C5: interleukin-13 antagonist

Sheet Olumiant
B2: Brand | C2: Olumiant
B3: Generic | C3: Baricitinib
B4: Indication | C4: Rheumatoid Arthritis, Alopecia Areata, COVID-19
B5: MOA | C5: JAK (Janus Kinase) Inhibitor

Sheet Omvoh
B2: Brand | C2: Omvoh
B3: Generic | C3: Mirikizumab-Mrkz
B4: Indication | C4: Crohn's Disease & Ulcerative Colitis
B5: MOA | C5: interleukin-23 antagonist

Sheet Taltz
B2: Brand | C2: Taltz
B3: Generic | C3: Ixekizumab
B4: Indication | C4: Plaque Psoriasis & Psoriatic Arthritis
B5: MOA | C5: interleukin antagonist

Sheet Emgality
B2: Brand | C2: Emgality
B3: Generic | C3: Galcanezumab
B4: Indication | C4: Migraine Prevention and Cluster Headache
B5: MOA | C5: CGRP Antagonist (Monoclonal Antibody)

Sheet Kisunla
B2: Brand | C2: Kisunla
B3: Generic | C3: donanemab-azbt
B4: Indication | C4: Alzheimer's Disease
B5: MOA | C5: amyloid beta-directed antibody
