Workbook

Sheet Main
B2: LLY | C2: as of 6/30/26 | E2: Name | F2: Indication | G2: Mechanism | H2: Economics | I2: Approved
B3: Price | C3: 1215.02 | E3: Mounjaro | F3: =Mounjaro!C4 -> Type 2 Diabetes | G3: =Mounjaro!C5 -> Dual GIP/GLP-1 Receptor Agonist | H3: 1 | I3: 44694
B4: Shares | C4: 893.7 | E4: Zepbound | F4: =Zepbound!C4 -> Obesity & Obstructive Sleep Apnea | G4: =Zepbound!C5 -> Dual GIP/GLP-1 Receptor Agonist | H4: 1 | I4: 45238
B5: Market Cap | C5: =C3*C4 -> 1085863.4 | E5: Trulicity | F5: =Trulicity!C4 -> Type-2 Diabetes | G5: =Trulicity!C5 -> GLP-1 Agonist | H5: 1 | I5: 41900
B6: Cash | C6: 8950 | E6: Retatrutide | F6: =Retatrutide!C4 -> Obesity & Type 2 Diabetes | G6: =Retatrutide!C5 -> GIP / GLP-1 / Glucagon Triple Receptor Agonist | H6: 1 | I6: TBD
B7: Debt | C7: =7050+47858 -> 54908 | E7: Foundayo | F7: =Foundayo!C4 -> Obesity / Chronic Weight Management | G7: =Foundayo!C5 -> GLP-1 Receptor Agonist (oral, nonpeptide) | H7: 1 | I7: 46113
B8: EV | C8: =C5+C7-C6 -> 1131821.4 | E8: Basaglar | F8: =Basaglar!C4 -> Type 1 and Type 2 Diabetes | G8: =Basaglar!C5 -> Long-Acting Insulin | H8: 1 | I8: =DATE(2015,12,16) -> 42354
E9: Humalog | F9: =Humalog!C4 -> Type 1 and Type 2 Diabetes | G9: =Humalog!C5 -> Rapid-Acting Insulin | H9: 1 | I9: 35230
B10: CEO: | C10: David Ricks | E10: Humulin | F10: =Humulin!C4 -> Type 1 and Type 2 Diabetes | G10: =Humulin!C5 -> Insulin (short- and intermediate-acting) | H10: 1 | I10: =DATE(1982,10,28) -> 30252
B11: CFO: | E11: Jardiance | F11: =Jardiance!C4 -> Type 2 Diabetes & Heart Failure | G11: =Jardiance!C5 -> SGLT2 Inhibitors | H11: Royalty only | I11: 41852
E12: Verzenio | F12: =Verzenio!C4 -> Breast Cancer | G12: =Verzenio!C5 -> CDK4/6 inhibitors | H12: 1 | I12: 43006
E13: Cyramza | F13: =Cyramza!C4 -> Gastric, NSCLC, and Colorectal Cancer | G13: =Cyramza!C5 -> VEGFR2 Antagonist (Monoclonal Antibody) | H13: 1 | I13: =DATE(2014,4,21) -> 41750
E14: Erbitux | F14: =Erbitux!C4 -> Colorectal and Head & Neck Cancer | G14: =Erbitux!C5 -> EGFR Inhibitor (Monoclonal Antibody) | H14: Royalty / share | I14: =DATE(2004,2,12) -> 38029
E15: Retevmo | F15: =Retevmo!C4 -> RET-Altered NSCLC and Thyroid Cancer | G15: =Retevmo!C5 -> RET Kinase Inhibitor | H15: 1 | I15: =DATE(2020,5,8) -> 43959
E16: Tyvyt | F16: =Tyvyt!C4 -> Hodgkin Lymphoma, NSCLC & other cancers (approved in China; not FDA-approved) | G16: =Tyvyt!C5 -> PD-1 Inhibitor (Monoclonal Antibody) | H16: Royalty / share | I16: Not FDA approved
E17: Jaypirca | F17: =Jaypirca!C4 -> Non-Hodgkin Lymphoma | G17: =Jaypirca!C5 -> Bruton’s tyrosine kinase (BTK) inhibitor | H17: 1 | I17: 44953
E18: Inluriyo | F18: =Inluriyo!C4 -> Breast Cancer | G18: =Inluriyo!C5 -> Estrogen Antagonist | H18: 1 | I18: 45925
E19: Ebglyss | F19: =Ebglyss!C4 -> Eczema | G19: =Ebglyss!C5 -> interleukin-13 antagonist | H19: 1 | I19: 45548
E20: Olumiant | F20: =Olumiant!C4 -> Rheumatoid Arthritis, Alopecia Areata, COVID-19 | G20: =Olumiant!C5 -> JAK (Janus Kinase) Inhibitor | H20: 1 | I20: =DATE(2018,5,31) -> 43251
E21: Omvoh | F21: =Omvoh!C4 -> Crohn's Disease & Ulcerative Colitis | G21: =Omvoh!C5 -> interleukin-23 antagonist | H21: 1 | I21: 45225
E22: Taltz | F22: =Taltz!C4 -> Plaque Psoriasis & Psoriatic Arthritis | G22: =Taltz!C5 -> interleukin antagonist | H22: 1 | I22: 42451
E23: Emgality | F23: =Emgality!C4 -> Migraine Prevention and Cluster Headache | G23: =Emgality!C5 -> CGRP Antagonist (Monoclonal Antibody) | H23: 1 | I23: =DATE(2018,9,27) -> 43370
E24: Kisunla | F24: =Kisunla!C4 -> Alzheimer's Disease | G24: =Kisunla!C5 -> amyloid beta-directed antibody | H24: 1 | I24: 45475

Sheet 10QIS
B2: Eli Lilly and Company (LLY)
B4: Historic Quarterly IS by Product | C4: Q1'22 | D4: Q2'22 | E4: Q3'22 | F4: Q4'22 | G4: Q1'23 | H4: Q2'23 | I4: Q3'23 | J4: Q4'23 | K4: Q1'24 | L4: Q2'24 | M4: Q3'24 | N4: Q4'24 | O4: Q1'25 | P4: Q2'25 | Q4: Q3'25 | R4: Q4'25 | S4: Q1'26 | T4: Q2'26
B5: Diabetes | C5: =SUM(C6:C14) -> 3243.6 | D5: =SUM(D6:D14) -> 3268.2 | E5: =SUM(E6:E14) -> 3489.2 | F5: =SUM(F6:F14) -> 3811.7 | G5: =SUM(G6:G14) -> 4045.3 | H5: =SUM(H6:H14) -> 4260.4 | I5: =SUM(I6:I14) -> 4565.4 | J5: =SUM(J6:J14) -> 5588.7 | ... T5: =SUM(T6:T14) -> 18126
B6: Mounjaro | E6: 187.3 | F6: 279.2 | G6: 568.5 | H6: 979.7 | I6: 1409.3 | J6: 2205.6 | K6: 1806.5 | L6: 3090.8 | M6: 3112.7 | N6: 3530 | O6: 3842 | P6: 5198.9 | Q6: 6515.1 | R6: 7409 | S6: 8662 | T6: 9943
B7: Zepbound | J7: 175.8 | K7: 517.4 | L7: 1243.2 | M7: 1257.8 | N7: 1907 | O7: 2312 | P7: 3381.4 | Q7: 3588 | R7: 4261 | S7: 4160 | T7: 4928
B8: Trulicity | C8: 1741.3 | D8: 1911.9 | E8: 1850.4 | F8: 1936.2 | G8: 1977.1 | H8: 1812.5 | I8: 1673.6 | J8: 1669.3 | K8: 1456.3 | L8: 1245.6 | M8: 1301.4 | N8: 1250.2 | O8: 1095 | P8: 1092.2 | Q8: 1051.8 | R8: =4276-Q8-P8-O8 -> 1037 | S8: 919 | T8: 1219
B9: Retatrutide
B10: Foundayo | T10: 98
B11: Basaglar | C11: 191.5 | D11: 174.2 | E11: 193 | F11: 201.7 | G11: 209.3 | H11: 154.2 | I11: 179.6 | J11: =728.3-I11-H11-G11 -> 185.2 | K11: 157.6 | L11: 180.8 | M11: 161.6 | N11: 176.9 | O11: 173.6 | P11: 145 | Q11: 162.2 | R11: =+N11 -> 176.9 | S11: =+O11-10 -> 163.6 | T11: 143
B12: Humalog | C12: 618.2 | D12: 447.1 | E12: 447 | F12: 548.3 | G12: 460.9 | H12: 440.4 | I12: 395.4 | J12: 366.6 | K12: 538.7 | L12: 631.6 | M12: 534.6 | N12: 619.9 | O12: 537.2 | P12: 503.1 | Q12: 599.1 | R12: =+Q12-5 -> 594.1 | S12: =+R12--15 -> 609.1 | T12: 410
B13: Humulin | C13: 273.2 | D13: 274 | E13: 238.2 | F13: 234 | G13: 252 | H13: 205.3 | I13: 206.7 | J13: =852.1-I13-H13-G13 -> 188.1 | K13: 206.2 | L13: 223.6 | M13: 207.1 | N13: 280.3 | O13: 173.2 | P13: 175.2 | Q13: 176.6 | R13: =+N13 -> 280.3 | S13: =+O13-10 -> 163.2 | T13: 153
B14: Jardiance | C14: 419.4 | D14: 461 | E14: 573.3 | F14: 612.3 | G14: 577.5 | H14: 668.3 | I14: 700.8 | J14: 798.1 | K14: 686.5 | L14: 1243.2 | M14: 686.4 | N14: 1198.4 | O14: 1014 | P14: 690 | Q14: 959 | R14: =3431-O14-P14-Q14 -> 768 | S14: 1114 | T14: 1232
B15: Oncology | C15: =SUM(C16:C22) -> 907.9 | D15: =SUM(D16:D22) -> 1034.2 | E15: =SUM(E16:E22) -> 1071.5 | F15: =SUM(F16:F22) -> 1207.9 | G15: =SUM(G16:G22) -> 1230 | H15: =SUM(H16:H22) -> 1518.6 | I15: =SUM(I16:I22) -> 1596.7 | J15: =SUM(J16:J22) -> 1736.2 | ... T15: =SUM(T16:T22) -> 2486
B16: Verzenio | C16: 469.4 | D16: 588.5 | E16: 617.7 | F16: 808 | G16: 750.9 | H16: 926.8 | I16: 1040.2 | J16: 1145.4 | K16: 1050.3 | L16: 1331.9 | M16: 1369.3 | N16: 1555 | O16: 1158.9 | P16: 1489.3 | Q16: 1470.2 | R16: 1604 | S16: 1302 | T16: 1474
B17: Cyramza | C17: 230.3 | D17: 231.3 | E17: 232.1 | F17: 277.8 | G17: 236.8 | H17: 260.3 | I17: 224.1 | J17: 253.6 | K17: 229.9 | L17: 248.9 | M17: 236 | N17: 258.6 | O17: 224.9 | P17: 253.7 | Q17: 245.5 | R17: =+N17 -> 258.6 | S17: =+O17+34 -> 258.9 | T17: 256
B18: Erbitux | C18: 122.7 | D18: 140.8 | E18: 144.9 | G18: 129.9 | H18: 162.5 | I18: 153.9 | J18: =596.5-I18-H18-G18 -> 150.2 | K18: 144.6 | L18: 155.8 | M18: 152 | N18: 175 | O18: 149 | P18: 183.7 | Q18: 198.6 | R18: =+N18 -> 175 | S18: =+O18+34 -> 183 | T18: 215
B19: Retevmo | F19: 64.6 | G19: 51.4 | H19: 65.4 | I19: 63.4 | J19: 73.4 | K19: 69.2 | L19: 91.2 | M19: 114 | N19: 90 | O19: 91 | P19: 125.3 | Q19: 112 | R19: =+Q19+5 -> 117 | S19: =+R19+34 -> 151 | T19: 144
B20: Tyvyt | C20: 85.5 | D20: 73.6 | E20: 76.8 | F20: 57.5 | G20: 61 | H20: 103.6 | I20: 115.1 | J20: 113.6 | K20: 116.7 | L20: 123 | M20: 150.2 | N20: 136 | O20: 137.5 | P20: 137.3 | Q20: 141.8 | R20: =+N20 -> 136 | S20: =+O20+34+2 -> 173.5 | T20: 130
B21: Jaypirca | K21: 50 | L21: 92.4 | M21: 81.1 | N21: 113.6 | O21: 92 | P21: 123.3 | Q21: 142.9 | R21: =+Q21+10 -> 152.9 | S21: 165 | T21: 192
B22: Inluriyo | P22: =Q22-10 -> 5 | Q22: =R22-10 -> 15 | R22: =S22-10 -> 25 | S22: 35 | T22: 75
B23: Immunology | C23: =SUM(C24:C27) -> 743.7 | D23: =SUM(D24:D27) -> 792.4 | E23: =SUM(E24:E27) -> 862.8 | F23: =SUM(F24:F27) -> 913.6 | G23: =SUM(G24:G27) -> 755.9 | H23: =SUM(H24:H27) -> 922.8 | I23: =SUM(I24:I27) -> 975.6 | J23: =SUM(J24:J27) -> 1028.1 | ... T23: =SUM(T24:T27) -> 1417
B24: Ebglyss | K24: 3.1 | L24: 4.3 | M24: 14.9 | N24: 20.4 | O24: 60.2 | P24: 86.8 | Q24: 127.1 | R24: =+Q24+5 -> 132.1 | S24: 145 | T24: 201
B25: Olumiant | C25: 255.6 | D25: 186.2 | E25: 182.9 | F25: 205.8 | G25: 228.9 | H25: 218.9 | I25: 231.4 | J25: 243.5 | K25: 217.4 | L25: 227.7 | M25: 250.8 | N25: 261.6 | O25: 228.7 | P25: 246.4 | Q25: 268.9 | R25: =+N25 -> 261.6 | S25: =+O25+16 -> 244.7 | T25: 258
B26: Omvoh | K26: 9.4 | L26: 25.6 | M26: 40.5 | N26: 56.9 | O26: 37.2 | P26: 74.8 | Q26: 64.9 | R26: =+Q26+25 -> 89.9 | S26: 80 | T26: 102
B27: Taltz | C27: 488.1 | D27: 606.2 | E27: 679.9 | F27: 707.8 | G27: 527 | H27: 703.9 | I27: 744.2 | J27: 784.6 | K27: 604.1 | L27: 824.7 | M27: 879.6 | N27: 952 | O27: 762 | P27: 847.6 | Q27: 901.5 | R27: =3563-O27-P27-Q27 -> 1051.9 | S27: 733 | T27: 856
B28: Neuroscience | C28: =SUM(C29:C30) -> 149.3 | D28: =SUM(D29:D30) -> 157.5 | E28: =SUM(E29:E30) -> 168.5 | F28: =SUM(F29:F30) -> 175.6 | G28: =SUM(G29:G30) -> 154.3 | H28: =SUM(H29:H30) -> 169.3 | I28: =SUM(I29:I30) -> 168.5 | J28: =SUM(J29:J30) -> 186.1 | ... T28: =SUM(T29:T30) -> 358
B29: Emgality | C29: 149.3 | D29: 157.5 | E29: 168.5 | F29: 175.6 | G29: 154.3 | H29: 169.3 | I29: 168.5 | J29: 186.1 | K29: 225.7 | L29: 192 | M29: 202.9 | N29: 249.8 | O29: 124.6 | P29: 201.1 | Q29: 175.7 | R29: =+N29*1.1 -> 274.78 | S29: =+O29*1.1 -> 137.06 | T29: 191
B30: Kisunla | M30: 1.4 | N30: 7.9 | O30: 21.5 | P30: 48.6 | Q30: 70.4 | R30: =+Q30+25 -> 95.4 | S30: 124 | T30: 167
B31: Other / Misc | C31: =C32-(C5+C15+C23+C28) -> 2765.5 | D31: =D32-(D5+D15+D23+D28) -> 1235.7 | E31: =E32-(E5+E15+E23+E28) -> 1349.6 | F31: =F32-(F5+F15+F23+F28) -> 1193 | G31: =G32-(G5+G15+G23+G28) -> 774.5 | H31: =H32-(H5+H15+H23+H28) -> 1441 | I31: =I32-(I5+I15+I23+I28) -> 2192.4 | J31: =J32-(J5+J15+J23+J28) -> 814.3 | ... S31: =S32-(S5+S15+S23+S28) -> 275.94 | T31: =T32-(T28+T23+T15+T5) -> 587
B32: Total Revenue | C32: 7810 | D32: 6488 | E32: 6941.6 | F32: 7301.8 | G32: 6960 | H32: 8312.1 | I32: 9498.6 | J32: 9353.4 | K32: 8768 | L32: 11302.8 | M32: 11439.1 | N32: 13532.8 | O32: 12729 | P32: 15557.7 | Q32: 17600.8 | R32: 19292 | S32: 19799 | T32: 22974
B33: COGS | C33: 2072.1 | D33: 1430.5 | E33: 1579.1 | F33: 1548.1 | G33: 1626.7 | H33: 1807.4 | I33: 1860.1 | J33: 1788 | K33: 1673.5 | L33: 2170.2 | M33: 2170.8 | N33: 2403.8 | O33: 2225 | P33: 2447.8 | Q33: 3008.3 | R33: 3371.7 | S33: 3577 | T33: 3268
B34: Gross Margin | C34: =C32-C33 -> 5737.9 | D34: =D32-D33 -> 5057.5 | E34: =E32-E33 -> 5362.5 | F34: =F32-F33 -> 5753.7 | G34: =G32-G33 -> 5333.3 | H34: =H32-H33 -> 6504.7 | I34: =I32-I33 -> 7638.5 | J34: =J32-J33 -> 7565.4 | ... T34: =T32-T33 -> 19706
B35: R&D | C35: 1610.1 | D35: 1781.9 | E35: 1802.9 | F35: 1995.9 | G35: 1985.1 | H35: 2356.5 | I35: 2409.1 | J35: 2562.7 | K35: 2522.8 | L35: 2711.2 | M35: 2734.1 | N35: 3022.5 | O35: 2734 | P35: 3336.1 | Q35: 3465.7 | R35: 3801.5 | S35: 3510 | T35: 3819
B36: SG&A | C36: 1557.9 | D36: 1625.1 | E36: 1614.2 | F36: 1643.2 | G36: 1749.2 | H36: 1925.4 | I36: 1803.9 | J36: 1924.6 | K36: 1952.2 | L36: 2117.3 | M36: 2099.8 | N36: 2424.5 | O36: 2468 | P36: 2753 | Q36: 2740.7 | R36: 3131.4 | S36: 2934 | T36: 3430
B37: IPR&D | C37: 165.6 | D37: 440.4 | E37: 62.4 | F37: 240.1 | G37: 105 | H37: 97.1 | I37: 2975.1 | J37: 622.6 | K37: 110.5 | L37: 154.3 | M37: 2826.4 | N37: 189.2 | O37: 1572 | P37: 153 | Q37: 655.7 | R37: 528.8 | S37: 584 | T37: 2776
B38: Asset Impairement/Resturcturing | C38: 0 | D38: 0 | E38: 206.5 | F38: 38.1 | G38: 0 | H38: 0 | I38: 0 | J38: 67.7 | K38: 0 | L38: 435 | M38: 81.6 | N38: 344 | O38: 35 | P38: 0 | Q38: 364.9 | R38: 84.1 | S38: 279 | T38: 703
B39: Other expenses | C39: 350.7 | D39: 119.2 | E39: -111 | F39: -260 | G39: -35.7 | H39: 36.8 | I39: 23.2 | J39: 121 | K39: -27.1 | L39: 197.6 | M39: -62 | N39: 110.2 | O39: 239 | P39: 90.6 | Q39: 133.1 | R39: 108.3 | S39: 65 | T39: -269
B40: Pre Tax Income | C40: 2053.6 | D40: 1090.9 | E40: 1565.5 | F40: 2096.4 | G40: =G34-(SUM(G35:G39)) -> 1529.7 | H40: =H34-(SUM(H35:H39)) -> 2088.9 | I40: =I34-(SUM(I35:I39)) -> 427.2 | J40: =J34-(SUM(J35:J39)) -> 2266.8 | K40: =K34-(SUM(K35:K39)) -> 2536.1 | L40: =L34-(SUM(L35:L39)) -> 3517.2 | M40: =M34-(SUM(M35:M39)) -> 1588.4 | N40: =N34-(SUM(N35:N39)) -> 5038.6 | ... T40: =T34-(SUM(T35:T39)) -> 9247
B41: Taxes | C41: 150.7 | D41: 138.4 | E41: 113.8 | F41: 158.7 | G41: 184.8 | H41: 325.7 | I41: 484.6 | J41: 319.1 | K41: 293.2 | L41: 550.2 | M41: 618.1 | N41: 628.9 | O41: 697 | P41: 1115.9 | Q41: 1649.9 | R41: 1628.5 | S41: 1454 | T41: 2152
B42: Net Income | C42: =C40-C41 -> 1902.9 | D42: =D40-D41 -> 952.5 | E42: =E40-E41 -> 1451.7 | F42: =F40-F41 -> 1937.7 | G42: =G40-G41 -> 1344.9 | H42: =H40-H41 -> 1763.2 | I42: =I40-I41 -> -57.4 | J42: =J40-J41 -> 1947.7 | ... T42: =T40-T41 -> 7095
...

Sheet IS
B2: IS Assumptions | C2: =C14 -> FY'22 | D2: =D14 -> FY'23 | E2: =E14 -> FY'24 | F2: =F14 -> FY'25 | G2: =G14 -> FY'26 | H2: =H14 -> FY'27 | I2: =I14 -> FY'28 | J2: =J14 -> FY'29 | K2: =K14 -> FY'30
B3: Diabetes Revenue Growth Rate | D3: =(D15-C15)/C15 -> 0.33643676 | E3: =(E15-D15)/D15 -> 0.59548316 | F3: =(F15-E15)/E15 -> 0.62672864 | G3: 0.5 | H3: 0.3 | I3: 0.2 | J3: 0.1 | K3: 0.05
B4: Oncology Revenue Growth Rate | D4: =(D25-C25)/C25 -> 0.44060168 | E4: =(E25-D25)/D25 -> 0.33761408 | F4: =(F25-E25)/E25 -> 0.10211809 | G4: -0.05 | H4: -0.05 | I4: -0.05 | J4: -0.05 | K4: -0.05
B5: Immunology Revenue Growth Rate | D5: =(D33-C33)/C33 -> 0.11166792 | E5: =(E33-D33)/D33 -> 0.19297197 | F5: =(F33-E33)/E33 -> 0.19317095 | G5: 0.15 | H5: 0.1333 | I5: 0.1167 | J5: 0.1 | K5: 0.0833
B6: Neuroscience Revenue Growth Rate | D6: =(D38-C38)/C38 -> 0.041941927 | E6: =(E38-D38)/D38 -> 0.29711 | F6: =(F38-E38)/E38 -> 0.15048312 | G6: 0.5 | H6: 0.25 | I6: 0.2 | J6: 0.19 | K6: 0.1533
B7: Other Revenue Growth Rate | D7: =(D41-C41)/C41 -> -0.20196216 | E7: =(E41-D41)/D41 -> -0.58197694 | F7: =(F41-E41)/E41 -> -0.061145213 | G7: -0.02 | H7: -0.02 | I7: -0.02 | J7: -0.02 | K7: -0.02
B8: Gross Margin % | C8: =C44/C42 -> 0.76771287 | D8: =D44/D42 -> 0.79245753 | E8: =E44/E42 -> 0.81310401 | F8: =F44/F42 -> 0.83042521 | G8: 0.85 | H8: 0.87 | I8: 0.87 | J8: 0.9 | K8: 0.9
B9: R&D % | C9: =C45/C42 -> 0.25194279 | D9: =D45/D42 -> 0.27292734 | E9: =E45/E42 -> 0.24400402 | F9: =F45/F42 -> 0.20462415 | G9: =AVERAGE('10QIS'!$C$53:$T$53) -> 0.23704715 | H9: =AVERAGE('10QIS'!$C$53:$T$53) -> 0.23704715 | I9: =AVERAGE('10QIS'!$C$53:$T$53) -> 0.23704715 | J9: =AVERAGE('10QIS'!$C$53:$T$53) -> 0.23704715 | K9: =AVERAGE('10QIS'!$C$53:$T$53) -> 0.23704715
B10: SG&A % | C10: =C46/C42 -> 0.22565116 | D10: =D46/D42 -> 0.21694638 | E10: =E46/E42 -> 0.19079229 | F10: =F46/F42 -> 0.17019308 | G10: =AVERAGE('10QIS'!$C$54:$T$54) -> 0.19695711 | H10: =AVERAGE('10QIS'!$C$54:$T$54) -> 0.19695711 | I10: =AVERAGE('10QIS'!$C$54:$T$54) -> 0.19695711 | J10: =AVERAGE('10QIS'!$C$54:$T$54) -> 0.19695711 | K10: =AVERAGE('10QIS'!$C$54:$T$54) -> 0.19695711
B11: IPR&D & | C11: =C47/C42 -> 0.031830954 | D11: =D47/D42 -> 0.11135239 | E11: =E47/E42 -> 0.072828671 | F11: =F47/F42 -> 0.044638268 | G11: 0.04 | H11: =G11 -> 0.04 | I11: =H11 -> 0.04 | J11: =I11 -> 0.04 | K11: =J11 -> 0.04
B12: Tax rate | C12: =C51/C50 -> 0.082510578 | D12: =D51/D50 -> 0.2081868 | E12: =E51/E50 -> 0.16485414 | F12: =F51/F50 -> 0.19786024 | G12: 0.19 | H12: =G12 -> 0.19 | I12: =H12 -> 0.19 | J12: =I12 -> 0.19 | K12: =J12 -> 0.19
B14: Annual Income Statement | C14: FY'22 | D14: FY'23 | E14: FY'24 | F14: FY'25 | G14: FY'26 | H14: FY'27 | I14: FY'28 | J14: FY'29 | K14: FY'30
B15: Diabetes | C15: =SUM('10QIS'!C5:F5) -> 13812.7 | D15: =SUM('10QIS'!G5:J5) -> 18459.8 | E15: =SUM('10QIS'!K5:N5) -> 29452.3 | F15: =SUM('10QIS'!O5:R5) -> 47910.9 | G15: =F15*(1+G3) -> 71866.35 | H15: =G15*(1+H3) -> 93426.255 | I15: =H15*(1+I3) -> 112111.51 | J15: =I15*(1+J3) -> 123322.66 | K15: =J15*(1+K3) -> 129488.79
B16: Mounjaro | C16: =SUM('10QIS'!C6:F6) -> 466.5 | D16: =SUM('10QIS'!G6:J6) -> 5163.1 | E16: =SUM('10QIS'!K6:N6) -> 11540 | F16: =SUM('10QIS'!O6:R6) -> 22965
B17: Zepbound | C17: =SUM('10QIS'!C7:F7) -> 0 | D17: =SUM('10QIS'!G7:J7) -> 175.8 | E17: =SUM('10QIS'!K7:N7) -> 4925.4 | F17: =SUM('10QIS'!O7:R7) -> 13542.4
B18: Trulicity | C18: =SUM('10QIS'!C8:F8) -> 7439.8 | D18: =SUM('10QIS'!G8:J8) -> 7132.5 | E18: =SUM('10QIS'!K8:N8) -> 5253.5 | F18: =SUM('10QIS'!O8:R8) -> 4276
B19: Retatrutide | C19: =SUM('10QIS'!C9:F9) -> 0 | D19: =SUM('10QIS'!G9:J9) -> 0 | E19: =SUM('10QIS'!K9:N9) -> 0 | F19: =SUM('10QIS'!O9:R9) -> 0
B20: Foundayo | C20: =SUM('10QIS'!C10:F10) -> 0 | D20: =SUM('10QIS'!G10:J10) -> 0 | E20: =SUM('10QIS'!K10:N10) -> 0 | F20: =SUM('10QIS'!O10:R10) -> 0
B21: Basaglar | C21: =SUM('10QIS'!C11:F11) -> 760.4 | D21: =SUM('10QIS'!G11:J11) -> 728.3 | E21: =SUM('10QIS'!K11:N11) -> 676.9 | F21: =SUM('10QIS'!O11:R11) -> 657.7
B22: Humalog | C22: =SUM('10QIS'!C12:F12) -> 2060.6 | D22: =SUM('10QIS'!G12:J12) -> 1663.3 | E22: =SUM('10QIS'!K12:N12) -> 2324.8 | F22: =SUM('10QIS'!O12:R12) -> 2233.5
B23: Humulin | C23: =SUM('10QIS'!C13:F13) -> 1019.4 | D23: =SUM('10QIS'!G13:J13) -> 852.1 | E23: =SUM('10QIS'!K13:N13) -> 917.2 | F23: =SUM('10QIS'!O13:R13) -> 805.3
B24: Jardiance | C24: =SUM('10QIS'!C14:F14) -> 2066 | D24: =SUM('10QIS'!G14:J14) -> 2744.7 | E24: =SUM('10QIS'!K14:N14) -> 3814.5 | F24: =SUM('10QIS'!O14:R14) -> 3431
B25: Oncology | C25: =SUM('10QIS'!C15:F15) -> 4221.5 | D25: =SUM('10QIS'!G15:J15) -> 6081.5 | E25: =SUM('10QIS'!K15:N15) -> 8134.7 | F25: =SUM('10QIS'!O15:R15) -> 8965.4 | G25: =F25*(1+G4) -> 8517.13 | H25: =G25*(1+H4) -> 8091.2735 | I25: =H25*(1+I4) -> 7686.7098 | J25: =I25*(1+J4) -> 7302.3743 | K25: =J25*(1+K4) -> 6937.2556
B26: Verzenio | C26: =SUM('10QIS'!C16:F16) -> 2483.6 | D26: =SUM('10QIS'!G16:J16) -> 3863.3 | E26: =SUM('10QIS'!K16:N16) -> 5306.5 | F26: =SUM('10QIS'!O16:R16) -> 5722.4
B27: Cyramza | C27: =SUM('10QIS'!C17:F17) -> 971.5 | D27: =SUM('10QIS'!G17:J17) -> 974.8 | E27: =SUM('10QIS'!K17:N17) -> 973.4 | F27: =SUM('10QIS'!O17:R17) -> 982.7
B28: Erbitux | C28: =SUM('10QIS'!C18:F18) -> 408.4 | D28: =SUM('10QIS'!G18:J18) -> 596.5 | E28: =SUM('10QIS'!K18:N18) -> 627.4 | F28: =SUM('10QIS'!O18:R18) -> 706.3
B29: Retevmo | C29: =SUM('10QIS'!C19:F19) -> 64.6 | D29: =SUM('10QIS'!G19:J19) -> 253.6 | E29: =SUM('10QIS'!K19:N19) -> 364.4 | F29: =SUM('10QIS'!O19:R19) -> 445.3
B30: Tyvyt | C30: =SUM('10QIS'!C20:F20) -> 293.4 | D30: =SUM('10QIS'!G20:J20) -> 393.3 | E30: =SUM('10QIS'!K20:N20) -> 525.9 | F30: =SUM('10QIS'!O20:R20) -> 552.6
B31: Jaypirca | C31: =SUM('10QIS'!C21:F21) -> 0 | D31: =SUM('10QIS'!G21:J21) -> 0 | E31: =SUM('10QIS'!K21:N21) -> 337.1 | F31: =SUM('10QIS'!O21:R21) -> 511.1
B32: Inluriyo | C32: =SUM('10QIS'!C22:F22) -> 0 | D32: =SUM('10QIS'!G22:J22) -> 0 | E32: =SUM('10QIS'!K22:N22) -> 0 | F32: =SUM('10QIS'!O22:R22) -> 45
B33: Immunology | C33: =SUM('10QIS'!C23:F23) -> 3312.5 | D33: =SUM('10QIS'!G23:J23) -> 3682.4 | E33: =SUM('10QIS'!K23:N23) -> 4393 | F33: =SUM('10QIS'!O23:R23) -> 5241.6 | G33: =F33*(1+G5) -> 6027.84 | H33: =G33*(1+H5) -> 6831.3511 | I33: =H33*(1+I5) -> 7628.5697 | J33: =I33*(1+J5) -> 8391.4267 | K33: =J33*(1+K5) -> 9090.4326
B34: Ebglyss | C34: =SUM('10QIS'!C24:F24) -> 0 | D34: =SUM('10QIS'!G24:J24) -> 0 | E34: =SUM('10QIS'!K24:N24) -> 42.7 | F34: =SUM('10QIS'!O24:R24) -> 406.2
B35: Olumiant | C35: =SUM('10QIS'!C25:F25) -> 830.5 | D35: =SUM('10QIS'!G25:J25) -> 922.7 | E35: =SUM('10QIS'!K25:N25) -> 957.5 | F35: =SUM('10QIS'!O25:R25) -> 1005.6
B36: Omvoh | C36: =SUM('10QIS'!C26:F26) -> 0 | D36: =SUM('10QIS'!G26:J26) -> 0 | E36: =SUM('10QIS'!K26:N26) -> 132.4 | F36: =SUM('10QIS'!O26:R26) -> 266.8
B37: Taltz | C37: =SUM('10QIS'!C27:F27) -> 2482 | D37: =SUM('10QIS'!G27:J27) -> 2759.7 | E37: =SUM('10QIS'!K27:N27) -> 3260.4 | F37: =SUM('10QIS'!O27:R27) -> 3563
B38: Neuroscience | C38: =SUM('10QIS'!C28:F28) -> 650.9 | D38: =SUM('10QIS'!G28:J28) -> 678.2 | E38: =SUM('10QIS'!K28:N28) -> 879.7 | F38: =SUM('10QIS'!O28:R28) -> 1012.08 | G38: =F38*(1+G6) -> 1518.12 | H38: =G38*(1+H6) -> 1897.65 | I38: =H38*(1+I6) -> 2277.18 | J38: =I38*(1+J6) -> 2709.8442 | K38: =J38*(1+K6) -> 3125.2633
B39: Emgality | C39: =SUM('10QIS'!C29:F29) -> 650.9 | D39: =SUM('10QIS'!G29:J29) -> 678.2 | E39: =SUM('10QIS'!K29:N29) -> 870.4 | F39: =SUM('10QIS'!O29:R29) -> 776.18
B40: Kisunla | C40: =SUM('10QIS'!C30:F30) -> 0 | D40: =SUM('10QIS'!G30:J30) -> 0 | E40: =SUM('10QIS'!K30:N30) -> 9.3 | F40: =SUM('10QIS'!O30:R30) -> 235.9
B41: Other | C41: =SUM('10QIS'!C31:F31) -> 6543.8 | D41: =SUM('10QIS'!G31:J31) -> 5222.2 | E41: =SUM('10QIS'!K31:N31) -> 2183 | F41: =SUM('10QIS'!O31:R31) -> 2049.52 | G41: =F41*(1+G7) -> 2008.5296 | H41: =G41*(1+H7) -> 1968.359 | I41: =H41*(1+I7) -> 1928.9918 | J41: =I41*(1+J7) -> 1890.412 | K41: =J41*(1+K7) -> 1852.6038
B42: Total Revenue | C42: =C15+C25+C33+C38+C41 -> 28541.4 | D42: =D15+D25+D33+D38+D41 -> 34124.1 | E42: =E15+E25+E33+E38+E41 -> 45042.7 | F42: =F15+F25+F33+F38+F41 -> 65179.5 | G42: =G15+G25+G33+G38+G41 -> 89937.97 | H42: =H15+H25+H33+H38+H41 -> 112214.89 | I42: =I15+I25+I33+I38+I41 -> 131632.96 | J42: =J15+J25+J33+J38+J41 -> 143616.71 | K42: =K15+K25+K33+K38+K41 -> 150494.34
...

Sheet BS
B2: BS Assumptions | C2: FY'22 | D2: FY'23 | E2: FY'24 | F2: FY'25 | G2: FY'26
B3: Accounts Receivable % of Revenue | C3: =BS!C15/IS!C42 -> 0.24161394 | D3: =BS!D15/IS!D42 -> 0.2663953 | E3: =BS!E15/IS!E42 -> 0.24434592 | F3: =BS!F15/IS!F42 -> 0.27247831 | G3: 0.27
B4: Other Receivables % of Revenue | C4: =BS!C16/IS!C42 -> 0.058266238 | D4: =BS!D16/IS!D42 -> 0.065809794 | E4: =BS!E16/IS!E42 -> 0.050396624 | F4: =BS!F16/IS!F42 -> 0.036744682 | G4: =BS!$F$16/IS!$F$42 -> 0.036744682
B5: Inventories % of COGS | C5: =BS!C17/IS!C43 -> 0.65009503 | D5: =BS!D17/IS!D43 -> 0.81511395 | E5: =BS!E17/IS!E43 -> 0.90148842 | F5: =BS!F17/IS!F43 -> 1.2434858 | G5: 1.4
B6: Prepaid Expenses % of Revenue | C6: =BS!C18/IS!C42 -> 0.10325352 | D6: =BS!D18/IS!D42 -> 0.16237205 | E6: =BS!E18/IS!E42 -> 0.18517984 | F6: =BS!F18/IS!F42 -> 0.21962427 | G6: 0.25
B7: Other Current Assets % of Revenue | C7: =BS!C19/IS!C42 -> 0.0053255972 | D7: =BS!D19/IS!D42 -> 0.0075782218 | E7: =BS!E19/IS!E42 -> 0.0059055074 | F7: =BS!F19/IS!F42 -> 0.0022553103 | G7: =BS!$F$19/IS!$F$42 -> 0.0022553103
B8: Accounts Payable % of COGS | C8: =(BS!C29+BS!C30)/IS!C43 -> 0.51761742 | D8: =(BS!D29+BS!D30)/IS!D43 -> 1.3418571 | E8: =(BS!E29+BS!E30)/IS!E43 -> 0.99141157 | F8: =(BS!F29+BS!F30)/IS!F43 -> 0.63459033 | G8: 0.63
B9: Employee Compensation % of Revenue | C9: =BS!C31/IS!C42 -> 0.037132026 | D9: =BS!D31/IS!D42 -> 0.048364646 | E9: =BS!E31/IS!E42 -> 0.04648922 | F9: =BS!F31/IS!F42 -> 0.036437837 | G9: =BS!$F$31/IS!$F$42 -> 0.036437837
B10: Sales Rebates and Discounts % of Revenue | C10: =BS!C32/IS!C42 -> 0.30776696 | D10: =BS!D32/IS!D42 -> 0.34254383 | E10: =BS!E32/IS!E42 -> 0.25617914 | F10: =BS!F32/IS!F42 -> 0.26667894 | G10: =BS!$F$32/IS!$F$42 -> 0.26667894
B11: Other Current Liabilities % of Revenue | C11: =BS!C33/IS!C42 -> 0.13533324 | D11: =BS!D33/IS!D42 -> 0.13042102 | E11: =BS!E33/IS!E42 -> 0.14202079 | F11: =BS!F33/IS!F42 -> 0.12974938 | G11: =BS!$F$33/IS!$F$42 -> 0.12974938
B13: Balance Sheet | C13: FY'22 | D13: FY'23 | E13: FY'24 | F13: FY'25 | G13: FY'26
B14: Cash and cash equivalents | C14: 2067 | D14: 2818.6 | E14: 3268 | F14: 7268 | G14: =CFS!G47 -> 15589.808
B15: Accounts receivable | C15: 6896 | D15: 9090.5 | E15: 11006 | F15: 17760 | G15: =IS!G$42*BS!G3 -> 24283.252
B16: Other receivables | C16: 1663 | D16: 2245.7 | E16: 2270 | F16: 2395 | G16: =IS!G$42*BS!G4 -> 3304.7421
B17: Inventories | C17: 4310 | D17: 5772.8 | E17: 7589 | F17: 13744 | G17: =IS!G$43*BS!G5 -> 18886.974
B18: Prepaid expenses | C18: 2947 | D18: 5540.8 | E18: 8341 | F18: 14315 | G18: =IS!G$42*BS!G6 -> 22484.492
B19: Other current assets | C19: 152 | D19: 258.6 | E19: 266 | F19: 147 | G19: =IS!G$42*BS!G7 -> 202.83803
B20: Total current assets | C20: 18035 | D20: 25727 | E20: 32740 | F20: 55629 | G20: =SUM(G14:G19) -> 84752.106
B21: Investments | C21: 2902 | D21: 3052.2 | E21: 3216 | F21: 2802 | G21: =F21-CFS!G28-CFS!G29 -> 2918.25
B22: Goodwill | C22: 4073 | D22: 4939.7 | E22: 5770 | F22: 5898 | G22: =F22-CFS!G32 -> 6643.05
B23: Other intangibles, net | C23: 7207 | D23: 6906.6 | E23: 6166 | F23: 6521 | G23: =F23 -> 6521
B24: Deferred tax assets | C24: 2793 | D24: 5477.3 | E24: 8001 | F24: 9959 | G24: =F24-CFS!G16 -> 12202.667
B25: Property and equipment, net | C25: 10144 | D25: 12913.6 | E25: 17102 | F25: 24675 | G25: =F25-CFS!G27-CFS!G15 -> 31388.954
B26: Other noncurrent assets | C26: 4337 | D26: 4989.9 | E26: 5720 | F26: 6992 | G26: =F26-CFS!G18-CFS!G20-CFS!G30-CFS!G33-CFS!G41 -> 7522.025
B27: Total assets | C27: 49489.8 | D27: 64006.3 | E27: 78715 | F27: 112476 | G27: =G20+SUM(G21:G26) -> 151948.05
B29: Short-term borrowings and current maturities | C29: 1501.1 | D29: 6904.5 | E29: 5117 | F29: 1635 | G29: =F29+CFS!G37 -> 1718.82
B30: Accounts payable | C30: 1930.6 | D30: 2598.8 | E30: 3229 | F30: 5379 | G30: =IS!G$43*BS!G8 -> 8499.1381
B31: Employee compensation | C31: 1059.8 | D31: 1650.4 | E31: 2094 | F31: 2375 | G31: =IS!G$42*BS!G9 -> 3277.1451
B32: Sales rebates and discounts | C32: 8784.1 | D32: 11689 | E32: 11539 | F32: 17382 | G32: =IS!G$42*BS!G10 -> 23984.562
B33: Other current liabilities | C33: 3862.6 | D33: 4450.5 | E33: 6397 | F33: 8457 | G33: =IS!G$42*BS!G11 -> 11669.396
B34: Total current liabilities | C34: 17138.2 | D34: 27293.2 | E34: 28376 | F34: 35228 | G34: =SUM(G29:G33) -> 49149.062
B35: Long-term debt | C35: 14737.5 | D35: 18320.8 | E35: 28527 | F35: 40868 | G35: =F35+CFS!G38+CFS!G39 -> 52610.562
B36: Long-term income taxes payable | C36: 3796.9 | D36: 3849.2 | E36: 4061 | F36: 5875 | G36: =F36 -> 5875
B37: Other noncurrent liabilities | C37: 3041.8 | D37: 3679.4 | E37: 3479 | F37: 3970 | G37: =F37 -> 3970
B38: Total noncurrent liabilities | C38: 21576.2 | D38: 25849.4 | E38: 36067 | F38: 50713 | G38: =SUM(G35:G37) -> 62455.562
B39: Total equity | C39: 10775.4 | D39: 10863.7 | E39: 14272 | F39: 26535 | G39: =F39+IS!G52+CFS!G17+CFS!G36+CFS!G40 -> 40343.428
B40: Total liabilities and equity | C40: 49489.8 | D40: 64006.3 | E40: 78715 | F40: 112476 | G40: =G34+G38+G39 -> 151948.05
B41: Check (Assets less Liab. & Equity) | C41: 0 | D41: 0 | E41: 0 | F41: 0 | G41: =G27-G40 -> 0

Sheet CFS
B2: CFS Assumptions | C2: FY'22 | D2: FY'23 | E2: FY'24 | F2: FY'25 | G2: FY'26
B3: D&A % of Revenue | C3: =CFS!C15/IS!C42 -> 0.053343564 | D3: =CFS!D15/IS!D42 -> 0.044748433 | E3: =CFS!E15/IS!E42 -> 0.039229442 | F3: =CFS!F15/IS!F42 -> 0.030638468 | G3: 0.025
B4: Stock-Based Compensation % of Revenue | C4: =CFS!C17/IS!C42 -> 0.013002165 | D4: =CFS!D17/IS!D42 -> 0.018432721 | E4: =CFS!E17/IS!E42 -> 0.014341947 | F4: =CFS!F17/IS!F42 -> 0.0096042467 | G4: =F4 -> 0.0096042467
B5: Capital Expenditures % of Revenue | C5: =CFS!C27/IS!C42 -> -0.064968782 | D5: =CFS!D27/IS!D42 -> -0.10104296 | E5: =CFS!E27/IS!E42 -> -0.11229345 | F5: =CFS!F27/IS!F42 -> -0.12029856 | G5: =AVERAGE(C5:F5) -> -0.099650937
B6: Dividend Payout Ratio (or Dividends per Share) | C6: =CFS!C36/IS!C52 -> -0.56619908 | D6: =CFS!D36/IS!D52 -> -0.8140605 | E6: =CFS!E36/IS!E52 -> -0.44193052 | F6: =CFS!F36/IS!F52 -> -0.26084639 | G6: -0.35
B7: Net Change in Short-Term Borrowings (assumption) | C7: =BS!C29/(BS!C34+BS!C38) -> 0.038773686 | D7: =BS!D29/(BS!D34+BS!D38) -> 0.12992402 | E7: =BS!E29/(BS!E34+BS!E38) -> 0.079403504 | F7: =BS!F29/(BS!F34+BS!F38) -> 0.01902468 | G7: 0.02
B8: Proceeds from Issuance of Long-Term Debt (assumption) | D8: =(CFS!D38)/(-CFS!D27+IS!D47) -> 0.54623472 | E8: =(CFS!E38)/(-CFS!E27+IS!E47) -> 1.3692075 | F8: =(CFS!F38)/(-CFS!F27+IS!F47) -> 1.2247802 | G8: 1
B9: Share Buybacks (% of Revenue or $ amount) | C9: =CFS!C40/IS!C42 -> -0.052555236 | D9: =CFS!D40/IS!D42 -> -0.021978602 | E9: =CFS!E40/IS!E42 -> -0.055502889 | F9: =CFS!F40/IS!F42 -> -0.063025951 | G9: =AVERAGE(C9:F9) -> -0.04826567
B10: LT Debt Repayment % of Prior LT Debt | G10: 0.02
B11: Net Interest/Other Exp % of Prior Total Debt | G11: =IS!$F$49/(BS!$F$29+BS!$F$35) -> 0.013434346
B13: Cash Flow Statement | C13: FY'22 | D13: FY'23 | E13: FY'24 | F13: FY'25 | G13: FY'26
B14: Net income | C14: 6244.8 | D14: 5240 | E14: 10590 | F14: 20640 | G14: =IS!G52 -> 26593.165
B15: Depreciation and amortization | C15: 1522.5 | D15: 1527 | E15: 1767 | F15: 1997 | G15: =IS!G$42*CFS!G3 -> 2248.4492
B16: Change in deferred income taxes | C16: -2185.2 | D16: -2341 | E16: -2683 | F16: -1707 | G16: =AVERAGE($D$16:$F$16) -> -2243.6667
B17: Stock-based compensation expense | C17: 371.1 | D17: 629 | E17: 646 | F17: 626 | G17: =IS!G$42*CFS!G4 -> 863.78645
B18: Gains on sale of product rights | C18: 0 | D18: -1879 | E18: -224 | F18: -180 | G18: =AVERAGE(C18:F18) -> -570.75
B19: Acquired in-process research and development | C19: 420.9 | D19: 3800 | E19: 3280 | F19: 2910 | G19: =IS!G47 -> 3597.5188
B20: Other operating activities, net | C20: 304.8 | D20: 319 | E20: 826 | F20: 620 | G20: =AVERAGE(C20:F20) -> 517.45
B21: Receivables - (increase) decrease | C21: -299.6 | D21: -2451 | E21: -2155 | F21: -7000 | G21: =-(BS!G15+BS!G16-BS!F15-BS!F16) -> -7432.9939
B22: Inventories - (increase) decrease | C22: -599.7 | D22: -1425 | E22: -2507 | F22: -4671 | G22: =-(BS!G17-BS!F17) -> -5142.9736
B23: Prepaid exp. and other assets - (incr.) decr. | C23: -793.5 | D23: -3453 | E23: -3331 | F23: -6609 | G23: =-(BS!G18+BS!G19-BS!F18-BS!F19) -> -8225.3304
B24: Accounts payable and other liab. - incr. (decr.) | C24: 1678.3 | D24: 4274 | E24: 2609 | F24: 10187 | G24: =(BS!G30+BS!G31+BS!G32+BS!G33+BS!G36+BS!G37)-(BS!F30+BS!F31+BS!F32+BS!F33+BS!F36+BS!F37) -> 13837.242
B25: Net Cash Provided by Operating Activities | C25: 7084.4 | D25: 4240 | E25: 8818 | F25: 16813 | G25: =SUM(G14:G24) -> 24041.897
B27: Purchases of property and equipment | C27: -1854.3 | D27: -3448 | E27: -5058 | F27: -7841 | G27: =IS!G$42*CFS!G5 -> -8962.4029
B28: Proceeds from sales of noncurrent investments | C28: 342.2 | D28: 508 | E28: 374 | F28: 964 | G28: =AVERAGE(C28:F28) -> 547.05
B29: Purchases of noncurrent investments | C29: -600.2 | D29: -731 | E29: -677 | F29: -645 | G29: =AVERAGE(C29:F29) -> -663.3
B30: Proceeds from sale of product rights | C30: 0 | D30: 1604 | E30: 601 | F30: 218 | G30: 0
B31: Purchases of in-process research and development | C31: -629.7 | D31: -3944 | E31: -3346 | F31: -3008 | G31: =-G19 -> -3597.5188
B32: Cash paid for acquisitions, net of cash acquired | C32: -327.2 | D32: -1044 | E32: -948 | F32: -661 | G32: =AVERAGE(C32:F32) -> -745.05
B33: Other investing activities, net | C33: -206.4 | D33: -98 | E33: -248 | F33: 1 | G33: 0
B34: Net Cash Used for Investing Activities | C34: -3261.6 | D34: -7153 | E34: -9302 | F34: -10972 | G34: =SUM(G27:G33) -> -13421.222
B36: Dividends paid | C36: -3535.8 | D36: -4069 | E36: -4680 | F36: -5384 | G36: =IS!G$52*CFS!G6 -> -9307.6078
B37: Net change in short-term borrowings | C37: 1498 | D37: 4691 | E37: -1852 | F37: -4338 | G37: =(BS!F34+BS!F38)*CFS!G7-BS!F29 -> 83.82
B38: Proceeds from issuance of long-term debt | C38: 0 | D38: 3959 | E38: 11417 | F38: 13167 | G38: =(-G27+IS!G47)*CFS!G8 -> 12559.922
B39: Repayments of long-term debt | C39: -1560 | D39: 0 | E39: -664 | F39: -778 | G39: =-BS!F35*CFS!G10 -> -817.36
B40: Purchases of common stock | C40: -1500 | D40: -750 | E40: -2500 | F40: -4108 | G40: =IS!G42*CFS!G9 -> -4340.9163
B41: Other financing activities, net | C41: -308.9 | D41: -335 | E41: -491 | F41: -772 | G41: =AVERAGE(C41:F41) -> -476.725
B42: Net Cash Provided by (Used for) Financing Activities | C42: -5406.7 | D42: 3496 | E42: 1230 | F42: -2213 | G42: =SUM(G36:G41) -> -2298.8675
B44: Effect of exchange rate changes on cash | C44: -167.6 | D44: 169 | E44: -297 | F44: 372 | G44: 0
B45: Net Increase (Decrease) in Cash | C45: -1751.5 | D45: 752 | E45: 449 | F45: 4000 | G45: =G25+G34+G42+G44 -> 8321.8078
...

Sheet DCF
B2: Eli Lilly and Company (LLY)
B4: Valuation Date: | H4: =TODAY() -> 46248
B5: Share Price on Valuation Date: | H5: =Main!C3 -> 1215.02
B6: Diluted Shares Outstanding | H6: =Main!C4 -> 893.7
B8: Select Operating Data
J9: Projected Annual Forecast
C10: =D10-365 -> -730 | D10: =E10-365 -> -365 | F10: FY'22 | G10: FY'23 | H10: FY'24 | I10: FY'25 | J10: FY'26 | K10: FY'27 | L10: FY'28 | M10: FY'29 | N10: FY'30
B11: Revenue | F11: =IS!C42 -> 28541.4 | G11: =IS!D42 -> 34124.1 | H11: =IS!E42 -> 45042.7 | I11: =IS!F42 -> 65179.5 | J11: =IS!G42 -> 89937.97 | K11: =IS!H42 -> 112214.89 | L11: =IS!I42 -> 131632.96 | M11: =IS!J42 -> 143616.71 | N11: =IS!K42 -> 150494.34
B13: EBIT | F13: =IS!C50+IS!C49 -> 6905.3 | G13: =IS!D50+IS!D49 -> 6457.9 | H13: =IS!E50+IS!E49 -> 12899 | I13: =IS!F50+IS!F49 -> 26302.8 | J13: =IS!G50+IS!G49 -> 33402.068 | K13: =IS!H50+IS!H49 -> 41735.689 | L13: =IS!I50+IS!I49 -> 48939.567 | M13: =IS!J50+IS!J49 -> 53522.092 | N13: =IS!K50+IS!K49 -> 56109.757
B15: Depreciation & Amortization | F15: =CFS!C15 -> 1522.5 | G15: =CFS!D15 -> 1527 | H15: =CFS!E15 -> 1767 | I15: =CFS!F15 -> 1997 | J15: =I15*(1+J16) -> 2056.91 | K15: =J15*(1+K16) -> 2108.3327 | L15: =K15*(1+L16) -> 2161.0411 | M15: =L15*(1+M16) -> 2215.0671 | N15: =M15*(1+N16) -> 2270.4438 | O15: Trend | P15: Arithmetic Avg | Q15: Geometric Avg
F16: =F15/F11 -> 0.053343564 | G16: =G15/G11 -> 0.044748433 | H16: =H15/H11 -> 0.039229442 | I16: =I15/I11 -> 0.030638468 | J16: 0.03 | K16: 0.025 | L16: =+K16 -> 0.025 | M16: =+L16 -> 0.025 | N16: =+M16 -> 0.025 | P16: =AVERAGE(C16:I16) -> 0.041989977 | Q16: =GEOMEAN(C16:I16) -> 0.041156152
B18: Select Balance Sheet And Other Data
J19: Projected Annual Forecast
C20: =D20-365 -> -730 | D20: =E20-365 -> -365 | F20: FY'22 | G20: FY'23 | H20: FY'24 | I20: FY'25 | J20: FY'26 | K20: FY'27 | L20: FY'28 | M20: FY'29 | N20: FY'30
B21: Accounts Receivable | F21: =BS!C15 -> 6896 | G21: =BS!D15 -> 9090.5 | H21: =BS!E15 -> 11006 | I21: =BS!F15 -> 17760 | J21: =J32*J11 -> 23042.86 | K21: =K32*K11 -> 28750.393 | L21: =L32*L11 -> 33725.465 | M21: =M32*M11 -> 36795.804 | N21: =N32*N11 -> 38557.91
B22: Inventories | F22: =BS!C17 -> 4310 | G22: =BS!D17 -> 5772.8 | H22: =BS!E17 -> 7589 | I22: =BS!F17 -> 13744 | J22: =J33*J11 -> 15728.529 | K22: =K33*K11 -> 19624.361 | L22: =L33*L11 -> 23020.231 | M22: =M33*M11 -> 25115.974 | N22: =N33*N11 -> 26318.748
B23: Prepaid Expenses | F23: =BS!C18 -> 2947 | G23: =BS!D18 -> 5540.8 | H23: =BS!E18 -> 8341 | I23: =BS!F18 -> 14315 | J23: =J34*J11 -> 15074.271 | K23: =K34*K11 -> 18808.048 | L23: =L34*L11 -> 22062.66 | M23: =M34*M11 -> 24071.227 | N23: =N34*N11 -> 25223.969
B25: Accounts Payable and Accruals | F25: =BS!C30 -> 1930.6 | G25: =BS!D30 -> 2598.8 | H25: =BS!E30 -> 3229 | I25: =BS!F30 -> 5379 | J25: =J35*J11 -> 6700.6686 | K25: =K35*K11 -> 8360.3709 | L25: =L35*L11 -> 9807.0796 | M25: =M35*M11 -> 10699.908 | N25: =N35*N11 -> 11212.314
B26: Accrued Expenses | F26: =BS!C31 -> 1059.8 | G26: =BS!D31 -> 1650.4 | H26: =BS!E31 -> 2094 | I26: =BS!F31 -> 2375 | J26: =J36*J11 -> 3786.922 | K26: =K36*K11 -> 4724.9125 | L26: =L36*L11 -> 5542.5284 | M26: =M36*M11 -> 6047.1156 | N26: =N36*N11 -> 6336.7047
B28: Debt | F28: =BS!C29+BS!C35 -> 16238.6 | G28: =BS!D29+BS!D35 -> 25225.3 | H28: =BS!E29+BS!E35 -> 33644 | I28: =BS!F29+BS!F35 -> 42503
B30: Capital Expenditures | F30: =CFS!C27 -> -1854.3 | G30: =CFS!D27 -> -3448 | H30: =CFS!E27 -> -5058 | I30: =CFS!F27 -> -7841 | J30: =J37*J11 -> -8962.4029 | K30: =K37*K11 -> -11182.319 | L30: =L37*L11 -> -13117.347 | M30: =M37*M11 -> -14311.54 | N30: =N37*N11 -> -14996.902
O31: Trend | P31: Arithmetic Mean | Q31: Geometric Mean
B32: Accounts Receivable as a % of revenue | C32: =C21/C8 -> #DIV/0! | D32: =D21/D8 -> #DIV/0! | E32: =E21/E8 -> #DIV/0! | F32: =F21/F11 -> 0.24161394 | G32: =G21/G11 -> 0.2663953 | H32: =H21/H11 -> 0.24434592 | I32: =I21/I11 -> 0.27247831 | J32: =$P32 -> 0.25620837 | K32: =$P32 -> 0.25620837 | L32: =$P32 -> 0.25620837 | M32: =$P32 -> 0.25620837 | N32: =$P32 -> 0.25620837 | P32: =AVERAGE(F32:I32) -> 0.25620837 | Q32: =GEOMEAN(F32:I32) -> 0.25585646
B33: Inventories as a % of revenue | C33: =C22/C8 -> #DIV/0! | D33: =D22/D8 -> #DIV/0! | E33: =E22/E8 -> #DIV/0! | F33: =F22/F11 -> 0.15100871 | G33: =G22/G11 -> 0.16917076 | H33: =H22/H11 -> 0.16848457 | I33: =I22/I11 -> 0.21086385 | J33: =$P33 -> 0.17488197 | K33: =$P33 -> 0.17488197 | L33: =$P33 -> 0.17488197 | M33: =$P33 -> 0.17488197 | N33: =$P33 -> 0.17488197 | O33: 0.03 | P33: =AVERAGE(F33:I33) -> 0.17488197 | Q33: =GEOMEAN(F33:I33) -> 0.17356909
B34: Prepaid Expenses as a % of revenue | C34: =C23/C8 -> #DIV/0! | D34: =D23/D8 -> #DIV/0! | E34: =E23/E8 -> #DIV/0! | F34: =F23/F11 -> 0.10325352 | G34: =G23/G11 -> 0.16237205 | H34: =H23/H11 -> 0.18517984 | I34: =I23/I11 -> 0.21962427 | J34: =$P34 -> 0.16760742 | K34: =$P34 -> 0.16760742 | L34: =$P34 -> 0.16760742 | M34: =$P34 -> 0.16760742 | N34: =$P34 -> 0.16760742 | O34: 0.02 | P34: =AVERAGE(F34:I34) -> 0.16760742 | Q34: =GEOMEAN(F34:I34) -> 0.161593
B35: Accounts Payable/Accruals as a % of revenue | C35: =C25/C8 -> #DIV/0! | D35: =D25/D8 -> #DIV/0! | E35: =E25/E8 -> #DIV/0! | F35: =F25/F11 -> 0.067642092 | G35: =G25/G11 -> 0.07615732 | H35: =H25/H11 -> 0.071687532 | I35: =I25/I11 -> 0.082525948 | J35: =$P35 -> 0.074503223 | K35: =$P35 -> 0.074503223 | L35: =$P35 -> 0.074503223 | M35: =$P35 -> 0.074503223 | N35: =$P35 -> 0.074503223 | O35: 0.01 | P35: =AVERAGE(F35:I35) -> 0.074503223 | Q35: =GEOMEAN(F35:I35) -> 0.074300324
B36: Accrued Expenses as a % of revenue | C36: =C26/C8 -> #DIV/0! | D36: =D26/D8 -> #DIV/0! | E36: =E26/E8 -> #DIV/0! | F36: =F26/F11 -> 0.037132026 | G36: =G26/G11 -> 0.048364646 | H36: =H26/H11 -> 0.04648922 | I36: =I26/I11 -> 0.036437837 | J36: =$P36 -> 0.042105932 | K36: =$P36 -> 0.042105932 | L36: =$P36 -> 0.042105932 | M36: =$P36 -> 0.042105932 | N36: =$P36 -> 0.042105932 | P36: =AVERAGE(F36:I36) -> 0.042105932 | Q36: =GEOMEAN(F36:I36) -> 0.041763355
B37: Capital Expenditures as a % of revenue | C37: =C30/C8 -> #DIV/0! | D37: =D30/D8 -> #DIV/0! | E37: =E30/E8 -> #DIV/0! | F37: =F30/F11 -> -0.064968782 | G37: =G30/G11 -> -0.10104296 | H37: =H30/H11 -> -0.11229345 | I37: =I30/I11 -> -0.12029856 | J37: =$P37 -> -0.099650937 | K37: =$P37 -> -0.099650937 | L37: =$P37 -> -0.099650937 | M37: =$P37 -> -0.099650937 | N37: =$P37 -> -0.099650937 | P37: =AVERAGE(F37:I37) -> -0.099650937 | Q37: =GEOMEAN(F37:I37) -> #NUM!
B38: Accounts Receivable Growth (%) | D38: =((D21/C21)-1) -> #DIV/0! | E38: =((E21/D21)-1) -> #DIV/0! | G38: =((G21/F21)-1) -> 0.31822796 | H38: =((H21/G21)-1) -> 0.21071448 | I38: =((I21/H21)-1) -> 0.61366527
B39: Inventories Growth (%) | D39: =((D22/C22)-1) -> #DIV/0! | E39: =((E22/D22)-1) -> #DIV/0! | G39: =((G22/F22)-1) -> 0.33939675 | H39: =((H22/G22)-1) -> 0.31461336 | I39: =((I22/H22)-1) -> 0.8110423
B40: Prepaid Expenses Growth (%) | D40: =((D23/C23)-1) -> #DIV/0! | E40: =((E23/D23)-1) -> #DIV/0! | G40: =((G23/F23)-1) -> 0.8801493 | H40: =((H23/G23)-1) -> 0.50537828 | I40: =((I23/H23)-1) -> 0.71622108
B41: Accounts Payable/Accruals Growth (%) | D41: =((D25/C25)-1) -> #DIV/0! | E41: =((E25/D25)-1) -> #DIV/0! | G41: =((G25/F25)-1) -> 0.34611002 | H41: =((H25/G25)-1) -> 0.24249654 | I41: =((I25/H25)-1) -> 0.66584082
B42: Accrued Expenses Growth (%) | D42: =((D26/C26)-1) -> #DIV/0! | E42: =((E26/D26)-1) -> #DIV/0! | G42: =((G26/F26)-1) -> 0.55727496 | H42: =((H26/G26)-1) -> 0.26878333 | I42: =((I26/H26)-1) -> 0.13419293
B43: Capital Expenditures Growth (%) | D43: =((D30/C30)-1) -> #DIV/0! | E43: =((E30/D30)-1) -> #DIV/0! | G43: =((G30/F30)-1) -> 0.85946179 | H43: =((H30/G30)-1) -> 0.46693735 | I43: =((I30/H30)-1) -> 0.55021748
B45: Free Cash Flow Buildup
B46: $mm | J46: Projected Annual Forecast
C47: =D47-365 -> -730 | D47: =E47-365 -> -365 | F47: FY'22 | G47: FY'23 | H47: FY'24 | I47: FY'25 | J47: FY'26 | K47: FY'27 | L47: FY'28 | M47: FY'29 | N47: FY'30
B48: Period | J48: 1 | K48: =J48+1 -> 2 | L48: =K48+1 -> 3 | M48: =L48+1 -> 4 | N48: =M48+1 -> 5
B49: Total Revenues | C49: =C11 -> 0 | D49: =D11 -> 0 | E49: =E11 -> 0 | F49: =F11 -> 28541.4 | G49: =G11 -> 34124.1 | H49: =H11 -> 45042.7 | I49: =I11 -> 65179.5 | J49: =J11 -> 89937.97 | ... N49: =N11 -> 150494.34
B50: EBIT | C50: =C13 -> 0 | D50: =D13 -> 0 | E50: =E13 -> 0 | F50: =F13 -> 6905.3 | G50: =G13 -> 6457.9 | H50: =H13 -> 12899 | I50: =I13 -> 26302.8 | J50: =J13 -> 33402.068 | ... N50: =N13 -> 56109.757
...

Sheet Mounjaro
B2: Brand | C2: Mounjaro
B3: Generic | C3: TIRZEPATIDE
B4: Indication | C4: Type 2 Diabetes
B5: MOA | C5: Dual GIP/GLP-1 Receptor Agonist

Sheet Zepbound
B2: Brand | C2: Zepbound
B3: Generic | C3: Tirzepatide
B4: Indication | C4: Obesity & Obstructive Sleep Apnea
B5: MOA | C5: Dual GIP/GLP-1 Receptor Agonist

Sheet Trulicity
B2: Brand | C2: Trulicity
B3: Generic | C3: dulaglutide
B4: Indication | C4: Type-2 Diabetes
B5: MOA | C5: GLP-1 Agonist

Sheet Retatrutide
B2: Brand | C2: None
B3: Generic | C3: Retatrutide
B4: Indication | C4: Obesity & Type 2 Diabetes
B5: MOA | C5: GIP / GLP-1 / Glucagon Triple Receptor Agonist

Sheet Foundayo
B2: Brand | C2: Foundayo
B3: Generic | C3: Orforglipron
B4: Indication | C4: Obesity / Chronic Weight Management
B5: MOA | C5: GLP-1 Receptor Agonist (oral, nonpeptide)

Sheet Basaglar
B2: Brand | C2: Basaglar
B3: Generic | C3: Insulin Glargine
B4: Indication | C4: Type 1 and Type 2 Diabetes
B5: MOA | C5: Long-Acting Insulin

Sheet Humalog
B2: Brand | C2: Humalog
B3: Generic | C3: Insulin Lispro
B4: Indication | C4: Type 1 and Type 2 Diabetes
B5: MOA | C5: Rapid-Acting Insulin

Sheet Humulin
B2: Brand | C2: Humulin
B3: Generic | C3: Human Insulin
B4: Indication | C4: Type 1 and Type 2 Diabetes
B5: MOA | C5: Insulin (short- and intermediate-acting)

Sheet Jardiance
B2: Brand | C2: Jardiance
B3: Generic | C3: empagliflozin
B4: Indication | C4: Type 2 Diabetes & Heart Failure
B5: MOA | C5: SGLT2 Inhibitors

Sheet Verzenio
B2: Brand | C2: Verzenio
B3: Generic | C3: abemaciclib
B4: Indication | C4: Breast Cancer
B5: MOA | C5: CDK4/6 inhibitors

Sheet Cyramza
B2: Brand | C2: Cyramza
B3: Generic | C3: Ramucirumab
B4: Indication | C4: Gastric, NSCLC, and Colorectal Cancer
B5: MOA | C5: VEGFR2 Antagonist (Monoclonal Antibody)

Sheet Erbitux
B2: Brand | C2: Erbitux
B3: Generic | C3: Cetuximab
B4: Indication | C4: Colorectal and Head & Neck Cancer
B5: MOA | C5: EGFR Inhibitor (Monoclonal Antibody)

Sheet Retevmo
B2: Brand | C2: Retevmo
B3: Generic | C3: Selpercatinib
B4: Indication | C4: RET-Altered NSCLC and Thyroid Cancer
B5: MOA | C5: RET Kinase Inhibitor

Sheet Tyvyt
B2: Brand | C2: Tyvyt
B3: Generic | C3: Sintilimab
B4: Indication | C4: Hodgkin Lymphoma, NSCLC & other cancers (approved in China; not FDA-approved)
B5: MOA | C5: PD-1 Inhibitor (Monoclonal Antibody)

Sheet Jaypirca
B2: Brand | C2: Jaypirca
B3: Generic | C3: Pirtobrutinib
B4: Indication | C4: Non-Hodgkin Lymphoma
B5: MOA | C5: Bruton’s tyrosine kinase (BTK) inhibitor

Sheet Inluriyo
B2: Brand | C2: Inluriyo
B3: Generic | C3: Imlunestrant
B4: Indication | C4: Breast Cancer
B5: MOA | C5: Estrogen Antagonist

Sheet Ebglyss
B2: Brand | C2: Ebglyss
B3: Generic | C3: Lebrikizumab
B4: Indication | C4: Eczema
B5: MOA | C5: interleukin-13 antagonist

Sheet Olumiant
B2: Brand | C2: Olumiant
B3: Generic | C3: Baricitinib
B4: Indication | C4: Rheumatoid Arthritis, Alopecia Areata, COVID-19
B5: MOA | C5: JAK (Janus Kinase) Inhibitor

Sheet Omvoh
B2: Brand | C2: Omvoh
B3: Generic | C3: Mirikizumab-Mrkz
B4: Indication | C4: Crohn's Disease & Ulcerative Colitis
B5: MOA | C5: interleukin-23 antagonist

Sheet Taltz
B2: Brand | C2: Taltz
B3: Generic | C3: Ixekizumab
B4: Indication | C4: Plaque Psoriasis & Psoriatic Arthritis
B5: MOA | C5: interleukin antagonist

Sheet Emgality
B2: Brand | C2: Emgality
B3: Generic | C3: Galcanezumab
B4: Indication | C4: Migraine Prevention and Cluster Headache
B5: MOA | C5: CGRP Antagonist (Monoclonal Antibody)

Sheet Kisunla
B2: Brand | C2: Kisunla
B3: Generic | C3: donanemab-azbt
B4: Indication | C4: Alzheimer's Disease
B5: MOA | C5: amyloid beta-directed antibody
