Workbook

Sheet IS Quarterly
B1: O'Reilly Automotive, Inc. | Income Statement (Quarterly)
B2: $mm except per share
C4: Q1 FY2023 | D4: Q2 FY2023 | E4: Q3 FY2023 | F4: Q4 FY2023 | G4: Q1 FY2024 | H4: Q2 FY2024 | I4: Q3 FY2024 | J4: Q4 FY2024 | K4: Q1 FY2025 | L4: Q2 FY2025 | M4: Q3 FY2025 | N4: Q4 FY2025 | O4: Q1 FY2026 | P4: Q2 FY2026
B6: Sales | C6: 3707.864 | D6: 4068.991 | E6: 4203.38 | F6: 3832.015 | G6: 3976.24 | H6: 4272.201 | I6: 4364.437 | J6: 4095.601 | K6: 4136.924 | L6: 4525.058 | M6: 4705.696 | N6: 4414.314 | O6: 4560.539 | P6: 4892.013
B7: Net Sales GR | G7: =(G6-C6)/C6 -> 0.072380217 | H7: =(H6-D6)/D6 -> 0.049941128 | I7: =(I6-E6)/E6 -> 0.038316069 | J7: =(J6-F6)/F6 -> 0.068785221 | K7: =(K6-G6)/G6 -> 0.040411042 | L7: =(L6-H6)/H6 -> 0.059186588 | M7: =(M6-I6)/I6 -> 0.078190841 | N7: =(N6-J6)/J6 -> 0.077818371 | ... P7: =(P6-L6)/L6 -> 0.081093988
B8: Cost of goods sold, including warehouse and distribution expenses | C8: 1817.535 | D8: 1982.409 | E8: 2042.917 | F8: 1864.586 | G8: 1942.068 | H8: 2104.141 | I8: 2113.212 | J8: 1994.569 | K8: 2015.439 | L8: 2198.52 | M8: 2265.75 | N8: 2128.142 | O8: 2213.328 | P8: 2375.273
B9: Gross profit | C9: 1890.329 | D9: 2086.582 | E9: 2160.463 | F9: 1967.429 | G9: 2034.172 | H9: 2168.06 | I9: 2251.225 | J9: 2101.032 | K9: 2121.485 | L9: 2326.538 | M9: 2439.946 | N9: 2286.172 | O9: 2347.211 | P9: 2516.74
B10: Gross profit % | C10: =C9/C6 -> 0.50981616 | D10: =D9/D6 -> 0.51280084 | E10: =E9/E6 -> 0.51398232 | F10: =F9/F6 -> 0.51341892 | G10: =G9/G6 -> 0.5115818 | H10: =H9/H6 -> 0.5074808 | I10: =I9/I6 -> 0.51581109 | J10: =J9/J6 -> 0.51299724 | ... P10: =P9/P6 -> 0.51445898
B11: Selling, general and administrative expenses | C11: 1173.684 | D11: 1232.809 | E11: 1263.241 | F11: 1248.693 | G11: 1281.691 | H11: 1304.762 | I11: 1354.497 | J11: 1362.382 | K11: 1380.019 | L11: 1412.068 | M11: 1463.879 | N11: 1457.563 | O11: 1505.603 | P11: 1530.994
B12: Operating income | C12: 716.645 | D12: 853.773 | E12: 897.222 | F12: 718.736 | G12: 752.481 | H12: 863.298 | I12: 896.728 | J12: 738.65 | K12: 741.466 | L12: 914.47 | M12: 976.067 | N12: 828.609 | O12: 841.608 | P12: 985.746
B13: Interest expense | C13: -44.572 | D13: -49.587 | E13: -51.361 | F13: -56.148 | G13: -57.148 | H13: -54.831 | I13: -55.166 | J13: -55.403 | K13: -57.564 | L13: -57.337 | M13: -59.566 | N13: -60.597 | O13: -62.745 | P13: -69.871
B14: Interest income | C14: 0.868 | D14: 0.76 | E14: 1.292 | F14: 1.98 | G14: 1.656 | H14: 1.528 | I14: 2.055 | J14: 2.056 | K14: 1.664 | L14: 1.885 | M14: 1.78 | N14: 1.994 | O14: 1.748 | P14: 1.589
B15: Other, net | C15: 4.479 | D15: 4.186 | E15: -0.486 | F15: 6.963 | G15: 3.401 | H15: 1.561 | I15: 4.304 | J15: -0.106 | K15: -1.215 | L15: 2.437 | M15: 5.369 | N15: 0.709 | O15: -0.522 | P15: 6.611
B16: Total other expense | C16: -39.225 | D16: -44.641 | E16: -50.555 | F16: -47.205 | G16: -52.091 | H16: -51.742 | I16: -48.807 | J16: -53.453 | K16: -57.115 | L16: -53.015 | M16: -52.417 | N16: -57.894 | O16: -61.519 | P16: -61.671
B17: Income before income taxes | C17: 677.42 | D17: 809.132 | E17: 846.667 | F17: 671.531 | G17: 700.39 | H17: 811.556 | I17: 847.921 | J17: 685.197 | K17: 684.351 | L17: 861.455 | M17: 923.65 | N17: 770.715 | O17: 780.089 | P17: 924.075
B18: Provision for income taxes | C18: 160.535 | D18: 181.767 | E18: 196.84 | F18: 119.027 | G18: 153.152 | H18: 188.708 | I18: 182.457 | J18: 134.067 | K18: 145.866 | L18: 192.86 | M18: 197.754 | N18: 165.482 | O18: 175.908 | P18: 209.011
B19: Net income | C19: 516.885 | D19: 627.365 | E19: 649.827 | F19: 552.504 | G19: 547.238 | H19: 622.848 | I19: 665.464 | J19: 551.13 | K19: 538.485 | L19: 668.595 | M19: 725.896 | N19: 605.233 | O19: 604.181 | P19: 715.064
B21: Earnings per share - basic | C21: 0.56 | D21: 0.69 | E21: 0.72 | F21: 0.62 | G21: 0.62 | H21: 0.71 | I21: 0.76 | J21: 0.64 | K21: 0.63 | L21: 0.78 | M21: 0.86 | N21: 0.72 | O21: 0.72 | P21: 0.87
B22: Weighted-average common shares outstanding - basic | C22: 927.6 | D22: 912.255 | E22: 901.23 | F22: 888 | G22: 885.255 | H22: 880.182 | I22: 869.971 | J22: 865.101 | K22: 859.564 | L22: 854.003 | M22: 848.292 | N22: 844.239 | O22: 838.578 | P22: 825.197
B23: Earnings per share - diluted | C23: 0.55 | D23: 0.68 | E23: 0.71 | F23: 0.62 | G23: 0.61 | H23: 0.7 | I23: 0.76 | J23: 0.63 | K23: 0.62 | L23: 0.78 | M23: 0.85 | N23: 0.71 | O23: 0.72 | P23: 0.86
B24: Weighted-average common shares outstanding - diluted | C24: 935.97 | D24: 920.49 | E24: 908.85 | F24: 895.095 | G24: 891.81 | H24: 885.655 | I24: 875.023 | J24: 869.956 | K24: 864.331 | L24: 858.44 | M24: 852.704 | N24: 848.42 | O24: 842.516 | P24: 828.875

Sheet IS Annual
B1: O'Reilly Automotive, Inc. | Income Statement (Annual)
B2: $mm except per share
C4: FY2023 | D4: FY2024 | E4: FY2025 | F4: TTM Q2 FY2026
C5: 45291 | D5: 45657 | E5: 46022 | F5: 46203
B6: Sales | C6: 15812.25 | D6: 16708.479 | E6: 17781.992 | F6: 18572.562
B7: Cost of goods sold, including warehouse and distribution expenses | C7: 7707.447 | D7: 8153.99 | E7: 8607.851 | F7: 8982.493
B8: Gross profit | C8: 8104.803 | D8: 8554.489 | E8: 9174.141 | F8: 9590.069
B9: Selling, general and administrative expenses | C9: 4918.427 | D9: 5303.332 | E9: 5713.529 | F9: 5958.039
B10: Operating income | C10: 3186.376 | D10: 3251.157 | E10: 3460.612 | F10: 3632.03
B11: Interest expense | C11: -201.668 | D11: -222.548 | E11: -235.064 | F11: -252.779
B12: Interest income | C12: 4.9 | D12: 7.295 | E12: 7.323 | F12: 7.111
B13: Other, net | C13: 15.142 | D13: 9.16 | E13: 7.3 | F13: 12.167
B14: Total other expense | C14: -181.626 | D14: -206.093 | E14: -220.441 | F14: -233.501
B15: Income before income taxes | C15: 3004.75 | D15: 3045.064 | E15: 3240.171 | F15: 3398.529
B16: Provision for income taxes | C16: 658.169 | D16: 658.384 | E16: 701.962 | F16: 748.155
B17: Net income | C17: 2346.581 | D17: 2386.68 | E17: 2538.209 | F17: 2650.374
... B22: Weighted-average common shares outstanding - diluted | C22: 914.976 | D22: 880.572 | E22: 855.919 | F22: 843.129

Sheet BS Annual
B1: O'Reilly Automotive, Inc. | Balance Sheet (Annual)
B2: $mm except per share
C4: FY2023 | D4: FY2024 | E4: FY2025 | F4: TTM Q2 FY2026
C5: 45291 | D5: 45657 | E5: 46022 | F5: 46203
B6: Current assets
B7: Cash and cash equivalents | C7: 279.132 | D7: 130.245 | E7: 193.793 | F7: 262.181
B8: Accounts receivable, net | C8: 375.049 | D8: 356.839 | E8: 389.793 | F8: 457.785
B9: Amounts receivable from suppliers | C9: 140.443 | D9: 139.091 | E9: 159.9 | F9: 170.728
B10: Inventory | C10: 4658.367 | D10: 5095.804 | E10: 5731.385 | F10: 5971.856
B11: Other current assets | C11: 105.311 | D11: 117.916 | E11: 269.406 | F11: 337.082
B12: Total current assets | C12: =SUM(C7:C11) -> 5558.302 | D12: =SUM(D7:D11) -> 5839.895 | E12: =SUM(E7:E11) -> 6744.277 | F12: =SUM(F7:F11) -> 7199.632
B13: Property and equipment, at cost | C13: 8312.367 | D13: 9192.254 | E13: 10222.249 | F13: 10741.816
B14: Less: accumulated depreciation and amortization | C14: 3275.387 | D14: 3587.098 | E14: 3964.824 | F14: 4191.571
B15: Net property and equipment | C15: 5036.98 | D15: 5605.156 | E15: 6257.425 | F15: 6550.245
B16: Operating lease, right-of-use assets | C16: 2200.554 | D16: 2324.638 | E16: 2391.15 | F16: 2484.413
B17: Goodwill | C17: 897.696 | D17: 930.161 | E17: 948.208 | F17: 955.211
B18: Other assets, net | C18: 179.463 | D18: 193.891 | E18: 197.193 | F18: 199.615
B19: Total assets | C19: =SUM(C12,C15:C18) -> 13872.995 | D19: =SUM(D12,D15:D18) -> 14893.741 | E19: =SUM(E12,E15:E18) -> 16538.253 | F19: =SUM(F12,F15:F18) -> 17389.116
B21: Current liabilities
B22: Accounts payable | C22: 6091.7 | D22: 6524.811 | E22: 7103.684 | F22: 7384.958
B23: Self-insurance reserves | C23: 128.548 | D23: 149.387 | E23: 297.304 | F23: 214.311
B24: Accrued payroll | C24: 138.122 | D24: 107.495 | E24: 119.603 | F24: 176.174
B25: Accrued benefits and withholdings | C25: 174.65 | D25: 199.593 | E25: 240.072 | F25: 275.493
B26: Income taxes payable | C26: 7.86 | D26: 6.274 | E26: 13.957 | F26: 0
B27: Current portion of operating lease liabilities | C27: 389.536 | D27: 419.213 | E27: 439.907 | F27: 452.275
B28: Other current liabilities | C28: 730.937 | D28: 876.732 | E28: 561.294 | F28: 1071.463
B29: Total current liabilities | C29: =SUM(C22:C28) -> 7661.353 | D29: =SUM(D22:D28) -> 8283.505 | E29: =SUM(E22:E28) -> 8775.821 | F29: =SUM(F22:F28) -> 9574.674
B30: Long-term debt | C30: 5570.125 | D30: 5520.932 | E30: 6016.904 | F30: 7014.543
B31: Operating lease liabilities, less current portion | C31: 1881.344 | D31: 1980.705 | E31: 2034.688 | F31: 2120.615
B32: Deferred income taxes | C32: 295.471 | D32: 247.599 | E32: 211.21 | F32: 238.615
B33: Other liabilities | C33: 203.98 | D33: 231.961 | E33: 262.982 | F33: 276.394
B34: Total liabilities | C34: =SUM(C29,C30:C33) -> 15612.273 | D34: =SUM(D29,D30:D33) -> 16264.702 | E34: =SUM(E29,E30:E33) -> 17301.605 | F34: =SUM(F29,F30:F33) -> 19224.841
B36: Shareholders' equity (deficit)
B37: Common stock | C37: 0.591 | D37: 8.622 | E37: 8.419 | F37: 8.162
B38: Additional paid-in capital | C38: 1352.275 | D38: 1454.518 | E38: 1530.292 | F38: 1536.955
B39: Retained deficit | C39: -3131.532 | D39: -2791.288 | E39: -2328.817 | F39: -3416.414
B40: Accumulated other comprehensive income (loss) | C40: 39.388 | D40: -42.813 | E40: 26.754 | F40: 35.572
B41: Total shareholders' deficit | C41: =SUM(C37:C40) -> -1739.278 | D41: =SUM(D37:D40) -> -1370.961 | E41: =SUM(E37:E40) -> -763.352 | F41: =SUM(F37:F40) -> -1835.725
B42: Total liabilities and shareholders' deficit | C42: =C34+C41 -> 13872.995 | D42: =D34+D41 -> 14893.741 | E42: =E34+E41 -> 16538.253 | F42: =F34+F41 -> 17389.116

Sheet CF Quarterly
B1: O'Reilly Automotive, Inc. | Cash Flow Statement (Quarterly)
B2: $mm except per share
C4: Q1 FY2023 | D4: Q2 FY2023 | E4: Q3 FY2023 | F4: Q4 FY2023 | G4: Q1 FY2024 | H4: Q2 FY2024 | I4: Q3 FY2024 | J4: Q4 FY2024 | K4: Q1 FY2025 | L4: Q2 FY2025 | M4: Q3 FY2025 | N4: Q4 FY2025 | O4: Q1 FY2026 | P4: Q2 FY2026
B6: Operating activities
B7: Net income | C7: =C45 -> 516.885 | D7: =D45-C45 -> 627.365 | E7: =E45-D45 -> 649.827 | F7: ='CF Annual'!C7-E45 -> 552.504 | G7: =G45 -> 547.238 | H7: =H45-G45 -> 622.848 | I7: =I45-H45 -> 665.464 | J7: ='CF Annual'!D7-I45 -> 551.13 | K7: =K45 -> 538.485 | L7: =L45-K45 -> 668.595 | M7: =M45-L45 -> 725.896 | N7: ='CF Annual'!E7-M45 -> 605.233 | O7: =O45 -> 604.181 | P7: =P45-O45 -> 715.064
B8: Depreciation and amortization of property, equipment and intangibles | C8: =C46 -> 93.747 | D8: =D46-C46 -> 97.926 | E8: =E46-D46 -> 104.91 | F8: ='CF Annual'!C8-E46 -> 112.478 | G8: =G46 -> 109.648 | H8: =H46-G46 -> 113.237 | I8: =I46-H46 -> 116.439 | J8: ='CF Annual'!D8-I46 -> 122.568 | K8: =K46 -> 122.224 | L8: =L46-K46 -> 124.935 | M8: =M46-L46 -> 128.666 | N8: ='CF Annual'!E8-M46 -> 135.405 | O8: =O46 -> 135.361 | P8: =P46-O46 -> 138.282
B9: Amortization of debt discount and issuance costs | C9: =C47 -> 1.215 | D9: =D47-C47 -> 1.216 | E9: =E47-D47 -> 1.166 | F9: ='CF Annual'!C9-E47 -> 1.357 | G9: =G47 -> 1.593 | H9: =H47-G47 -> 1.608 | I9: =I47-H47 -> 1.669 | J9: ='CF Annual'!D9-I47 -> 1.743 | K9: =K47 -> 1.851 | L9: =L47-K47 -> 1.816 | M9: =M47-L47 -> 1.835 | N9: ='CF Annual'!E9-M47 -> 1.877 | O9: =O47 -> 1.887 | P9: =P47-O47 -> 1.931
B10: Deferred income taxes | C10: =C48 -> 3.393 | D10: =D48-C48 -> 10.114 | E10: =E48-D48 -> 22.475 | F10: ='CF Annual'!C10-E48 -> 12.25 | G10: =G48 -> 2.374 | H10: =H48-G48 -> 15.801 | I10: =I48-H48 -> -9.639 | J10: ='CF Annual'!D10-I48 -> -58.774 | K10: =K48 -> -11.159 | L10: =L48-K48 -> -25.52 | M10: =M48-L48 -> 28.806 | N10: ='CF Annual'!E10-M48 -> -29.671 | O10: =O48 -> 13.291 | P10: =P48-O48 -> 14.213
B11: Share-based compensation programs | C11: =C49 -> 7.435 | D11: =D49-C49 -> 7.136 | E11: =E49-D49 -> 7.377 | F11: ='CF Annual'!C11-E49 -> 5.563 | G11: =G49 -> 7.022 | H11: =H49-G49 -> 7.207 | I11: =I49-H49 -> 7.371 | J11: ='CF Annual'!D11-I49 -> 7.331 | K11: =K49 -> 8.444 | L11: =L49-K49 -> 10.368 | M11: =M49-L49 -> 8.296 | N11: ='CF Annual'!E11-M49 -> 8.007 | O11: =O49 -> 8.816 | P11: =P49-O49 -> 8.696
B12: Other non-cash items | C12: =C50 -> 0.029 | D12: =D50-C50 -> 0.046 | E12: =E50-D50 -> 3.499 | F12: ='CF Annual'!C12-E50 -> -1.458 | G12: =G50 -> 2.997 | H12: =H50-G50 -> 2.218 | I12: =I50-H50 -> 0.713 | J12: ='CF Annual'!D12-I50 -> 0.432 | K12: =K50 -> 3.191 | L12: =L50-K50 -> 4.754 | M12: =M50-L50 -> -0.564 | N12: ='CF Annual'!E12-M50 -> 3.688 | O12: =O50 -> 1.987 | P12: =P50-O50 -> 3.735
B13: Accounts receivable | C13: =C51 -> -2.61 | D13: =D51-C51 -> -28.833 | E13: =E51-D51 -> -27.215 | F13: ='CF Annual'!C13-E51 -> 23.119 | G13: =G51 -> -36.954 | H13: =H51-G51 -> -42.521 | I13: =I51-H51 -> 70.3 | J13: ='CF Annual'!D13-I51 -> 39.67 | K13: =K51 -> -37.758 | L13: =L51-K51 -> -36.208 | M13: =M51-L51 -> 7.068 | N13: ='CF Annual'!E13-M51 -> 31.393 | O13: =O51 -> -45.716 | P13: =P51-O51 -> -29.54
B14: Inventory | C14: =C52 -> -179.481 | D14: =D52-C52 -> -77.856 | E14: =E52-D52 -> -6.559 | F14: ='CF Annual'!C14-E52 -> -24.427 | G14: =G52 -> -92.042 | H14: =H52-G52 -> 6.905 | I14: =I52-H52 -> -127.354 | J14: ='CF Annual'!D14-I52 -> -191.395 | K14: =K52 -> -75.081 | L14: =L52-K52 -> -205.818 | M14: =M52-L52 -> -205.469 | N14: ='CF Annual'!E14-M52 -> -118.169 | O14: =O52 -> -79.069 | P14: =P52-O52 -> -160.243
B15: Accounts payable | C15: =C53 -> 172.701 | D15: =D53-C53 -> 162.598 | E15: =E53-D53 -> -19.389 | F15: ='CF Annual'!C15-E53 -> -108.849 | G15: =G53 -> 6.107 | H15: =H53-G53 -> 111.475 | I15: =I53-H53 -> 134.872 | J15: ='CF Annual'!D15-I53 -> 168.91 | K15: =K53 -> 9.952 | L15: =L53-K53 -> 321.13 | M15: =M53-L53 -> 201.517 | N15: ='CF Annual'!E15-M53 -> 43.814 | O15: =O53 -> 135.531 | P15: =P53-O53 -> 149.284
B16: Income taxes payable | C16: =C54 -> 145.441 | D16: =D54-C54 -> 115.767 | E16: =E54-D54 -> 92.158 | F16: ='CF Annual'!C16-E54 -> -319.477 | G16: =G54 -> 140.025 | H16: =H54-G54 -> -58.797 | I16: =I54-H54 -> 117.552 | J16: ='CF Annual'!D16-I54 -> -207.47 | K16: =K54 -> 138.513 | L16: =L54-K54 -> 176.266 | M16: =M54-L54 -> -316.661 | N16: ='CF Annual'!E16-M54 -> 6.419 | O16: =O54 -> 0.951 | P16: =P54-O54 -> -34.787
B17: Net cash provided by operating activities | C17: =C55 -> 713.764 | D17: =D55-C55 -> 937.605 | E17: =E55-D55 -> 866.286 | F17: ='CF Annual'!C20-E55 -> 516.429 | G17: =G55 -> 704.215 | H17: =H55-G55 -> 948.859 | I17: =I55-H55 -> 772.015 | J17: ='CF Annual'!D20-I55 -> 624.487 | K17: =K55 -> 755.12 | L17: =L55-K55 -> 756.846 | M17: =M55-L55 -> 616.535 | N17: ='CF Annual'!E20-M55 -> 633.492 | O17: =O55 -> 1032.913 | P17: =P55-O55 -> 1006.499
B18: Investing activities
B19: Purchases of property and equipment | C19: =C57 -> -223.268 | D19: =D57-C57 -> -237.674 | E19: =E57-D57 -> -293.016 | F19: ='CF Annual'!C23-E57 -> -252.306 | G19: =G57 -> -249.24 | H19: =H57-G57 -> -225.367 | I19: =I57-H57 -> -258.309 | J19: ='CF Annual'!D23-I57 -> -290.471 | K19: =K57 -> -286.951 | L19: =L57-K57 -> -300.734 | M19: =M57-L57 -> -312.098 | N19: ='CF Annual'!E23-M57 -> -269.032 | O19: =O57 -> -244.447 | P19: =P57-O57 -> -307.603
B20: Proceeds from sale of property and equipment | C20: =C58 -> 2.704 | D20: =D58-C58 -> 4.352 | E20: =E58-D58 -> 3.405 | F20: ='CF Annual'!C24-E58 -> 7.228 | G20: =G58 -> 3.853 | H20: =H58-G58 -> 3.675 | I20: =I58-H58 -> 2.74 | J20: ='CF Annual'!D24-I58 -> 6.082 | K20: =K58 -> 1.948 | L20: =L58-K58 -> 0.747 | M20: =M58-L58 -> 14.187 | N20: ='CF Annual'!E24-M58 -> 13.963 | O20: =O58 -> 1.542 | P20: =P58-O58 -> 3.6
B21: Return of (investment in) tax credit equity investments | C21: =C59 -> 0 | D21: =D59-C59 -> -4.149 | E21: =E59-D59 -> -0.001 | F21: ='CF Annual'!C25-E59 -> 0 | G21: =G59 -> 0 | H21: =H59-G59 -> 0 | I21: =I59-H59 -> 0 | J21: ='CF Annual'!D25-I59 -> 1.49 | K21: =K59 -> 0 | L21: =L59-K59 -> 0 | M21: =M59-L59 -> 0 | N21: ='CF Annual'!E25-M59 -> 0 | O21: =O59 -> 0 | P21: =P59-O59 -> 0
B22: Other, including acquisitions, net of cash acquired | C22: =C60 -> -0.956 | D22: =D60-C60 -> -1.015 | E22: =E60-D60 -> -0.155 | F22: ='CF Annual'!C26-E60 -> -1.085 | G22: =G60 -> -155.366 | H22: =H60-G60 -> -0.01 | I22: =I60-H60 -> -5.584 | J22: ='CF Annual'!D26-I60 -> -0.298 | K22: =K60 -> 0 | L22: =L60-K60 -> -10.008 | M22: =M60-L60 -> -3.656 | N22: ='CF Annual'!E26-M60 -> -0.722 | O22: =O60 -> -1.751 | P22: =P60-O60 -> -1.016
B23: Net cash used in investing activities | C23: =C61 -> -221.52 | D23: =D61-C61 -> -238.486 | E23: =E61-D61 -> -289.767 | F23: ='CF Annual'!C27-E61 -> -246.163 | G23: =G61 -> -400.753 | H23: =H61-G61 -> -221.702 | I23: =I61-H61 -> -261.153 | J23: ='CF Annual'!D27-I61 -> -283.197 | K23: =K61 -> -285.003 | L23: =L61-K61 -> -309.995 | M23: =M61-L61 -> -301.567 | N23: ='CF Annual'!E27-M61 -> -255.791 | O23: =O61 -> -244.656 | P23: =P61-O61 -> -305.019
B24: Financing activities
B25: Proceeds from borrowings on revolving credit facility | C25: =C63 -> 1216 | D25: =D63-C63 -> 1560 | E25: =E63-D63 -> 451 | F25: ='CF Annual'!C30-E63 -> 0 | G25: =G63 -> 30 | H25: =H63-G63 -> 0 | I25: =I63-H63 -> 0 | J25: ='CF Annual'!D30-I63 -> 0 | K25: =K63 -> 0 | L25: =L63-K63 -> 0 | M25: =M63-L63 -> 0 | N25: ='CF Annual'!E30-M63 -> 0 | O25: =O63 -> 0 | P25: =P63-O63 -> 0
B26: Payments on revolving credit facility | C26: =C64 -> -661 | D26: =D64-C64 -> -1315 | E26: =E64-D64 -> -1251 | F26: ='CF Annual'!C31-E64 -> 0 | G26: =G64 -> 0 | H26: =H64-G64 -> -30 | I26: =I64-H64 -> 0 | J26: ='CF Annual'!D31-I64 -> 0 | K26: =K64 -> 0 | L26: =L64-K64 -> 0 | M26: =M64-L64 -> 0 | N26: ='CF Annual'!E31-M64 -> 0 | O26: =O64 -> 0 | P26: =P64-O64 -> 0
B27: Net proceeds (payments) of commercial paper | C27: =C65 -> 0 | D27: =D65-C65 -> 0 | E27: =E65-D65 -> 1025.075 | F27: ='CF Annual'!C32-E65 -> -278.286 | G27: =G65 -> -310.805 | H27: =H65-G65 -> 137.305 | I27: =I65-H65 -> -533.35 | J27: ='CF Annual'!D32-I65 -> 159.246 | K27: =K65 -> 129.288 | L27: =L65-K65 -> 169.63 | M27: =M65-L65 -> 90.878 | N27: ='CF Annual'!E32-M65 -> 98.99 | O27: =O65 -> -163.887 | P27: =P65-O65 -> 815.775
B28: Proceeds from the issuance of long-term debt | C28: =C66 -> 0 | D28: =D66-C66 -> 0 | E28: =E66-D66 -> 0 | F28: ='CF Annual'!C33-E66 -> 749.655 | G28: =G66 -> 0 | H28: =H66-G66 -> 0 | I28: =I66-H66 -> 498.91 | J28: ='CF Annual'!D33-I66 -> 0 | K28: =K66 -> 0 | L28: =L66-K66 -> 0 | M28: =M66-L66 -> 0 | N28: ='CF Annual'!E33-M66 -> 0 | O28: =O66 -> 847.365 | P28: =P66-O66 -> 0
B29: Principal payments on long-term debt | C29: =C67 -> 0 | D29: =D67-C67 -> -300 | E29: =E67-D67 -> 0 | F29: ='CF Annual'!C34-E67 -> 0 | G29: =G67 -> 0 | H29: =H67-G67 -> 0 | I29: =I67-H67 -> 0 | J29: ='CF Annual'!D34-I67 -> 0 | K29: =K67 -> 0 | L29: =L67-K67 -> 0 | M29: =M67-L67 -> 0 | N29: ='CF Annual'!E34-M67 -> 0 | O29: =O67 -> -500 | P29: =P67-O67 -> 0
B30: Payment of debt issuance costs | C30: =C68 -> 0 | D30: =D68-C68 -> -0.024 | E30: =E68-D68 -> -0.015 | F30: ='CF Annual'!C35-E68 -> -4.95 | G30: =G68 -> 0 | H30: =H68-G68 -> 0 | I30: =I68-H68 -> -3.9 | J30: ='CF Annual'!D35-I68 -> -0.176 | K30: =K68 -> -3.801 | L30: =L68-K68 -> -0.014 | M30: =M68-L68 -> -0.014 | N30: ='CF Annual'!E35-M68 -> -0.168 | O30: =O68 -> -5.909 | P30: =P68-O68 -> -0.746
B31: Payment of excise tax on share repurchases | C31: =C69 -> 0 | D31: =D69-C69 -> 0 | E31: =E69-D69 -> 0 | F31: ='CF Annual'!C36-E69 -> 0 | G31: =G69 -> 0 | H31: =H69-G69 -> 0 | I31: =I69-H69 -> 0 | J31: ='CF Annual'!D36-I69 -> -28.83 | K31: =K69 -> 0 | L31: =L69-K69 -> -17.012 | M31: =M69-L69 -> 0 | N31: ='CF Annual'!E36-M69 -> 0 | O31: =O69 -> 0 | P31: =P69-O69 -> -18.718
B32: Repurchases of common stock | C32: =C70 -> -1111.461 | D32: =D70-C70 -> -679.99 | E32: =E70-D70 -> -799.529 | F32: ='CF Annual'!C37-E70 -> -560.175 | G32: =G70 -> -270.019 | H32: =H70-G70 -> -793.772 | I32: =I70-H70 -> -540.718 | J32: ='CF Annual'!D37-I70 -> -472.02 | K32: =K70 -> -559.432 | L32: =L70-K70 -> -617.208 | M32: =M70-L70 -> -420.01 | N32: ='CF Annual'!E37-M70 -> -500.312 | O32: =O70 -> -922.947 | P32: =P70-O70 -> -1510.076
B33: Net proceeds from issuance of common stock | C33: =C71 -> 15.146 | D33: =D71-C71 -> 33.534 | E33: =E71-D71 -> 22.924 | F33: ='CF Annual'!C38-E71 -> 19.712 | G33: =G71 -> 57.815 | H33: =H71-G71 -> 15.975 | I33: =I71-H71 -> 39.035 | J33: ='CF Annual'!D38-I71 -> 16.156 | K33: =K71 -> 24.926 | L33: =L71-K71 -> 23.241 | M33: =M71-L71 -> 20.113 | N33: ='CF Annual'!E38-M71 -> 12.543 | O33: =O71 -> 16.609 | P33: =P71-O71 -> 21.154
B34: Other financing activities | C34: =C72 -> -0.354 | D34: =D72-C72 -> 0 | E34: =E72-D72 -> 0 | F34: ='CF Annual'!C39-E72 -> 0 | G34: =G72 -> -0.569 | H34: =H72-G72 -> 0 | I34: =I72-H72 -> 0 | J34: ='CF Annual'!D39-I72 -> 0 | K34: =K72 -> -0.433 | L34: =L72-K72 -> 0 | M34: =M72-L72 -> 0 | N34: ='CF Annual'!E39-M72 -> 0 | O34: =O72 -> -0.27 | P34: =P72-O72 -> 0
B35: Net cash used in financing activities | C35: =C73 -> -541.669 | D35: =D73-C73 -> -701.48 | E35: =E73-D73 -> -551.545 | F35: ='CF Annual'!C40-E73 -> -74.044 | G35: =G73 -> -493.578 | H35: =H73-G73 -> -670.492 | I35: =I73-H73 -> -540.023 | J35: ='CF Annual'!D40-I73 -> -325.624 | K35: =K73 -> -409.452 | L35: =L73-K73 -> -441.363 | M35: =M73-L73 -> -309.033 | N35: ='CF Annual'!E40-M73 -> -388.947 | O35: =O73 -> -729.039 | P35: =P73-O73 -> -692.611
B36: Effect of exchange rate changes on cash | C36: =C74 -> 0.714 | D36: =D74-C74 -> 0.369 | E36: =E74-D74 -> -0.19 | F36: ='CF Annual'!C41-E74 -> 0.246 | G36: =G74 -> 0.248 | H36: =H74-G74 -> -0.887 | I36: =I74-H74 -> -0.268 | J36: ='CF Annual'!D41-I74 -> -1.034 | K36: =K74 -> 0.338 | L36: =L74-K74 -> 1.877 | M36: =M74-L74 -> -0.035 | N36: ='CF Annual'!E41-M74 -> 0.526 | O36: =O74 -> -0.379 | P36: =P74-O74 -> 0.68
B37: Net increase (decrease) in cash and cash equivalents | C37: =C75 -> -48.711 | D37: =D75-C75 -> -1.992 | E37: =E75-D75 -> 24.784 | F37: ='CF Annual'!C42-E75 -> 196.468 | G37: =G75 -> -189.868 | H37: =H75-G75 -> 55.778 | I37: =I75-H75 -> -29.429 | J37: ='CF Annual'!D42-I75 -> 14.632 | K37: =K75 -> 61.003 | L37: =L75-K75 -> 7.365 | M37: =M75-L75 -> 5.9 | N37: ='CF Annual'!E42-M75 -> -10.72 | O37: =O75 -> 58.839 | P37: =P75-O75 -> 9.549
B42: Year to Date, as Reported (blank for Q4 - see quarterly figure above)
C43: Q1 FY2023 | D43: Q2 FY2023 | E43: Q3 FY2023 | F43: Q4 FY2023 | G43: Q1 FY2024 | H43: Q2 FY2024 | I43: Q3 FY2024 | J43: Q4 FY2024 | K43: Q1 FY2025 | L43: Q2 FY2025 | M43: Q3 FY2025 | N43: Q4 FY2025 | O43: Q1 FY2026 | P43: Q2 FY2026
B44: Operating activities
B45: Net income | C45: 516.885 | D45: 1144.25 | E45: 1794.077 | G45: 547.238 | H45: 1170.086 | I45: 1835.55 | K45: 538.485 | L45: 1207.08 | M45: 1932.976 | O45: 604.181 | P45: 1319.245
B46: Depreciation and amortization of property, equipment and intangibles | C46: 93.747 | D46: 191.673 | E46: 296.583 | G46: 109.648 | H46: 222.885 | I46: 339.324 | K46: 122.224 | L46: 247.159 | M46: 375.825 | O46: 135.361 | P46: 273.643
...

Sheet CF Annual
B1: O'Reilly Automotive, Inc. | Cash Flow Statement (Annual)
B2: $mm except per share
C4: FY2023 | D4: FY2024 | E4: FY2025 | F4: TTM Q2 FY2026
C5: 45291 | D5: 45657 | E5: 46022 | F5: 46203
B6: Operating activities
B7: Net income | C7: 2346.581 | D7: 2386.68 | E7: 2538.209 | F7: 2650.374
B8: Depreciation and amortization of property, equipment and intangibles | C8: 409.061 | D8: 461.892 | E8: 511.23 | F8: 537.714
B9: Amortization of debt discount and issuance costs | C9: 4.954 | D9: 6.613 | E9: 7.379 | F9: 7.53
B10: Deferred income taxes | C10: 48.232 | D10: -50.238 | E10: -37.544 | F10: 26.639
B11: Share-based compensation programs | C11: 27.511 | D11: 28.931 | E11: 35.115 | F11: 33.815
B12: Other non-cash items | C12: 2.116 | D12: 6.36 | E12: 11.069 | F12: 8.846
B13: Accounts receivable | C13: -35.539 | D13: 30.495 | E13: -35.505 | F13: -36.795
B14: Inventory | C14: -288.323 | D14: -403.886 | E14: -604.537 | F14: -562.95
B15: Accounts payable | C15: 207.061 | D15: 421.364 | E15: 576.413 | F15: 530.146
B16: Income taxes payable | C16: 33.889 | D16: -8.69 | E16: 4.537 | F16: -344.078
B17: Accrued payroll | C17: 11.234 | D17: -30.81 | E17: 12.072
B18: Accrued benefits and withholdings | C18: -12.763 | D18: 71.128 | E18: 35.561
B19: Other operating assets and liabilities | C19: 280.07 | D19: 129.737 | E19: -292.006 | F19: 438.198
B20: Net cash provided by operating activities | C20: 3034.084 | D20: 3049.576 | E20: 2761.993 | F20: 3289.439
B22: Investing activities
B23: Purchases of property and equipment | C23: -1006.264 | D23: -1023.387 | E23: -1168.815 | F23: -1133.18
B24: Proceeds from sale of property and equipment | C24: 17.689 | D24: 16.35 | E24: 30.845 | F24: 33.292
B25: Return of (investment in) tax credit equity investments | C25: -4.15 | D25: 1.49 | E25: 0 | F25: 0
B26: Other, including acquisitions, net of cash acquired | C26: -3.211 | D26: -161.258 | E26: -14.386 | F26: -7.145
B27: Net cash used in investing activities | C27: -995.936 | D27: -1166.805 | E27: -1152.356 | F27: -1107.033
B29: Financing activities
B30: Proceeds from borrowings on revolving credit facility | C30: 3227 | D30: 30 | E30: 0 | F30: 0
B31: Payments on revolving credit facility | C31: -3227 | D31: -30 | E31: 0 | F31: 0
B32: Net proceeds (payments) of commercial paper | C32: 746.789 | D32: -547.604 | E32: 488.786 | F32: 841.756
B33: Proceeds from the issuance of long-term debt | C33: 749.655 | D33: 498.91 | E33: 0 | F33: 847.365
B34: Principal payments on long-term debt | C34: -300 | D34: 0 | E34: 0 | F34: -500
B35: Payment of debt issuance costs | C35: -4.989 | D35: -4.076 | E35: -3.997 | F35: -6.837
B36: Payment of excise tax on share repurchases | C36: 0 | D36: -28.83 | E36: -17.012 | F36: -18.718
B37: Repurchases of common stock | C37: -3151.155 | D37: -2076.529 | E37: -2096.962 | F37: -3353.345
B38: Net proceeds from issuance of common stock | C38: 91.316 | D38: 128.981 | E38: 80.823 | F38: 70.419
B39: Other financing activities | C39: -0.354 | D39: -0.569 | E39: -0.433 | F39: -0.27
B40: Net cash used in financing activities | C40: -1868.738 | D40: -2029.717 | E40: -1548.795 | F40: -2119.63
B41: Effect of exchange rate changes on cash | C41: 1.139 | D41: -1.941 | E41: 2.706 | F41: 0.792
... B44: Cash and cash equivalents at end of the period | C44: 279.132 | D44: 130.245 | E44: 193.793 | F44: 262.181

Sheet DCF Model
C1: #VALUE!
U2: Scenario Assumptions | V2: Bear | W2: Base | X2: Bull | Z2: Selected
C3: Valuation Date: | I3: =TODAY() -> 46294 | U3: Revenue Growth Rate (%) | V3: 0.02 | W3: =$Q$13 -> 0.055129343 | X3: 0.065 | Z3: =INDEX(V3:X3,MATCH($I$6,$V$2:$X$2,0)) -> 0.055129343
C4: Share Price on Valuation Date: | I4: {=_FV(C1,"Price")} -> 86.07 | U4: EBIT Margin (%) | V4: 0.18 | W4: =IFERROR($R$17+0,$Q$17) -> 0.19654573 | X4: 0.21 | Z4: =INDEX(V4:X4,MATCH($I$6,$V$2:$X$2,0)) -> 0.19654573
C5: Diluted Shares Outstanding | I5: 808.96079 | J5: mm | U5: D&A as a % of Revenue | V5: 0.03 | W5: 0.03 | X5: 0.03 | Z5: =INDEX(V5:X5,MATCH($I$6,$V$2:$X$2,0)) -> 0.03
C6: Scenario: | I6: Base | U6: Accounts Receivable as a % of Revenue | V6: 0.036 | W6: 0.034 | X6: 0.032 | Z6: =INDEX(V6:X6,MATCH($I$6,$V$2:$X$2,0)) -> 0.034
C7: Next Fiscal Year-End (after last modeled year): | I7: =K50 -> 46387 | U7: Inventories as a % of Revenue | V7: 0.311 | W7: =$Q$37 -> 0.31086098 | X7: 0.311 | Z7: =INDEX(V7:X7,MATCH($I$6,$V$2:$X$2,0)) -> 0.31086098
C8: Stub Period to Next FY-End (fraction of year): | I8: =MAX(0.01,MIN(1,(I7-$J$11)/365)) -> 0.50410959 | U8: Prepaid Expenses as a % of Revenue | V8: 0.02 | W8: 0.02 | X8: 0.02 | Z8: =INDEX(V8:X8,MATCH($I$6,$V$2:$X$2,0)) -> 0.02
C9: Select Operating Data | U9: Accounts Payable/Accruals as a % of Revenue | V9: =W9 -> 0.39321894 | W9: =$Q$39 -> 0.39321894 | X9: =W9 -> 0.39321894 | Z9: =INDEX(V9:X9,MATCH($I$6,$V$2:$X$2,0)) -> 0.39321894
K10: Projected Annual Forecast | U10: Accrued Expenses as a % of Revenue | V10: =W10 -> 0.078997166 | W10: =$Q$40 -> 0.078997166 | X10: =W10 -> 0.078997166 | Z10: =INDEX(V10:X10,MATCH($I$6,$V$2:$X$2,0)) -> 0.078997166
G11: 45291 | H11: 45657 | I11: 46022 | J11: 46203 | K11: =DATE(YEAR(J11),12,31) -> 46387 | L11: =EDATE(K11,12) -> 46752 | M11: =EDATE(L11,12) -> 47118 | N11: =EDATE(M11,12) -> 47483 | O11: =EDATE(N11,12) -> 47848 | U11: Capital Expenditures as a % of Revenue | V11: =W11 -> 0.062907935 | W11: =$Q$41 -> 0.062907935 | X11: =W11 -> 0.062907935 | Z11: =INDEX(V11:X11,MATCH($I$6,$V$2:$X$2,0)) -> 0.062907935
C12: Revenue | G12: ='IS Annual'!C6 -> 15812.25 | H12: ='IS Annual'!D6 -> 16708.479 | I12: ='IS Annual'!E6 -> 17781.992 | J12: ='IS Annual'!F6 -> 18572.562 | K12: =I12*(1+K13)*$I$8 -> 9458.2561 | L12: =(K12/$I$8)*(1+L13) -> 19796.655 | M12: =L12*(1+M13) -> 20888.031 | N12: =M12*(1+N13) -> 22039.575 | O12: =N12*(1+O13) -> 23254.602 | Q12: Arithmetic Avg | R12: Geometric Avg | S12: Harmean | U12: Effective Tax Rate (%) | V12: =W12 -> 0.21800404 | W12: =IFERROR($R$54+0,$Q$54) -> 0.21800404 | X12: =W12 -> 0.21800404 | Z12: =INDEX(V12:X12,MATCH($I$6,$V$2:$X$2,0)) -> 0.21800404
C13: Revenue Growth Rate (%) | H13: =(H12/G12)-1 -> 0.05667941 | I13: =(I12/H12)-1 -> 0.064249594 | J13: =(J12/I12)-1 -> 0.044459023 | K13: =$Z$3 -> 0.055129343 | L13: =+K13 -> 0.055129343 | M13: =+L13 -> 0.055129343 | N13: =+M13 -> 0.055129343 | O13: =+N13 -> 0.055129343 | Q13: =AVERAGE(H13:J13) -> 0.055129343 | R13: =GEOMEAN(H14:J14)-1 -> 0.055097794 | S13: =HARMEAN(H14:J14)-1 -> 0.0550662 | U13: Long-Term (Terminal) Growth Rate (%) | V13: 0.01 | W13: 0.02 | X13: 0.025 | Z13: =INDEX(V13:X13,MATCH($I$6,$V$2:$X$2,0)) -> 0.02
C14: Revenue Growth Rate (%) +1 | H14: =H13+1 -> 1.0566794 | I14: =I13+1 -> 1.0642496 | J14: =J13+1 -> 1.044459
C16: EBIT | G16: ='IS Annual'!C10 -> 3186.376 | H16: ='IS Annual'!D10 -> 3251.157 | I16: ='IS Annual'!E10 -> 3460.612 | J16: ='IS Annual'!F10 -> 3632.03 | K16: =K17*K12 -> 1858.9799 | L16: =L17*L12 -> 3890.9481 | M16: =M17*M12 -> 4105.4535 | N16: =N17*N12 -> 4331.7844 | O16: =O17*O12 -> 4570.5928 | Q16: Arithmetic Avg | R16: Geometric Avg | S16: Harmean
C17: EBIT Margin (%) | G17: =IFERROR(G16/G12,"") -> 0.20151313 | H17: =IFERROR(H16/H12,"") -> 0.19458127 | I17: =IFERROR(I16/I12,"") -> 0.19461329 | J17: =IFERROR(J16/J12,"") -> 0.19555891 | K17: =$Z$4 -> 0.19654573 | L17: =+K17 -> 0.19654573 | M17: =+L17 -> 0.19654573 | N17: =+M17 -> 0.19654573 | O17: =+N17 -> 0.19654573 | Q17: =AVERAGE(G17:J17) -> 0.19656665 | R17: =IFERROR(GEOMEAN(G17:J17),"") -> 0.19654573 | S17: =IFERROR(HARMEAN(G17:J17),"") -> 0.19652504
C19: Depreciation & Amortization | G19: ='CF Annual'!C8 -> 409.061 | H19: ='CF Annual'!D8 -> 461.892 | I19: ='CF Annual'!E8 -> 511.23 | J19: ='CF Annual'!F8 -> 537.714 | K19: =K20*K12 -> 283.74768 | L19: =L20*L12 -> 593.89965 | M19: =M20*M12 -> 626.64094 | N19: =N20*N12 -> 661.18725 | O19: =O20*O12 -> 697.63807 | Q19: Arithmetic Avg | R19: Geometric Avg | S19: Harmean
C20: D&A as a % of revenue | G20: =IFERROR(G19/G12,"") -> 0.025869879 | H20: =IFERROR(H19/H12,"") -> 0.027644168 | I20: =IFERROR(I19/I12,"") -> 0.028749872 | J20: =IFERROR(J19/J12,"") -> 0.028952064 | K20: =$Z$5 -> 0.03 | L20: =+K20 -> 0.03 | M20: =+L20 -> 0.03 | N20: =+M20 -> 0.03 | O20: =+N20 -> 0.03 | Q20: =AVERAGE(G20:J20) -> 0.027803996 | R20: =IFERROR(GEOMEAN(G20:J20),"") -> 0.027776553 | S20: =IFERROR(HARMEAN(G20:J20),"") -> 0.027748564
C22: Select Balance Sheet And Other Data
K23: Projected Annual Forecast
G24: 45291 | H24: 45657 | I24: 46022 | J24: 46203 | K24: =DATE(YEAR(J24),12,31) -> 46387 | L24: =EDATE(K24,12) -> 46752 | M24: =EDATE(L24,12) -> 47118 | N24: =EDATE(M24,12) -> 47483 | O24: =EDATE(N24,12) -> 47848
C25: Accounts Receivable | G25: =('BS Annual'!C8+'BS Annual'!C9) -> 515.492 | H25: =('BS Annual'!D8+'BS Annual'!D9) -> 495.93 | I25: =('BS Annual'!E8+'BS Annual'!E9) -> 549.693 | J25: =('BS Annual'!F8+'BS Annual'!F9) -> 628.513 | K25: =K36*(K12/$I$8) -> 637.91825 | L25: =L36*L12 -> 673.08627 | M25: =M36*M12 -> 710.19307 | N25: =N36*N12 -> 749.34555 | O25: =O36*O12 -> 790.65647
C26: Inventories | G26: ='BS Annual'!C10 -> 4658.367 | H26: ='BS Annual'!D10 -> 5095.804 | I26: ='BS Annual'!E10 -> 5731.385 | J26: ='BS Annual'!F10 -> 5971.856 | K26: =K37*(K12/$I$8) -> 5832.4674 | L26: =L37*L12 -> 6154.0075 | M26: =M37*M12 -> 6493.2739 | N26: =N37*N12 -> 6851.2438 | O26: =O37*O12 -> 7228.9484
C27: Prepaid Expenses | G27: ='BS Annual'!C11 -> 105.311 | H27: ='BS Annual'!D11 -> 117.916 | I27: ='BS Annual'!E11 -> 269.406 | J27: ='BS Annual'!F11 -> 337.082 | K27: =K38*(K12/$I$8) -> 375.24603 | L27: =L38*L12 -> 395.9331 | M27: =M38*M12 -> 417.76063 | N27: =N38*N12 -> 440.7915 | O27: =O38*O12 -> 465.09204
C29: Accounts Payable and Accruals | G29: ='BS Annual'!C22 -> 6091.7 | H29: ='BS Annual'!D22 -> 6524.811 | I29: ='BS Annual'!E22 -> 7103.684 | J29: ='BS Annual'!F22 -> 7384.958 | K29: =K39*(K12/$I$8) -> 7377.6923 | L29: =L39*L12 -> 7784.4196 | M29: =M39*M12 -> 8213.5696 | N29: =N39*N12 -> 8666.3783 | O29: =O39*O12 -> 9144.15
C30: Accrued Expenses | G30: =('BS Annual'!C23+'BS Annual'!C24+'BS Annual'!C25+'BS Annual'!C28) -> 1172.257 | H30: =('BS Annual'!D23+'BS Annual'!D24+'BS Annual'!D25+'BS Annual'!D28) -> 1333.207 | I30: =('BS Annual'!E23+'BS Annual'!E24+'BS Annual'!E25+'BS Annual'!E28) -> 1218.273 | J30: =('BS Annual'!F23+'BS Annual'!F24+'BS Annual'!F25+'BS Annual'!F28) -> 1737.441 | K30: =K40*(K12/$I$8) -> 1482.1687 | L30: =L40*L12 -> 1563.8796 | M30: =M40*M12 -> 1650.0953 | N30: =N40*N12 -> 1741.064 | O30: =O40*O12 -> 1837.0477
C32: Debt | G32: =0+'BS Annual'!C30 -> 5570.125 | H32: =0+'BS Annual'!D30 -> 5520.932 | I32: =0+'BS Annual'!E30 -> 6016.904 | J32: =0+'BS Annual'!F30 -> 7014.543
C34: Capital Expenditures | G34: =-('CF Annual'!C23) -> 1006.264 | H34: =-('CF Annual'!D23) -> 1023.387 | I34: =-('CF Annual'!E23) -> 1168.815 | J34: =-('CF Annual'!F23) -> 1133.18 | K34: =K41*K12 -> 594.99936 | L34: =L41*L12 -> 1245.3667 | M34: =M41*M12 -> 1314.0229 | N34: =N41*N12 -> 1386.4641 | O34: =O41*O12 -> 1462.899
Q35: Arithmetic Avg | R35: Geometric Avg | S35: Harmean
C36: Accounts Receivable as a % of revenue | G36: =IFERROR(G25/G12,"") -> 0.0326008 | H36: =IFERROR(H25/H12,"") -> 0.029681337 | I36: =IFERROR(I25/I12,"") -> 0.030912903 | J36: =IFERROR(J25/J12,"") -> 0.033840942 | K36: =$Z$6 -> 0.034 | L36: =$Z$6 -> 0.034 | M36: =$Z$6 -> 0.034 | N36: =$Z$6 -> 0.034 | O36: =$Z$6 -> 0.034 | Q36: =AVERAGE(G36:J36) -> 0.031758996 | R36: =IFERROR(GEOMEAN(G36:J36),"") -> 0.031719292 | S36: =IFERROR(HARMEAN(G36:J36),"") -> 0.031679592
C37: Inventories as a % of revenue | G37: =IFERROR(G26/G12,"") -> 0.29460494 | H37: =IFERROR(H26/H12,"") -> 0.30498312 | I37: =IFERROR(I26/I12,"") -> 0.322314 | J37: =IFERROR(J26/J12,"") -> 0.32154185 | K37: =$Z$7 -> 0.31086098 | L37: =$Z$7 -> 0.31086098 | M37: =$Z$7 -> 0.31086098 | N37: =$Z$7 -> 0.31086098 | O37: =$Z$7 -> 0.31086098 | Q37: =AVERAGE(G37:J37) -> 0.31086098 | R37: =IFERROR(GEOMEAN(G37:J37),"") -> 0.31064054 | S37: =IFERROR(HARMEAN(G37:J37),"") -> 0.3104186
C38: Prepaid Expenses as a % of revenue | G38: =IFERROR(G27/G12,"") -> 0.0066600895 | H38: =IFERROR(H27/H12,"") -> 0.0070572552 | I38: =IFERROR(I27/I12,"") -> 0.015150496 | J38: =IFERROR(J27/J12,"") -> 0.018149462 | K38: =$Z$8 -> 0.02 | L38: =$Z$8 -> 0.02 | M38: =$Z$8 -> 0.02 | N38: =$Z$8 -> 0.02 | O38: =$Z$8 -> 0.02 | Q38: =AVERAGE(G38:J38) -> 0.011754326 | R38: =IFERROR(GEOMEAN(G38:J38),"") -> 0.010662318 | S38: =IFERROR(HARMEAN(G38:J38),"") -> 0.0096864314
C39: Accounts Payable/Accruals as a % of revenue | G39: =IFERROR(G29/G12,"") -> 0.38525194 | H39: =IFERROR(H29/H12,"") -> 0.39050897 | I39: =IFERROR(I29/I12,"") -> 0.39948753 | J39: =IFERROR(J29/J12,"") -> 0.39762732 | K39: =$Z$9 -> 0.39321894 | L39: =$Z$9 -> 0.39321894 | M39: =$Z$9 -> 0.39321894 | N39: =$Z$9 -> 0.39321894 | O39: =$Z$9 -> 0.39321894 | Q39: =AVERAGE(G39:J39) -> 0.39321894 | R39: =IFERROR(GEOMEAN(G39:J39),"") -> 0.39317765 | S39: =IFERROR(HARMEAN(G39:J39),"") -> 0.39313626
C40: Accrued Expenses as a % of revenue | G40: =IFERROR(G30/G12,"") -> 0.074136002 | H40: =IFERROR(H30/H12,"") -> 0.079792242 | I40: =IFERROR(I30/I12,"") -> 0.068511616 | J40: =IFERROR(J30/J12,"") -> 0.093548806 | K40: =$Z$10 -> 0.078997166 | L40: =$Z$10 -> 0.078997166 | M40: =$Z$10 -> 0.078997166 | N40: =$Z$10 -> 0.078997166 | O40: =$Z$10 -> 0.078997166 | Q40: =AVERAGE(G40:J40) -> 0.078997166 | R40: =IFERROR(GEOMEAN(G40:J40),"") -> 0.078468992 | S40: =IFERROR(HARMEAN(G40:J40),"") -> 0.077962159
C41: Capital Expenditures as a % of revenue | G41: =IFERROR(G34/G12,"") -> 0.063638255 | H41: =IFERROR(H34/H12,"") -> 0.061249561 | I41: =IFERROR(I34/I12,"") -> 0.065730262 | J41: =IFERROR(J34/J12,"") -> 0.061013661 | K41: =$Z$11 -> 0.062907935 | L41: =$Z$11 -> 0.062907935 | M41: =$Z$11 -> 0.062907935 | N41: =$Z$11 -> 0.062907935 | O41: =$Z$11 -> 0.062907935 | Q41: =AVERAGE(G41:J41) -> 0.062907935 | R41: =IFERROR(GEOMEAN(G41:J41),"") -> 0.062878681 | S41: =IFERROR(HARMEAN(G41:J41),"") -> 0.062849669
C42: Accounts Receivable Growth (%) | H42: =IFERROR((H25/G25)-1,"") -> -0.037948213 | I42: =IFERROR((I25/H25)-1,"") -> 0.10840844 | J42: =IFERROR((J25/I25)-1,"") -> 0.14338913
C43: Inventories Growth (%) | H43: =IFERROR((H26/G26)-1,"") -> 0.093903507 | I43: =IFERROR((I26/H26)-1,"") -> 0.12472634 | J43: =IFERROR((J26/I26)-1,"") -> 0.041956874
C44: Prepaid Expenses Growth (%) | H44: =IFERROR((H27/G27)-1,"") -> 0.1196931 | I44: =IFERROR((I27/H27)-1,"") -> 1.2847281 | J44: =IFERROR((J27/I27)-1,"") -> 0.2512045
C45: Accounts Payable/Accruals Growth (%) | H45: =IFERROR((H29/G29)-1,"") -> 0.071098544 | I45: =IFERROR((I29/H29)-1,"") -> 0.088718738 | J45: =IFERROR((J29/I29)-1,"") -> 0.039595511
C46: Accrued Expenses Growth (%) | H46: =IFERROR((H30/G30)-1,"") -> 0.13729924 | I46: =IFERROR((I30/H30)-1,"") -> -0.086208668 | J46: =IFERROR((J30/I30)-1,"") -> 0.42615079
...

Sheet Comps
B1: O'Reilly Automotive, Inc. | Comparable Companies and Precedent Transactions
B2: $mm except per share; blue cells on yellow are inputs
B4: Trading Comparables
B5: Company | C5: Ticker | D5: Share Price | E5: Diluted Shares (mm) | F5: Market Cap | G5: Net Debt | H5: Enterprise Value | I5: EPS (LTM) | J5: EPS Growth (%) | K5: EBITDA (LTM) | L5: EBIT (LTM) | M5: EBITDAR (TTM) | N5: P/E | O5: EV/EBITDA | P5: EV/EBIT | Q5: PEG | R5: EV/EBITDAR
B6: AutoZone, Inc. | C6: AZO | D6: 2895.07 | E6: 16.62 | F6: =IF(COUNT(D6,E6)<2,"",D6*E6) -> 48116.063 | G6: 8762.748 | H6: =IF(F6="","",F6+G6) -> 56878.811 | I6: 152.55 | J6: 0.1193 | K6: 4384.852 | L6: 3723.314 | M6: 4727.016 | N6: =IF(COUNT(D6,I6)<2,"",IF(I6<=0,"NM",D6/I6)) -> 18.977843 | O6: =IF(COUNT(H6,K6)<2,"",IF(K6<=0,"NM",H6/K6)) -> 12.97166 | P6: =IF(COUNT(H6,L6)<2,"",IF(L6<=0,"NM",H6/L6)) -> 15.276394 | Q6: =IF(OR(ISNUMBER(N6)=FALSE(),COUNT(J6)=0),"",IF(J6<=0,"NM",N6/(J6*100))) -> 1.5907664 | R6: =IF(COUNT(H6,M6)<2,"",IF(M6<=0,"NM",H6/M6)) -> 12.03271
B7: Advance Auto Parts, Inc. | C7: AAP | D7: 41.99 | E7: 61.11 | F7: =IF(COUNT(D7,E7)<2,"",D7*E7) -> 2566.0089 | G7: 4821 | H7: =IF(F7="","",F7+G7) -> 7387.0089 | I7: 1.38 | J7: 0.2543 | K7: 739 | L7: 337 | M7: 1240 | N7: =IF(COUNT(D7,I7)<2,"",IF(I7<=0,"NM",D7/I7)) -> 30.427536 | O7: =IF(COUNT(H7,K7)<2,"",IF(K7<=0,"NM",H7/K7)) -> 9.9959525 | P7: =IF(COUNT(H7,L7)<2,"",IF(L7<=0,"NM",H7/L7)) -> 21.919908 | Q7: =IF(OR(ISNUMBER(N7)=FALSE(),COUNT(J7)=0),"",IF(J7<=0,"NM",N7/(J7*100))) -> 1.1965213 | R7: =IF(COUNT(H7,M7)<2,"",IF(M7<=0,"NM",H7/M7)) -> 5.9572652
B8: Genuine Parts Company | C8: GPC | D8: 130.525 | E8: 137.915 | F8: =IF(COUNT(D8,E8)<2,"",D8*E8) -> 18001.355 | G8: 6093.66 | H8: =IF(F8="","",F8+G8) -> 24095.015 | I8: 0.25 | J8: 0.0698 | K8: 1782.32 | L8: 1217 | M8: 2313.7 | N8: =IF(COUNT(D8,I8)<2,"",IF(I8<=0,"NM",D8/I8)) -> 522.1 | O8: =IF(COUNT(H8,K8)<2,"",IF(K8<=0,"NM",H8/K8)) -> 13.518905 | P8: =IF(COUNT(H8,L8)<2,"",IF(L8<=0,"NM",H8/L8)) -> 19.798698 | Q8: =IF(OR(ISNUMBER(N8)=FALSE(),COUNT(J8)=0),"",IF(J8<=0,"NM",N8/(J8*100))) -> 74.799427 | R8: =IF(COUNT(H8,M8)<2,"",IF(M8<=0,"NM",H8/M8)) -> 10.414062
B9: LKQ Corporation | C9: LKQ | D9: 23.38 | E9: 253.703 | F9: =IF(COUNT(D9,E9)<2,"",D9*E9) -> 5931.5761 | G9: 5012 | H9: =IF(F9="","",F9+G9) -> 10943.576 | I9: 1.82 | J9: 0.0337 | K9: 1404 | L9: 991 | N9: =IF(COUNT(D9,I9)<2,"",IF(I9<=0,"NM",D9/I9)) -> 12.846154 | O9: =IF(COUNT(H9,K9)<2,"",IF(K9<=0,"NM",H9/K9)) -> 7.7945699 | P9: =IF(COUNT(H9,L9)<2,"",IF(L9<=0,"NM",H9/L9)) -> 11.042963 | Q9: =IF(OR(ISNUMBER(N9)=FALSE(),COUNT(J9)=0),"",IF(J9<=0,"NM",N9/(J9*100))) -> 3.8119151 | R9: =IF(COUNT(H9,M9)<2,"",IF(M9<=0,"NM",H9/M9))
B10: Monro, Inc. | C10: MNRO | D10: 14.03 | E10: 31.125 | F10: =IF(COUNT(D10,E10)<2,"",D10*E10) -> 436.68375 | G10: 518.31 | H10: =IF(F10="","",F10+G10) -> 954.99375 | I10: 0.2 | J10: 0.2361 | K10: 87.93 | L10: 26.19 | N10: =IF(COUNT(D10,I10)<2,"",IF(I10<=0,"NM",D10/I10)) -> 70.15 | O10: =IF(COUNT(H10,K10)<2,"",IF(K10<=0,"NM",H10/K10)) -> 10.860841 | P10: =IF(COUNT(H10,L10)<2,"",IF(L10<=0,"NM",H10/L10)) -> 36.464061 | Q10: =IF(OR(ISNUMBER(N10)=FALSE(),COUNT(J10)=0),"",IF(J10<=0,"NM",N10/(J10*100))) -> 2.9711986 | R10: =IF(COUNT(H10,M10)<2,"",IF(M10<=0,"NM",H10/M10))
B12: Mean | N12: =IF(COUNT(N6:N10)=0,"",AVERAGE(N6:N10)) -> 130.90031 | O12: =IF(COUNT(O6:O10)=0,"",AVERAGE(O6:O10)) -> 11.028386 | P12: =IF(COUNT(P6:P10)=0,"",AVERAGE(P6:P10)) -> 20.900405 | Q12: =IF(COUNT(Q6:Q10)=0,"",AVERAGE(Q6:Q10)) -> 16.873966 | R12: =IF(COUNT(R6:R10)=0,"",AVERAGE(R6:R10)) -> 9.4680123
B13: Median | N13: =IF(COUNT(N6:N10)=0,"",MEDIAN(N6:N10)) -> 30.427536 | O13: =IF(COUNT(O6:O10)=0,"",MEDIAN(O6:O10)) -> 10.860841 | P13: =IF(COUNT(P6:P10)=0,"",MEDIAN(P6:P10)) -> 19.798698 | Q13: =IF(COUNT(Q6:Q10)=0,"",MEDIAN(Q6:Q10)) -> 2.9711986 | R13: =IF(COUNT(R6:R10)=0,"",MEDIAN(R6:R10)) -> 10.414062
B14: 25th Percentile | N14: =IF(COUNT(N6:N10)=0,"",QUARTILE(N6:N10,1)) -> 18.977843 | O14: =IF(COUNT(O6:O10)=0,"",QUARTILE(O6:O10,1)) -> 9.9959525 | P14: =IF(COUNT(P6:P10)=0,"",QUARTILE(P6:P10,1)) -> 15.276394 | Q14: =IF(COUNT(Q6:Q10)=0,"",QUARTILE(Q6:Q10,1)) -> 1.5907664 | R14: =IF(COUNT(R6:R10)=0,"",QUARTILE(R6:R10,1)) -> 8.1856636
B15: 75th Percentile | N15: =IF(COUNT(N6:N10)=0,"",QUARTILE(N6:N10,3)) -> 70.15 | O15: =IF(COUNT(O6:O10)=0,"",QUARTILE(O6:O10,3)) -> 12.97166 | P15: =IF(COUNT(P6:P10)=0,"",QUARTILE(P6:P10,3)) -> 21.919908 | Q15: =IF(COUNT(Q6:Q10)=0,"",QUARTILE(Q6:Q10,3)) -> 3.8119151 | R15: =IF(COUNT(R6:R10)=0,"",QUARTILE(R6:R10,3)) -> 11.223386
B16: High | N16: =IF(COUNT(N6:N10)=0,"",MAX(N6:N10)) -> 522.1 | O16: =IF(COUNT(O6:O10)=0,"",MAX(O6:O10)) -> 13.518905 | P16: =IF(COUNT(P6:P10)=0,"",MAX(P6:P10)) -> 36.464061 | Q16: =IF(COUNT(Q6:Q10)=0,"",MAX(Q6:Q10)) -> 74.799427 | R16: =IF(COUNT(R6:R10)=0,"",MAX(R6:R10)) -> 12.03271
B17: Low | N17: =IF(COUNT(N6:N10)=0,"",MIN(N6:N10)) -> 12.846154 | O17: =IF(COUNT(O6:O10)=0,"",MIN(O6:O10)) -> 7.7945699 | P17: =IF(COUNT(P6:P10)=0,"",MIN(P6:P10)) -> 11.042963 | Q17: =IF(COUNT(Q6:Q10)=0,"",MIN(Q6:Q10)) -> 1.1965213 | R17: =IF(COUNT(R6:R10)=0,"",MIN(R6:R10)) -> 5.9572652
B19: Precedent Transactions
B20: Target | C20: Acquirer | D20: Date Announced | E20: Enterprise Value | F20: Equity Value | G20: Net Income (LTM) | H20: Net Income Growth (%) | I20: EBITDA (LTM) | J20: EBIT (LTM) | K20: EBITDAR (TTM) | N20: P/E | O20: EV/EBITDA | P20: EV/EBIT | Q20: PEG | R20: EV/EBITDAR
N21: =IF(COUNT(F21,G21)<2,"",IF(G21<=0,"NM",F21/G21)) | O21: =IF(COUNT(E21,I21)<2,"",IF(I21<=0,"NM",E21/I21)) | P21: =IF(COUNT(E21,J21)<2,"",IF(J21<=0,"NM",E21/J21)) | Q21: =IF(OR(ISNUMBER(N21)=FALSE(),COUNT(H21)=0),"",IF(H21<=0,"NM",N21/(H21*100))) | R21: =IF(COUNT(E21,K21)<2,"",IF(K21<=0,"NM",E21/K21))
N22: =IF(COUNT(F22,G22)<2,"",IF(G22<=0,"NM",F22/G22)) | O22: =IF(COUNT(E22,I22)<2,"",IF(I22<=0,"NM",E22/I22)) | P22: =IF(COUNT(E22,J22)<2,"",IF(J22<=0,"NM",E22/J22)) | Q22: =IF(OR(ISNUMBER(N22)=FALSE(),COUNT(H22)=0),"",IF(H22<=0,"NM",N22/(H22*100))) | R22: =IF(COUNT(E22,K22)<2,"",IF(K22<=0,"NM",E22/K22))
N23: =IF(COUNT(F23,G23)<2,"",IF(G23<=0,"NM",F23/G23)) | O23: =IF(COUNT(E23,I23)<2,"",IF(I23<=0,"NM",E23/I23)) | P23: =IF(COUNT(E23,J23)<2,"",IF(J23<=0,"NM",E23/J23)) | Q23: =IF(OR(ISNUMBER(N23)=FALSE(),COUNT(H23)=0),"",IF(H23<=0,"NM",N23/(H23*100))) | R23: =IF(COUNT(E23,K23)<2,"",IF(K23<=0,"NM",E23/K23))
N24: =IF(COUNT(F24,G24)<2,"",IF(G24<=0,"NM",F24/G24)) | O24: =IF(COUNT(E24,I24)<2,"",IF(I24<=0,"NM",E24/I24)) | P24: =IF(COUNT(E24,J24)<2,"",IF(J24<=0,"NM",E24/J24)) | Q24: =IF(OR(ISNUMBER(N24)=FALSE(),COUNT(H24)=0),"",IF(H24<=0,"NM",N24/(H24*100))) | R24: =IF(COUNT(E24,K24)<2,"",IF(K24<=0,"NM",E24/K24))
N25: =IF(COUNT(F25,G25)<2,"",IF(G25<=0,"NM",F25/G25)) | O25: =IF(COUNT(E25,I25)<2,"",IF(I25<=0,"NM",E25/I25)) | P25: =IF(COUNT(E25,J25)<2,"",IF(J25<=0,"NM",E25/J25)) | Q25: =IF(OR(ISNUMBER(N25)=FALSE(),COUNT(H25)=0),"",IF(H25<=0,"NM",N25/(H25*100))) | R25: =IF(COUNT(E25,K25)<2,"",IF(K25<=0,"NM",E25/K25))
B27: Mean | N27: =IF(COUNT(N21:N25)=0,"",AVERAGE(N21:N25)) | O27: =IF(COUNT(O21:O25)=0,"",AVERAGE(O21:O25)) | P27: =IF(COUNT(P21:P25)=0,"",AVERAGE(P21:P25)) | Q27: =IF(COUNT(Q21:Q25)=0,"",AVERAGE(Q21:Q25)) | R27: =IF(COUNT(R21:R25)=0,"",AVERAGE(R21:R25))
B28: Median | N28: =IF(COUNT(N21:N25)=0,"",MEDIAN(N21:N25)) | O28: =IF(COUNT(O21:O25)=0,"",MEDIAN(O21:O25)) | P28: =IF(COUNT(P21:P25)=0,"",MEDIAN(P21:P25)) | Q28: =IF(COUNT(Q21:Q25)=0,"",MEDIAN(Q21:Q25)) | R28: =IF(COUNT(R21:R25)=0,"",MEDIAN(R21:R25))
B29: 25th Percentile | N29: =IF(COUNT(N21:N25)=0,"",QUARTILE(N21:N25,1)) | O29: =IF(COUNT(O21:O25)=0,"",QUARTILE(O21:O25,1)) | P29: =IF(COUNT(P21:P25)=0,"",QUARTILE(P21:P25,1)) | Q29: =IF(COUNT(Q21:Q25)=0,"",QUARTILE(Q21:Q25,1)) | R29: =IF(COUNT(R21:R25)=0,"",QUARTILE(R21:R25,1))
B30: 75th Percentile | N30: =IF(COUNT(N21:N25)=0,"",QUARTILE(N21:N25,3)) | O30: =IF(COUNT(O21:O25)=0,"",QUARTILE(O21:O25,3)) | P30: =IF(COUNT(P21:P25)=0,"",QUARTILE(P21:P25,3)) | Q30: =IF(COUNT(Q21:Q25)=0,"",QUARTILE(Q21:Q25,3)) | R30: =IF(COUNT(R21:R25)=0,"",QUARTILE(R21:R25,3))
B31: High | N31: =IF(COUNT(N21:N25)=0,"",MAX(N21:N25)) | O31: =IF(COUNT(O21:O25)=0,"",MAX(O21:O25)) | P31: =IF(COUNT(P21:P25)=0,"",MAX(P21:P25)) | Q31: =IF(COUNT(Q21:Q25)=0,"",MAX(Q21:Q25)) | R31: =IF(COUNT(R21:R25)=0,"",MAX(R21:R25))
B32: Low | N32: =IF(COUNT(N21:N25)=0,"",MIN(N21:N25)) | O32: =IF(COUNT(O21:O25)=0,"",MIN(O21:O25)) | P32: =IF(COUNT(P21:P25)=0,"",MIN(P21:P25)) | Q32: =IF(COUNT(Q21:Q25)=0,"",MIN(Q21:Q25)) | R32: =IF(COUNT(R21:R25)=0,"",MIN(R21:R25))
B34: O'Reilly Automotive, Inc. Metrics (TTM Q2 FY2026)
B35: EPS (Diluted) | C35: ='IS Annual'!F21 -> 3.14
B36: EPS Growth (%) | C36: 0.1105
B37: EBITDA | C37: ='IS Annual'!F10+'CF Annual'!F8 -> 4169.744
B38: EBIT | C38: ='IS Annual'!F10 -> 3632.03
B39: EBITDAR (TTM) | C39: 4639.029
B40: Net Debt | C40: ='DCF Model'!I95 -> 6752.362
B41: Diluted Shares (mm) | C41: ='DCF Model'!I5 -> 808.96079
B44: Implied Value Per Share: Trading Comps
B45: Multiple | C45: 25th Percentile | D45: Median | E45: 75th Percentile
B46: P/E | C46: =IF(OR(ISNUMBER($N$14)=FALSE(),ISNUMBER($C$35)=FALSE()),"",IF($C$35<=0,"NM",$N$14*$C$35)) -> 59.590428 | D46: =IF(OR(ISNUMBER($N$13)=FALSE(),ISNUMBER($C$35)=FALSE()),"",IF($C$35<=0,"NM",$N$13*$C$35)) -> 95.542464 | E46: =IF(OR(ISNUMBER($N$15)=FALSE(),ISNUMBER($C$35)=FALSE()),"",IF($C$35<=0,"NM",$N$15*$C$35)) -> 220.271
B47: EV/EBITDA | C47: =IF(OR(ISNUMBER($O$14)=FALSE(),ISNUMBER($C$37)=FALSE()),"",IF($C$37<=0,"NM",($O$14*$C$37-$C$40)/$C$41)) -> 43.17663 | D47: =IF(OR(ISNUMBER($O$13)=FALSE(),ISNUMBER($C$37)=FALSE()),"",IF($C$37<=0,"NM",($O$13*$C$37-$C$40)/$C$41)) -> 47.634651 | E47: =IF(OR(ISNUMBER($O$15)=FALSE(),ISNUMBER($C$37)=FALSE()),"",IF($C$37<=0,"NM",($O$15*$C$37-$C$40)/$C$41)) -> 58.514754
...

Sheet Liquidation
B1: O'Reilly Automotive, Inc. | Liquidation Value (TTM Q2 FY2026 Balance Sheet)
B2: $mm except per share
B4: Asset | C4: Book Value | D4: Orderly Recovery | E4: Orderly Value | F4: Fire Sale Recovery | G4: Fire Sale Value
B5: Cash and cash equivalents | C5: ='BS Annual'!F7 -> 262.181 | D5: 1 | E5: =C5*D5 -> 262.181 | F5: 1 | G5: =C5*F5 -> 262.181
B6: Accounts receivable, net | C6: ='BS Annual'!F8 -> 457.785 | D6: 0.85 | E6: =C6*D6 -> 389.11725 | F6: 0.6 | G6: =C6*F6 -> 274.671
B7: Amounts receivable from suppliers | C7: ='BS Annual'!F9 -> 170.728 | D7: 0.85 | E7: =C7*D7 -> 145.1188 | F7: 0.6 | G7: =C7*F7 -> 102.4368
B8: Inventory | C8: ='BS Annual'!F10 -> 5971.856 | D8: 0.65 | E8: =C8*D8 -> 3881.7064 | F8: 0.4 | G8: =C8*F8 -> 2388.7424
B9: Other current assets | C9: ='BS Annual'!F11 -> 337.082 | D9: 0.25 | E9: =C9*D9 -> 84.2705 | F9: 0 | G9: =C9*F9 -> 0
B10: Net property and equipment | C10: ='BS Annual'!F15 -> 6550.245 | D10: 0.4 | E10: =C10*D10 -> 2620.098 | F10: 0.15 | G10: =C10*F10 -> 982.53675
B11: Operating lease, right-of-use assets | C11: ='BS Annual'!F16 -> 2484.413 | D11: 0 | E11: =C11*D11 -> 0 | F11: 0 | G11: =C11*F11 -> 0
B12: Goodwill | C12: ='BS Annual'!F17 -> 955.211 | D12: 0 | E12: =C12*D12 -> 0 | F12: 0 | G12: =C12*F12 -> 0
B13: Other assets, net | C13: ='BS Annual'!F18 -> 199.615 | D13: 0.1 | E13: =C13*D13 -> 19.9615 | F13: 0 | G13: =C13*F13 -> 0
B14: Gross Proceeds | C14: =SUM(C5:C13) -> 17389.116 | E14: =SUM(E5:E13) -> 7402.4534 | G14: =SUM(G5:G13) -> 4010.568
B15: Less: Wind-Down Costs | D15: 0.05 | E15: =-E14*D15 -> -370.12267 | F15: 0.1 | G15: =-G14*F15 -> -401.0568
B16: Less: Total Liabilities | C16: =-'BS Annual'!F34 -> -19224.841 | E16: =C16 -> -19224.841 | G16: =C16 -> -19224.841
B17: Net Liquidation Value | E17: =E14+E15+E16 -> -12192.51 | G17: =G14+G15+G16 -> -15615.33
B18: Diluted Shares (mm) | E18: ='DCF Model'!I5 -> 808.96079 | G18: ='DCF Model'!I5 -> 808.96079
B19: Liquidation Value Per Share | E19: =E17/E18 -> -15.071818 | G19: =G17/G18 -> -19.30295

Sheet Summary
B1: O'Reilly Automotive, Inc. | Valuation Summary
B2: $ per share
B4: Current Share Price | C4: ='DCF Model'!I4 -> 86.07
B6: Method | C6: Low | D6: Base | E6: High | F6: Base vs. Price
B7: DCF (WACC +/- 1%) | C7: ='DCF Model'!K103 -> 48.970837 | D7: ='DCF Model'!I98 -> 60.65505 | E7: ='DCF Model'!I103 -> 78.306784 | F7: =IF(ISNUMBER(D7),D7/$C$4-1,"") -> -0.29528233 | H7: =IF(AND(ISNUMBER(C7),ISNUMBER(E7)),MAX(0,MIN(C7,E7)),0) -> 48.970837 | I7: =IF(AND(ISNUMBER(C7),ISNUMBER(E7)),MAX(0,MAX(C7,E7))-H7,0) -> 29.335948
B8: Trading Comps: P/E | C8: =Comps!C46 -> 59.590428 | D8: =Comps!D46 -> 95.542464 | E8: =Comps!E46 -> 220.271 | F8: =IF(ISNUMBER(D8),D8/$C$4-1,"") -> 0.11005535 | H8: =IF(AND(ISNUMBER(C8),ISNUMBER(E8)),MAX(0,MIN(C8,E8)),0) -> 59.590428 | I8: =IF(AND(ISNUMBER(C8),ISNUMBER(E8)),MAX(0,MAX(C8,E8))-H8,0) -> 160.68057
B9: Trading Comps: EV/EBITDA | C9: =Comps!C47 -> 43.17663 | D9: =Comps!D47 -> 47.634651 | E9: =Comps!E47 -> 58.514754 | F9: =IF(ISNUMBER(D9),D9/$C$4-1,"") -> -0.44655919 | H9: =IF(AND(ISNUMBER(C9),ISNUMBER(E9)),MAX(0,MIN(C9,E9)),0) -> 43.17663 | I9: =IF(AND(ISNUMBER(C9),ISNUMBER(E9)),MAX(0,MAX(C9,E9))-H9,0) -> 15.338123
B10: Trading Comps: EV/EBIT | C10: =Comps!C48 -> 60.240199 | D10: =Comps!D48 -> 80.544204 | E10: =Comps!E48 -> 90.067901 | F10: =IF(ISNUMBER(D10),D10/$C$4-1,"") -> -0.064201188 | H10: =IF(AND(ISNUMBER(C10),ISNUMBER(E10)),MAX(0,MIN(C10,E10)),0) -> 60.240199 | I10: =IF(AND(ISNUMBER(C10),ISNUMBER(E10)),MAX(0,MAX(C10,E10))-H10,0) -> 29.827702
B11: Trading Comps: PEG | C11: =Comps!C49 -> 55.194822 | D11: =Comps!D49 -> 103.09168 | E11: =Comps!E49 -> 132.26202 | F11: =IF(ISNUMBER(D11),D11/$C$4-1,"") -> 0.19776553 | H11: =IF(AND(ISNUMBER(C11),ISNUMBER(E11)),MAX(0,MIN(C11,E11)),0) -> 55.194822 | I11: =IF(AND(ISNUMBER(C11),ISNUMBER(E11)),MAX(0,MAX(C11,E11))-H11,0) -> 77.067196
B12: Trading Comps: EV/EBITDAR | C12: =Comps!C50 -> 38.594168 | D12: =Comps!D50 -> 51.373038 | E12: =Comps!E50 -> 56.014149 | F12: =IF(ISNUMBER(D12),D12/$C$4-1,"") -> -0.40312492 | H12: =IF(AND(ISNUMBER(C12),ISNUMBER(E12)),MAX(0,MIN(C12,E12)),0) -> 38.594168 | I12: =IF(AND(ISNUMBER(C12),ISNUMBER(E12)),MAX(0,MAX(C12,E12))-H12,0) -> 17.419981
B13: Precedent Transactions: P/E | C13: =Comps!C55 | D13: =Comps!D55 | E13: =Comps!E55 | F13: =IF(ISNUMBER(D13),D13/$C$4-1,"") | H13: =IF(AND(ISNUMBER(C13),ISNUMBER(E13)),MAX(0,MIN(C13,E13)),0) -> 0 | I13: =IF(AND(ISNUMBER(C13),ISNUMBER(E13)),MAX(0,MAX(C13,E13))-H13,0) -> 0
B14: Precedent Transactions: EV/EBITDA | C14: =Comps!C56 | D14: =Comps!D56 | E14: =Comps!E56 | F14: =IF(ISNUMBER(D14),D14/$C$4-1,"") | H14: =IF(AND(ISNUMBER(C14),ISNUMBER(E14)),MAX(0,MIN(C14,E14)),0) -> 0 | I14: =IF(AND(ISNUMBER(C14),ISNUMBER(E14)),MAX(0,MAX(C14,E14))-H14,0) -> 0
B15: Precedent Transactions: EV/EBIT | C15: =Comps!C57 | D15: =Comps!D57 | E15: =Comps!E57 | F15: =IF(ISNUMBER(D15),D15/$C$4-1,"") | H15: =IF(AND(ISNUMBER(C15),ISNUMBER(E15)),MAX(0,MIN(C15,E15)),0) -> 0 | I15: =IF(AND(ISNUMBER(C15),ISNUMBER(E15)),MAX(0,MAX(C15,E15))-H15,0) -> 0
B16: Precedent Transactions: PEG | C16: =Comps!C58 | D16: =Comps!D58 | E16: =Comps!E58 | F16: =IF(ISNUMBER(D16),D16/$C$4-1,"") | H16: =IF(AND(ISNUMBER(C16),ISNUMBER(E16)),MAX(0,MIN(C16,E16)),0) -> 0 | I16: =IF(AND(ISNUMBER(C16),ISNUMBER(E16)),MAX(0,MAX(C16,E16))-H16,0) -> 0
B17: Precedent Transactions: EV/EBITDAR | C17: =Comps!C59 | D17: =Comps!D59 | E17: =Comps!E59 | F17: =IF(ISNUMBER(D17),D17/$C$4-1,"") | H17: =IF(AND(ISNUMBER(C17),ISNUMBER(E17)),MAX(0,MIN(C17,E17)),0) -> 0 | I17: =IF(AND(ISNUMBER(C17),ISNUMBER(E17)),MAX(0,MAX(C17,E17))-H17,0) -> 0
B18: Liquidation (Fire Sale to Orderly) | C18: =Liquidation!G19 -> -19.30295 | E18: =Liquidation!E19 -> -15.071818 | F18: =IF(ISNUMBER(D18),D18/$C$4-1,"") | H18: =IF(AND(ISNUMBER(C18),ISNUMBER(E18)),MAX(0,MIN(C18,E18)),0) -> 0 | I18: =IF(AND(ISNUMBER(C18),ISNUMBER(E18)),MAX(0,MAX(C18,E18))-H18,0) -> 0
