Workbook

Sheet Positions
B1: Positions | C1: =TODAY() -> 46282
B2: Ticker | C2: Name | D2: Type | E2: Current Price ($) | F2: Shares | G2: Avg Cost / Share ($) | H2: Cost Basis ($) | I2: Dividends Received ($) | J2: Market Value ($) | K2: Gain / Loss ($) | L2: Gain % | M2: Total Return % | N2: Allocation %
A3: #VALUE! | B3: SPY | C3: SPDR S&P 500 ETF Trust | D3: ETF | E3: {=_FV(A3,"Price")} -> 762.43 | F3: 2.284804 | G3: 771.9 | H3: =IF(A3="","",F3*G3) -> 1763.6402 | I3: 3.37 | J3: =IF(A3="","",F3*E3) -> 1742.0031 | K3: =IF(A3="","",J3-H3) -> -21.637094 | L3: =IF(OR(A3="",H3=0),"",K3/H3) -> -0.012268429 | M3: =IF(OR(A3="",H3=0),"",(K3+I3)/H3) -> -0.010357608 | N3: =IF(OR(A3="",$J$12=0),"",J3/$J$12) -> 0.25457832
A4: #VALUE! | B4: QQQ | C4: {=_FV(A4,"Name")} -> Invesco QQQ Trust 1 | D4: ETF | E4: {=_FV(A4,"Price")} -> 716.83 | F4: 2.4565 | G4: 692.68 | H4: =IF(B4="","",F4*G4) -> 1701.5684 | I4: =0.25+0.22+0.24+0.21+0.18+0.22+0.17+0.07 -> 1.56 | J4: =IF(B4="","",F4*E4) -> 1760.8929 | K4: =IF(B4="","",J4-H4) -> 59.324475 | L4: =IF(OR(B4="",H4=0),"",K4/H4) -> 0.034864584 | M4: =IF(OR(B4="",H4=0),"",(K4+I4)/H4) -> 0.035781385 | N4: =IF(OR(B4="",$J$12=0),"",J4/$J$12) -> 0.2573389
A5: #VALUE! | B5: VNQ | C5: {=_FV(A5,"Name")} -> Vanguard RE;ETF | D5: ETF | E5: {=_FV(A5,"Price")} -> 94 | F5: 6.655606 | G5: 97.8 | H5: =IF(B5="","",F5*G5) -> 650.91827 | I5: 0.92 | J5: =IF(B5="","",F5*E5) -> 625.62696 | K5: =IF(B5="","",J5-H5) -> -25.291303 | L5: =IF(OR(B5="",H5=0),"",K5/H5) -> -0.038854806 | M5: =IF(OR(B5="",H5=0),"",(K5+I5)/H5) -> -0.037441418 | N5: =IF(OR(B5="",$J$12=0),"",J5/$J$12) -> 0.091429838
A6: #VALUE! | B6: LLY | C6: {=_FV(A6,"Name")} -> ELI LILLY AND COMPANY | D6: Stock | E6: {=_FV(A6,"Price")} -> 1144.43 | F6: 0.204902 | G6: 867.59 | H6: =IF(B6="","",F6*G6) -> 177.77093 | I6: 1.17 | J6: =IF(B6="","",F6*E6) -> 234.496 | K6: =IF(B6="","",J6-H6) -> 56.72507 | L6: =IF(OR(B6="",H6=0),"",K6/H6) -> 0.31909081 | M6: =IF(OR(B6="",H6=0),"",(K6+I6)/H6) -> 0.32567232 | N6: =IF(OR(B6="",$J$12=0),"",J6/$J$12) -> 0.034269512
A7: #VALUE! | B7: ADBE | C7: {=_FV(A7,"Name")} -> ADOBE INC. | D7: Stock | E7: {=_FV(A7,"Price")} -> 250.2563 | F7: 1.817496 | G7: 275.1 | H7: =IF(B7="","",F7*G7) -> 499.99315 | I7: 0 | J7: =IF(B7="","",F7*E7) -> 454.83982 | K7: =IF(B7="","",J7-H7) -> -45.153325 | L7: =IF(OR(B7="",H7=0),"",K7/H7) -> -0.090307888 | M7: =IF(OR(B7="",H7=0),"",(K7+I7)/H7) -> -0.090307888 | N7: =IF(OR(B7="",$J$12=0),"",J7/$J$12) -> 0.066470811
A8: #VALUE! | B8: UBER | C8: {=_FV(A8,"Name")} -> UBER TECHNOLOGIES, INC. | D8: Stock | E8: {=_FV(A8,"Price")} -> 70.87 | F8: 6.557377 | G8: 76.25 | H8: =IF(B8="","",F8*G8) -> 500 | I8: 0 | J8: =IF(B8="","",F8*E8) -> 464.72131 | K8: =IF(B8="","",J8-H8) -> -35.278688 | L8: =IF(OR(B8="",H8=0),"",K8/H8) -> -0.070557377 | M8: =IF(OR(B8="",H8=0),"",(K8+I8)/H8) -> -0.070557377 | N8: =IF(OR(B8="",$J$12=0),"",J8/$J$12) -> 0.067914902
A10: $ | B10: USD | C10: Cash | D10: Cash | E10: =G10 -> 1 | F10: 1560.12 | G10: 1 | H10: =IF(B10="","",F10*G10) -> 1560.12 | J10: =IF(B10="","",F10*E10) -> 1560.12 | K10: =IF(B10="","",J10-H10) -> 0 | L10: =IF(OR(B10="",H10=0),"",K10/H10) -> 0 | M10: =IF(OR(B10="",H10=0),"",(K10+I10)/H10) -> 0 | N10: =IF(OR(B10="",$J$12=0),"",J10/$J$12) -> 0.22799772
H11: =IF(B11="","",F11*G11) | J11: =IF(B11="","",F11*E11) | K11: =IF(B11="","",J11-H11) | L11: =IF(OR(B11="",H11=0),"",K11/H11) | M11: =IF(OR(B11="",H11=0),"",(K11+I11)/H11) | N11: =IF(OR(B11="",$J$12=0),"",J11/$J$12)
B12: Total | H12: =SUM(H3:H11) -> 6854.011 | I12: =SUM(I3:I11) -> 7.02 | J12: =SUM(J3:J11) -> 6842.7001 | K12: =J12-H12 -> -11.310866 | L12: =IF(H12=0,"",K12/H12) -> -0.001650255 | M12: =IF(H12=0,"",(K12+I12)/H12) -> -0.00062603717 | N12: =IF(J12=0,"",SUM(N3:N11)) -> 1

Sheet Summary
A1: Portfolio Summary
A3: Metric | B3: Value
A4: Total Value | B4: =Positions!J12 -> 6842.7001
A5: Amount Invested (Cost Basis) | B5: =Positions!H12 -> 6854.011
A6: Unrealized Gain / Loss | B6: =Positions!K12 -> -11.310866
A7: Gain % (price only) | B7: =Positions!L12 -> -0.001650255
A8: Dividends Received | B8: =Positions!I12 -> 7.02
A9: Total Return % (incl. dividends) | B9: =Positions!M12 -> -0.00062603717
A10: Number of Positions | B10: =COUNTA(Positions!$B$3:$B$11) -> 7
A11: Largest Holding | B11: =IF(COUNT(Positions!$J$3:$J$11)=0,"",INDEX(Positions!$B$3:$B$11,MATCH(MAX(Positions!$J$3:$J$11),Positions!$J$3:$J$11,0))) -> QQQ
A12: Largest Holding Share | B12: =IF(COUNT(Positions!$N$3:$N$11)=0,"",MAX(Positions!$N$3:$N$11)) -> 0.2573389
A13: Best Total Return | B13: =IF(COUNT(Positions!$M$3:$M$11)=0,"",INDEX(Positions!$B$3:$B$11,MATCH(MAX(Positions!$M$3:$M$11),Positions!$M$3:$M$11,0))) -> LLY
A14: Best Total Return % | B14: =IF(COUNT(Positions!$M$3:$M$11)=0,"",MAX(Positions!$M$3:$M$11)) -> 0.32567232
A15: Worst Total Return | B15: =IF(COUNT(Positions!$M$3:$M$11)=0,"",INDEX(Positions!$B$3:$B$11,MATCH(MIN(Positions!$M$3:$M$11),Positions!$M$3:$M$11,0))) -> ADBE
A16: Worst Total Return % | B16: =IF(COUNT(Positions!$M$3:$M$11)=0,"",MIN(Positions!$M$3:$M$11)) -> -0.090307888
A18: Allocation by Type
A19: Type | B19: Market Value ($) | C19: Share of Portfolio | D19: Positions
A20: Stock | B20: =SUMIF(Positions!$D$3:$D$11,A20,Positions!$J$3:$J$11) -> 1154.0571 | C20: =IF($B$27=0,"",B20/$B$27) -> 0.16865523 | D20: =COUNTIF(Positions!$D$3:$D$11,A20) -> 3
A21: ETF | B21: =SUMIF(Positions!$D$3:$D$11,A21,Positions!$J$3:$J$11) -> 4128.523 | C21: =IF($B$27=0,"",B21/$B$27) -> 0.60334706 | D21: =COUNTIF(Positions!$D$3:$D$11,A21) -> 3
A22: Mutual Fund | B22: =SUMIF(Positions!$D$3:$D$11,A22,Positions!$J$3:$J$11) -> 0 | C22: =IF($B$27=0,"",B22/$B$27) -> 0 | D22: =COUNTIF(Positions!$D$3:$D$11,A22) -> 0
A23: Bond | B23: =SUMIF(Positions!$D$3:$D$11,A23,Positions!$J$3:$J$11) -> 0 | C23: =IF($B$27=0,"",B23/$B$27) -> 0 | D23: =COUNTIF(Positions!$D$3:$D$11,A23) -> 0
A24: Crypto | B24: =SUMIF(Positions!$D$3:$D$11,A24,Positions!$J$3:$J$11) -> 0 | C24: =IF($B$27=0,"",B24/$B$27) -> 0 | D24: =COUNTIF(Positions!$D$3:$D$11,A24) -> 0
A25: Cash | B25: =SUMIF(Positions!$D$3:$D$11,A25,Positions!$J$3:$J$11) -> 1560.12 | C25: =IF($B$27=0,"",B25/$B$27) -> 0.22799772 | D25: =COUNTIF(Positions!$D$3:$D$11,A25) -> 1
A26: Other | B26: =SUMIF(Positions!$D$3:$D$11,A26,Positions!$J$3:$J$11) -> 0 | C26: =IF($B$27=0,"",B26/$B$27) -> 0 | D26: =COUNTIF(Positions!$D$3:$D$11,A26) -> 0
A27: Total | B27: =SUM(B20:B26) -> 6842.7001 | C27: =IF(B27=0,"",SUM(C20:C26)) -> 1 | D27: =SUM(D20:D26) -> 7

Sheet Activity
A1: Activity
I2: Check Against Positions
A3: Date | B3: Ticker | C3: Activity | D3: Shares | E3: Price / Share ($) | F3: Amount ($) | G3: Notes | I3: Ticker | J3: Shares per Activity | K3: Shares per Positions | L3: Difference | M3: Money Invested ($) | N3: Dividends ($) | O3: Sale Proceeds ($)
A4: 45492 | B4: SPY | C4: Buy | D4: 0.04543 | E4: 550.18 | F4: 24.99 | I4: =IF(Positions!B3="","",Positions!B3) -> SPY | J4: =IF(I4="","",SUMIF($B$4:$B$499,I4,$D$4:$D$499)) -> 2.284804 | K4: =IF(I4="","",INDEX(Positions!$F$3:$F$11,MATCH(I4,Positions!$B$3:$B$11,0))) -> 2.284804 | L4: =IF(I4="","",ROUND(J4-K4,6)) -> 0 | M4: =IF($I4="","",SUMIFS($F$4:$F$499,$B$4:$B$499,$I4,$C$4:$C$499,"Buy")) -> 2199.99 | N4: =IF($I4="","",SUMIFS($F$4:$F$499,$B$4:$B$499,$I4,$C$4:$C$499,"Dividend")) -> 3.37 | O4: =IF($I4="","",SUMIFS($F$4:$F$499,$B$4:$B$499,$I4,$C$4:$C$499,"Sell")) -> 500
A5: 45505 | B5: QQQ | C5: Buy | D5: 0.05366 | E5: 465.87 | F5: 25 | I5: =IF(Positions!B4="","",Positions!B4) -> QQQ | J5: =IF(I5="","",SUMIF($B$4:$B$499,I5,$D$4:$D$499)) -> 2.4565 | K5: =IF(I5="","",INDEX(Positions!$F$3:$F$11,MATCH(I5,Positions!$B$3:$B$11,0))) -> 2.4565 | L5: =IF(I5="","",ROUND(J5-K5,6)) -> 0 | M5: =IF($I5="","",SUMIFS($F$4:$F$499,$B$4:$B$499,$I5,$C$4:$C$499,"Buy")) -> 1700 | N5: =IF($I5="","",SUMIFS($F$4:$F$499,$B$4:$B$499,$I5,$C$4:$C$499,"Dividend")) -> 1.56 | O5: =IF($I5="","",SUMIFS($F$4:$F$499,$B$4:$B$499,$I5,$C$4:$C$499,"Sell")) -> 0
A6: 45513 | B6: QQQ | C6: Buy | D6: 0.055965 | E6: 446.71 | F6: 25 | G6: Limit order | I6: =IF(Positions!B5="","",Positions!B5) -> VNQ | J6: =IF(I6="","",SUMIF($B$4:$B$499,I6,$D$4:$D$499)) -> 6.655606 | K6: =IF(I6="","",INDEX(Positions!$F$3:$F$11,MATCH(I6,Positions!$B$3:$B$11,0))) -> 6.655606 | L6: =IF(I6="","",ROUND(J6-K6,6)) -> 0 | M6: =IF($I6="","",SUMIFS($F$4:$F$499,$B$4:$B$499,$I6,$C$4:$C$499,"Buy")) -> 650 | N6: =IF($I6="","",SUMIFS($F$4:$F$499,$B$4:$B$499,$I6,$C$4:$C$499,"Dividend")) -> 0.92 | O6: =IF($I6="","",SUMIFS($F$4:$F$499,$B$4:$B$499,$I6,$C$4:$C$499,"Sell")) -> 0
A7: 45520 | B7: SPY | C7: Buy | D7: 0.045105 | E7: 554.25 | F7: 25 | I7: =IF(Positions!B6="","",Positions!B6) -> LLY | J7: =IF(I7="","",SUMIF($B$4:$B$499,I7,$D$4:$D$499)) -> 0.204902 | K7: =IF(I7="","",INDEX(Positions!$F$3:$F$11,MATCH(I7,Positions!$B$3:$B$11,0))) -> 0.204902 | L7: =IF(I7="","",ROUND(J7-K7,6)) -> 0 | M7: =IF($I7="","",SUMIFS($F$4:$F$499,$B$4:$B$499,$I7,$C$4:$C$499,"Buy")) -> 176.6 | N7: =IF($I7="","",SUMIFS($F$4:$F$499,$B$4:$B$499,$I7,$C$4:$C$499,"Dividend")) -> 1.17 | O7: =IF($I7="","",SUMIFS($F$4:$F$499,$B$4:$B$499,$I7,$C$4:$C$499,"Sell")) -> 0
A8: 45596 | B8: SPY | C8: Dividend | F8: 0.16 | I8: =IF(Positions!B7="","",Positions!B7) -> ADBE | J8: =IF(I8="","",SUMIF($B$4:$B$499,I8,$D$4:$D$499)) -> 1.817496 | K8: =IF(I8="","",INDEX(Positions!$F$3:$F$11,MATCH(I8,Positions!$B$3:$B$11,0))) -> 1.817496 | L8: =IF(I8="","",ROUND(J8-K8,6)) -> 0 | M8: =IF($I8="","",SUMIFS($F$4:$F$499,$B$4:$B$499,$I8,$C$4:$C$499,"Buy")) -> 500 | N8: =IF($I8="","",SUMIFS($F$4:$F$499,$B$4:$B$499,$I8,$C$4:$C$499,"Dividend")) -> 0 | O8: =IF($I8="","",SUMIFS($F$4:$F$499,$B$4:$B$499,$I8,$C$4:$C$499,"Sell")) -> 0
A9: 45596 | B9: SPY | C9: Dividend Reinvest | D9: 0.000278 | E9: 575.01 | F9: 0.16 | I9: =IF(Positions!B8="","",Positions!B8) -> UBER | J9: =IF(I9="","",SUMIF($B$4:$B$499,I9,$D$4:$D$499)) -> 6.557377 | K9: =IF(I9="","",INDEX(Positions!$F$3:$F$11,MATCH(I9,Positions!$B$3:$B$11,0))) -> 6.557377 | L9: =IF(I9="","",ROUND(J9-K9,6)) -> 0 | M9: =IF($I9="","",SUMIFS($F$4:$F$499,$B$4:$B$499,$I9,$C$4:$C$499,"Buy")) -> 500 | N9: =IF($I9="","",SUMIFS($F$4:$F$499,$B$4:$B$499,$I9,$C$4:$C$499,"Dividend")) -> 0 | O9: =IF($I9="","",SUMIFS($F$4:$F$499,$B$4:$B$499,$I9,$C$4:$C$499,"Sell")) -> 0
A10: 45596 | B10: QQQ | C10: Dividend | F10: 0.07 | I10: USD | J10: =IF(I10="","",SUMIF($B$4:$B$499,I10,$D$4:$D$499)) -> 1560.12 | K10: =IF(I10="","",INDEX(Positions!$F$3:$F$11,MATCH(I10,Positions!$B$3:$B$11,0))) -> 1560.12 | L10: =IF(I10="","",ROUND(J10-K10,6)) -> 0 | M10: =IF($I10="","",SUMIFS($F$4:$F$499,$B$4:$B$499,$I10,$C$4:$C$499,"Buy")) -> 1560.12 | N10: =IF($I10="","",SUMIFS($F$4:$F$499,$B$4:$B$499,$I10,$C$4:$C$499,"Dividend")) -> 0 | O10: =IF($I10="","",SUMIFS($F$4:$F$499,$B$4:$B$499,$I10,$C$4:$C$499,"Sell")) -> 0
A11: 45596 | B11: QQQ | C11: Dividend Reinvest | D11: 0.000142 | E11: 490.32 | F11: 0.07 | I11: Total | M11: =SUM(M4:M10) -> 7286.71 | N11: =SUM(N4:N10) -> 7.02 | O11: =SUM(O4:O10) -> 500
A12: 45618 | B12: SPY | C12: Buy | D12: 0.084226 | E12: 593.64 | F12: 50
A13: 45618 | B13: QQQ | C13: Buy | D13: 0.099117 | E13: 504.45 | F13: 50
A14: 45657 | B14: QQQ | C14: Dividend | F14: 0.17
A15: 45657 | B15: QQQ | C15: Dividend Reinvest | D15: 0.000331 | E15: 512.19 | F15: 0.17
A16: 45688 | B16: SPY | C16: Dividend | F16: 0.34
A17: 45688 | B17: SPY | C17: Dividend Reinvest | D17: 0.00057 | E17: 596.28 | F17: 0.34
A18: 45695 | B18: SPY | C18: Buy | D18: 0.08312 | E18: 601.5 | F18: 50
A19: 45695 | B19: QQQ | C19: Buy | D19: 0.09545 | E19: 523.81 | F19: 50
A20: 45777 | B20: SPY | C20: Dividend | F20: 0.44
A21: 45777 | B21: SPY | C21: Dividend Reinvest | D21: 0.000781 | E21: 563.02 | F21: 0.44
A22: 45777 | B22: QQQ | C22: Dividend | F22: 0.22
A23: 45777 | B23: QQQ | C23: Dividend Reinvest | D23: 0.000453 | E23: 485.22 | F23: 0.22
A24: 45869 | B24: SPY | C24: Dividend | F24: 0.46
A25: 45869 | B25: SPY | C25: Dividend Reinvest | D25: 0.000739 | E25: 621.64 | F25: 0.46
A26: 45869 | B26: QQQ | C26: Dividend | F26: 0.18
A27: 45869 | B27: QQQ | C27: Dividend Reinvest | D27: 0.000325 | E27: 552.86 | F27: 0.18
A28: 45876 | B28: LLY | C28: Buy | D28: 0.12596 | E28: 639.85 | F28: 80.6
A29: 45910 | B29: LLY | C29: Dividend | F29: 0.19
A30: 45910 | B30: LLY | C30: Dividend Reinvest | D30: 0.000252 | E30: 753.96 | F30: 0.19
A31: 45961 | B31: SPY | C31: Dividend | F31: 0.48
A32: 45961 | B32: SPY | C32: Dividend Reinvest | D32: 0.000703 | E32: 682.74 | F32: 0.48
A33: 45961 | B33: QQQ | C33: Dividend | F33: 0.21
A34: 45961 | B34: QQQ | C34: Dividend Reinvest | D34: 0.000332 | E34: 631.85 | F34: 0.21
A35: 46001 | B35: LLY | C35: Dividend | F35: 0.19
A36: 46001 | B36: LLY | C36: Dividend Reinvest | D36: 0.000191 | E36: 992.13 | F36: 0.19
A37: 46022 | B37: QQQ | C37: Dividend | F37: 0.24
A38: 46022 | B38: QQQ | C38: Dividend Reinvest | D38: 0.000386 | E38: 621.23 | F38: 0.24
A39: 46052 | B39: SPY | C39: Dividend | F39: 0.52
A40: 46052 | B40: SPY | C40: Dividend Reinvest | D40: 0.00075 | E40: 692.98 | F40: 0.52
...
