Workbook

Sheet Main
B2: STDN | C2: as of 7/15/26
B3: Price | C3: 13.31
B4: Shares | C4: 160.67
B5: Market Cap | C5: =C3*C4 -> 2138.5177
B6: Cash
B7: Debt
B8: EV | C8: =C5+C7-C6 -> 2138.5177
B10: Founder/exec chairman: | C10: Thomas Hendrix
B11: CEO: | C11: Dr. Kurt Terrani
B12: CFO: | C12: Tom Dale/Kevin Harrill
B13: COO: | C13: Keeley Marracco

Sheet 10QIS
B2: Eli Lilly and Company (LLY)
B4: Historic Quarterly IS by Product | C4: Q1'26 | D4: Q2'26
B5: TRISO
B6: Other / Misc
B7: Total Revenue | C7: 593802
B8: COGS | C8: 5006006
B9: Gross Margin | C9: =C7-C8 -> -4412204 | D9: =D7-D8 -> 0
B10: SG&A | C10: 3832048
B11: Other expenses | C11: -529301
B12: Pre Tax Income | C12: =C9-SUM(C10:C11) -> -7714951
B13: Taxes | C13: 0
B14: Net Income (Loss) | C14: =C12-C13 -> -7714951 | D14: =D12-D13 -> 0
B15: EPS | C15: =C14/C16 -> #DIV/0! | D15: =D14/D16 -> #DIV/0!
B16: Shares
B18: Historic Drivers
B19: Historic Revenue Growth Rate | D19: =(D7-C7)/C7 -> -1
B20: Historic Gross Margin % | C20: =C9/C7 -> -7.4304297 | D20: =D9/D7 -> #DIV/0!
B21: Historic SG&A % | C21: =C10/C7 -> 6.4534104 | D21: =D10/D7 -> #DIV/0!
B22: Historic Tax rate | C22: =C13/C12 -> 0 | D22: =D13/D12 -> #DIV/0!

Sheet IS
B2: IS Assumptions | C2: =C10 -> FY'24 | D2: =D10 -> FY'25 | E2: =E10 -> FY'26 | F2: =F10 -> FY'27 | G2: =G10 -> FY'28 | H2: =H10 -> FY'29 | I2: =I10 -> FY'30
B3: TRISO Revenue Growth Rate
B4: Other Revenue Growth Rate
B5: Gross Margin %
B6: R&D %
B7: SG&A %
B8: Tax rate
B10: Annual Income Statement | C10: FY'24 | D10: FY'25 | E10: FY'26 | F10: FY'27 | G10: FY'28 | H10: FY'29 | I10: FY'30
B11: TRISO | C11: 0 | D11: 3140065
B12: Mounjaro | E12: =SUM('10QIS'!#REF!) -> #REF!
B13: Zepbound | E13: =SUM('10QIS'!#REF!) -> #REF!
B14: Trulicity | E14: =SUM('10QIS'!#REF!) -> #REF!
B15: Retatrutide | E15: =SUM('10QIS'!#REF!) -> #REF!
B16: Foundayo | E16: =SUM('10QIS'!#REF!) -> #REF!
B17: Basaglar | E17: =SUM('10QIS'!#REF!) -> #REF!
B18: Humalog | E18: =SUM('10QIS'!#REF!) -> #REF!
B19: Humulin | E19: =SUM('10QIS'!#REF!) -> #REF!
B20: Jardiance | E20: =SUM('10QIS'!#REF!) -> #REF!
B21: Emgality | E21: =SUM('10QIS'!#REF!) -> #REF!
B22: Kisunla | E22: =SUM('10QIS'!#REF!) -> #REF!
B23: Other | C23: 0 | D23: 0
B24: Total Revenue | C24: =C11+C23 -> 0 | D24: =D11+D23 -> 3140065 | E24: =E11+E23 -> 0
B25: COGS | C25: 0 | D25: 7672905
B26: Gross Margin | C26: =C24-C25 -> 0 | D26: =D24-D25 -> -4532840 | E26: =E24-E25 -> 0
B27: R&D | C27: 30297773 | D27: 0
B28: SG&A | C28: 669774 | D28: 4420156
B29: Asset retirement obligation | C29: 895 | D29: 79364
B30: Other expenses | C30: 25628000 | D30: =7725000-(853000+363415) -> 6508585
B31: Pre Tax Income | C31: =C26-SUM(C27:C30) -> -56596442 | D31: =D26-SUM(D27:D30) -> -15540945
B32: Taxes | C32: 0 | D32: 0
B33: Net Income (Loss) | C33: =C31-C32 -> -56596442 | D33: =D31-D32 -> -15540945 | E33: =E31-E32 -> 0
B34: EPS | C34: =(C33/100)/C35 -> -3522.527 | D34: =(D33/100)/D35 -> -967.25867 | E34: =(E33/100)/E35 -> 0
B35: Shares | C35: 160.67 | D35: 160.67 | E35: 160.67

Sheet BS
B2: BS Assumptions | C2: FY'26 | D2: FY'27
B3: Accounts Receivable % of Revenue
B4: Other Receivables % of Revenue
B5: Inventories % of COGS
B6: Prepaid Expenses % of Revenue
B7: Other Current Assets % of Revenue
B8: Accounts Payable % of COGS
B9: Employee Compensation % of Revenue
B10: Sales Rebates and Discounts % of Revenue
B11: Other Current Liabilities % of Revenue
B13: Balance Sheet
B14: Cash and cash equivalents
B15: Accounts receivable
... B41: Check (Assets less Liab. & Equity)

Sheet CFS
B2: CFS Assumptions | C2: FY'24 | D2: FY'25 | E2: FY'26
B3: D&A % of Revenue
B4: Stock-Based Compensation % of Revenue
B5: Capital Expenditures % of Revenue
B6: Dividend Payout Ratio (or Dividends per Share)
B7: Net Change in Short-Term Borrowings (assumption)
B8: Proceeds from Issuance of Long-Term Debt (assumption)
B9: Share Buybacks (% of Revenue or $ amount)
B10: LT Debt Repayment % of Prior LT Debt
B11: Net Interest/Other Exp % of Prior Total Debt
B13: Cash Flow Statement | C13: FY'24 | D13: FY'25 | E13: FY'26
B14: Net income | C14: =IS!C33 -> -56596442 | D14: =IS!D33 -> -15540945
B15: Depreciation and amortization
B16: Change in deferred income taxes
B17: Stock-based compensation expense
B18: Gains on sale of product rights
B19: Acquired in-process research and development
B20: Other operating activities, net
B21: Receivables - (increase) decrease
B22: Inventories - (increase) decrease
B23: Prepaid exp. and other assets - (incr.) decr.
B24: Accounts payable and other liab. - incr. (decr.)
B25: Net Cash Provided by Operating Activities | C25: -38594 | D25: -6728118 | E25: =SUM(E14:E24) -> 0
B27: Purchases of property and equipment
B28: Proceeds from sales of noncurrent investments
B29: Purchases of noncurrent investments
B30: Proceeds from sale of product rights
B31: Purchases of in-process research and development
B32: Cash paid for acquisitions, net of cash acquired
B33: Other investing activities, net
B34: Net Cash Used for Investing Activities | C34: -32485510 | D34: -9735670 | E34: =SUM(E27:E33) -> 0
B36: Dividends paid
B37: Net change in short-term borrowings
B38: Proceeds from issuance of long-term debt
B39: Repayments of long-term debt
B40: Purchases of common stock
B41: Other financing activities, net
B42: Net Cash Provided by (Used for) Financing Activities | C42: 77945674 | D42: 77945674 | E42: =SUM(E36:E41) -> 0
B44: Effect of exchange rate changes on cash
B45: Net Increase (Decrease) in Cash | C45: =C25+C34+C42+C44 -> 45421570 | D45: =D25+D34+D42+D44 -> 61481886 | E45: =E25+E34+E42+E44 -> 0
...

Sheet DCF
B2: Eli Lilly and Company (LLY)
B4: Valuation Date: | H4: =TODAY() -> 46248
B5: Share Price on Valuation Date: | H5: =Main!C3 -> 13.31
B6: Diluted Shares Outstanding | H6: =Main!C4 -> 160.67
B8: Select Operating Data
J9: Projected Annual Forecast
C10: =D10-365 -> -730 | D10: =E10-365 -> -365 | F10: FY'22 | G10: FY'23 | H10: FY'24 | I10: FY'25 | J10: FY'26 | K10: FY'27 | L10: FY'28 | M10: FY'29 | N10: FY'30
B11: Revenue | F11: =IS!#REF! -> #REF! | G11: =IS!#REF! -> #REF! | H11: =IS!#REF! -> #REF! | I11: =IS!E24 -> 0 | J11: =IS!F24 -> 0 | K11: =IS!G24 -> 0 | L11: =IS!H24 -> 0 | M11: =IS!I24 -> 0 | N11: =IS!#REF! -> #REF!
B13: EBIT | F13: =IS!#REF!+IS!#REF! -> #REF! | G13: =IS!#REF!+IS!#REF! -> #REF! | H13: =IS!#REF!+IS!#REF! -> #REF! | I13: =IS!E31+IS!E30 -> 0 | J13: =IS!F31+IS!F30 -> 0 | K13: =IS!G31+IS!G30 -> 0 | L13: =IS!H31+IS!H30 -> 0 | M13: =IS!I31+IS!I30 -> 0 | N13: =IS!#REF!+IS!#REF! -> #REF!
B15: Depreciation & Amortization | F15: =CFS!#REF! -> #REF! | G15: =CFS!#REF! -> #REF! | H15: =CFS!#REF! -> #REF! | I15: =CFS!D15 -> 0 | J15: =I15*(1+J16) -> 0 | K15: =J15*(1+K16) -> 0 | L15: =K15*(1+L16) -> 0 | M15: =L15*(1+M16) -> 0 | N15: =M15*(1+N16) -> 0 | P15: Arithmetic Avg | Q15: Geometric Avg
F16: =F15/F11 -> #REF! | G16: =G15/G11 -> #REF! | H16: =H15/H11 -> #REF! | I16: =I15/I11 -> #DIV/0! | J16: 0.03 | K16: 0.025 | L16: =+K16 -> 0.025 | M16: =+L16 -> 0.025 | N16: =+M16 -> 0.025 | P16: =AVERAGE(C16:I16) -> #REF! | Q16: =GEOMEAN(C16:I16) -> #REF!
B18: Select Balance Sheet And Other Data
J19: Projected Annual Forecast
C20: =D20-365 -> -730 | D20: =E20-365 -> -365 | F20: FY'22 | G20: FY'23 | H20: FY'24 | I20: FY'25 | J20: FY'26 | K20: FY'27 | L20: FY'28 | M20: FY'29 | N20: FY'30
B21: Accounts Receivable | F21: =BS!#REF! -> #REF! | G21: =BS!#REF! -> #REF! | H21: =BS!#REF! -> #REF! | I21: =BS!C15 -> 0 | J21: =J32*J11 -> #REF! | K21: =K32*K11 -> #REF! | L21: =L32*L11 -> #REF! | M21: =M32*M11 -> #REF! | N21: =N32*N11 -> #REF!
B22: Inventories | F22: =BS!#REF! -> #REF! | G22: =BS!#REF! -> #REF! | H22: =BS!#REF! -> #REF! | I22: =BS!C17 -> 0 | J22: =J33*J11 -> #REF! | K22: =K33*K11 -> #REF! | L22: =L33*L11 -> #REF! | M22: =M33*M11 -> #REF! | N22: =N33*N11 -> #REF!
B23: Prepaid Expenses | F23: =BS!#REF! -> #REF! | G23: =BS!#REF! -> #REF! | H23: =BS!#REF! -> #REF! | I23: =BS!C18 -> 0 | J23: =J34*J11 -> #REF! | K23: =K34*K11 -> #REF! | L23: =L34*L11 -> #REF! | M23: =M34*M11 -> #REF! | N23: =N34*N11 -> #REF!
B25: Accounts Payable and Accruals | F25: =BS!#REF! -> #REF! | G25: =BS!#REF! -> #REF! | H25: =BS!#REF! -> #REF! | I25: =BS!C30 -> 0 | J25: =J35*J11 -> #REF! | K25: =K35*K11 -> #REF! | L25: =L35*L11 -> #REF! | M25: =M35*M11 -> #REF! | N25: =N35*N11 -> #REF!
B26: Accrued Expenses | F26: =BS!#REF! -> #REF! | G26: =BS!#REF! -> #REF! | H26: =BS!#REF! -> #REF! | I26: =BS!C31 -> 0 | J26: =J36*J11 -> #REF! | K26: =K36*K11 -> #REF! | L26: =L36*L11 -> #REF! | M26: =M36*M11 -> #REF! | N26: =N36*N11 -> #REF!
B28: Debt | F28: =BS!#REF!+BS!#REF! -> #REF! | G28: =BS!#REF!+BS!#REF! -> #REF! | H28: =BS!#REF!+BS!#REF! -> #REF! | I28: =BS!C29+BS!C35 -> 0
B30: Capital Expenditures | F30: =CFS!#REF! -> #REF! | G30: =CFS!#REF! -> #REF! | H30: =CFS!#REF! -> #REF! | I30: =CFS!D27 -> 0 | J30: =J37*J11 -> #REF! | K30: =K37*K11 -> #REF! | L30: =L37*L11 -> #REF! | M30: =M37*M11 -> #REF! | N30: =N37*N11 -> #REF!
P31: Arithmetic Mean | Q31: Geometric Mean
B32: Accounts Receivable as a % of revenue | C32: =C21/C8 -> #DIV/0! | D32: =D21/D8 -> #DIV/0! | E32: =E21/E8 -> #DIV/0! | F32: =F21/F11 -> #REF! | G32: =G21/G11 -> #REF! | H32: =H21/H11 -> #REF! | I32: =I21/I11 -> #DIV/0! | J32: =$Q32 -> #REF! | K32: =$P32 -> #REF! | L32: =$P32 -> #REF! | M32: =$P32 -> #REF! | N32: =$P32 -> #REF! | P32: =AVERAGE(F32:I32) -> #REF! | Q32: =GEOMEAN(F32:I32) -> #REF!
B33: Inventories as a % of revenue | C33: =C22/C8 -> #DIV/0! | D33: =D22/D8 -> #DIV/0! | E33: =E22/E8 -> #DIV/0! | F33: =F22/F11 -> #REF! | G33: =G22/G11 -> #REF! | H33: =H22/H11 -> #REF! | I33: =I22/I11 -> #DIV/0! | J33: =$Q33 -> #REF! | K33: =$P33 -> #REF! | L33: =$P33 -> #REF! | M33: =$P33 -> #REF! | N33: =$P33 -> #REF! | P33: =AVERAGE(F33:I33) -> #REF! | Q33: =GEOMEAN(F33:I33) -> #REF!
B34: Prepaid Expenses as a % of revenue | C34: =C23/C8 -> #DIV/0! | D34: =D23/D8 -> #DIV/0! | E34: =E23/E8 -> #DIV/0! | F34: =F23/F11 -> #REF! | G34: =G23/G11 -> #REF! | H34: =H23/H11 -> #REF! | I34: =I23/I11 -> #DIV/0! | J34: =$Q34 -> #REF! | K34: =$P34 -> #REF! | L34: =$P34 -> #REF! | M34: =$P34 -> #REF! | N34: =$P34 -> #REF! | P34: =AVERAGE(F34:I34) -> #REF! | Q34: =GEOMEAN(F34:I34) -> #REF!
B35: Accounts Payable/Accruals as a % of revenue | C35: =C25/C8 -> #DIV/0! | D35: =D25/D8 -> #DIV/0! | E35: =E25/E8 -> #DIV/0! | F35: =F25/F11 -> #REF! | G35: =G25/G11 -> #REF! | H35: =H25/H11 -> #REF! | I35: =I25/I11 -> #DIV/0! | J35: =$Q35 -> #REF! | K35: =$P35 -> #REF! | L35: =$P35 -> #REF! | M35: =$P35 -> #REF! | N35: =$P35 -> #REF! | P35: =AVERAGE(F35:I35) -> #REF! | Q35: =GEOMEAN(F35:I35) -> #REF!
B36: Accrued Expenses as a % of revenue | C36: =C26/C8 -> #DIV/0! | D36: =D26/D8 -> #DIV/0! | E36: =E26/E8 -> #DIV/0! | F36: =F26/F11 -> #REF! | G36: =G26/G11 -> #REF! | H36: =H26/H11 -> #REF! | I36: =I26/I11 -> #DIV/0! | J36: =$Q36 -> #REF! | K36: =$P36 -> #REF! | L36: =$P36 -> #REF! | M36: =$P36 -> #REF! | N36: =$P36 -> #REF! | P36: =AVERAGE(F36:I36) -> #REF! | Q36: =GEOMEAN(F36:I36) -> #REF!
B37: Capital Expenditures as a % of revenue | C37: =C30/C8 -> #DIV/0! | D37: =D30/D8 -> #DIV/0! | E37: =E30/E8 -> #DIV/0! | F37: =F30/F11 -> #REF! | G37: =G30/G11 -> #REF! | H37: =H30/H11 -> #REF! | I37: =I30/I11 -> #DIV/0! | J37: =$P37 -> #REF! | K37: =$P37 -> #REF! | L37: =$P37 -> #REF! | M37: =$P37 -> #REF! | N37: =$P37 -> #REF! | P37: =AVERAGE(F37:I37) -> #REF! | Q37: =GEOMEAN(F37:I37) -> #REF!
B38: Accounts Receivable Growth (%) | D38: =((D21/C21)-1) -> #DIV/0! | E38: =((E21/D21)-1) -> #DIV/0! | G38: =((G21/F21)-1) -> #REF! | H38: =((H21/G21)-1) -> #REF! | I38: =((I21/H21)-1) -> #REF!
B39: Inventories Growth (%) | D39: =((D22/C22)-1) -> #DIV/0! | E39: =((E22/D22)-1) -> #DIV/0! | G39: =((G22/F22)-1) -> #REF! | H39: =((H22/G22)-1) -> #REF! | I39: =((I22/H22)-1) -> #REF!
B40: Prepaid Expenses Growth (%) | D40: =((D23/C23)-1) -> #DIV/0! | E40: =((E23/D23)-1) -> #DIV/0! | G40: =((G23/F23)-1) -> #REF! | H40: =((H23/G23)-1) -> #REF! | I40: =((I23/H23)-1) -> #REF!
B41: Accounts Payable/Accruals Growth (%) | D41: =((D25/C25)-1) -> #DIV/0! | E41: =((E25/D25)-1) -> #DIV/0! | G41: =((G25/F25)-1) -> #REF! | H41: =((H25/G25)-1) -> #REF! | I41: =((I25/H25)-1) -> #REF!
B42: Accrued Expenses Growth (%) | D42: =((D26/C26)-1) -> #DIV/0! | E42: =((E26/D26)-1) -> #DIV/0! | G42: =((G26/F26)-1) -> #REF! | H42: =((H26/G26)-1) -> #REF! | I42: =((I26/H26)-1) -> #REF!
B43: Capital Expenditures Growth (%) | D43: =((D30/C30)-1) -> #DIV/0! | E43: =((E30/D30)-1) -> #DIV/0! | G43: =((G30/F30)-1) -> #REF! | H43: =((H30/G30)-1) -> #REF! | I43: =((I30/H30)-1) -> #REF!
B45: Free Cash Flow Buildup
B46: $mm | J46: Projected Annual Forecast
C47: =D47-365 -> -730 | D47: =E47-365 -> -365 | F47: FY'22 | G47: FY'23 | H47: FY'24 | I47: FY'25 | J47: FY'26 | K47: FY'27 | L47: FY'28 | M47: FY'29 | N47: FY'30
B48: Period | J48: 1 | K48: =J48+1 -> 2 | L48: =K48+1 -> 3 | M48: =L48+1 -> 4 | N48: =M48+1 -> 5
B49: Total Revenues | C49: =C11 -> 0 | D49: =D11 -> 0 | E49: =E11 -> 0 | F49: =F11 -> #REF! | G49: =G11 -> #REF! | H49: =H11 -> #REF! | I49: =I11 -> 0 | J49: =J11 -> 0 | ... N49: =N11 -> #REF!
B50: EBIT | C50: =C13 -> 0 | D50: =D13 -> 0 | E50: =E13 -> 0 | F50: =F13 -> #REF! | G50: =G13 -> #REF! | H50: =H13 -> #REF! | I50: =I13 -> 0 | J50: =J13 -> 0 | ... N50: =N13 -> #REF!
...
