Workbook

Sheet Main
B2: UBER | C2: Statements as of 6/30/26
B3: Price | C3: 76.04
B4: Shares | C4: 2050.23
B5: Market Cap | C5: =C3*C4 -> 155899.49
B6: Cash | C6: 7105
B7: Debt | C7: =10521 -> 10521
B8: EV | C8: =C5+C7-C6 -> 159315.49
B10: Founder/exec chairman:
B11: CEO:
B12: CFO:

Sheet 10QIS
B2: Uber Technologies, Inc. (UBER)
B4: Historic Quarterly IS by Product | C4: Q1'21 | D4: Q2'21 | E4: Q3'21 | F4: Q4'21 | G4: Q1'22 | H4: Q2'22 | I4: Q3'22 | J4: Q4'22 | K4: Q1'23 | L4: Q2'23 | M4: Q3'23 | N4: Q4'23 | O4: Q1'24 | P4: Q2'24 | Q4: Q3'24 | R4: Q4'24 | S4: Q1'25 | T4: Q2'25 | U4: Q3'25 | V4: Q4'25 | W4: Q1'26 | X4: Q2'26
B5: Mobility | C5: 853 | D5: 1618 | E5: 2205 | F5: =6953-4676 -> 2277 | G5: 2518 | H5: 3553 | I5: 3822 | J5: =14029-9893 -> 4136 | K5: 4330 | L5: 4894 | M5: 5071 | N5: =19832-14295 -> 5537 | O5: 5633 | P5: 6134 | Q5: 6409 | R5: =25087-18176 -> 6911 | S5: 6496 | T5: 7288 | U5: 7682 | V5: =29670-21466 -> 8204 | W5: 6798 | X5: 7363
B6: Delivery | C6: 1741 | D6: 1963 | E6: 2238 | F6: =8362-5942 -> 2420 | G6: 2512 | H6: 2688 | I6: 2770 | J6: =10901-7970 -> 2931 | K6: 3093 | L6: 3057 | M6: 2935 | N6: =12204-9085 -> 3119 | O6: 3214 | P6: 3293 | Q6: 3470 | R6: =13750-9977 -> 3773 | S6: 3777 | T6: 4102 | U6: 4477 | V6: =17248-12356 -> 4892 | W6: 5068 | X6: 5245
B7: Freight | C7: 301 | D7: 348 | E7: 402 | F7: =2132-1051 -> 1081 | G7: 1824 | H7: 1832 | I7: 1751 | J7: =6947-5407 -> 1540 | K7: 1400 | L7: 1279 | M7: 1286 | N7: =5245-3965 -> 1280 | O7: 1284 | P7: 1273 | Q7: 1309 | R7: =5141-3866 -> 1275 | S7: 1260 | T7: 1261 | U7: 1308 | V7: =5099-3829 -> 1270 | W7: 1337 | X7: 1583
B8: Total Revenue | C8: 2903 | D8: 3929 | E8: 4845 | F8: =17455-11677 -> 5778 | G8: 6854 | H8: 8073 | I8: 8343 | J8: =31877-23270 -> 8607 | K8: 8823 | L8: 9230 | M8: 9292 | N8: =37281-27345 -> 9936 | O8: 10131 | P8: 10700 | Q8: 11188 | R8: =43978-32019 -> 11959 | S8: 11533 | T8: 12651 | U8: 13467 | V8: =52017-37651 -> 14366 | W8: 13203 | X8: 14191
B9: COGS | C9: 1710 | D9: 2099 | E9: 2438 | F9: =9351-6247 -> 3104 | G9: 4026 | H9: 5153 | I9: 5173 | J9: =19659-14352 -> 5307 | K9: 5259 | L9: 5515 | M9: 5626 | N9: =22457-16400 -> 6057 | O9: 6168 | P9: 6488 | Q9: 6761 | R9: =26651-19417 -> 7234 | S9: 6937 | T9: 7611 | U9: 8109 | V9: =31338-22657 -> 8681 | W9: 7258 | X9: 7815
B10: Gross Margin | C10: =C8-C9 -> 1193 | D10: =D8-D9 -> 1830 | E10: =E8-E9 -> 2407 | F10: =F8-F9 -> 2674 | G10: =G8-G9 -> 2828 | H10: =H8-H9 -> 2920 | I10: =I8-I9 -> 3170 | J10: =J8-J9 -> 3300 | ... X10: =X8-X9 -> 6376
B11: SG&A | C11: =423+1103+464 -> 1990 | D11: =432+1256+616 -> 2304 | E11: =475+1168+625 -> 2268 | F11: =(1877-1330)+(4789-3527)+(2316-1705) -> 2420 | G11: =574+1263+632 -> 2469 | H11: =617+1218+851 -> 2686 | I11: =617+1153+908 -> 2678 | J11: =(2413-1808)+(4756-3634)+(3136-2391) -> 2472 | K11: =640+1262+942 -> 2844 | L11: =664+1218+491 -> 2373 | M11: =683+941+646 -> 2270 | N11: =(2689-1987)+(4356-3421)+(2682-2079) -> 2240 | O11: =685+917+1209 -> 2811 | P11: =682+1115+686 -> 2483 | Q11: =687+1096+630 -> 2413 | R11: =(2732-2054)+(4337-3128)+(3639-2525) -> 3001 | S11: =668+1057+657 -> 2382 | T11: =696+1210+669 -> 2575 | U11: =735+1277+1183 -> 3195 | V11: =(2854-2099)+(4898-3544)+(3241-2509) -> 2841 | W11: =763+1326+798 -> 2887 | X11: =805+1515+935 -> 3255
B12: R&D | C12: 515 | D12: 488 | E12: 493 | F12: =2054-1496 -> 558 | G12: 587 | H12: 704 | I12: 760 | J12: =2798-2051 -> 747 | K12: 775 | L12: 808 | M12: 797 | N12: =3164-2380 -> 784 | O12: 790 | P12: 760 | Q12: 774 | R12: =3109-2324 -> 785 | S12: 815 | T12: 840 | U12: 862 | V12: =3402-2517 -> 885 | W12: 951 | X12: 1043
B13: Depreciation & Amortization | C13: 212 | D13: 226 | E13: 218 | F13: =902-656 -> 246 | G13: 254 | H13: 243 | I13: 227 | J13: =947-724 -> 223 | K13: 207 | L13: 208 | M13: 205 | N13: =823-620 -> 203 | O13: 190 | P13: 173 | Q13: 179 | R13: =711-542 -> 169 | S13: 171 | T13: 175 | U13: 188 | V13: =719-534 -> 185 | W13: 184 | X13: 188
B14: Other expenses (Income) | C14: =115-1710 -> -1595 | D14: =115-1943 -> -1828 | E14: =123-(-1832) -> 1955 | F14: =(483-353)-(3292-1821) -> -1341 | G14: =129-(-5557) -> 5686 | H14: =139-(-1704) -> 1843 | I14: =146-(-535) -> 681 | J14: =(565-414)-(-7029-(-7796)) -> -616 | K14: =168-292 -> -124 | L14: =144-273 -> -129 | M14: =166-(-52) -> 218 | N14: =(633-478)-(1844-513) -> -1176 | O14: =124-(-678) -> 802 | P14: =139-420 -> -281 | Q14: =143-1851 -> -1708 | R14: =(523-406)-((721+1128)-1593) -> -139 | S14: =105-169-93 -> -157 | T14: =108-162 -> -54 | U14: =112-1619 -> -1507 | V14: =(440-325)-((743-68)-2043) -> 1483 | W14: =108-175-(-1494) -> 1427 | X14: =127-172-1342 -> -1387
B15: Pre Tax Income | C15: =C10-SUM(C11:C14) -> 71 | D15: =D10-SUM(D11:D14) -> 640 | E15: =E10-SUM(E11:E14) -> -2527 | F15: =F10-SUM(F11:F14) -> 791 | G15: =G10-SUM(G11:G14) -> -6168 | H15: =H10-SUM(H11:H14) -> -2556 | I15: =I10-SUM(I11:I14) -> -1176 | J15: =J10-SUM(J11:J14) -> 474 | ... X15: =X10-SUM(X11:X14) -> 3277
B16: Loss from Equity Method Investments (Gain) | C16: 8 | D16: 7 | E16: 13 | F16: =37-28 -> 9 | G16: -18 | H16: -17 | I16: -30 | J16: =-107-(-65) -> -42 | K16: -36 | L16: -4 | M16: -3 | N16: =-48-(-43) -> -5 | O16: 4 | P16: 12 | Q16: 12 | R16: =38-28 -> 10 | S16: 13 | T16: 12 | U16: 14 | V16: =53-39 -> 14 | W16: 20 | X16: 21
B17: Taxes | C17: 185 | D17: -479 | E17: -101 | F17: =-492-(-395) -> -97 | G17: -232 | H17: 77 | I17: 58 | J17: =-181-(-97) -> -84 | K17: 55 | L17: 65 | M17: -40 | N17: =213-80 -> 133 | O17: 29 | P17: 57 | Q17: 158 | R17: =-5758-244 -> -6002 | S17: -402 | T17: 142 | U17: -4046 | V17: =-4346-(-4306) -> -40 | W17: 194 | X17: 840
B18: Net income (Loss) from non controlling interest | C18: -14 | D18: -32 | E18: -15 | F18: =-74-(-61) -> -13 | G18: 12 | H18: -15 | I18: 2 | J18: =3-(-2) -> 5 | K18: 0 | L18: 0 | M18: -2 | N18: =269-(-2) -> 271 | O18: -9 | P18: -7 | Q18: -13 | R18: =-11-(-29) -> 18 | S18: -2 | T18: -5 | U18: 26 | V18: =40-19 -> 21 | W18: 19 | X18: 22
B19: Net Income (Loss) | C19: =C15-C17-C16-C18 -> -108 | D19: =D15-D17-D16-D18 -> 1144 | E19: =E15-E17-E16-E18 -> -2424 | F19: =F15-F17-F16-F18 -> 892 | G19: =G15-G17-G16-G18 -> -5930 | H19: =H15-H17-H16-H18 -> -2601 | I19: =I15-I17-I16-I18 -> -1206 | J19: =J15-J17-J16-J18 -> 595 | ... X19: =X15-X17-X16-X18 -> 2394
B20: EPS | C20: =C19/C21 -> -0.058110598 | D20: =D19/D21 -> 0.58487455 | E20: =E19/E21 -> -1.2764922 | F20: =F19/F21 -> 0.47058352 | G20: =G19/G21 -> -3.0290168 | H20: =H19/H21 -> -1.3210543 | I20: =I19/I21 -> -0.60930663 | J20: =J19/J21 -> 0.29842512 | ... X20: =X19/X21 -> 1.1676739
B21: Shares | C21: 1858.525 | D21: 1955.975 | E21: 1898.954 | F21: 1895.519 | G21: 1957.731 | H21: 1968.882 | I21: 1979.299 | J21: =4*1974.928-(1957.731+1968.882+1979.299) -> 1993.8 | K21: 2009.557 | L21: 2079.265 | M21: 2108.479 | N21: =4*2091.782-(2009.557+2079.265+2108.479) -> 2169.827 | O21: 2080.168 | P21: 2150.019 | Q21: 2154.466 | R21: =4*2150.508-(2080.168+2150.019+2154.466) -> 2217.379 | S21: 2122.618 | T21: 2125.628 | U21: 2124.391 | V21: =4*2119.689-(2122.618+2125.628+2124.391) -> 2106.119 | W21: 2071.391 | X21: 2050.23
B23: Historic Drivers
B24: Historic Mobility Revenue Growth Rate | F24: =(F5-C5)/C5 -> 1.6694021 | G24: =(G5-C5)/C5 -> 1.9519343 | H24: =(H5-D5)/D5 -> 1.1959209 | I24: =(I5-E5)/E5 -> 0.73333333 | J24: =(J5-F5)/F5 -> 0.81642512 | K24: =(K5-G5)/G5 -> 0.71961875 | L24: =(L5-H5)/H5 -> 0.37742753 | M24: =(M5-I5)/I5 -> 0.32679226 | N24: =(N5-J5)/J5 -> 0.33873308 | ... X24: =(X5-T5)/T5 -> 0.010290889
B25: Historic Delivery Revenue Growth Rate | F25: =(F6-C6)/C6 -> 0.39000574 | G25: =(G6-C6)/C6 -> 0.44284894 | H25: =(H6-D6)/D6 -> 0.36933265 | I25: =(I6-E6)/E6 -> 0.23771224 | J25: =(J6-F6)/F6 -> 0.21115702 | K25: =(K6-G6)/G6 -> 0.23128981 | L25: =(L6-H6)/H6 -> 0.13727679 | M25: =(M6-I6)/I6 -> 0.059566787 | N25: =(N6-J6)/J6 -> 0.064141931 | ... X25: =(X6-T6)/T6 -> 0.27864456
B26: Historic Freight Revenue Growth Rate | F26: =(F7-C7)/C7 -> 2.5913621 | G26: =(G7-C7)/C7 -> 5.0598007 | H26: =(H7-D7)/D7 -> 4.2643678 | I26: =(I7-E7)/E7 -> 3.3557214 | J26: =(J7-F7)/F7 -> 0.42460685 | K26: =(K7-G7)/G7 -> -0.23245614 | L26: =(L7-H7)/H7 -> -0.3018559 | M26: =(M7-I7)/I7 -> -0.26556254 | N26: =(N7-J7)/J7 -> -0.16883117 | ... X26: =(X7-T7)/T7 -> 0.25535289
B27: Historic Revenue Growth Rate | F27: =(F8-C8)/C8 -> 0.99035481 | G27: =(G8-C8)/C8 -> 1.3610059 | H27: =(H8-D8)/D8 -> 1.0547213 | I27: =(I8-E8)/E8 -> 0.72198142 | J27: =(J8-F8)/F8 -> 0.48961578 | K27: =(K8-G8)/G8 -> 0.2872775 | L27: =(L8-H8)/H8 -> 0.14331723 | M27: =(M8-I8)/I8 -> 0.11374805 | N27: =(N8-J8)/J8 -> 0.1544092 | ... X27: =(X8-T8)/T8 -> 0.12172951
B28: Historic Gross Margin % | C28: =C10/C8 -> 0.41095419 | D28: =D10/D8 -> 0.46576737 | E28: =E10/E8 -> 0.49680083 | F28: =F10/F8 -> 0.46278989 | G28: =G10/G8 -> 0.41260578 | H28: =H10/H8 -> 0.36169949 | I28: =I10/I8 -> 0.37995925 | J28: =J10/J8 -> 0.38340885 | ... X28: =X10/X8 -> 0.44929885
B29: Historic SG&A % | C29: =C11/C8 -> 0.68549776 | D29: =D11/D8 -> 0.58640876 | E29: =E11/E8 -> 0.46811146 | F29: =F11/F8 -> 0.41883004 | G29: =G11/G8 -> 0.3602276 | H29: =H11/H8 -> 0.33271398 | I29: =I11/I8 -> 0.32098765 | J29: =J11/J8 -> 0.28720809 | ... X29: =X11/X8 -> 0.22937073
B30: Historic R&D % | C30: =C12/C8 -> 0.17740269 | D30: =D12/D8 -> 0.12420463 | E30: =E12/E8 -> 0.10175439 | F30: =F12/F8 -> 0.096573209 | G30: =G12/G8 -> 0.08564342 | H30: =H12/H8 -> 0.087204261 | I30: =I12/I8 -> 0.091094331 | J30: =J12/J8 -> 0.086789822 | ... X30: =X12/X8 -> 0.073497287
B31: Historic Depreciation & Amortization % | C31: =C13/C8 -> 0.073027902 | D31: =D13/D8 -> 0.057520998 | E31: =E13/E8 -> 0.04499484 | F31: =F13/F8 -> 0.042575286 | G31: =G13/G8 -> 0.037058652 | H31: =H13/H8 -> 0.030100334 | I31: =I13/I8 -> 0.027208438 | J31: =J13/J8 -> 0.025909144 | ... X31: =X13/X8 -> 0.013247833
B32: Historic Tax rate | C32: =C17/C15 -> 2.6056338 | D32: =D17/D15 -> -0.7484375 | E32: =E17/E15 -> 0.039968342 | F32: =F17/F15 -> -0.12262958 | G32: =G17/G15 -> 0.037613489 | H32: =H17/H15 -> -0.030125196 | I32: =I17/I15 -> -0.049319728 | J32: =J17/J15 -> -0.17721519 | ... X32: =X17/X15 -> 0.25633201

Sheet IS
B2: IS Assumptions | C2: =C13 -> FY'21 | D2: =D13 -> FY'22 | E2: =E13 -> FY'23 | F2: =F13 -> FY'24 | G2: =G13 -> FY'25 | H2: =H13 -> FY'26 | I2: =I13 -> FY'27 | J2: =J13 -> FY'28 | ... L2: =L13 -> FY'30
B3: Mobility Revenue Growth Rate | D3: =(D14-C14)/C14 -> 1.0176902 | E3: =(E14-D14)/D14 -> 0.41364317 | F3: =(F14-E14)/E14 -> 0.2649758 | G3: =(G14-F14)/F14 -> 0.18268426 | H3: 0.1 | I3: 0.1 | J3: 0.1 | K3: 0.05 | L3: 0.05
B4: Delivery Revenue Growth Rate | D4: =(D15-C15)/C15 -> 0.30363549 | E4: =(E15-D15)/D15 -> 0.11953032 | F4: =(F15-E15)/E15 -> 0.12667978 | G4: =(G15-F15)/F15 -> 0.2544 | H4: 0.25 | I4: 0.25 | J4: 0.2 | K4: 0.1 | L4: 0.1
B5: Freight Revenue Growth Rate | D5: =(D16-C16)/C16 -> 2.2584428 | E5: =(E16-D16)/D16 -> -0.24499784 | F5: =(F16-E16)/E16 -> -0.019828408 | G5: =(G16-F16)/F16 -> -0.0081696168 | H5: -0.05 | I5: -0.05 | J5: -0.05 | K5: -0.05 | L5: -0.05
B6: Total Revenue Growth Rate | D6: =(D17-C17)/C17 -> 0.8262389 | E6: =(E17-D17)/D17 -> 0.16952662 | F6: =(F17-E17)/E17 -> 0.17963574 | G6: =(G17-F17)/F17 -> 0.18279594 | H6: =(H17-G17)/G17 -> 0.13480112 | I6: =(I17-H17)/H17 -> 0.14232283 | J6: =(J17-I17)/I17 -> 0.1294814 | K6: =(K17-J17)/J17 -> 0.065326171 | L6: =(L17-K17)/K17 -> 0.066720829
B7: Gross Margin % | C7: =C19/C17 -> 0.46427958 | D7: =D19/D17 -> 0.38328575 | E7: =E19/E17 -> 0.39762882 | F7: =F19/F17 -> 0.39399245 | G7: =G19/G17 -> 0.39754311 | H7: =G7 -> 0.39754311 | I7: =H7 -> 0.39754311 | J7: =I7 -> 0.39754311 | K7: =J7 -> 0.39754311 | L7: =K7 -> 0.39754311
B8: SG&A % | C8: =C20/C17 -> 0.51458035 | D8: =D20/D17 -> 0.32327383 | E8: =E20/E17 -> 0.26091038 | F8: =F20/F17 -> 0.24348538 | G8: =G20/G17 -> 0.21133476 | H8: 0.2 | I8: =H8 -> 0.2 | J8: =I8 -> 0.2 | K8: =J8 -> 0.2 | L8: =K8 -> 0.2
B9: R&D % | C9: =C21/C17 -> 0.11767402 | D9: =D21/D17 -> 0.087774885 | E9: =E21/E17 -> 0.084868968 | F9: =F21/F17 -> 0.070694438 | G9: =G21/G17 -> 0.065401696 | H9: =G9 -> 0.065401696 | I9: =H9 -> 0.065401696 | J9: 0.06 | K9: 0.06 | L9: 0.05
B10: Depreciation & Amortization % | C10: =C22/C17 -> 0.051675738 | D10: =D22/D17 -> 0.02970794 | E10: =E22/E17 -> 0.022075588 | F10: =F22/F17 -> 0.016167174 | G10: =G22/G17 -> 0.013822404 | H10: 0.0125 | I10: 0.01 | J10: 0.0075 | K10: 0.005 | L10: 0.005
B11: Tax rate | C11: =C25/C24 -> 0.49797571 | D11: =D25/D24 -> 0.019414352 | E11: =E25/E24 -> 0.10142857 | F11: =F25/F24 -> -1.4050756 | G11: =G25/G24 -> -0.76152094 | H11: 0 | I11: =H11 -> 0 | J11: =I11 -> 0 | K11: =J11 -> 0 | L11: =K11 -> 0
B13: Annual Income Statement | C13: FY'21 | D13: FY'22 | E13: FY'23 | F13: FY'24 | G13: FY'25 | H13: FY'26 | I13: FY'27 | J13: FY'28 | K13: FY'29 | L13: FY'30
B14: Mobility | C14: =SUM('10QIS'!C5:F5) -> 6953 | D14: =SUM('10QIS'!G5:J5) -> 14029 | E14: =SUM('10QIS'!K5:N5) -> 19832 | F14: =SUM('10QIS'!O5:R5) -> 25087 | G14: =SUM('10QIS'!S5:V5) -> 29670 | H14: =SUM('10QIS'!W5:X5)+SUM('10QIS'!U5:V5)*(1+H3) -> 31635.6 | I14: =H14*(1+I3) -> 34799.16 | J14: =I14*(1+J3) -> 38279.076 | K14: =J14*(1+K3) -> 40193.03 | L14: =K14*(1+L3) -> 42202.681
B15: Delivery | C15: =SUM('10QIS'!C6:F6) -> 8362 | D15: =SUM('10QIS'!G6:J6) -> 10901 | E15: =SUM('10QIS'!K6:N6) -> 12204 | F15: =SUM('10QIS'!O6:R6) -> 13750 | G15: =SUM('10QIS'!S6:V6) -> 17248 | H15: =SUM('10QIS'!W6:X6)+SUM('10QIS'!U6:V6)*(1+H4) -> 22024.25 | I15: =H15*(1+I4) -> 27530.312 | J15: =I15*(1+J4) -> 33036.375 | K15: =J15*(1+K4) -> 36340.013 | L15: =K15*(1+L4) -> 39974.014
B16: Freight | C16: =SUM('10QIS'!C7:F7) -> 2132 | D16: =SUM('10QIS'!G7:J7) -> 6947 | E16: =SUM('10QIS'!K7:N7) -> 5245 | F16: =SUM('10QIS'!O7:R7) -> 5141 | G16: =SUM('10QIS'!S7:V7) -> 5099 | H16: =SUM('10QIS'!W7:X7)+SUM('10QIS'!U7:V7)*(1+H5) -> 5369.1 | I16: =H16*(1+I5) -> 5100.645 | J16: =I16*(1+J5) -> 4845.6128 | K16: =J16*(1+K5) -> 4603.3321 | L16: =K16*(1+L5) -> 4373.1655
B17: Total Revenue | C17: =SUM('10QIS'!C8:F8) -> 17455 | D17: =SUM('10QIS'!G8:J8) -> 31877 | E17: =SUM('10QIS'!K8:N8) -> 37281 | F17: =SUM('10QIS'!O8:R8) -> 43978 | G17: =SUM('10QIS'!S8:V8) -> 52017 | H17: =SUM(H14:H16) -> 59028.95 | I17: =SUM(I14:I16) -> 67430.118 | J17: =SUM(J14:J16) -> 76161.064 | K17: =SUM(K14:K16) -> 81136.374 | L17: =SUM(L14:L16) -> 86549.861
B18: COGS | C18: =SUM('10QIS'!C9:F9) -> 9351 | D18: =SUM('10QIS'!G9:J9) -> 19659 | E18: =SUM('10QIS'!K9:N9) -> 22457 | F18: =SUM('10QIS'!O9:R9) -> 26651 | G18: =SUM('10QIS'!S9:V9) -> 31338 | H18: =H17-H19 -> 35562.398 | I18: =I17-I19 -> 40623.739 | J18: =J17-J19 -> 45883.758 | K18: =K17-K19 -> 48881.168 | L18: =L17-L19 -> 52142.56
B19: Gross Margin | C19: =C17-C18 -> 8104 | D19: =D17-D18 -> 12218 | E19: =E17-E18 -> 14824 | F19: =F17-F18 -> 17327 | G19: =G17-G18 -> 20679 | H19: =H17*H7 -> 23466.552 | I19: =I17*I7 -> 26806.379 | J19: =J17*J7 -> 30277.306 | K19: =K17*K7 -> 32255.207 | L19: =L17*L7 -> 34407.301
B20: SG&A | C20: =SUM('10QIS'!C11:F11) -> 8982 | D20: =SUM('10QIS'!G11:J11) -> 10305 | E20: =SUM('10QIS'!K11:N11) -> 9727 | F20: =SUM('10QIS'!O11:R11) -> 10708 | G20: =SUM('10QIS'!S11:V11) -> 10993 | H20: =H17*H8 -> 11805.79 | I20: =I17*I8 -> 13486.024 | J20: =J17*J8 -> 15232.213 | K20: =K17*K8 -> 16227.275 | L20: =L17*L8 -> 17309.972
B21: R&D | C21: =SUM('10QIS'!C12:F12) -> 2054 | D21: =SUM('10QIS'!G12:J12) -> 2798 | E21: =SUM('10QIS'!K12:N12) -> 3164 | F21: =SUM('10QIS'!O12:R12) -> 3109 | G21: =SUM('10QIS'!S12:V12) -> 3402 | H21: =H17*H9 -> 3860.5934 | I21: =I17*I9 -> 4410.044 | J21: =J17*J9 -> 4569.6638 | K21: =K17*K9 -> 4868.1825 | L21: =L17*L9 -> 4327.493
B22: Depreciation & Amortization | C22: =SUM('10QIS'!C13:F13) -> 902 | D22: =SUM('10QIS'!G13:J13) -> 947 | E22: =SUM('10QIS'!K13:N13) -> 823 | F22: =SUM('10QIS'!O13:R13) -> 711 | G22: =SUM('10QIS'!S13:V13) -> 719 | H22: =H17*H10 -> 737.86188 | I22: =I17*I10 -> 674.30118 | J22: =J17*J10 -> 571.20798 | K22: =K17*K10 -> 405.68187 | L22: =L17*L10 -> 432.7493
B23: Other expenses | C23: =SUM('10QIS'!C13:F13)+SUM('10QIS'!C14:F14)+SUM('10QIS'!C16:F16)+SUM('10QIS'!C18:F18) -> -1944 | D23: =SUM('10QIS'!G13:J13)+SUM('10QIS'!G14:J14)+SUM('10QIS'!G16:J16)+SUM('10QIS'!G18:J18) -> 8438 | E23: =SUM('10QIS'!K13:N13)+SUM('10QIS'!K14:N14)+SUM('10QIS'!K16:N16)+SUM('10QIS'!K18:N18) -> -167 | F23: =SUM('10QIS'!O13:R13)+SUM('10QIS'!O14:R14)+SUM('10QIS'!O16:R16)+SUM('10QIS'!O18:R18) -> -588 | G23: =SUM('10QIS'!S13:V13)+SUM('10QIS'!S14:V14)+SUM('10QIS'!S16:V16)+SUM('10QIS'!S18:V18) -> 577 | H23: 0 | I23: 0 | J23: 0 | K23: 0 | L23: 0
B24: Pre Tax Income | C24: =C19-C20-C21-C23 -> -988 | D24: =D19-D20-D21-D23 -> -9323 | E24: =E19-E20-E21-E23 -> 2100 | F24: =F19-F20-F21-F23 -> 4098 | G24: =G19-G20-G21-G23 -> 5707 | H24: =H19-H20-H21-H23 -> 7800.169 | I24: =I19-I20-I21-I23 -> 8910.3112 | J24: =J19-J20-J21-J23 -> 10475.43 | ... L24: =L19-L20-L21-L23 -> 12769.836
B25: Taxes | C25: =SUM('10QIS'!C17:F17) -> -492 | D25: =SUM('10QIS'!G17:J17) -> -181 | E25: =SUM('10QIS'!K17:N17) -> 213 | F25: =SUM('10QIS'!O17:R17) -> -5758 | G25: =SUM('10QIS'!S17:V17) -> -4346 | H25: 0 | I25: 0 | J25: 0 | K25: 0 | L25: 0
B26: Net Income (Loss) | C26: =C24-C25 -> -496 | D26: =D24-D25 -> -9142 | E26: =E24-E25 -> 1887 | F26: =F24-F25 -> 9856 | G26: =G24-G25 -> 10053 | H26: =H24-H25 -> 7800.169 | I26: =I24-I25 -> 8910.3112 | J26: =J24-J25 -> 10475.43 | ... L26: =L24-L25 -> 12769.836
B27: EPS | C27: =C26/C28 -> -0.26074478 | D27: =D26/D28 -> -4.6290295 | E27: =E26/E28 -> 0.90210165 | F27: =F26/F28 -> 4.5831032 | G27: =G26/G28 -> 4.7426769 | H27: =H26/H28 -> 3.8045336 | I27: =I26/I28 -> 4.3460056 | J27: =J26/J28 -> 5.1093924 | ... L27: =L26/L28 -> 6.2284893
B28: Shares | C28: =AVERAGE('10QIS'!C21:F21) -> 1902.2432 | D28: =AVERAGE('10QIS'!G21:J21) -> 1974.928 | E28: =AVERAGE('10QIS'!K21:N21) -> 2091.782 | F28: =AVERAGE('10QIS'!O21:R21) -> 2150.508 | G28: =AVERAGE('10QIS'!S21:V21) -> 2119.689 | H28: =Main!C4 -> 2050.23 | I28: =H28 -> 2050.23 | J28: =I28 -> 2050.23 | K28: =J28 -> 2050.23 | L28: =K28 -> 2050.23

Sheet BS
B2: Balance Sheet | C2: FY'21 | D2: FY'22 | E2: FY'23 | F2: FY'24 | G2: FY'25 | H2: FY'26
B3: Cash and cash equivalents | C3: 4295 | D3: 4208 | E3: 4680 | F3: 5893 | G3: 7105 | H3: 4870
B4: Short-term investments | C4: 0 | D4: 103 | E4: 727 | F4: 1084 | G4: 528 | H4: 521
B5: Restricted cash and cash equivalents | C5: 631 | D5: 680 | E5: 805 | F5: 545 | G5: 631 | H5: 661
B6: Accounts receivable, net | C6: 2439 | D6: 2779 | E6: 3404 | F6: 3333 | G6: 3827 | H6: 4298
B7: Prepaid expenses and other current assets | C7: 1454 | D7: 1479 | E7: 1681 | F7: 1390 | G7: 1902 | H7: 2179
B8: Total current assets | C8: =SUM(C3:C7) -> 8819 | D8: =SUM(D3:D7) -> 9249 | E8: =SUM(E3:E7) -> 11297 | F8: =SUM(F3:F7) -> 12245 | G8: =SUM(G3:G7) -> 13993 | H8: =SUM(H3:H7) -> 12529
B9: Restricted cash and cash equivalents (noncurrent) | C9: 2879 | D9: 1789 | E9: 1519 | F9: 2172 | G9: 1911 | H9: 1646
B10: Restricted investments | D10: 1614 | E10: 4779 | F10: 7019 | G10: 8874 | H10: 9486
B11: Investments | C11: 11806 | D11: 4401 | E11: 6101 | F11: 8460 | G11: 9178 | H11: 8759
B12: Equity method investments | C12: 800 | D12: 870 | E12: 353 | F12: 302 | G12: 287 | H12: 3773
B13: Property and equipment, net | C13: 1853 | D13: 2082 | E13: 2073 | F13: 1952 | G13: 1897 | H13: 1809
B14: Operating lease right-of-use assets | C14: 1388 | D14: 1449 | E14: 1241 | F14: 1158 | G14: 1114 | H14: 1558
B15: Intangible assets, net | C15: 2412 | D15: 1874 | E15: 1425 | F15: 1125 | G15: 1048 | H15: 1132
B16: Goodwill | C16: 8420 | D16: 8263 | E16: 8151 | F16: 8066 | G16: 8931 | H16: 9472
B17: Deferred tax assets | F17: 6171 | G17: 10951 | H17: 10162
B18: Other assets | C18: 397 | D18: 518 | E18: 1760 | F18: 2574 | G18: 3618 | H18: 5475
B19: Total assets | C19: =C8+SUM(C9:C18) -> 38774 | D19: =D8+SUM(D9:D18) -> 32109 | E19: =E8+SUM(E9:E18) -> 38699 | F19: =F8+SUM(F9:F18) -> 51244 | G19: =G8+SUM(G9:G18) -> 61802 | H19: =H8+SUM(H9:H18) -> 65801
B21: Accounts payable | C21: 860 | D21: 728 | E21: 790 | F21: 858 | G21: 1013 | H21: 1366
B22: Short-term insurance reserves | C22: 1442 | D22: 1692 | E22: 2016 | F22: 2754 | G22: 3387 | H22: 3758
B23: Operating lease liabilities, current | C23: 185 | D23: 201 | E23: 190 | F23: 175 | G23: 169 | H23: 178
B24: Short-term debt | C24: 0 | D24: 0 | E24: 0 | F24: 0 | G24: 0 | H24: 1997
B25: Accrued and other current liabilities | C25: 6537 | D25: 6232 | E25: 6458 | F25: 7689 | G25: 7751 | H25: 7572
B26: Total current liabilities | C26: =SUM(C21:C25) -> 9024 | D26: =SUM(D21:D25) -> 8853 | E26: =SUM(E21:E25) -> 9454 | F26: =SUM(F21:F25) -> 11476 | G26: =SUM(G21:G25) -> 12320 | H26: =SUM(H21:H25) -> 14871
B27: Long-term insurance reserves | C27: 2546 | D27: 3028 | E27: 4722 | F27: 7042 | G27: 9076 | H27: 9528
B28: Long-term debt, net of current portion | C28: 9276 | D28: 9265 | E28: 9459 | F28: 8347 | G28: 10521 | H28: 10726
B29: Operating lease liabilities, non-current | C29: 1644 | D29: 1673 | E29: 1550 | F29: 1454 | G29: 1390 | H29: 1830
B30: Other long-term liabilities | C30: 935 | D30: 786 | E30: 832 | F30: 449 | G30: 412 | H30: 447
B31: Total liabilities | C31: =C26+SUM(C27:C30) -> 23425 | D31: =D26+SUM(D27:D30) -> 23605 | E31: =E26+SUM(E27:E30) -> 26017 | F31: =F26+SUM(F27:F30) -> 28768 | G31: =G26+SUM(G27:G30) -> 33719 | H31: =H26+SUM(H27:H30) -> 37402
B32: Redeemable non-controlling interests | C32: 204 | D32: 430 | E32: 654 | F32: 93 | G32: 165 | H32: 180
B33: Additional paid-in capital | C33: 38608 | D33: 40550 | E33: 42264 | F33: 42801 | G33: 38101 | H33: 35698
B34: Accumulated other comprehensive loss | C34: -524 | D34: -443 | E34: -421 | F34: -517 | G34: -432 | H34: -432
B35: Accumulated deficit | C35: -23626 | D35: -32767 | E35: -30594 | F35: -20726 | G35: -10628 | H35: -7950
B36: Total Uber Technologies, Inc. stockholders' equity | C36: =SUM(C33:C35) -> 14458 | D36: =SUM(D33:D35) -> 7340 | E36: =SUM(E33:E35) -> 11249 | F36: =SUM(F33:F35) -> 21558 | G36: =SUM(G33:G35) -> 27041 | H36: =SUM(H33:H35) -> 27316
B37: Non-redeemable non-controlling interests | C37: 687 | D37: 734 | E37: 779 | F37: 825 | G37: 877 | H37: 903
B38: Total equity | C38: =C36+C37 -> 15145 | D38: =D36+D37 -> 8074 | E38: =E36+E37 -> 12028 | F38: =F36+F37 -> 22383 | G38: =G36+G37 -> 27918 | H38: =H36+H37 -> 28219
B39: Total liabilities, redeemable non-controlling interests and equity | C39: =C31+C32+C38 -> 38774 | D39: =D31+D32+D38 -> 32109 | E39: =E31+E32+E38 -> 38699 | F39: =F31+F32+F38 -> 51244 | G39: =G31+G32+G38 -> 61802 | H39: =H31+H32+H38 -> 65801
B40: Check (Assets less Liab. & Equity) | C40: =C19-C39 -> 0 | D40: =D19-D39 -> 0 | E40: =E19-E39 -> 0 | F40: =F19-F39 -> 0 | G40: =G19-G39 -> 0 | H40: =H19-H39 -> 0

Sheet CFS
B2: Cash Flow Statement | C2: FY'21 | D2: FY'22 | E2: FY'23 | F2: FY'24 | G2: FY'25 | H2: FY'26 (1/2)
B3: Net income including non-controlling interests | C3: -570 | D3: -9138 | E3: 2156 | F3: 9845 | G3: 10093 | H3: 2698
B4: Depreciation and amortization | C4: 902 | D4: 947 | E4: 823 | F4: 737 | G4: 747 | H4: 386
B5: Stock-based compensation | C5: 1168 | D5: 1793 | E5: 1935 | F5: 1796 | G5: 1826 | H5: 0
B6: Deferred income taxes | C6: -692 | D6: -441 | E6: 26 | F6: -6027 | G6: -4779 | H6: 1023
B7: Accretion of discounts on marketable debt securities, net | C7: 0 | D7: 0 | E7: -154 | F7: -251 | G7: -158 | H7: 771
B8: Unrealized (gain) loss on debt and equity securities, net | C8: -1142 | D8: 7045 | E8: -1610 | F8: -1832 | G8: 97 | H8: -138
B9: Unrealized foreign currency transactions | C9: 38 | D9: 96 | E9: 138 | F9: 308 | G9: -120 | H9: -53
B10: Other | C10: -1831 | D10: 5 | E10: 106 | F10: 187 | G10: 166 | H10: 316
B11: Accounts receivable | C11: -597 | D11: -542 | E11: -758 | F11: -142 | G11: -466 | H11: -499
B12: Prepaid expenses and other assets | C12: 624 | D12: -196 | E12: -1462 | F12: -694 | G12: -1028 | H12: -375
B13: Operating lease right-of-use assets | C13: 165 | D13: 193 | E13: 191 | F13: 196 | G13: 177 | H13: 100
B14: Accounts payable | C14: 90 | D14: -133 | E14: 64 | F14: 86 | G14: 126 | H14: 345
... B17: Operating lease liabilities | C17: -184 | D17: -215 | E17: -180 | F17: -221 | G17: -209 | H17: -97
B18: Net cash provided by operating activities | C18: =SUM(C3:C17) -> -445 | D18: =SUM(D3:D17) -> 642 | E18: =SUM(E3:E17) -> 3585 | F18: =SUM(F3:F17) -> 7137 | G18: =SUM(G3:G17) -> 10099 | H18: =SUM(H3:H17) -> 5213
B20: Purchases of property and equipment | C20: -298 | D20: -252 | E20: -223 | F20: -242 | G20: -336 | H20: -135
B21: Purchases of non-marketable equity securities | C21: -982 | D21: -14 | E21: -52 | F21: -289 | G21: -676 | H21: -507
B22: Purchases of marketable securities | C22: -1113 | D22: -1708 | E22: -8774 | F22: -12765 | G22: -21447 | H22: -17646
B23: Proceeds from maturities and sales of marketable securities | C23: 2291 | D23: 376 | E23: 5069 | F23: 10204 | G23: 20046 | H23: -298
B24: Proceeds from sale of equity method investments | C24: 1000 | D24: 0 | E24: 721 | F24: 17 | G24: 0 | H24: 14665
B25: Acquisition of businesses, net of cash acquired | C25: -2314 | D25: -59 | E25: 0 | F25: 0 | G25: -815 | H25: -653
B26: Purchase of total return swaps | C26: 0 | D26: 0 | E26: 0 | F26: 0 | G26: 0 | H26: -1640
B27: Other investing activities | C27: 215 | D27: 20 | E27: 33 | F27: -102 | G27: -336 | H27: 52
B28: Net cash used in investing activities | C28: =SUM(C20:C27) -> -1201 | D28: =SUM(D20:D27) -> -1637 | E28: =SUM(E20:E27) -> -3226 | F28: =SUM(F20:F27) -> -3177 | G28: =SUM(G20:G27) -> -3564 | H28: =SUM(H20:H27) -> -6162
B30: Proceeds from the issuance of common stock under the Employee Stock Purchase Plan | C30: 107 | D30: 92 | E30: 130 | F30: 156 | G30: 183 | H30: 3997
B31: Issuance of term loan and notes, net of issuance costs | C31: 1484 | D31: 0 | E31: 2824 | F31: 3972 | G31: 3359 | H31: -2000
B32: Principal repayment on term loan and notes | C32: -27 | D32: 0 | E32: -2675 | F32: -3986 | G32: -2350 | H32: -82
B33: Principal payments on finance leases | C33: -226 | D33: -184 | E33: -171 | F33: -172 | G33: -157 | H33: 136
B34: Repurchases of common stock | C34: 0 | D34: 0 | E34: 0 | F34: -1252 | G34: -6523 | H34: -3529
B35: Redemption of non-controlling interests | C35: 0 | D35: 0 | E35: 0 | F35: -851 | G35: -109 | H35: -73
B36: Other financing activities | C36: 442 | D36: 107 | E36: -203 | F36: 46 | G36: -116 | H36: 0
B37: Net cash used in financing activities | C37: =SUM(C30:C36) -> 1780 | D37: =SUM(D30:D36) -> 15 | E37: =SUM(E30:E36) -> -95 | F37: =SUM(F30:F36) -> -2087 | G37: =SUM(G30:G36) -> -5713 | H37: =SUM(H30:H36) -> -1551
B39: Effect of exchange rate changes on cash and cash equivalents, and restricted cash and cash equivalents | C39: -69 | D39: -148 | E39: 63 | F39: -267 | G39: 215 | H39: 30
B40: Net increase in cash and cash equivalents, and restricted cash and cash equivalents | C40: =C18+C28+C37+C39 -> 65 | D40: =D18+D28+D37+D39 -> -1128 | E40: =E18+E28+E37+E39 -> 327 | F40: =F18+F28+F37+F39 -> 1606 | G40: =G18+G28+G37+G39 -> 1037 | H40: =H18+H28+H37+H39 -> -2470
B41: Beginning of period | C41: 7740 | D41: =C42 -> 7805 | E41: =D42 -> 6677 | F41: =E42 -> 7004 | G41: =F42 -> 8610 | H41: =G42 -> 9647
B42: End of period | C42: =C41+C40 -> 7805 | D42: =D41+D40 -> 6677 | E42: =E41+E40 -> 7004 | F42: =F41+F40 -> 8610 | G42: =G41+G40 -> 9647 | H42: =H41+H40 -> 7177

Sheet DCF
B2: Uber Technologies, Inc. (UBER)
B4: Valuation Date: | F4: =TODAY() -> 46254
B5: Share Price on Valuation Date: | F5: 78
B6: Diluted Shares Outstanding | F6: =Main!C4 -> 2050.23
B7: Stub Period to FY26 Year-End (yrs) | F7: =(DATE(YEAR(F4),12,31)-F4)/365 -> 0.36438356
B8: Select Operating Data
H9: Projected Annual Forecast
C10: FY'21 | D10: FY'22 | E10: FY'23 | F10: FY'24 | G10: FY'25 | H10: FY'26 | I10: FY'27 | J10: FY'28 | K10: FY'29 | L10: FY'30
B11: Revenue | C11: =IS!C17 -> 17455 | D11: =IS!D17 -> 31877 | E11: =IS!E17 -> 37281 | F11: =IS!F17 -> 43978 | G11: =IS!G17 -> 52017 | H11: =IS!H17 -> 59028.95 | I11: =IS!I17 -> 67430.118 | J11: =IS!J17 -> 76161.064 | ... L11: =IS!L17 -> 86549.861
B13: EBIT | C13: =IS!C24+IS!C23-IS!C22 -> -3834 | D13: =IS!D24+IS!D23-IS!D22 -> -1832 | E13: =IS!E24+IS!E23-IS!E22 -> 1110 | F13: =IS!F24+IS!F23-IS!F22 -> 2799 | G13: =IS!G24+IS!G23-IS!G22 -> 5565 | H13: =IS!H24-IS!H22 -> 7062.3071 | I13: =IS!I24-IS!I22 -> 8236.01 | J13: =IS!J24-IS!J22 -> 9904.2217 | K13: =IS!K24-IS!K22 -> 10754.067 | L13: =IS!L24-IS!L22 -> 12337.086
B15: Depreciation & Amortization | C15: =IS!C22 -> 902 | D15: =IS!D22 -> 947 | E15: =IS!E22 -> 823 | F15: =IS!F22 -> 711 | G15: =IS!G22 -> 719 | H15: =H11*(H16) -> 737.86188 | I15: =I11*(I16) -> 674.30118 | J15: =J11*(J16) -> 571.20798 | K15: =K11*(K16) -> 405.68187 | L15: =L11*(L16) -> 432.7493 | N15: Arithmetic Avg | O15: Geometric Avg
C16: =C15/C11 -> 0.051675738 | D16: =D15/D11 -> 0.02970794 | E16: =E15/E11 -> 0.022075588 | F16: =F15/F11 -> 0.016167174 | G16: =G15/G11 -> 0.013822404 | H16: =IS!H10 -> 0.0125 | I16: =IS!I10 -> 0.01 | J16: =IS!J10 -> 0.0075 | K16: =IS!K10 -> 0.005 | L16: =IS!L10 -> 0.005 | N16: =AVERAGE(C16:G16) -> 0.026689769 | O16: =GEOMEAN(C16:G16) -> 0.023760624
B18: Select Balance Sheet And Other Data
H19: Projected Annual Forecast
C20: FY'21 | D20: FY'22 | E20: FY'23 | F20: FY'24 | G20: FY'25 | H20: FY'26 | I20: FY'27 | J20: FY'28 | K20: FY'29 | L20: FY'30
B21: Accounts Receivable | C21: =BS!C6 -> 2439 | D21: =BS!D6 -> 2779 | E21: =BS!E6 -> 3404 | F21: =BS!F6 -> 3333 | G21: =BS!G6 -> 3827 | H21: =H32*H11 -> 4818.0531 | I21: =I32*I11 -> 5503.7721 | J21: =J32*J11 -> 6216.4082 | K21: =K32*K11 -> 6622.5024 | L21: =L32*L11 -> 7064.3612
B22: Inventories | C22: 0 | D22: 0 | E22: 0 | F22: 0 | G22: 0 | H22: =H33*H11 -> 0 | I22: =I33*I11 -> 0 | J22: =J33*J11 -> 0 | K22: =K33*K11 -> 0 | L22: =L33*L11 -> 0
B23: Prepaid Expenses | C23: =BS!C7 -> 1454 | D23: =BS!D7 -> 1479 | E23: =BS!E7 -> 1681 | F23: =BS!F7 -> 1390 | G23: =BS!G7 -> 1902 | H23: =H34*H11 -> 2356.1223 | I23: =I34*I11 -> 2691.4523 | J23: =J34*J11 -> 3039.9453 | K23: =K34*K11 -> 3238.5333 | L23: =L34*L11 -> 3454.6109
B25: Accounts Payable and Accruals | C25: =BS!C21 -> 860 | D25: =BS!D21 -> 728 | E25: =BS!E21 -> 790 | F25: =BS!F21 -> 858 | G25: =BS!G21 -> 1013 | H25: =H35*H11 -> 1225.0331 | I25: =I35*I11 -> 1399.3833 | J25: =J35*J11 -> 1580.5774 | K25: =K35*K11 -> 1683.8305 | L25: =L35*L11 -> 1796.177
B26: Accrued Expenses | C26: =BS!C25 -> 6537 | D26: =BS!D25 -> 6232 | E26: =BS!E25 -> 6458 | F26: =BS!F25 -> 7689 | G26: =BS!G25 -> 7751 | H26: =H36*H11 -> 10173.418 | I26: =I36*I11 -> 11675.067 | J26: =J36*J11 -> 13186.771 | K26: =K36*K11 -> 14048.212 | L26: =L36*L11 -> 14985.52
B28: Debt | C28: =BS!C28+BS!C24 -> 9276 | D28: =BS!D28+BS!D24 -> 9265 | E28: =BS!E28+BS!E24 -> 9459 | F28: =BS!F28+BS!F24 -> 8347 | G28: =BS!G28+BS!G24 -> 10521
B30: Capital Expenditures | C30: =CFS!C20 -> -298 | D30: =CFS!D20 -> -252 | E30: =CFS!E20 -> -223 | F30: =CFS!F20 -> -242 | G30: =CFS!G20 -> -336 | H30: =H37*H11 -> -381.46225 | I30: =I37*I11 -> -435.75304 | J30: =J37*J11 -> -492.17495 | K30: =K37*K11 -> -524.32685 | L30: =L37*L11 -> -559.31038
N31: Arithmetic Mean | O31: Geometric Mean
B32: Accounts Receivable as a % of revenue | C32: =C21/C11 -> 0.13973074 | D32: =D21/D11 -> 0.087178844 | E32: =E21/E11 -> 0.091306564 | F32: =F21/F11 -> 0.075787894 | G32: =G21/G11 -> 0.073572101 | H32: =$O32 -> 0.081621867 | I32: =$O32 -> 0.081621867 | J32: =$O32 -> 0.081621867 | K32: =$O32 -> 0.081621867 | L32: =$O32 -> 0.081621867 | N32: =AVERAGE(D32:G32) -> 0.081961351 | O32: =GEOMEAN(D32:G32) -> 0.081621867
B33: Inventories as a % of revenue | C33: =C22/C11 -> 0 | D33: =D22/D11 -> 0 | E33: =E22/E11 -> 0 | F33: =F22/F11 -> 0 | G33: =G22/G11 -> 0 | H33: =$N33 -> 0 | I33: =$N33 -> 0 | J33: =$N33 -> 0 | K33: =$N33 -> 0 | L33: =$N33 -> 0 | N33: =AVERAGE(D33:G33) -> 0 | O33: =IFERROR(GEOMEAN(D33:G33),"n/a") -> n/a
B34: Prepaid Expenses as a % of revenue | C34: =C23/C11 -> 0.083299914 | D34: =D23/D11 -> 0.046397089 | E34: =E23/E11 -> 0.045089992 | F34: =F23/F11 -> 0.031606712 | G34: =G23/G11 -> 0.036564969 | H34: =$N34 -> 0.039914691 | I34: =$N34 -> 0.039914691 | J34: =$N34 -> 0.039914691 | K34: =$N34 -> 0.039914691 | L34: =$N34 -> 0.039914691 | N34: =AVERAGE(D34:G34) -> 0.039914691 | O34: =GEOMEAN(D34:G34) -> 0.039432459
B35: Accounts Payable/Accruals as a % of revenue | C35: =C25/C11 -> 0.04926955 | D35: =D25/D11 -> 0.022837783 | E35: =E25/E11 -> 0.021190419 | F35: =F25/F11 -> 0.019509755 | G35: =G25/G11 -> 0.019474403 | H35: =$N35 -> 0.02075309 | I35: =$N35 -> 0.02075309 | J35: =$N35 -> 0.02075309 | K35: =$N35 -> 0.02075309 | L35: =$N35 -> 0.02075309 | N35: =AVERAGE(D35:G35) -> 0.02075309 | O35: =GEOMEAN(D35:G35) -> 0.020707485
B36: Accrued Expenses as a % of revenue | C36: =C26/C11 -> 0.37450587 | D36: =D26/D11 -> 0.19550146 | E36: =E26/E11 -> 0.17322497 | F36: =F26/F11 -> 0.17483742 | G36: =G26/G11 -> 0.14900898 | H36: =$O36 -> 0.17234625 | I36: =$N36 -> 0.17314321 | J36: =$N36 -> 0.17314321 | K36: =$N36 -> 0.17314321 | L36: =$N36 -> 0.17314321 | N36: =AVERAGE(D36:G36) -> 0.17314321 | O36: =GEOMEAN(D36:G36) -> 0.17234625
B37: Capital Expenditures as a % of revenue | C37: =C30/C11 -> -0.017072472 | D37: =D30/D11 -> -0.0079053863 | E37: =E30/E11 -> -0.0059815992 | F37: =F30/F11 -> -0.0055027514 | G37: =G30/G11 -> -0.0064594267 | H37: =$N37 -> -0.0064622909 | I37: =$N37 -> -0.0064622909 | J37: =$N37 -> -0.0064622909 | K37: =$N37 -> -0.0064622909 | L37: =$N37 -> -0.0064622909 | N37: =AVERAGE(D37:G37) -> -0.0064622909 | O37: =IFERROR(GEOMEAN(D37:G37),"n/a") -> n/a
B38: Accounts Receivable Growth (%) | D38: =((D21/C21)-1) -> 0.13940139 | E38: =((E21/D21)-1) -> 0.22490104 | F38: =((F21/E21)-1) -> -0.020857814 | G38: =((G21/F21)-1) -> 0.14821482
B39: Inventories Growth (%) | D39: =IFERROR((D22/C22)-1,0) -> 0 | E39: =IFERROR((E22/D22)-1,0) -> 0 | F39: =IFERROR((F22/E22)-1,0) -> 0 | G39: =IFERROR((G22/F22)-1,0) -> 0
B40: Prepaid Expenses Growth (%) | D40: =((D23/C23)-1) -> 0.017193948 | E40: =((E23/D23)-1) -> 0.13657877 | F40: =((F23/E23)-1) -> -0.17311124 | G40: =((G23/F23)-1) -> 0.36834532
B41: Accounts Payable/Accruals Growth (%) | D41: =((D25/C25)-1) -> -0.15348837 | E41: =((E25/D25)-1) -> 0.085164835 | F41: =((F25/E25)-1) -> 0.086075949 | G41: =((G25/F25)-1) -> 0.18065268
B42: Accrued Expenses Growth (%) | D42: =((D26/C26)-1) -> -0.046657488 | E42: =((E26/D26)-1) -> 0.036264442 | F42: =((F26/E26)-1) -> 0.19061629 | G42: =((G26/F26)-1) -> 0.0080634673
B43: Capital Expenditures Growth (%) | D43: =((D30/C30)-1) -> -0.15436242 | E43: =((E30/D30)-1) -> -0.11507937 | F43: =((F30/E30)-1) -> 0.085201794 | G43: =((G30/F30)-1) -> 0.38842975
B45: Free Cash Flow Buildup
B46: $mm | H46: Projected Annual Forecast
C47: FY'21 | D47: FY'22 | E47: FY'23 | F47: FY'24 | G47: FY'25 | H47: FY'26 | I47: FY'27 | J47: FY'28 | K47: FY'29 | L47: FY'30
B48: Period | H48: =$F$7/2 -> 0.18219178 | I48: =$F$7+0.5 -> 0.86438356 | J48: =$F$7+1.5 -> 1.8643836 | K48: =$F$7+2.5 -> 2.8643836 | L48: =$F$7+3.5 -> 3.8643836
B49: Total Revenues | C49: =C11 -> 17455 | D49: =D11 -> 31877 | E49: =E11 -> 37281 | F49: =F11 -> 43978 | G49: =G11 -> 52017 | H49: =H11 -> 59028.95 | I49: =I11 -> 67430.118 | J49: =J11 -> 76161.064 | ... L49: =L11 -> 86549.861
...
